# Cursed Village Plot
# MC 1.7.10; 8 Nov 2014
# Created by Ruins mod version 14.2 Ingame Parser
# authoring Player: Kujaku10

weight=1
embed_into_distance=0
acceptable_target_blocks=
unacceptable_target_blocks=flowing_water,water,flowing_lava,lava
dimensions=3,9,13
allowable_overhang=0
max_leveling=8
leveling_buffer=0
preserve_water=0
preserve_lava=0
preserve_plants=1

rule1=0,100,minecraft:log-0
rule2=0,100,minecraft:dirt,minecraft:farmland-4,minecraft:farmland-7,minecraft:farmland-1,minecraft:grass,minecraft:sand
rule3=0,100,minecraft:water-0
rule4=0,75,minecraft:tallgrass-1,minecraft:wheat-7
rule5=0,100,minecraft:double_plant-2
rule6=0,100,minecraft:double_plant-8
rule7=0,100,minecraft:double_plant-11
rule8=0,100,minecraft:double_plant-9

layer
1,1,1,1,1,1,1,1,1,1,1,1,1
1,2,2,3,2,2,1,2,2,3,2,2,1
1,2,2,3,2,2,1,2,2,3,2,2,1
1,2,2,3,2,2,1,2,2,3,2,2,1
1,2,2,3,2,2,1,2,2,3,2,2,1
1,2,2,3,2,2,1,2,2,3,2,2,1
1,2,2,3,2,2,1,2,2,3,2,2,1
1,2,2,3,2,2,1,2,2,3,2,2,1
1,1,1,1,1,1,1,1,1,1,1,1,1
endlayer

layer
0,0,0,0,0,0,0,0,0,0,0,0,0
0,4,4,0,4,4,0,4,4,0,5,4,0
0,4,4,0,4,5,0,4,4,0,4,5,0
0,5,4,0,4,4,0,4,5,0,4,4,0
0,4,4,0,4,4,0,4,4,0,4,4,0
0,4,4,0,4,4,0,5,4,0,4,4,0
0,4,4,0,5,4,0,4,4,0,4,4,0
0,4,4,0,4,4,0,4,4,0,4,5,0
0,0,0,0,0,0,0,0,0,0,0,0,0
endlayer

layer
0,0,0,0,0,0,0,0,0,0,0,0,0
0,0,0,0,0,0,0,0,0,0,6,0,0
0,0,0,0,0,7,0,0,0,0,0,6,0
0,7,0,0,0,0,0,0,8,0,0,0,0
0,0,0,0,0,0,0,0,0,0,0,0,0
0,0,0,0,0,0,0,7,0,0,0,0,0
0,0,0,0,7,0,0,0,0,0,0,0,0
0,0,0,0,0,0,0,0,0,0,0,6,0
0,0,0,0,0,0,0,0,0,0,0,0,0
endlayer

