# Cursed Village Pig Pen
# MC 1.7.10; 8 Nov 2014
# Created by Ruins mod version 14.2 Ingame Parser
# authoring Player: Kujaku10
# Special Instructions: Place in /templateparser folder.

weight=1
embed_into_distance=1
acceptable_target_blocks=
unacceptable_target_blocks=flowing_water,water,flowing_lava,lava
dimensions=7,12,9
allowable_overhang=0
max_leveling=6
leveling_buffer=0
preserve_water=0
preserve_lava=0
preserve_plants=1

rule1=0,100,minecraft:dirt-0,minecraft:grass,minecraft:mycelium,minecraft:sand,minecraft:gravel
rule2=0,100,minecraft:cobblestone,minecraft:cobblestone,minecraft:mossy_cobblestone,minecraft:monster_egg-1
rule3=0,100,minecraft:planks-0
rule4=0,100,minecraft:planks-0,minecraft:wooden_slab,minecraft:grass
rule5=0,100,minecraft:double_stone_slab-0
rule6=0,100,minecraft:gravel-0
rule7=1,95,minecraft:fence-0
rule8=0,90,minecraft:oak_stairs-1
rule9=0,90,minecraft:oak_stairs-3
rule10=0,100,minecraft:web-0
rule11=0,50,minecraft:glass_pane-0
rule12=0,100,minecraft:log-0
rule13=1,90,minecraft:wooden_pressure_plate-0
rule14=0,90,minecraft:oak_stairs-0

layer
1,1,1,1,1,1,1,1,1
1,1,1,1,1,1,1,1,1
1,1,1,1,1,1,1,1,1
1,1,1,1,1,1,1,1,1
1,1,2,1,1,1,1,1,1
2,2,2,2,2,2,2,2,2
2,4,4,4,4,4,4,3,2
2,5,5,5,4,4,4,4,2
2,5,5,5,4,4,4,4,2
2,5,5,5,4,4,4,4,2
2,2,2,2,2,2,2,2,2
6,6,6,6,6,6,6,6,6
endlayer

layer
7,7,7,7,7,7,7,0,0
7,0,0,0,0,0,7,0,0
7,0,0,0,0,0,7,0,0
7,0,0,0,0,0,7,0,0
7,0,0,0,0,0,7,0,0
2,2,0,2,2,2,2,2,2
2,0,0,0,0,0,8,3,2
2,0,0,0,0,0,7,9,2
2,0,5,0,0,0,0,0,2
2,10,5,0,0,0,0,0,2
2,2,2,2,2,2,0,2,2
0,0,0,0,0,0,0,0,0
endlayer

layer
0,0,0,0,0,0,0,0,0
0,0,0,0,0,0,0,0,0
0,0,0,0,0,0,0,0,0
0,0,0,0,0,0,0,0,0
0,0,0,0,0,0,0,0,0
2,3,0,3,3,11,11,3,2
12,0,0,0,0,0,0,0,12
11,0,0,0,0,0,13,0,11
11,0,0,0,0,0,0,0,11
12,0,0,0,0,0,0,0,12
2,3,3,11,3,3,0,3,2
0,0,0,0,0,0,0,0,0
endlayer

layer
0,0,0,0,0,0,0,0,0
0,0,0,0,0,0,0,0,0
0,0,0,0,0,0,0,0,0
0,0,0,0,0,0,0,0,0
14,14,14,14,14,14,14,14,14
2,3,3,3,3,3,3,3,2
2,10,0,0,10,0,0,10,2
2,0,0,0,0,0,0,0,2
2,0,0,0,0,0,0,0,2
2,10,0,0,0,0,0,10,2
2,3,3,3,3,3,3,3,2
8,8,8,8,8,8,8,8,8
endlayer

layer
0,0,0,0,0,0,0,0,0
0,0,0,0,0,0,0,0,0
0,0,0,0,0,0,0,0,0
0,0,0,0,0,0,0,0,0
0,0,0,0,0,0,0,0,0
14,14,14,14,14,14,14,14,14
3,3,3,3,3,3,3,3,3
3,10,0,0,0,0,0,0,3
3,0,0,10,10,0,0,10,3
3,3,3,3,3,3,3,3,3
8,8,8,8,8,8,8,8,8
0,0,0,0,0,0,0,0,0
endlayer

layer
0,0,0,0,0,0,0,0,0
0,0,0,0,0,0,0,0,0
0,0,0,0,0,0,0,0,0
0,0,0,0,0,0,0,0,0
0,0,0,0,0,0,0,0,0
0,0,0,0,0,0,0,0,0
14,14,14,14,14,14,14,14,14
3,3,3,3,3,3,3,3,3
3,3,3,3,3,3,3,3,3
8,8,8,8,8,8,8,8,8
0,0,0,0,0,0,0,0,0
0,0,0,0,0,0,0,0,0
endlayer

layer
0,0,0,0,0,0,0,0,0
0,0,0,0,0,0,0,0,0
0,0,0,0,0,0,0,0,0
0,0,0,0,0,0,0,0,0
0,0,0,0,0,0,0,0,0
0,0,0,0,0,0,0,0,0
0,0,0,0,0,0,0,0,0
14,14,14,14,14,14,14,14,14
8,8,8,8,8,8,8,8,8
0,0,0,0,0,0,0,0,0
0,0,0,0,0,0,0,0,0
0,0,0,0,0,0,0,0,0
endlayer

