# Cursed Village Library
# MC 1.7.10; 8 Nov 2014
# Created by Ruins mod version 14.2 Ingame Parser
# authoring Player: Kujaku10
# Special Instructions: Place in /templateparser folder.

weight=1
embed_into_distance=1
acceptable_target_blocks=
unacceptable_target_blocks=flowing_water,water,flowing_lava,lava
dimensions=9,8,9
allowable_overhang=0
max_leveling=8
leveling_buffer=0
preserve_water=0
preserve_lava=0
preserve_plants=1

rule1=0,100,minecraft:dirt-0
rule2=0,100,minecraft:cobblestone,minecraft:cobblestone,minecraft:mossy_cobblestone,minecraft:monster_egg-1,minecraft:gravel
rule3=0,100,minecraft:gravel-0
rule4=0,100,minecraft:planks-0
rule5=0,90,minecraft:oak_stairs-1
rule6=0,100,minecraft:web-0
rule7=0,90,minecraft:oak_stairs-3
rule8=1,90,minecraft:fence-0
rule9=0,100,CommandBlock:RUINSTRIGGER /summon Zombie ~0 ~0 ~0 {Equipment:[{Count:1,id:340,tag:{display:{Name:Battered Tome},ench:[{id:18,lvl:5},{id:19,lvl:2},{id:17,lvl:5}]}},{},{},{},{Count:1,id:298,tag:{display:{Name:Skullcap}}}],CustomName:Zombie Librarian,DropChances:[2.0F,0.0F,0.0F,0.0F,0.2F],PersistenceRequired:1,CanBreakDoors:1,IsVillager:1}:@
rule10=0,90,minecraft:crafting_table-0
rule11=0,50,minecraft:glass_pane-0
rule12=1,90,minecraft:wooden_pressure_plate-0
rule13=0,90,minecraft:bookshelf-0
rule14=0,90,minecraft:oak_stairs-0

layer
1,1,1,1,1,1,1,1,1
2,2,2,2,2,2,2,2,2
2,2,2,2,2,2,2,2,2
2,2,2,2,2,2,2,2,2
2,2,2,2,2,2,2,2,2
2,2,2,2,2,2,2,2,2
2,2,2,2,2,2,2,2,2
3,3,3,3,3,3,3,3,3
endlayer

layer
0,0,0,0,0,0,0,0,0
2,2,2,2,2,2,2,2,2
2,6,0,5,5,5,5,4,2
2,0,0,0,8,0,8,7,2
2,9,0,0,0,0,0,6,2
2,0,0,0,0,0,0,10,2
2,0,2,2,2,2,2,2,2
0,0,0,0,0,0,0,0,0
endlayer

layer
0,0,0,0,0,0,0,0,0
2,4,11,11,4,11,11,4,2
4,6,0,0,0,0,0,6,4
11,0,0,0,12,0,12,0,11
11,0,0,0,0,0,0,0,11
4,0,0,0,0,0,0,0,4
2,0,4,4,11,11,11,4,2
0,0,0,0,0,0,0,0,0
endlayer

layer
0,0,0,0,0,0,0,0,0
2,4,4,4,4,4,4,4,2
4,13,13,13,13,13,13,13,4
11,0,0,0,0,0,0,0,11
11,0,0,0,0,0,0,0,11
4,6,0,0,0,0,0,6,4
2,4,4,4,11,11,11,4,2
0,0,0,0,0,0,0,0,0
endlayer

layer
0,0,0,0,0,0,0,0,0
2,4,4,4,4,4,4,4,2
4,4,4,4,4,4,4,4,4
4,6,0,0,0,0,0,6,4
4,6,0,0,6,0,0,0,4
4,4,4,4,4,4,4,4,4
2,4,4,4,4,4,4,4,2
0,0,0,0,0,0,0,0,0
endlayer

layer
14,14,14,14,14,14,14,14,14
2,2,2,2,2,2,2,2,2
2,2,2,2,2,2,2,2,2
2,2,2,2,2,2,2,2,2
2,2,2,2,2,2,2,2,2
2,2,2,2,2,2,2,2,2
2,2,2,2,2,2,2,2,2
5,5,5,5,5,5,5,5,5
endlayer

layer
0,0,0,0,0,0,0,0,0
14,14,14,14,14,14,14,14,14
2,2,2,2,2,2,2,2,2
2,2,2,2,2,2,2,2,2
2,2,2,2,2,2,2,2,2
2,2,2,2,2,2,2,2,2
5,5,5,5,5,5,5,5,5
0,0,0,0,0,0,0,0,0
endlayer

layer
0,0,0,0,0,0,0,0,0
0,0,0,0,0,0,0,0,0
14,14,14,14,14,14,14,14,14
2,2,2,2,2,2,2,2,2
2,2,2,2,2,2,2,2,2
5,5,5,5,5,5,5,5,5
0,0,0,0,0,0,0,0,0
0,0,0,0,0,0,0,0,0
endlayer

layer
0,0,0,0,0,0,0,0,0
0,0,0,0,0,0,0,0,0
0,0,0,0,0,0,0,0,0
14,14,14,14,14,14,14,14,14
5,5,5,5,5,5,5,5,5
0,0,0,0,0,0,0,0,0
0,0,0,0,0,0,0,0,0
0,0,0,0,0,0,0,0,0
endlayer

