# Fletchery Shoppe
# MC 1.7.10; 25 Oct 2014
# Created by Ruins mod version 13.8 Ingame Parser
# authoring Player: Jordan_Greywolf

biomesToSpawnIn=forest,foresthills,extreme hills edge,birch forest,plains,taiga,mega spruce taiga

weight=1
embed_into_distance=0
acceptable_target_blocks=
unacceptable_target_blocks=flowing_lava,lava
dimensions=17,12,12
allowable_overhang=25
max_leveling=5
leveling_buffer=0
preserve_water=0
preserve_lava=0
preserve_plants=1

rule1=0,100,minecraft:grass-0
rule2=0,100,minecraft:dirt-0
rule3=0,100,minecraft:cobblestone-0
rule4=0,100,minecraft:oak_stairs-3
rule5=0,100,minecraft:stone_slab-0
rule6=0,100,minecraft:planks-0
rule7=0,100,minecraft:oak_stairs-0
rule8=0,100,minecraft:oak_stairs-5
rule9=0,100,minecraft:fence-0
rule10=0,100,IInventory;minecraft:chest;minecraft:arrow#8#0#0+minecraft:string#6#0#1+minecraft:bow#1#214#2+minecraft:stick#5#0#3+minecraft:log#3#0#4-3
rule11=0,100,minecraft:ladder-2
rule12=1,100,minecraft:torch-5
rule13=0,100,minecraft:cobblestone_wall-0
rule14=0,100,minecraft:stone_stairs-0
rule15=0,100,minecraft:log-4
rule16=0,100,minecraft:stone_stairs-4
rule17=0,100,minecraft:stone_stairs-5
rule18=0,100,minecraft:wooden_slab-8
rule19=0,100,minecraft:stone_slab-11
rule20=0,100,minecraft:stone_stairs-2
rule21=0,100,minecraft:spruce_stairs-0
rule22=1,100,minecraft:wooden_door-2
rule23=0,100,minecraft:fence_gate-2
rule24=0,100,minecraft:stone_stairs-6
rule25=0,100,minecraft:carpet-14
rule26=1,100,minecraft:wooden_door-8
rule27=2,100,WallSign:--*--:Fletcher's:Shoppe:--*---5
rule28=0,100,minecraft:oak_stairs-4
rule29=0,100,minecraft:oak_stairs-6
rule30=0,100,minecraft:oak_stairs-7
rule31=0,100,minecraft:log-0
rule32=0,100,minecraft:log-8
rule33=0,100,minecraft:stained_hardened_clay-8
rule34=0,100,minecraft:stained_glass_pane-1
rule35=2,100,minecraft:ladder-3
rule36=0,100,minecraft:lit_furnace-3
rule37=0,100,minecraft:spruce_stairs-5
rule38=0,100,minecraft:wooden_slab-9
rule39=0,100,minecraft:spruce_stairs-4
rule40=2,100,minecraft:trapdoor-10
rule41=0,100,CommandBlock:RUINSTRIGGER /summon Villager ~0 ~0 ~0 {Profession:2,CustomName:FLETCHER,CustomNameVisible:1,Offers:{Recipes:[{maxUses:1000,buy:{id:388,Count:1},sell:{id:262,Count:24}},{maxUses:50,buy:{id:288,Count:64},sell:{id:388,Count:1}},{maxUses:50,buy:{id:318,Count:64},sell:{id:388,Count:1}},{maxUses:50,buy:{id:287,Count:20},sell:{id:388,Count:1}},{maxUses:1000,buy:{id:261,Count:1},sell:{id:287,Count:3}},{maxUses:1000,buy:{id:263,Count:64},sell:{id:388,Count:1}},{maxUses:1000,buy:{id:388,Count:25},buyB:{id:261,Count:1},sell:{id:261,Count:1,tag:{ench:[{id:48,lvl:5},{id:50,lvl:10},{id:51,lvl:1},{id:21,lvl:3},{id:34,lvl:10}],display:{Name:"Fiery Sun Bow of Ra"}}}}]}}:@
rule42=0,100,minecraft:crafting_table-0
rule43=0,100,minecraft:bookshelf-0
rule44=0,100,minecraft:stained_glass_pane-4
rule45=0,100,minecraft:flower_pot-0
rule46=2,100,minecraft:torch-4
rule47=2,100,minecraft:trapdoor-14
rule48=2,100,minecraft:trapdoor-12
rule49=0,100,minecraft:glowstone-0
rule50=2,100,minecraft:trapdoor-13
rule51=2,100,minecraft:trapdoor-15
rule52=0,100,minecraft:double_stone_slab-0
rule53=2,100,minecraft:trapdoor-2
rule54=0,100,minecraft:wooden_slab-0
rule55=0,100,minecraft:oak_stairs-2
rule56=0,100,minecraft:oak_stairs-1

layer
0,0,0,1,1,1,1,1,1,0,0,0
0,0,1,1,2,2,2,2,1,1,0,0
0,1,1,3,3,3,3,3,2,1,1,0
1,2,3,5,5,5,5,4,3,2,1,1
1,2,3,5,5,5,5,6,3,2,1,1
1,2,3,5,5,5,5,5,3,2,2,1
1,2,3,5,5,5,5,5,3,2,2,1
1,2,3,5,5,5,5,6,3,2,1,1
1,2,2,3,3,3,3,3,2,2,1,1
0,1,2,2,2,2,2,2,2,2,1,0
0,0,1,2,2,2,2,2,1,1,0,0
0,0,0,1,3,1,1,3,1,0,0,0
endlayer

layer
0,0,0,0,0,0,0,0,0,0,0,0
0,0,0,0,1,1,1,1,0,0,0,0
0,0,0,3,3,3,3,3,1,0,0,0
0,1,3,0,0,0,0,0,3,1,0,0
0,1,3,0,0,0,0,7,3,1,0,0
0,1,3,9,0,0,0,8,3,1,1,0
0,1,3,0,0,0,0,0,3,1,1,0
0,1,3,0,0,0,0,10,3,1,0,0
0,1,1,3,3,3,3,3,2,1,0,0
0,0,1,2,2,2,2,2,1,1,0,0
0,0,0,1,1,1,1,6,11,0,0,0
0,0,0,0,3,0,0,3,0,0,0,0
endlayer

layer
0,0,0,0,0,0,0,0,0,0,0,0
0,0,0,0,0,0,0,0,0,0,0,0
0,0,0,3,3,3,3,3,0,0,0,0
0,0,3,0,0,0,0,0,3,0,0,0
0,0,3,0,0,0,0,0,3,0,0,0
0,0,3,12,0,0,0,7,3,0,0,0
0,0,3,0,0,0,0,8,3,0,0,0
0,0,3,0,0,0,0,0,3,0,0,0
0,0,0,3,3,3,3,3,1,0,0,0
0,0,0,1,1,1,1,1,0,0,0,0
0,0,0,0,0,0,0,6,11,0,0,0
0,0,0,0,13,0,0,13,0,0,0,0
endlayer

layer
0,0,0,0,0,0,0,0,0,0,0,0
0,0,0,0,0,0,0,0,0,0,0,0
0,0,0,3,3,3,3,3,0,0,0,0
0,0,3,0,0,0,0,0,3,0,0,0
0,0,3,0,0,0,0,0,3,0,0,0
0,0,3,0,0,0,0,0,14,0,0,0
0,0,3,0,0,0,0,7,3,0,0,0
0,0,3,0,0,0,0,8,3,0,0,0
0,0,0,3,3,3,3,3,0,0,0,0
0,0,0,0,0,0,0,0,0,0,0,0
0,0,0,0,0,0,0,6,11,0,0,0
0,0,0,0,13,0,0,13,0,0,0,0
endlayer

layer
0,0,0,0,0,0,0,0,0,0,0,0
0,0,0,0,0,0,0,0,0,0,0,0
0,0,0,3,3,3,3,3,0,0,0,0
0,0,3,15,15,15,15,0,3,0,0,0
0,0,3,15,15,15,15,0,3,0,0,0
0,0,3,15,15,15,15,0,16,0,0,0
0,0,3,15,15,15,15,0,3,0,0,0
0,0,3,15,15,15,15,7,3,0,0,0
0,0,0,3,3,3,3,3,0,0,0,0
0,0,0,0,17,18,18,17,0,0,0,0
0,0,0,0,16,18,18,3,11,0,0,0
0,0,0,0,3,19,19,3,0,0,0,0
endlayer

layer
0,0,0,0,0,0,0,0,0,0,0,0
0,0,0,0,0,0,0,0,0,0,0,0
0,0,0,3,3,20,3,3,0,0,0,0
0,0,3,0,0,0,0,4,3,0,0,0
0,0,3,0,0,0,9,8,3,0,0,0
0,0,14,0,0,0,9,0,3,0,0,0
0,0,3,9,0,0,9,0,3,0,0,0
0,0,3,21,0,0,0,0,3,0,0,0
0,0,0,3,3,22,3,3,0,0,0,0
0,0,0,0,9,0,0,9,0,0,0,0
0,0,0,0,9,0,0,23,0,0,0,0
0,0,0,0,9,9,9,9,0,0,0,0
endlayer

layer
0,0,0,0,0,0,0,0,0,0,0,0
0,0,0,0,0,0,0,0,0,0,0,0
0,0,0,3,3,24,3,3,0,0,0,0
0,0,3,0,0,0,0,0,3,0,0,0
0,0,3,0,0,0,12,7,3,0,0,0
0,0,16,0,0,0,0,8,3,0,0,0
0,0,3,25,0,0,12,0,3,0,0,0
0,0,3,0,0,0,0,0,3,0,0,0
0,0,0,3,3,26,3,3,0,0,0,0
0,0,0,0,0,0,27,0,0,0,0,0
0,0,0,0,0,0,0,0,0,0,0,0
0,0,0,0,12,0,0,12,0,0,0,0
endlayer

layer
0,0,0,0,0,0,0,0,0,0,0,0
0,0,0,0,28,0,28,0,0,0,0,0
0,0,0,3,3,3,3,3,0,0,0,0
0,0,3,0,0,0,0,0,3,0,0,0
0,30,3,0,0,0,0,0,3,29,0,0
0,0,3,0,0,0,0,7,3,0,0,0
0,30,3,0,0,0,0,8,3,29,0,0
0,0,3,0,0,0,0,0,3,0,0,0
0,0,0,3,3,3,3,3,0,0,0,0
0,0,0,0,8,0,8,0,0,0,0,0
0,0,0,0,0,0,0,0,0,0,0,0
0,0,0,0,0,0,0,0,0,0,0,0
endlayer

layer
0,0,0,0,0,0,0,0,0,0,0,0
0,31,32,32,32,32,32,32,32,31,0,0
0,15,6,6,6,6,6,6,6,15,0,0
0,15,6,6,6,6,6,0,6,15,0,0
0,15,6,6,6,6,6,0,6,15,0,0
0,15,6,6,6,6,6,0,6,15,0,0
0,15,6,6,6,6,6,7,6,15,0,0
0,15,6,6,6,6,6,6,6,15,0,0
0,15,6,6,6,6,6,6,6,15,0,0
0,31,32,32,32,32,32,32,32,31,0,0
0,0,0,0,0,0,0,0,0,0,0,0
0,0,0,0,0,0,0,0,0,0,0,0
endlayer

layer
0,0,0,0,0,0,0,0,0,0,0,0
0,31,33,31,33,34,33,31,33,31,0,0
0,33,37,0,36,0,0,0,35,33,0,0
0,31,38,0,37,0,0,0,0,31,0,0
0,33,39,0,38,0,0,0,0,33,0,0
0,34,0,0,38,0,0,0,0,34,0,0
0,33,21,0,39,0,0,0,0,33,0,0
0,31,41,0,40,0,0,0,0,31,0,0
0,33,43,0,42,0,21,21,0,33,0,0
0,31,33,31,33,34,33,31,33,31,0,0
0,0,0,0,0,0,0,0,0,0,0,0
0,0,0,0,0,0,0,0,0,0,0,0
endlayer

layer
0,0,0,0,0,0,0,0,0,0,0,0
0,31,33,31,33,44,33,31,33,31,0,0
0,33,0,0,13,0,0,0,35,33,0,0
0,31,25,0,0,0,0,0,0,31,0,0
0,33,45,0,0,0,0,0,0,33,0,0
0,44,0,0,0,0,0,0,0,44,0,0
0,33,0,0,0,0,0,0,0,33,0,0
0,31,46,0,0,0,0,0,0,31,0,0
0,33,43,0,0,0,0,0,0,33,0,0
0,31,33,31,33,44,33,31,33,31,0,0
0,0,0,0,0,0,0,0,0,0,0,0
0,0,0,0,0,0,0,0,0,0,0,0
endlayer

layer
0,0,0,0,0,0,0,0,0,0,0,0
0,31,33,31,33,34,33,31,33,31,0,0
0,33,0,9,13,0,0,0,35,33,0,0
0,31,0,9,0,0,0,0,0,31,0,0
0,33,0,9,0,47,0,0,0,33,0,0
0,34,0,9,50,49,48,0,0,34,0,0
0,33,0,9,0,51,0,0,0,33,0,0
0,31,0,9,0,0,0,0,0,31,0,0
0,33,0,9,0,0,0,0,0,33,0,0
0,31,33,31,33,34,33,31,33,31,0,0
0,0,0,0,0,0,0,0,0,0,0,0
0,0,0,0,0,0,0,0,0,0,0,0
endlayer

layer
0,0,0,0,0,0,0,0,0,0,0,0
0,31,32,32,32,32,32,32,32,31,0,0
0,15,18,18,52,6,18,18,35,15,0,0
0,15,18,18,18,6,18,18,18,15,0,0
0,15,18,18,18,6,18,18,18,15,0,0
0,15,6,6,6,6,6,6,6,15,0,0
0,15,18,18,18,6,18,18,18,15,0,0
0,15,18,18,18,6,18,18,18,15,0,0
0,15,18,18,18,6,18,18,18,15,0,0
0,31,32,32,32,32,32,32,32,31,0,0
0,0,0,0,0,0,0,0,0,0,0,0
0,0,0,0,0,0,0,0,0,0,0,0
endlayer

layer
0,0,0,0,0,0,0,0,0,0,0,0
0,9,9,9,9,9,9,9,9,9,0,0
0,9,0,0,36,0,0,0,53,9,0,0
0,9,0,0,0,0,0,0,54,9,0,0
0,9,0,0,9,9,9,0,0,9,0,0
0,9,0,0,0,35,42,0,0,9,0,0
0,9,0,0,9,9,9,0,0,9,0,0
0,9,0,0,0,0,0,0,0,9,0,0
0,9,0,0,0,0,0,0,0,9,0,0
0,9,9,9,9,9,9,9,9,9,0,0
0,0,0,0,0,0,0,0,0,0,0,0
0,0,0,0,0,0,0,0,0,0,0,0
endlayer

layer
0,0,0,0,0,0,0,0,0,0,0,0
0,0,0,0,0,0,0,0,0,0,0,0
0,0,0,0,13,0,0,0,0,0,0,0
0,0,0,0,0,0,0,0,0,0,0,0
0,0,0,0,9,12,9,0,0,0,0,0
0,0,0,0,0,35,6,0,0,0,0,0
0,0,0,0,9,12,9,0,0,0,0,0
0,0,0,0,0,0,0,0,0,0,0,0
0,0,0,0,0,0,0,0,0,0,0,0
0,0,0,0,0,0,0,0,0,0,0,0
0,0,0,0,0,0,0,0,0,0,0,0
0,0,0,0,0,0,0,0,0,0,0,0
endlayer

layer
0,0,0,0,0,0,0,0,0,0,0,0
0,0,0,0,0,0,0,0,0,0,0,0
0,0,0,0,13,0,0,0,0,0,0,0
0,0,0,0,7,7,7,0,0,0,0,0
0,0,0,4,9,9,9,55,0,0,0,0
0,0,0,4,9,35,6,55,0,0,0,0
0,0,0,4,9,9,9,55,0,0,0,0
0,0,0,0,56,56,56,0,0,0,0,0
0,0,0,0,0,0,0,0,0,0,0,0
0,0,0,0,0,0,0,0,0,0,0,0
0,0,0,0,0,0,0,0,0,0,0,0
0,0,0,0,0,0,0,0,0,0,0,0
endlayer

layer
0,0,0,0,0,0,0,0,0,0,0,0
0,0,0,0,0,0,0,0,0,0,0,0
0,0,0,0,0,0,0,0,0,0,0,0
0,0,0,0,0,0,0,0,0,0,0,0
0,0,0,0,54,54,54,0,0,0,0,0
0,0,0,0,54,53,54,0,0,0,0,0
0,0,0,0,54,54,54,0,0,0,0,0
0,0,0,0,0,0,0,0,0,0,0,0
0,0,0,0,0,0,0,0,0,0,0,0
0,0,0,0,0,0,0,0,0,0,0,0
0,0,0,0,0,0,0,0,0,0,0,0
0,0,0,0,0,0,0,0,0,0,0,0
endlayer

