# DesertIsland
# 13 Mar 2014; updated to 1.7.10, 9 Oct 2014
# Created by Ruins mod version 12.3 Ingame Parser
# authoring Player: Jordan_Greywolf

biomesToSpawnIn=ocean,deep ocean,desert
weight=1
embed_into_distance=34

acceptable_target_blocks=water,flowing_water,sand,dirt,gravel,stone,sandstone,grass
unacceptable_target_blocks=lava,flowing_lava
dimensions=46,12,12

allowable_overhang=0
max_cut_in=0
cut_in_buffer=0
max_leveling=30
leveling_buffer=0
preserve_water=0
preserve_lava=0
preserve_plants=0

rule1=0,100,PreserveBlock
rule2=0,100,minecraft:sand-0
rule3=0,100,minecraft:dirt-0
rule4=0,100,minecraft:sandstone-0
rule5=0,100,minecraft:grass-0
rule6=0,100,minecraft:log-3
rule7=0,100,minecraft:tallgrass-1,minecraft:tallgrass-0
rule8=0,100,minecraft:log-15
rule9=0,100,minecraft:leaves-7

layer
1,1,1,4,4,4,4,4,4,4,4,1
1,1,4,4,4,4,4,4,4,4,4,4
1,4,4,4,4,4,4,4,4,4,4,4
1,4,4,4,4,4,4,4,4,4,4,4
4,4,4,4,4,4,4,4,4,4,4,4
4,4,4,4,4,4,4,4,4,4,4,4
4,4,4,4,4,4,4,4,4,4,4,4
4,4,4,4,4,4,4,4,4,4,4,4
4,4,4,4,4,4,4,4,4,4,4,4
1,4,4,4,4,4,4,4,4,4,4,1
1,1,4,4,4,4,4,4,4,4,1,1
1,1,1,1,4,4,4,4,1,1,1,1
endlayer

layer
1,1,1,2,2,2,2,2,2,2,2,1
1,1,2,2,2,2,2,2,2,2,2,2
1,2,2,2,2,2,2,2,2,2,2,2
1,2,2,2,2,2,2,2,2,2,2,2
2,2,2,2,2,2,2,2,2,2,2,2
2,2,2,2,2,2,2,2,2,2,2,2
2,2,2,2,2,2,2,2,2,2,2,2
2,2,2,2,2,2,2,2,2,2,2,2
2,2,2,2,2,2,2,2,2,2,2,2
1,2,2,2,2,2,2,2,2,2,2,1
1,1,2,2,2,2,2,2,2,2,1,1
1,1,1,1,2,2,2,2,1,1,1,1
endlayer

layer
1,1,1,2,2,2,2,2,2,2,2,1
1,1,2,2,2,2,2,2,2,2,2,2
1,2,2,2,2,2,2,2,2,2,2,2
1,2,2,2,2,2,2,2,2,2,2,2
2,2,2,2,2,2,2,2,2,2,2,2
2,2,2,2,2,2,2,2,2,2,2,2
2,2,2,2,2,2,2,2,2,2,2,2
2,2,2,2,2,2,2,2,2,2,2,2
2,2,2,2,2,2,2,2,2,2,2,2
1,2,2,2,2,2,2,2,2,2,2,1
1,1,2,2,2,2,2,2,2,2,1,1
1,1,1,1,2,2,2,2,1,1,1,1
endlayer

layer
1,1,1,2,2,2,2,2,2,2,2,1
1,1,2,2,2,2,2,2,2,2,2,2
1,2,2,2,2,2,2,2,2,2,2,2
1,2,2,2,2,2,2,2,2,2,2,2
2,2,2,2,2,2,2,2,2,2,2,2
2,2,2,2,2,2,2,2,2,2,2,2
2,2,2,2,2,2,2,2,2,2,2,2
2,2,2,2,2,2,2,2,2,2,2,2
2,2,2,2,2,2,2,2,2,2,2,2
1,2,2,2,2,2,2,2,2,2,2,1
1,1,2,2,2,2,2,2,2,2,1,1
1,1,1,1,2,2,2,2,1,1,1,1
endlayer

layer
1,1,1,2,2,2,2,2,2,2,2,1
1,1,2,2,2,2,2,2,2,2,2,2
1,2,2,2,2,2,2,2,2,2,2,2
1,2,2,2,2,2,2,2,2,2,2,2
2,2,2,2,2,2,2,2,2,2,2,2
2,2,2,2,2,2,2,2,2,2,2,2
2,2,2,2,2,2,2,2,2,2,2,2
2,2,2,2,2,2,2,2,2,2,2,2
2,2,2,2,2,2,2,2,2,2,2,2
1,2,2,2,2,2,2,2,2,2,2,1
1,1,2,2,2,2,2,2,2,2,1,1
1,1,1,1,2,2,2,2,1,1,1,1
endlayer

layer
1,1,1,2,2,2,2,2,2,2,2,1
1,1,2,2,2,2,2,2,2,2,2,2
1,2,2,2,2,2,2,2,2,2,2,2
1,2,2,2,2,2,2,2,2,2,2,2
2,2,2,2,2,2,2,2,2,2,2,2
2,2,2,2,2,2,2,2,2,2,2,2
2,2,2,2,2,2,2,2,2,2,2,2
2,2,2,2,2,2,2,2,2,2,2,2
2,2,2,2,2,2,2,2,2,2,2,2
1,2,2,2,2,2,2,2,2,2,2,1
1,1,2,2,2,2,2,2,2,2,1,1
1,1,1,1,2,2,2,2,1,1,1,1
endlayer

layer
1,1,1,2,2,2,2,2,2,2,2,1
1,1,2,2,2,2,2,2,2,2,2,2
1,2,2,2,2,2,2,2,2,2,2,2
1,2,2,2,2,2,2,2,2,2,2,2
2,2,2,2,2,2,2,2,2,2,2,2
2,2,2,2,2,2,2,2,2,2,2,2
2,2,2,2,2,2,2,2,2,2,2,2
2,2,2,2,2,2,2,2,2,2,2,2
2,2,2,2,2,2,2,2,2,2,2,2
1,2,2,2,2,2,2,2,2,2,2,1
1,1,2,2,2,2,2,2,2,2,1,1
1,1,1,1,2,2,2,2,1,1,1,1
endlayer

layer
1,1,1,2,2,2,2,2,2,2,2,1
1,1,2,2,2,2,2,2,2,2,2,2
1,2,2,2,2,2,2,2,2,2,2,2
1,2,2,2,2,2,2,2,2,2,2,2
2,2,2,2,2,2,2,2,2,2,2,2
2,2,2,2,2,2,2,2,2,2,2,2
2,2,2,2,2,2,2,2,2,2,2,2
2,2,2,2,2,2,2,2,2,2,2,2
2,2,2,2,2,2,2,2,2,2,2,2
1,2,2,2,2,2,2,2,2,2,2,1
1,1,2,2,2,2,2,2,2,2,1,1
1,1,1,1,2,2,2,2,1,1,1,1
endlayer

layer
1,1,1,2,2,2,2,2,2,2,2,1
1,1,2,2,2,2,2,2,2,2,2,2
1,2,2,2,2,2,2,2,2,2,2,2
1,2,2,2,2,2,2,2,2,2,2,2
2,2,2,2,2,2,2,2,2,2,2,2
2,2,2,2,2,2,2,2,2,2,2,2
2,2,2,2,2,2,2,2,2,2,2,2
2,2,2,2,2,2,2,2,2,2,2,2
2,2,2,2,2,2,2,2,2,2,2,2
1,2,2,2,2,2,2,2,2,2,2,1
1,1,2,2,2,2,2,2,2,2,1,1
1,1,1,1,2,2,2,2,1,1,1,1
endlayer

layer
1,1,1,2,2,2,2,2,2,2,2,1
1,1,2,2,2,2,2,2,2,2,2,2
1,2,2,2,2,2,2,2,2,2,2,2
1,2,2,2,2,2,2,2,2,2,2,2
2,2,2,2,2,2,2,2,2,2,2,2
2,2,2,2,2,2,2,2,2,2,2,2
2,2,2,2,2,2,2,2,2,2,2,2
2,2,2,2,2,2,2,2,2,2,2,2
2,2,2,2,2,2,2,2,2,2,2,2
1,2,2,2,2,2,2,2,2,2,2,1
1,1,2,2,2,2,2,2,2,2,1,1
1,1,1,1,2,2,2,2,1,1,1,1
endlayer

layer
1,1,1,2,2,2,2,2,2,2,2,1
1,1,2,2,2,2,2,2,2,2,2,2
1,2,2,2,2,2,2,2,2,2,2,2
1,2,2,2,2,2,2,2,2,2,2,2
2,2,2,2,2,2,2,2,2,2,2,2
2,2,2,2,2,2,2,2,2,2,2,2
2,2,2,2,2,2,2,2,2,2,2,2
2,2,2,2,2,2,2,2,2,2,2,2
2,2,2,2,2,2,2,2,2,2,2,2
1,2,2,2,2,2,2,2,2,2,2,1
1,1,2,2,2,2,2,2,2,2,1,1
1,1,1,1,2,2,2,2,1,1,1,1
endlayer

layer
1,1,1,2,2,2,2,2,2,2,2,1
1,1,2,2,2,2,2,2,2,2,2,2
1,2,2,2,2,2,2,2,2,2,2,2
1,2,2,2,2,2,2,2,2,2,2,2
2,2,2,2,2,2,2,2,2,2,2,2
2,2,2,2,2,2,2,2,2,2,2,2
2,2,2,2,2,2,2,2,2,2,2,2
2,2,2,2,2,2,2,2,2,2,2,2
2,2,2,2,2,2,2,2,2,2,2,2
1,2,2,2,2,2,2,2,2,2,2,1
1,1,2,2,2,2,2,2,2,2,1,1
1,1,1,1,2,2,2,2,1,1,1,1
endlayer

layer
1,1,1,2,2,2,2,2,2,2,2,1
1,1,2,2,2,2,2,2,2,2,2,2
1,2,2,2,2,2,2,2,2,2,2,2
1,2,2,2,2,2,2,2,2,2,2,2
2,2,2,2,2,2,2,2,2,2,2,2
2,2,2,2,2,2,2,2,2,2,2,2
2,2,2,2,2,2,2,2,2,2,2,2
2,2,2,2,2,2,2,2,2,2,2,2
2,2,2,2,2,2,2,2,2,2,2,2
1,2,2,2,2,2,2,2,2,2,2,1
1,1,2,2,2,2,2,2,2,2,1,1
1,1,1,1,2,2,2,2,1,1,1,1
endlayer

layer
1,1,1,2,2,2,2,2,2,2,2,1
1,1,2,2,2,2,2,2,2,2,2,2
1,2,2,2,2,2,2,2,2,2,2,2
1,2,2,2,2,2,2,2,2,2,2,2
2,2,2,2,2,2,2,2,2,2,2,2
2,2,2,2,2,2,2,2,2,2,2,2
2,2,2,2,2,2,2,2,2,2,2,2
2,2,2,2,2,2,2,2,2,2,2,2
2,2,2,2,2,2,2,2,2,2,2,2
1,2,2,2,2,2,2,2,2,2,2,1
1,1,2,2,2,2,2,2,2,2,1,1
1,1,1,1,2,2,2,2,1,1,1,1
endlayer

layer
1,1,1,2,2,2,2,2,2,2,2,1
1,1,2,2,2,2,2,2,2,2,2,2
1,2,2,2,2,2,2,2,2,2,2,2
1,2,2,2,2,2,2,2,2,2,2,2
2,2,2,2,2,2,2,2,2,2,2,2
2,2,2,2,2,2,2,2,2,2,2,2
2,2,2,2,2,2,2,2,2,2,2,2
2,2,2,2,2,2,2,2,2,2,2,2
2,2,2,2,2,2,2,2,2,2,2,2
1,2,2,2,2,2,2,2,2,2,2,1
1,1,2,2,2,2,2,2,2,2,1,1
1,1,1,1,2,2,2,2,1,1,1,1
endlayer

layer
1,1,1,2,2,2,2,2,2,2,2,1
1,1,2,2,2,2,2,2,2,2,2,2
1,2,2,2,2,2,2,2,2,2,2,2
1,2,2,2,2,2,2,2,2,2,2,2
2,2,2,2,2,2,2,2,2,2,2,2
2,2,2,2,2,2,2,2,2,2,2,2
2,2,2,2,2,2,2,2,2,2,2,2
2,2,2,2,2,2,2,2,2,2,2,2
2,2,2,2,2,2,2,2,2,2,2,2
1,2,2,2,2,2,2,2,2,2,2,1
1,1,2,2,2,2,2,2,2,2,1,1
1,1,1,1,2,2,2,2,1,1,1,1
endlayer

layer
1,1,1,2,2,2,2,2,2,2,2,1
1,1,2,2,2,2,2,2,2,2,2,2
1,2,2,2,2,2,2,2,2,2,2,2
1,2,2,2,2,2,2,2,2,2,2,2
2,2,2,2,2,2,2,2,2,2,2,2
2,2,2,2,2,2,2,2,2,2,2,2
2,2,2,2,2,2,2,2,2,2,2,2
2,2,2,2,2,2,2,2,2,2,2,2
2,2,2,2,2,2,2,2,2,2,2,2
1,2,2,2,2,2,2,2,2,2,2,1
1,1,2,2,2,2,2,2,2,2,1,1
1,1,1,1,2,2,2,2,1,1,1,1
endlayer

layer
1,1,1,2,2,2,2,2,2,2,2,1
1,1,2,2,2,2,2,2,2,2,2,2
1,2,2,2,2,2,2,2,2,2,2,2
1,2,2,2,2,2,2,2,2,2,2,2
2,2,2,2,2,2,2,2,2,2,2,2
2,2,2,2,2,2,2,2,2,2,2,2
2,2,2,2,2,2,2,2,2,2,2,2
2,2,2,2,2,2,2,2,2,2,2,2
2,2,2,2,2,2,2,2,2,2,2,2
1,2,2,2,2,2,2,2,2,2,2,1
1,1,2,2,2,2,2,2,2,2,1,1
1,1,1,1,2,2,2,2,1,1,1,1
endlayer

layer
1,1,1,2,2,2,2,2,2,2,2,1
1,1,2,2,2,2,2,2,2,2,2,2
1,2,2,2,2,2,2,2,2,2,2,2
1,2,2,2,2,2,2,2,2,2,2,2
2,2,2,2,2,2,2,2,2,2,2,2
2,2,2,2,2,2,2,2,2,2,2,2
2,2,2,2,2,2,2,2,2,2,2,2
2,2,2,2,2,2,2,2,2,2,2,2
2,2,2,2,2,2,2,2,2,2,2,2
1,2,2,2,2,2,2,2,2,2,2,1
1,1,2,2,2,2,2,2,2,2,1,1
1,1,1,1,2,2,2,2,1,1,1,1
endlayer

layer
1,1,1,2,2,2,2,2,2,2,2,1
1,1,2,2,2,2,2,2,2,2,2,2
1,2,2,2,2,2,2,2,2,2,2,2
1,2,2,2,2,2,2,2,2,2,2,2
2,2,2,2,2,2,2,2,2,2,2,2
2,2,2,2,2,2,2,2,2,2,2,2
2,2,2,2,2,2,2,2,2,2,2,2
2,2,2,2,2,2,2,2,2,2,2,2
2,2,2,2,2,2,2,2,2,2,2,2
1,2,2,2,2,2,2,2,2,2,2,1
1,1,2,2,2,2,2,2,2,2,1,1
1,1,1,1,2,2,2,2,1,1,1,1
endlayer

layer
1,1,1,2,2,2,2,2,2,2,2,1
1,1,2,2,2,2,2,2,2,2,2,2
1,2,2,2,2,2,2,2,2,2,2,2
1,2,2,2,2,2,2,2,2,2,2,2
2,2,2,2,2,2,2,2,2,2,2,2
2,2,2,2,2,2,2,2,2,2,2,2
2,2,2,2,2,2,2,2,2,2,2,2
2,2,2,2,2,2,2,2,2,2,2,2
2,2,2,2,2,2,2,2,2,2,2,2
1,2,2,2,2,2,2,2,2,2,2,1
1,1,2,2,2,2,2,2,2,2,1,1
1,1,1,1,2,2,2,2,1,1,1,1
endlayer

layer
1,1,1,2,2,2,2,2,2,2,2,1
1,1,2,2,2,2,2,2,2,2,2,2
1,2,2,2,2,2,2,2,2,2,2,2
1,2,2,2,2,2,2,2,2,2,2,2
2,2,2,2,2,2,2,2,2,2,2,2
2,2,2,2,2,2,2,2,2,2,2,2
2,2,2,2,2,2,2,2,2,2,2,2
2,2,2,2,2,2,2,2,2,2,2,2
2,2,2,2,2,2,2,2,2,2,2,2
1,2,2,2,2,2,2,2,2,2,2,1
1,1,2,2,2,2,2,2,2,2,1,1
1,1,1,1,2,2,2,2,1,1,1,1
endlayer

layer
1,1,1,2,2,2,2,2,2,2,2,1
1,1,2,2,2,2,2,2,2,2,2,2
1,2,2,2,2,2,2,2,2,2,2,2
1,2,2,2,2,2,2,2,2,2,2,2
2,2,2,2,2,2,2,2,2,2,2,2
2,2,2,2,2,2,2,2,2,2,2,2
2,2,2,2,2,2,2,2,2,2,2,2
2,2,2,2,2,2,2,2,2,2,2,2
2,2,2,2,2,2,2,2,2,2,2,2
1,2,2,2,2,2,2,2,2,2,2,1
1,1,2,2,2,2,2,2,2,2,1,1
1,1,1,1,2,2,2,2,1,1,1,1
endlayer

layer
1,1,1,2,2,2,2,2,2,2,2,1
1,1,2,2,2,2,2,2,2,2,2,2
1,2,2,2,2,2,2,2,2,2,2,2
1,2,2,2,2,2,2,2,2,2,2,2
2,2,2,2,2,2,2,2,2,2,2,2
2,2,2,2,2,2,2,2,2,2,2,2
2,2,2,2,2,2,2,2,2,2,2,2
2,2,2,2,2,2,2,2,2,2,2,2
2,2,2,2,2,2,2,2,2,2,2,2
1,2,2,2,2,2,2,2,2,2,2,1
1,1,2,2,2,2,2,2,2,2,1,1
1,1,1,1,2,2,2,2,1,1,1,1
endlayer

layer
1,1,1,2,2,2,2,2,2,2,2,1
1,1,2,2,2,2,2,2,2,2,2,2
1,2,2,2,2,2,2,2,2,2,2,2
1,2,2,2,2,2,2,2,2,2,2,2
2,2,2,2,2,2,2,2,2,2,2,2
2,2,2,2,2,2,2,2,2,2,2,2
2,2,2,2,2,2,2,2,2,2,2,2
2,2,2,2,2,2,2,2,2,2,2,2
2,2,2,2,2,2,2,2,2,2,2,2
1,2,2,2,2,2,2,2,2,2,2,1
1,1,2,2,2,2,2,2,2,2,1,1
1,1,1,1,2,2,2,2,1,1,1,1
endlayer

layer
1,1,1,2,2,2,2,2,2,2,2,1
1,1,2,2,2,2,2,2,2,2,2,2
1,2,2,2,2,2,2,2,2,2,2,2
1,2,2,2,2,2,2,2,2,2,2,2
2,2,2,2,2,2,2,2,2,2,2,2
2,2,2,2,2,2,2,2,2,2,2,2
2,2,2,2,2,2,2,2,2,2,2,2
2,2,2,2,2,2,2,2,2,2,2,2
2,2,2,2,2,2,2,2,2,2,2,2
1,2,2,2,2,2,2,2,2,2,2,1
1,1,2,2,2,2,2,2,2,2,1,1
1,1,1,1,2,2,2,2,1,1,1,1
endlayer

layer
1,1,1,2,2,2,2,2,2,2,2,1
1,1,2,2,2,2,2,2,2,2,2,2
1,2,2,2,2,2,2,2,2,2,2,2
1,2,2,2,2,2,2,2,2,2,2,2
2,2,2,2,2,2,2,2,2,2,2,2
2,2,2,2,2,2,2,2,2,2,2,2
2,2,2,2,2,2,2,2,2,2,2,2
2,2,2,2,2,2,2,2,2,2,2,2
2,2,2,2,2,2,2,2,2,2,2,2
1,2,2,2,2,2,2,2,2,2,2,1
1,1,2,2,2,2,2,2,2,2,1,1
1,1,1,1,2,2,2,2,1,1,1,1
endlayer

layer
1,1,1,2,2,2,2,2,2,2,2,1
1,1,2,2,2,2,2,2,2,2,2,2
1,2,2,2,2,2,2,2,2,2,2,2
1,2,2,2,2,2,2,2,2,2,2,2
2,2,2,2,2,2,2,2,2,2,2,2
2,2,2,2,2,2,2,2,2,2,2,2
2,2,2,2,2,2,2,2,2,2,2,2
2,2,2,2,2,2,2,2,2,2,2,2
2,2,2,2,2,2,2,2,2,2,2,2
1,2,2,2,2,2,2,2,2,2,2,1
1,1,2,2,2,2,2,2,2,2,1,1
1,1,1,1,2,2,2,2,1,1,1,1
endlayer

layer
1,1,1,2,2,2,2,2,2,2,2,1
1,1,2,2,2,2,2,2,2,2,2,2
1,2,2,2,2,2,2,2,2,2,2,2
1,2,2,2,2,2,2,2,2,2,2,2
2,2,2,2,2,2,2,2,2,2,2,2
2,2,2,2,2,2,2,2,2,2,2,2
2,2,2,2,2,2,2,2,2,2,2,2
2,2,2,2,2,2,2,2,2,2,2,2
2,2,2,2,2,2,2,2,2,2,2,2
1,2,2,2,2,2,2,2,2,2,2,1
1,1,2,2,2,2,2,2,2,2,1,1
1,1,1,1,2,2,2,2,1,1,1,1
endlayer

layer
1,1,1,2,2,2,2,2,2,2,2,1
1,1,2,2,2,2,2,2,2,2,2,2
1,2,2,2,2,2,2,2,2,2,2,2
1,2,2,2,2,2,2,2,2,2,2,2
2,2,2,2,2,2,2,2,2,2,2,2
2,2,2,2,2,2,2,2,2,2,2,2
2,2,2,2,2,2,2,2,2,2,2,2
2,2,2,2,2,2,2,2,2,2,2,2
2,2,2,2,2,2,2,2,2,2,2,2
1,2,2,2,2,2,2,2,2,2,2,1
1,1,2,2,2,2,2,2,2,2,1,1
1,1,1,1,2,2,2,2,1,1,1,1
endlayer


layer
1,1,1,2,2,2,2,2,2,2,2,1
1,1,2,2,2,2,2,2,2,2,2,2
1,2,2,2,2,2,2,2,2,2,2,2
1,2,2,2,2,2,2,2,2,2,2,2
2,2,2,2,2,2,2,2,2,2,2,2
2,2,2,2,2,2,2,2,2,2,2,2
2,2,2,2,2,2,2,2,2,2,2,2
2,2,2,2,2,2,2,2,2,2,2,2
2,2,2,2,2,2,2,2,2,2,2,2
1,2,2,2,2,2,2,2,2,2,2,1
1,1,2,2,2,2,2,2,2,2,1,1
1,1,1,1,2,2,2,2,1,1,1,1
endlayer

layer
1,1,1,1,1,2,2,2,2,1,1,1
1,1,1,1,2,2,2,2,2,2,1,1
1,1,1,2,2,2,2,2,2,2,2,1
1,1,2,2,2,2,2,2,2,2,2,2
1,2,2,2,2,2,2,2,2,2,2,2
2,2,2,2,2,2,2,2,2,2,2,2
2,2,2,2,2,2,2,2,2,2,2,2
2,2,2,2,2,2,2,2,2,2,2,1
1,1,2,2,2,2,2,2,2,2,1,1
1,1,2,2,2,2,2,2,2,2,1,1
1,1,1,1,2,2,2,2,1,1,1,1
1,1,1,1,1,2,2,1,1,1,1,1
endlayer

layer
1,1,1,1,1,1,1,2,1,1,1,1
1,1,1,1,2,2,2,2,2,1,1,1
1,1,1,2,2,3,3,3,3,2,1,1
1,1,2,2,3,3,4,4,3,3,2,1
1,2,2,3,3,4,4,4,4,3,2,2
2,2,2,3,4,4,4,4,4,3,2,2
2,2,2,3,4,4,4,4,3,3,2,2
2,2,2,3,3,3,4,3,3,2,1,1
1,1,2,2,2,3,3,3,2,2,1,1
1,1,1,2,2,2,2,2,2,1,1,1
1,1,1,1,2,2,2,1,1,1,1,1
1,1,1,1,1,2,1,1,1,1,1,1
endlayer

layer
1,1,1,1,1,1,1,2,1,1,1,1
1,1,1,1,1,2,2,2,2,1,1,1
1,1,1,1,2,3,3,3,3,2,1,1
1,1,1,2,3,3,2,2,3,3,2,1
1,2,2,3,3,2,2,2,2,3,2,1
1,2,2,3,2,2,2,2,2,3,2,2
2,2,2,3,3,2,2,2,3,3,2,1
1,2,2,3,3,3,2,3,3,2,1,1
1,1,2,2,2,3,3,3,2,1,1,1
1,1,1,2,2,2,2,2,2,1,1,1
1,1,1,1,2,2,2,1,1,1,1,1
1,1,1,1,1,1,1,1,1,1,1,1
endlayer

layer
0,0,0,0,0,0,0,2,0,0,0,0
0,0,0,0,0,2,2,5,2,0,0,0
0,0,0,0,2,5,5,5,5,2,0,0
0,0,0,2,5,6,5,5,5,5,2,0
0,0,2,5,5,5,5,5,5,5,2,0
0,2,2,5,5,5,5,5,5,5,5,2
0,2,5,5,5,5,5,5,5,5,2,0
0,0,2,5,5,5,5,6,5,2,0,0
0,0,0,2,2,5,5,5,2,0,0,0
0,0,0,2,2,2,5,2,0,0,0,0
0,0,0,0,0,2,2,0,0,0,0,0
0,0,0,0,0,0,0,0,0,0,0,0
endlayer

layer
0,0,0,0,0,0,0,0,0,0,0,0
0,0,0,0,0,0,0,7,0,0,0,0
0,0,0,0,0,7,7,7,7,0,0,0
0,0,0,0,7,6,7,7,7,7,0,0
0,0,0,7,7,7,7,7,7,7,0,0
0,0,0,7,7,7,7,7,7,7,7,0
0,0,7,7,7,7,7,7,7,7,0,0
0,0,0,7,7,7,7,6,7,0,0,0
0,0,0,0,0,7,7,7,0,0,0,0
0,0,0,0,0,0,7,0,0,0,0,0
0,0,0,0,0,0,0,0,0,0,0,0
0,0,0,0,0,0,0,0,0,0,0,0
endlayer

layer
0,0,0,0,0,0,0,0,0,0,0,0
0,0,0,0,0,0,0,0,0,0,0,0
0,0,0,0,0,0,0,0,0,0,0,0
0,0,0,0,0,6,0,0,0,0,0,0
0,0,0,0,0,0,0,0,0,0,0,0
0,0,0,0,0,0,0,0,0,0,0,0
0,0,0,0,0,0,0,0,0,0,0,0
0,0,0,0,0,0,0,6,0,0,0,0
0,0,0,0,0,0,0,0,0,0,0,0
0,0,0,0,0,0,0,0,0,0,0,0
0,0,0,0,0,0,0,0,0,0,0,0
0,0,0,0,0,0,0,0,0,0,0,0
endlayer

layer
0,0,0,0,0,0,0,0,0,0,0,0
0,0,0,0,0,0,0,0,0,0,0,0
0,0,0,0,0,0,0,0,0,0,0,0
0,0,0,0,0,6,0,0,0,0,0,0
0,0,0,0,0,0,0,0,0,0,0,0
0,0,0,0,0,0,0,0,0,0,0,0
0,0,0,0,0,0,0,0,0,0,0,0
0,0,0,0,0,0,0,6,0,0,0,0
0,0,0,0,0,0,0,0,0,0,0,0
0,0,0,0,0,0,0,0,0,0,0,0
0,0,0,0,0,0,0,0,0,0,0,0
0,0,0,0,0,0,0,0,0,0,0,0
endlayer

layer
0,0,0,0,0,0,0,0,0,0,0,0
0,0,0,0,0,0,0,0,0,0,0,0
0,0,0,0,0,0,0,0,0,0,0,0
0,0,0,0,8,8,0,0,0,0,0,0
0,0,0,0,0,0,0,0,0,0,0,0
0,0,0,0,0,0,0,0,0,0,0,0
0,0,0,0,0,0,0,0,0,0,0,0
0,0,0,0,0,0,0,6,0,0,0,0
0,0,0,0,0,0,0,0,0,0,0,0
0,0,0,0,0,0,0,0,0,0,0,0
0,0,0,0,0,0,0,0,0,0,0,0
0,0,0,0,0,0,0,0,0,0,0,0
endlayer

layer
0,0,0,0,0,0,0,0,0,0,0,0
0,0,0,0,0,0,0,0,0,0,0,0
0,0,0,0,0,0,0,0,0,0,0,0
0,0,0,0,6,0,0,0,0,0,0,0
0,0,0,0,0,0,0,0,0,0,0,0
0,0,0,0,0,0,0,0,0,0,0,0
0,0,0,0,0,0,0,0,0,0,0,0
0,0,0,0,0,0,0,8,0,0,0,0
0,0,0,0,0,0,0,8,0,0,0,0
0,0,0,0,0,0,0,0,0,0,0,0
0,0,0,0,0,0,0,0,0,0,0,0
0,0,0,0,0,0,0,0,0,0,0,0
endlayer

layer
0,0,9,0,0,0,9,0,0,0,0,0
0,0,0,0,0,0,0,0,0,0,0,0
0,0,0,0,0,0,0,0,0,0,0,0
9,9,0,0,6,0,0,9,9,0,0,0
0,0,0,0,0,0,0,0,0,0,0,0
0,0,0,0,0,0,0,0,0,0,0,0
0,0,9,0,0,0,9,0,0,0,0,0
0,0,0,0,0,0,0,0,0,0,0,0
0,0,0,0,0,0,0,6,0,0,0,0
0,0,0,0,0,0,0,0,0,0,0,0
0,0,0,0,0,0,0,0,0,0,0,0
0,0,0,0,0,0,0,0,0,0,0,0
endlayer

layer
0,0,9,0,0,0,9,0,0,0,0,0
0,0,0,9,0,9,0,0,0,0,0,0
0,0,0,9,9,9,0,0,0,0,0,0
0,0,9,9,6,9,9,0,0,0,0,0
0,0,0,9,9,9,0,0,0,0,0,0
0,0,0,9,0,9,0,0,0,0,0,0
0,0,9,0,0,0,9,0,0,0,0,0
0,0,0,0,0,0,0,0,0,0,0,0
0,0,0,0,0,0,0,6,0,0,0,0
0,0,0,0,0,0,0,0,0,0,0,0
0,0,0,0,0,0,0,0,0,0,0,0
0,0,0,0,0,0,0,0,0,0,0,0
endlayer

layer
0,0,0,0,0,0,0,0,0,0,0,0
0,0,0,0,0,0,0,0,0,0,0,0
0,0,0,0,9,0,0,0,0,0,0,0
0,0,0,9,9,9,0,0,0,0,0,0
0,0,0,0,9,0,0,0,0,0,0,0
0,0,0,0,0,0,0,0,0,0,0,0
0,0,0,0,0,0,0,0,0,0,0,0
0,0,0,0,0,0,0,0,0,0,0,0
0,0,0,0,0,0,0,6,0,0,0,0
0,0,0,0,0,0,0,0,0,0,0,0
0,0,0,0,0,0,0,0,0,0,0,0
0,0,0,0,0,0,0,0,0,0,0,0
endlayer

layer
0,0,0,0,0,0,0,0,0,0,0,0
0,0,0,0,0,0,0,0,0,0,0,0
0,0,0,0,0,0,0,0,0,0,0,0
0,0,0,0,0,0,0,0,0,0,0,0
0,0,0,0,0,0,0,0,0,0,0,0
0,0,0,0,0,9,0,0,0,9,0,0
0,0,0,0,0,0,0,0,0,0,0,0
0,0,0,0,0,0,0,0,0,0,0,0
0,0,0,9,9,0,0,6,0,0,9,9
0,0,0,0,0,0,0,0,0,0,0,0
0,0,0,0,0,0,0,0,0,0,0,0
0,0,0,0,0,9,0,0,0,9,0,0
endlayer

layer
0,0,0,0,0,0,0,0,0,0,0,0
0,0,0,0,0,0,0,0,0,0,0,0
0,0,0,0,0,0,0,0,0,0,0,0
0,0,0,0,0,0,0,0,0,0,0,0
0,0,0,0,0,0,0,0,0,0,0,0
0,0,0,0,0,9,0,0,0,9,0,0
0,0,0,0,0,0,9,0,9,0,0,0
0,0,0,0,0,0,9,9,9,0,0,0
0,0,0,0,0,9,9,9,9,9,0,0
0,0,0,0,0,0,9,9,9,0,0,0
0,0,0,0,0,0,9,0,9,0,0,0
0,0,0,0,0,9,0,0,0,9,0,0
endlayer

layer
0,0,0,0,0,0,0,0,0,0,0,0
0,0,0,0,0,0,0,0,0,0,0,0
0,0,0,0,0,0,0,0,0,0,0,0
0,0,0,0,0,0,0,0,0,0,0,0
0,0,0,0,0,0,0,0,0,0,0,0
0,0,0,0,0,0,0,0,0,0,0,0
0,0,0,0,0,0,0,0,0,0,0,0
0,0,0,0,0,0,0,9,0,0,0,0
0,0,0,0,0,0,9,9,9,0,0,0
0,0,0,0,0,0,0,9,0,0,0,0
0,0,0,0,0,0,0,0,0,0,0,0
0,0,0,0,0,0,0,0,0,0,0,0
endlayer

