# GiantClam -- 13 Oct 2014
# Created by Ruins mod version 13.8 Ingame Parser
# authoring Player: Jordan_Greywolf

biomesToSpawnIn=deep ocean,ocean

weight=1
embed_into_distance=1
acceptable_target_blocks=sand,clay,gravel,stone,dirt,grass,sandstone

unacceptable_target_blocks=flowing_lava,lava

dimensions=7,7,9
allowable_overhang=60
max_leveling=0
leveling_buffer=0
preserve_water=1
preserve_lava=0

rule1=0,100,preserveBlock
rule2=0,100,minecraft:hardened_clay-0
rule3=0,100,minecraft:stained_hardened_clay-0
rule4=0,100,minecraft:quartz_block-0,minecraft:quartz_block-0,minecraft:glowstone

layer
1,1,1,1,1,1,1,1,1
1,1,1,1,1,1,1,1,1
1,1,2,2,2,2,2,1,1
1,2,2,2,2,2,2,2,1
1,1,2,2,2,2,2,1,1
1,1,1,1,1,1,1,1,1
1,1,1,1,1,1,1,1,1
endlayer

layer
1,1,1,2,2,2,1,1,1
1,1,2,2,2,2,2,1,1
1,2,0,3,3,3,0,2,1
2,0,3,3,3,3,3,0,2
2,2,0,3,3,3,0,2,2
1,2,2,2,2,2,2,2,1
1,1,1,2,1,2,1,1,1
endlayer

layer
1,1,2,2,2,2,2,1,1
1,0,0,3,3,3,0,0,1
0,0,0,3,0,3,0,0,0
2,0,0,0,4,0,0,0,2
2,0,0,0,0,0,0,0,2
0,0,0,0,0,0,0,0,0
1,0,2,0,2,0,2,0,1
endlayer

layer
1,0,0,0,2,0,0,0,1
0,0,2,2,2,2,2,0,0
0,0,0,0,3,0,0,0,0
0,0,0,0,0,0,0,0,0
0,0,0,0,0,0,0,0,0
0,0,0,0,0,0,0,0,0
0,0,0,0,0,0,0,0,0
endlayer

layer
0,0,0,0,0,0,0,0,0
0,0,0,2,2,2,0,0,0
0,2,2,0,3,0,2,2,0
0,0,0,0,0,0,0,0,0
0,0,0,0,0,0,0,0,0
0,0,0,0,0,0,0,0,0
0,0,0,0,0,0,0,0,0
endlayer

layer
0,0,0,0,0,0,0,0,0
0,0,0,2,2,2,0,0,0
0,2,2,2,2,2,2,2,0
2,2,2,2,2,2,2,2,2
0,0,0,0,0,0,0,0,0
0,0,0,0,0,0,0,0,0
0,0,0,0,0,0,0,0,0
endlayer

layer
0,0,0,0,0,0,0,0,0
0,0,0,0,0,0,0,0,0
0,0,2,0,2,0,2,0,0
0,2,2,2,2,2,2,2,0
0,2,0,2,0,2,0,2,0
0,0,0,0,0,0,0,0,0
0,0,0,0,0,0,0,0,0
endlayer

