# Lighthouse_Island (2 May 2014)
# Updated to MC 1.7.10, 10 Oct 2014
# Created by Ruins mod version 12.3 Ingame Parser
# authoring Player: Jordan_Greywolf


biomesToSpawnIn=beach,forested island,frozen ocean,gravel beach,mushroomislandshore,ocean,stone beach

weight=1
embed_into_distance=16

acceptable_target_blocks=water,sand,stone,gravel,clay,dirt,grass,sandstone,mycelium,flowing_water

unacceptable_target_blocks=lava,flowing_lava

dimensions=50,23,23
allowable_overhang=200
max_cut_in=0
cut_in_buffer=0
max_leveling=0
leveling_buffer=0
preserve_water=0
preserve_lava=0
preserve_plants=0

# White Stained Clay
rule1=0,100,minecraft:stained_hardened_clay-0

# Red Stained Clay
rule2=0,100,minecraft:stained_hardened_clay-14

# Stone Slab
rule3=0,100,minecraft:stone_slab

# Stone Slabs
rule4=0,100,minecraft:double_stone_slab

# Stone Slab (Upper)
rule5=0,100,minecraft:stone_slab-8

# Iron Bars
rule6=0,100,minecraft:iron_bars

# Redstone Lamp
rule7=0,100,minecraft:redstone_lamp

# Stone
rule8=0,100,minecraft:cobblestone,minecraft:mossy_cobblestone

# Glowstone
rule9=0,100,minecraft:glowstone

# Terrain Preserve (water line)
rule10=0,100,preserveBlock

# Spruce Planks (floor)
rule11=0,100,minecraft:planks-1

# Glass
rule12=0,100,minecraft:glass

# Redstone Block
rule13=0,100,minecraft:redstone_block

# Monster Spawner
rule14=0,100,MobSpawner:Skeleton,MobSpawner:Creeper

# Loot!
rule15=0,100,ChestGenHook:dungeonChest:4,ChestGenHook:villageBlacksmith:4,ChestGenHook:pyramidJungleChest:4,ChestGenHook:pyramidJungleDispenser:6

# -------------------

# Tower Floor Base (-18)
layer
10,10,10,10,10,10,10,10,08,08,08,08,08,08,08,10,10,10,10,10,10,10,10
10,10,10,10,10,10,08,08,08,08,08,08,08,08,08,08,08,10,10,10,10,10,10
10,10,10,10,08,08,08,08,08,08,08,08,08,08,08,08,08,08,10,10,10,10,10
10,10,10,08,08,08,08,08,08,08,08,08,08,08,08,08,08,08,08,10,10,10,10
10,10,08,08,08,08,08,08,08,08,08,08,08,08,08,08,08,08,08,08,10,10,10
10,10,08,08,08,08,08,08,08,08,08,08,08,08,08,08,08,08,08,08,08,10,10
10,08,08,08,08,08,08,08,08,08,08,08,08,08,08,08,08,08,08,08,08,10,10
10,08,08,08,08,08,08,08,08,08,08,08,08,08,08,08,08,08,08,08,08,08,10
10,08,08,08,08,08,08,08,08,08,08,08,08,08,08,08,08,08,08,08,08,08,10
8,08,08,08,08,08,08,08,08,08,08,08,08,08,08,08,08,08,08,08,08,08,10
8,08,08,08,08,08,08,08,08,08,08,08,08,08,08,08,08,08,08,08,08,08,8
8,08,08,08,08,08,08,08,08,08,08,08,08,08,08,08,08,08,08,08,08,08,8
8,08,08,08,08,08,08,08,08,08,08,08,08,08,08,08,08,08,08,08,08,08,8
8,08,08,08,08,08,08,08,08,08,08,08,08,08,08,08,08,08,08,08,08,08,8
8,08,08,08,08,08,08,08,08,08,08,08,08,08,08,08,08,08,08,08,08,08,8
10,08,08,08,08,08,08,08,08,08,08,08,08,08,08,08,08,08,08,08,08,08,10
10,10,08,08,08,08,08,08,08,08,08,08,08,08,08,08,08,08,08,08,08,08,10
10,10,08,08,08,08,08,08,08,08,08,08,08,08,08,08,08,08,08,08,08,08,10
10,10,10,08,08,08,08,08,08,08,08,08,08,08,08,08,08,08,08,08,08,08,10
10,10,10,08,08,08,08,08,08,08,08,08,08,08,08,08,08,08,08,08,08,10,10
10,10,10,10,10,08,08,08,08,08,08,08,08,08,08,08,08,08,08,08,10,10,10
10,10,10,10,10,10,08,08,08,08,08,08,08,08,08,08,08,08,08,10,10,10,10
10,10,10,10,10,10,10,10,10,08,08,08,08,08,10,10,08,08,10,10,10,10,10
endlayer


# Tower Floor Base (-17)
layer
10,10,10,10,10,10,10,10,08,08,08,08,08,08,08,10,10,10,10,10,10,10,10
10,10,10,10,10,10,08,08,08,08,08,08,08,08,08,08,08,10,10,10,10,10,10
10,10,10,10,08,08,08,08,08,08,08,08,08,08,08,08,08,08,10,10,10,10,10
10,10,10,08,08,08,08,08,08,08,08,08,08,08,08,08,08,08,08,10,10,10,10
10,10,08,08,08,08,08,08,08,08,08,08,08,08,08,08,08,08,08,08,10,10,10
10,10,08,08,08,08,08,08,08,08,08,08,08,08,08,08,08,08,08,08,08,10,10
10,08,08,08,08,08,08,08,08,08,08,08,08,08,08,08,08,08,08,08,08,10,10
10,08,08,08,08,08,08,08,08,08,08,08,08,08,08,08,08,08,08,08,08,08,10
10,08,08,08,08,08,08,08,08,08,08,08,08,08,08,08,08,08,08,08,08,08,10
8,08,08,08,08,08,08,08,08,08,08,08,08,08,08,08,08,08,08,08,08,08,10
8,08,08,08,08,08,08,08,08,08,08,08,08,08,08,08,08,08,08,08,08,08,8
8,08,08,08,08,08,08,08,08,08,08,08,08,08,08,08,08,08,08,08,08,08,8
8,08,08,08,08,08,08,08,08,08,08,08,08,08,08,08,08,08,08,08,08,08,8
8,08,08,08,08,08,08,08,08,08,08,08,08,08,08,08,08,08,08,08,08,08,8
8,08,08,08,08,08,08,08,08,08,08,08,08,08,08,08,08,08,08,08,08,08,8
10,08,08,08,08,08,08,08,08,08,08,08,08,08,08,08,08,08,08,08,08,08,10
10,10,08,08,08,08,08,08,08,08,08,08,08,08,08,08,08,08,08,08,08,08,10
10,10,08,08,08,08,08,08,08,08,08,08,08,08,08,08,08,08,08,08,08,08,10
10,10,10,08,08,08,08,08,08,08,08,08,08,08,08,08,08,08,08,08,08,08,10
10,10,10,08,08,08,08,08,08,08,08,08,08,08,08,08,08,08,08,08,08,10,10
10,10,10,10,10,08,08,08,08,08,08,08,08,08,08,08,08,08,08,08,10,10,10
10,10,10,10,10,10,08,08,08,08,08,08,08,08,08,08,08,08,08,10,10,10,10
10,10,10,10,10,10,10,10,10,08,08,08,08,08,10,10,08,08,10,10,10,10,10
endlayer


# Tower Floor Base (-16)
layer
10,10,10,10,10,10,10,10,08,08,08,08,08,08,08,10,10,10,10,10,10,10,10
10,10,10,10,10,10,08,08,08,08,08,08,08,08,08,08,08,10,10,10,10,10,10
10,10,10,10,08,08,08,08,08,08,08,08,08,08,08,08,08,08,10,10,10,10,10
10,10,10,08,08,08,08,08,08,08,08,08,08,08,08,08,08,08,08,10,10,10,10
10,10,08,08,08,08,08,08,08,08,08,08,08,08,08,08,08,08,08,08,10,10,10
10,10,08,08,08,08,08,08,08,08,08,08,08,08,08,08,08,08,08,08,08,10,10
10,08,08,08,08,08,08,08,08,08,08,08,08,08,08,08,08,08,08,08,08,10,10
10,08,08,08,08,08,08,08,08,08,08,08,08,08,08,08,08,08,08,08,08,08,10
10,08,08,08,08,08,08,08,08,08,08,08,08,08,08,08,08,08,08,08,08,08,10
8,08,08,08,08,08,08,08,08,08,08,08,08,08,08,08,08,08,08,08,08,08,10
8,08,08,08,08,08,08,08,08,08,08,08,08,08,08,08,08,08,08,08,08,08,8
8,08,08,08,08,08,08,08,08,08,08,08,08,08,08,08,08,08,08,08,08,08,8
8,08,08,08,08,08,08,08,08,08,08,08,08,08,08,08,08,08,08,08,08,08,8
8,08,08,08,08,08,08,08,08,08,08,08,08,08,08,08,08,08,08,08,08,08,8
8,08,08,08,08,08,08,08,08,08,08,08,08,08,08,08,08,08,08,08,08,08,8
10,08,08,08,08,08,08,08,08,08,08,08,08,08,08,08,08,08,08,08,08,08,10
10,10,08,08,08,08,08,08,08,08,08,08,08,08,08,08,08,08,08,08,08,08,10
10,10,08,08,08,08,08,08,08,08,08,08,08,08,08,08,08,08,08,08,08,08,10
10,10,10,08,08,08,08,08,08,08,08,08,08,08,08,08,08,08,08,08,08,08,10
10,10,10,08,08,08,08,08,08,08,08,08,08,08,08,08,08,08,08,08,08,10,10
10,10,10,10,10,08,08,08,08,08,08,08,08,08,08,08,08,08,08,08,10,10,10
10,10,10,10,10,10,08,08,08,08,08,08,08,08,08,08,08,08,08,10,10,10,10
10,10,10,10,10,10,10,10,10,08,08,08,08,08,10,10,08,08,10,10,10,10,10
endlayer


# Tower Floor Base (-15)
layer
10,10,10,10,10,10,10,10,10,08,08,08,08,08,08,10,10,10,10,10,10,10,10
10,10,10,10,10,10,08,08,08,08,08,08,08,08,08,08,10,10,10,10,10,10,10
10,10,10,10,08,08,08,08,08,08,08,08,08,08,08,08,08,08,10,10,10,10,10
10,10,10,08,08,08,08,08,08,08,08,08,08,08,08,08,08,08,08,10,10,10,10
10,10,08,08,08,08,08,08,08,08,08,08,08,08,08,08,08,08,08,08,10,10,10
10,10,08,08,08,08,08,08,08,08,08,08,08,08,08,08,08,08,08,08,08,10,10
10,08,08,08,08,08,08,08,08,08,08,08,08,08,08,08,08,08,08,08,08,10,10
10,08,08,08,08,08,08,08,08,08,08,08,08,08,08,08,08,08,08,08,08,08,10
10,08,08,08,08,08,08,08,08,08,08,08,08,08,08,08,08,08,08,08,08,08,10
8,08,08,08,08,08,08,08,08,08,08,08,08,08,08,08,08,08,08,08,08,08,10
8,08,08,08,08,08,08,08,08,08,08,08,08,08,08,08,08,08,08,08,08,08,8
8,08,08,08,08,08,08,08,08,08,08,08,08,08,08,08,08,08,08,08,08,08,8
8,08,08,08,08,08,08,08,08,08,08,08,08,08,08,08,08,08,08,08,08,08,8
8,08,08,08,08,08,08,08,08,08,08,08,08,08,08,08,08,08,08,08,08,08,8
8,08,08,08,08,08,08,08,08,08,08,08,08,08,08,08,08,08,08,08,08,08,8
10,10,08,08,08,08,08,08,08,08,08,08,08,08,08,08,08,08,08,08,08,08,10
10,10,08,08,08,08,08,08,08,08,08,08,08,08,08,08,08,08,08,08,08,08,10
10,10,10,08,08,08,08,08,08,08,08,08,08,08,08,08,08,08,08,08,08,08,10
10,10,10,08,08,08,08,08,08,08,08,08,08,08,08,08,08,08,08,08,08,08,10
10,10,10,10,08,08,08,08,08,08,08,08,08,08,08,08,08,08,08,08,08,10,10
10,10,10,10,10,08,08,08,08,08,08,08,08,08,08,08,08,08,08,08,10,10,10
10,10,10,10,10,10,08,08,08,08,08,08,08,08,08,08,08,08,08,10,10,10,10
10,10,10,10,10,10,10,10,10,08,08,08,08,08,10,10,08,08,10,10,10,10,10
endlayer


# Tower Floor Base (-14)
layer
10,10,10,10,10,10,10,10,10,08,08,08,08,08,08,10,10,10,10,10,10,10,10
10,10,10,10,10,10,10,08,08,08,08,08,08,08,08,08,10,10,10,10,10,10,10
10,10,10,10,10,08,08,08,08,08,08,08,08,08,08,08,08,08,10,10,10,10,10
10,10,10,08,08,08,08,08,08,08,08,08,08,08,08,08,08,08,08,10,10,10,10
10,10,08,08,08,08,08,08,08,08,08,08,08,08,08,08,08,08,08,08,10,10,10
10,10,08,08,08,08,08,08,08,08,08,08,08,08,08,08,08,08,08,08,08,10,10
10,08,08,08,08,08,08,08,08,08,08,08,08,08,08,08,08,08,08,08,08,10,10
10,08,08,08,08,08,08,08,08,08,08,08,08,08,08,08,08,08,08,08,08,08,10
10,08,08,08,08,08,08,08,08,08,08,08,08,08,08,08,08,08,08,08,08,08,10
8,08,08,08,08,08,08,08,08,08,08,08,08,08,08,08,08,08,08,08,08,08,10
8,08,08,08,08,08,08,08,08,08,08,08,08,08,08,08,08,08,08,08,08,08,8
8,08,08,08,08,08,08,08,08,08,08,08,08,08,08,08,08,08,08,08,08,08,8
8,08,08,08,08,08,08,08,08,08,08,08,08,08,08,08,08,08,08,08,08,08,8
8,08,08,08,08,08,08,08,08,08,08,08,08,08,08,08,08,08,08,08,08,08,8
8,08,08,08,08,08,08,08,08,08,08,08,08,08,08,08,08,08,08,08,08,08,8
10,10,08,08,08,08,08,08,08,08,08,08,08,08,08,08,08,08,08,08,08,08,10
10,10,08,08,08,08,08,08,08,08,08,08,08,08,08,08,08,08,08,08,08,08,10
10,10,10,08,08,08,08,08,08,08,08,08,08,08,08,08,08,08,08,08,08,08,10
10,10,10,08,08,08,08,08,08,08,08,08,08,08,08,08,08,08,08,08,08,10,10
10,10,10,10,08,08,08,08,08,08,08,08,08,08,08,08,08,08,08,08,08,10,10
10,10,10,10,10,08,08,08,08,08,08,08,08,08,08,08,08,08,08,08,10,10,10
10,10,10,10,10,10,10,08,08,08,08,08,08,08,08,08,08,08,08,10,10,10,10
10,10,10,10,10,10,10,10,10,08,08,08,08,08,10,10,08,08,10,10,10,10,10
endlayer


# Tower Floor Base (-13)
layer
10,10,10,10,10,10,10,10,10,08,08,08,08,08,08,10,10,10,10,10,10,10,10
10,10,10,10,10,10,10,08,08,08,08,08,08,08,08,10,10,10,10,10,10,10,10
10,10,10,10,10,08,08,08,08,08,08,08,08,08,08,08,08,08,10,10,10,10,10
10,10,10,10,08,08,08,08,08,08,08,08,08,08,08,08,08,08,08,10,10,10,10
10,10,08,08,08,08,08,08,08,08,08,08,08,08,08,08,08,08,08,08,10,10,10
10,10,08,08,08,08,08,08,08,08,08,08,08,08,08,08,08,08,08,08,08,10,10
10,10,08,08,08,08,08,08,08,08,08,08,08,08,08,08,08,08,08,08,08,10,10
10,08,08,08,08,08,08,08,08,08,08,08,08,08,08,08,08,08,08,08,08,08,10
10,08,08,08,08,08,08,08,08,08,08,08,08,08,08,08,08,08,08,08,08,08,10
8,08,08,08,08,08,08,08,08,08,08,08,08,08,08,08,08,08,08,08,08,08,10
8,08,08,08,08,08,08,08,08,08,08,08,08,08,08,08,08,08,08,08,08,08,8
8,08,08,08,08,08,08,08,08,08,08,08,08,08,08,08,08,08,08,08,08,08,8
8,08,08,08,08,08,08,08,08,08,08,08,08,08,08,08,08,08,08,08,08,08,8
8,08,08,08,08,08,08,08,08,08,08,08,08,08,08,08,08,08,08,08,08,08,8
8,08,08,08,08,08,08,08,08,08,08,08,08,08,08,08,08,08,08,08,08,08,8
10,10,08,08,08,08,08,08,08,08,08,08,08,08,08,08,08,08,08,08,08,08,10
10,10,08,08,08,08,08,08,08,08,08,08,08,08,08,08,08,08,08,08,08,08,10
10,10,10,08,08,08,08,08,08,08,08,08,08,08,08,08,08,08,08,08,08,08,10
10,10,10,08,08,08,08,08,08,08,08,08,08,08,08,08,08,08,08,08,08,10,10
10,10,10,10,08,08,08,08,08,08,08,08,08,08,08,08,08,08,08,08,08,10,10
10,10,10,10,10,08,08,08,08,08,08,08,08,08,08,08,08,08,08,08,10,10,10
10,10,10,10,10,10,10,08,08,08,08,08,08,08,08,08,08,08,08,10,10,10,10
10,10,10,10,10,10,10,10,10,10,08,08,08,10,10,10,08,08,10,10,10,10,10
endlayer


# Tower Floor Base (-12)
layer
10,10,10,10,10,10,10,10,10,08,08,08,08,08,08,10,10,10,10,10,10,10,10
10,10,10,10,10,10,10,08,08,08,08,08,08,08,08,10,10,10,10,10,10,10,10
10,10,10,10,10,08,08,08,08,08,08,08,08,08,08,08,08,08,10,10,10,10,10
10,10,10,10,08,08,08,08,08,08,08,08,08,08,08,08,08,08,08,10,10,10,10
10,10,08,08,08,08,08,08,08,08,08,08,08,08,08,08,08,08,08,08,10,10,10
10,10,08,08,08,08,08,08,08,08,08,08,08,08,08,08,08,08,08,08,08,10,10
10,10,08,08,08,08,08,08,08,08,08,08,08,08,08,08,08,08,08,08,08,10,10
10,08,08,08,08,08,08,08,08,08,08,08,08,08,08,08,08,08,08,08,08,08,10
10,08,08,08,08,08,08,08,08,08,08,08,08,08,08,08,08,08,08,08,08,08,10
8,08,08,08,08,08,08,08,08,08,08,08,08,08,08,08,08,08,08,08,08,08,10
8,08,08,08,08,08,08,08,08,08,08,08,08,08,08,08,08,08,08,08,08,08,8
8,08,08,08,08,08,08,08,08,08,08,08,08,08,08,08,08,08,08,08,08,08,8
8,08,08,08,08,08,08,08,08,08,08,08,08,08,08,08,08,08,08,08,08,08,8
8,08,08,08,08,08,08,08,08,08,08,08,08,08,08,08,08,08,08,08,08,08,8
8,08,08,08,08,08,08,08,08,08,08,08,08,08,08,08,08,08,08,08,08,08,8
10,10,08,08,08,08,08,08,08,08,08,08,08,08,08,08,08,08,08,08,08,08,10
10,10,08,08,08,08,08,08,08,08,08,08,08,08,08,08,08,08,08,08,08,08,10
10,10,10,08,08,08,08,08,08,08,08,08,08,08,08,08,08,08,08,08,08,08,10
10,10,10,08,08,08,08,08,08,08,08,08,08,08,08,08,08,08,08,08,08,10,10
10,10,10,10,08,08,08,08,08,08,08,08,08,08,08,08,08,08,08,08,08,10,10
10,10,10,10,10,08,08,08,08,08,08,08,08,08,08,08,08,08,08,08,10,10,10
10,10,10,10,10,10,10,08,08,08,08,08,08,08,08,08,08,08,08,10,10,10,10
10,10,10,10,10,10,10,10,10,10,08,08,08,10,10,10,08,08,10,10,10,10,10
endlayer


# Tower Floor Base (-11)
layer
10,10,10,10,10,10,10,10,10,08,08,08,08,08,10,10,10,10,10,10,10,10,10
10,10,10,10,10,10,10,08,08,08,08,08,08,08,08,10,10,10,10,10,10,10,10
10,10,10,10,10,08,08,08,08,08,08,08,08,08,08,08,08,08,10,10,10,10,10
10,10,10,10,08,08,08,08,08,08,08,08,08,08,08,08,08,08,08,10,10,10,10
10,10,10,08,08,08,08,08,08,08,08,08,08,08,08,08,08,08,08,08,10,10,10
10,10,10,08,08,08,08,08,08,08,08,08,08,08,08,08,08,08,08,08,10,10,10
10,10,08,08,08,08,08,08,08,08,08,08,08,08,08,08,08,08,08,08,08,10,10
10,10,08,08,08,08,08,08,08,08,08,08,08,08,08,08,08,08,08,08,08,10,10
10,08,08,08,08,08,08,08,08,08,08,08,08,08,08,08,08,08,08,08,08,08,10
8,08,08,08,08,08,08,08,08,08,08,08,08,08,08,08,08,08,08,08,08,08,10
8,08,08,08,08,08,08,08,08,08,08,08,08,08,08,08,08,08,08,08,08,08,8
8,08,08,08,08,08,08,08,08,08,08,08,08,08,08,08,08,08,08,08,08,08,8
8,08,08,08,08,08,08,08,08,08,08,08,08,08,08,08,08,08,08,08,08,08,8
8,08,08,08,08,08,08,08,08,08,08,08,08,08,08,08,08,08,08,08,08,08,8
8,08,08,08,08,08,08,08,08,08,08,08,08,08,08,08,08,08,08,08,08,08,8
10,10,08,08,08,08,08,08,08,08,08,08,08,08,08,08,08,08,08,08,08,08,10
10,10,08,08,08,08,08,08,08,08,08,08,08,08,08,08,08,08,08,08,08,08,10
10,10,10,08,08,08,08,08,08,08,08,08,08,08,08,08,08,08,08,08,08,10,10
10,10,10,10,08,08,08,08,08,08,08,08,08,08,08,08,08,08,08,08,08,10,10
10,10,10,10,08,08,08,08,08,08,08,08,08,08,08,08,08,08,08,08,10,10,10
10,10,10,10,10,08,08,08,08,08,08,08,08,08,08,08,08,08,08,08,10,10,10
10,10,10,10,10,10,10,10,08,08,08,08,08,08,08,08,08,08,08,10,10,10,10
10,10,10,10,10,10,10,10,10,10,08,08,08,10,10,10,08,08,10,10,10,10,10
endlayer


# Tower Floor Base (-10)
layer
10,10,10,10,10,10,10,10,10,08,08,08,10,08,10,10,10,10,10,10,10,10,10
10,10,10,10,10,10,10,08,08,08,08,08,08,08,08,10,10,10,10,10,10,10,10
10,10,10,10,10,08,08,08,08,08,08,08,08,08,08,08,08,08,10,10,10,10,10
10,10,10,10,08,08,08,08,08,08,08,08,08,08,08,08,08,08,10,10,10,10,10
10,10,10,08,08,08,08,08,08,08,08,08,08,08,08,08,08,08,08,10,10,10,10
10,10,10,08,08,08,08,08,08,08,08,08,08,08,08,08,08,08,08,08,10,10,10
10,10,08,08,08,08,08,08,08,08,08,08,08,08,08,08,08,08,08,08,10,10,10
10,10,08,08,08,08,08,08,08,08,08,08,08,08,08,08,08,08,08,08,08,10,10
10,08,08,08,08,08,08,08,08,08,08,08,08,08,08,08,08,08,08,08,08,08,10
8,08,08,08,08,08,08,08,08,08,08,08,08,08,08,08,08,08,08,08,08,08,10
8,08,08,08,08,08,08,08,08,08,08,08,08,08,08,08,08,08,08,08,08,08,8
8,08,08,08,08,08,08,08,08,08,08,08,08,08,08,08,08,08,08,08,08,08,8
8,08,08,08,08,08,08,08,08,08,08,08,08,08,08,08,08,08,08,08,08,08,8
8,08,08,08,08,08,08,08,08,08,08,08,08,08,08,08,08,08,08,08,08,08,8
10,08,08,08,08,08,08,08,08,08,08,08,08,08,08,08,08,08,08,08,08,08,10
10,10,08,08,08,08,08,08,08,08,08,08,08,08,08,08,08,08,08,08,08,08,10
10,10,10,08,08,08,08,08,08,08,08,08,08,08,08,08,08,08,08,08,08,08,10
10,10,10,08,08,08,08,08,08,08,08,08,08,08,08,08,08,08,08,08,08,10,10
10,10,10,10,08,08,08,08,08,08,08,08,08,08,08,08,08,08,08,08,08,10,10
10,10,10,10,10,08,08,08,08,08,08,08,08,08,08,08,08,08,08,08,10,10,10
10,10,10,10,10,10,08,08,08,08,08,08,08,08,08,08,08,08,08,08,10,10,10
10,10,10,10,10,10,10,10,08,08,08,08,08,08,08,10,08,08,08,10,10,10,10
10,10,10,10,10,10,10,10,10,10,08,08,10,10,10,10,10,08,10,10,10,10,10
endlayer


# Tower Floor Base (-9)
layer
10,10,10,10,10,10,10,10,10,08,08,08,10,10,10,10,10,10,10,10,10,10,10
10,10,10,10,10,10,10,08,08,08,08,08,08,08,08,10,10,10,10,10,10,10,10
10,10,10,10,10,08,08,08,08,08,08,08,08,08,08,08,10,08,10,10,10,10,10
10,10,10,10,08,08,08,08,08,08,08,08,08,08,08,08,08,10,10,10,10,10,10
10,10,10,08,08,08,08,08,08,08,08,08,08,08,08,08,08,08,10,10,10,10,10
10,10,10,08,08,08,08,08,08,08,08,08,08,08,08,08,08,08,08,08,10,10,10
10,10,08,08,08,08,08,08,08,08,08,08,08,08,08,08,08,08,08,08,10,10,10
10,10,08,08,08,08,08,08,08,08,08,08,08,08,08,08,08,08,08,08,08,10,10
10,08,08,08,08,08,08,08,08,08,08,08,08,08,08,08,08,08,08,08,08,08,10
10,08,08,08,08,08,08,08,08,08,08,08,08,08,08,08,08,08,08,08,08,08,10
8,08,08,08,08,08,08,08,08,08,08,08,08,08,08,08,08,08,08,08,08,08,10
8,08,08,08,08,08,08,08,08,08,08,08,08,08,08,08,08,08,08,08,08,08,8
10,08,08,08,08,08,08,08,08,08,08,08,08,08,08,08,08,08,08,08,08,08,8
10,08,08,08,08,08,08,08,08,08,08,08,08,08,08,08,08,08,08,08,08,08,8
10,10,08,08,08,08,08,08,08,08,08,08,08,08,08,08,08,08,08,08,08,08,10
10,10,10,08,08,08,08,08,08,08,08,08,08,08,08,08,08,08,08,08,08,08,10
10,10,10,08,08,08,08,08,08,08,08,08,08,08,08,08,08,08,08,08,08,10,10
10,10,10,08,08,08,08,08,08,08,08,08,08,08,08,08,08,08,08,08,08,10,10
10,10,10,10,08,08,08,08,08,08,08,08,08,08,08,08,08,08,08,08,08,10,10
10,10,10,10,10,08,08,08,08,08,08,08,08,08,08,08,08,08,08,08,10,10,10
10,10,10,10,10,10,08,08,08,08,08,08,08,08,08,08,08,08,08,08,10,10,10
10,10,10,10,10,10,10,10,08,08,08,08,08,08,10,10,08,08,08,10,10,10,10
10,10,10,10,10,10,10,10,10,10,10,08,10,10,10,10,10,08,10,10,10,10,10
endlayer


# Tower Floor Base (-8)
layer
10,10,10,10,10,10,10,10,10,08,08,08,10,10,10,10,10,10,10,10,10,10,10
10,10,10,10,10,10,10,08,08,08,08,08,08,08,08,10,10,10,10,10,10,10,10
10,10,10,10,10,08,08,08,08,08,08,08,08,08,08,10,10,08,10,10,10,10,10
10,10,10,10,08,08,08,08,08,08,08,08,08,08,08,08,10,10,10,10,10,10,10
10,10,10,08,08,08,08,08,08,08,08,08,08,08,08,08,08,10,10,10,10,10,10
10,10,10,08,08,08,08,08,08,08,08,08,08,08,08,08,08,08,08,08,10,10,10
10,10,08,08,08,08,08,08,08,08,08,08,08,08,08,08,08,08,08,08,10,10,10
10,10,08,08,08,08,08,08,08,08,08,08,08,08,08,08,08,08,08,08,08,10,10
10,08,08,08,08,08,08,08,08,08,08,08,08,08,08,08,08,08,08,08,08,10,10
10,08,08,08,08,08,08,08,08,08,08,08,08,08,08,08,08,08,08,08,08,10,10
10,08,08,08,08,08,08,08,08,08,08,08,08,08,08,08,08,08,08,08,08,08,10
8,08,08,08,08,08,08,08,08,08,08,08,08,08,08,08,08,08,08,08,08,08,8
10,08,08,08,08,08,08,08,08,08,08,08,08,08,08,08,08,08,08,08,08,08,10
10,08,08,08,08,08,08,08,08,08,08,08,08,08,08,08,08,08,08,08,08,08,10
10,10,08,08,08,08,08,08,08,08,08,08,08,08,08,08,08,08,08,08,08,08,10
10,10,10,08,08,08,08,08,08,08,08,08,08,08,08,08,08,08,08,08,08,08,10
10,10,10,08,08,08,08,08,08,08,08,08,08,08,08,08,08,08,08,08,08,10,10
10,10,10,08,08,08,08,08,08,08,08,08,08,08,08,08,08,08,08,08,08,10,10
10,10,10,10,08,08,08,08,08,08,08,08,08,08,08,08,08,08,08,08,08,10,10
10,10,10,10,10,08,08,08,08,08,08,08,08,08,08,08,08,08,08,08,10,10,10
10,10,10,10,10,10,08,08,08,08,08,08,08,08,08,08,08,08,08,08,10,10,10
10,10,10,10,10,10,10,10,08,08,08,08,08,08,10,10,10,08,08,10,10,10,10
10,10,10,10,10,10,10,10,10,10,10,10,10,10,10,10,10,10,10,10,10,10,10
endlayer


# Tower Floor Base (-7)
layer
10,10,10,10,10,10,10,10,10,08,08,08,10,10,10,10,10,10,10,10,10,10,10
10,10,10,10,10,10,10,08,08,08,08,08,08,10,10,10,10,10,10,10,10,10,10
10,10,10,10,10,08,08,08,08,08,08,08,08,08,08,10,10,08,10,10,10,10,10
10,10,10,10,08,08,08,08,08,08,08,08,08,08,08,08,10,10,10,10,10,10,10
10,10,10,08,08,08,08,08,08,08,08,08,08,08,08,08,08,10,10,10,10,10,10
10,10,10,08,08,08,08,08,08,08,08,08,08,08,08,08,08,08,08,08,10,10,10
10,10,10,08,08,08,08,08,08,08,08,08,08,08,08,08,08,08,08,08,10,10,10
10,10,10,08,08,08,08,08,08,08,08,08,08,08,08,08,08,08,08,08,10,10,10
10,10,08,08,08,08,08,08,08,08,08,08,08,08,08,08,08,08,08,08,08,10,10
10,08,08,08,08,08,08,08,08,08,08,08,08,08,08,08,08,08,08,08,08,10,10
10,08,08,08,08,08,08,08,08,08,08,08,08,08,08,08,08,08,08,08,08,08,10
8,08,08,08,08,08,08,08,08,08,08,08,08,08,08,08,08,08,08,08,08,08,8
10,08,08,08,08,08,08,08,08,08,08,08,08,08,08,08,08,08,08,08,08,10,10
10,08,08,08,08,08,08,08,08,08,08,08,08,08,08,08,08,08,08,08,08,10,10
10,10,08,08,08,08,08,08,08,08,08,08,08,08,08,08,08,08,08,08,08,10,10
10,10,10,08,08,08,08,08,08,08,08,08,08,08,08,08,08,08,08,08,08,10,10
10,10,10,08,08,08,08,08,08,08,08,08,08,08,08,08,08,08,08,08,08,10,10
10,10,10,10,08,08,08,08,08,08,08,08,08,08,08,08,08,08,08,08,08,10,10
10,10,10,10,08,08,08,08,08,08,08,08,08,08,08,08,08,08,08,08,08,10,10
10,10,10,10,10,08,08,08,08,08,08,08,08,08,08,08,08,08,08,08,10,10,10
10,10,10,10,10,10,08,08,08,08,08,08,08,08,08,10,08,08,08,08,10,10,10
10,10,10,10,10,10,10,10,08,10,10,08,08,08,10,10,10,08,08,10,10,10,10
10,10,10,10,10,10,10,10,10,10,10,10,10,10,10,10,10,10,10,10,10,10,10
endlayer


# Tower Floor Base (-6)
layer
10,10,10,10,10,10,10,10,10,10,10,10,10,10,10,10,10,10,10,10,10,10,10
10,10,10,10,10,10,10,10,08,08,08,10,10,10,10,10,10,10,10,10,10,10,10
10,10,10,10,10,10,10,08,08,08,08,08,08,08,10,10,10,10,10,10,10,10,10
10,10,10,10,10,10,08,08,08,08,08,08,08,08,08,08,10,10,10,10,10,10,10
10,10,10,10,08,10,08,08,08,08,08,08,08,08,08,08,08,10,10,10,10,10,10
10,10,10,10,10,08,08,08,08,08,08,08,08,08,08,08,08,08,10,10,10,10,10
10,10,10,10,08,08,08,08,08,08,08,08,08,08,08,08,08,08,08,10,10,10,10
10,10,10,08,08,08,08,08,08,08,08,08,08,08,08,08,08,08,08,10,10,10,10
10,10,08,08,08,08,08,08,08,08,08,08,08,08,08,08,08,08,08,08,08,10,10
10,08,08,08,08,08,08,08,08,08,08,08,08,08,08,08,08,08,08,08,08,10,10
10,08,08,08,08,08,08,08,08,08,08,08,08,08,08,08,08,08,08,08,08,08,10
10,08,08,08,08,08,08,08,08,08,08,08,08,08,08,08,08,08,08,08,08,08,10
10,10,08,08,08,08,08,08,08,08,08,08,08,08,08,08,08,08,08,08,08,10,10
10,10,08,08,08,08,08,08,08,08,08,08,08,08,08,08,08,08,08,08,08,10,10
10,10,10,08,08,08,08,08,08,08,08,08,08,08,08,08,08,08,08,08,08,10,10
10,10,10,08,08,08,08,08,08,08,08,08,08,08,08,08,08,08,08,08,10,10,10
10,10,10,08,08,08,08,08,08,08,08,08,08,08,08,08,08,08,08,08,10,10,10
10,10,10,10,10,08,08,08,08,08,08,08,08,08,08,08,08,08,08,10,10,10,10
10,10,10,10,10,08,08,08,08,08,08,08,08,08,08,08,08,08,08,10,10,10,10
10,10,10,10,10,10,08,08,08,08,08,08,08,08,08,08,08,08,10,10,10,10,10
10,10,10,10,10,10,10,10,08,08,08,08,08,08,08,10,08,08,10,10,10,10,10
10,10,10,10,10,10,10,10,10,10,10,08,08,08,10,10,10,10,10,10,10,10,10
10,10,10,10,10,10,10,10,10,10,10,10,10,10,10,10,10,10,10,10,10,10,10
endlayer


# Tower Floor Base (-5)
layer
10,10,10,10,10,10,10,10,10,10,10,10,10,10,10,10,10,10,10,10,10,10,10
10,10,10,10,10,10,10,10,10,08,10,10,10,10,10,10,10,10,10,10,10,10,10
10,10,10,10,10,10,10,10,10,08,08,08,08,10,10,10,10,10,10,10,10,10,10
10,10,10,10,10,10,10,10,08,08,08,08,08,08,10,10,10,10,10,10,10,10,10
10,10,10,10,10,10,10,08,08,08,08,08,08,08,08,10,08,10,10,10,10,10,10
10,10,10,10,10,08,08,08,08,08,08,08,08,08,08,08,10,10,10,10,10,10,10
10,10,10,10,08,08,08,08,08,08,08,08,08,08,08,08,08,08,10,10,10,10,10
10,10,10,10,08,08,08,08,08,08,08,08,08,08,08,08,08,08,08,10,10,10,10
10,10,10,08,08,08,08,08,08,08,08,08,08,08,08,08,08,08,08,08,10,10,10
10,08,10,08,08,08,08,08,08,08,08,08,08,08,08,08,08,08,08,08,08,10,10
10,08,08,08,08,08,08,08,08,08,08,08,08,08,08,08,08,08,08,08,08,10,10
10,10,08,08,08,08,08,08,08,08,08,08,08,08,08,08,08,08,08,08,08,08,10
10,10,08,08,08,08,08,08,08,08,08,08,08,08,08,08,08,08,08,08,08,10,10
10,10,08,08,08,08,08,08,08,08,08,08,08,08,08,08,08,08,08,08,08,10,10
10,10,10,08,08,08,08,08,08,08,08,08,08,08,08,08,08,08,08,08,10,10,10
10,10,10,10,10,08,08,08,08,08,08,08,08,08,08,08,08,08,08,08,10,10,10
10,10,10,08,10,08,08,08,08,08,08,08,08,08,08,08,08,08,08,10,10,10,10
10,10,10,10,10,10,08,08,08,08,08,08,08,08,08,08,08,08,08,10,10,10,10
10,10,10,10,10,10,08,08,08,08,08,08,08,08,08,08,08,10,10,10,10,10,10
10,10,10,10,10,10,10,10,08,08,08,08,08,08,08,08,08,08,10,10,10,10,10
10,10,10,10,10,10,10,10,08,08,08,08,08,08,10,10,08,08,10,10,10,10,10
10,10,10,10,10,10,10,10,10,10,10,08,10,10,10,10,10,10,10,10,10,10,10
10,10,10,10,10,10,10,10,10,10,10,10,10,10,10,10,10,10,10,10,10,10,10
endlayer


# Tower Floor Base (-4)
layer
10,10,10,10,10,10,10,10,10,10,10,10,10,10,10,10,10,10,10,10,10,10,10
10,10,10,10,10,10,10,10,10,10,10,10,10,10,10,10,10,10,10,10,10,10,10
10,10,10,10,10,10,10,10,10,10,10,08,08,10,10,10,10,10,10,10,10,10,10
10,10,10,10,10,10,10,10,10,08,08,08,08,08,10,10,10,10,10,10,10,10,10
10,10,10,10,10,10,10,08,08,08,08,08,08,08,08,10,08,10,10,10,10,10,10
10,10,10,10,10,08,08,08,08,08,08,08,08,08,08,08,10,10,10,10,10,10,10
10,10,10,10,10,08,08,08,08,08,08,08,08,08,08,08,08,08,10,10,10,10,10
10,10,10,10,08,08,08,08,08,08,08,08,08,08,08,08,08,08,08,10,10,10,10
10,10,10,08,08,08,08,08,08,08,08,08,08,08,08,08,08,08,08,10,10,10,10
10,10,10,08,08,08,08,08,08,08,08,08,08,08,08,08,08,08,08,08,10,10,10
10,10,08,08,08,08,08,08,08,08,08,08,08,08,08,08,08,08,08,08,10,10,10
10,10,08,08,08,08,08,08,08,08,08,08,08,08,08,08,08,08,08,08,10,10,10
10,10,10,08,08,08,08,08,08,08,08,08,08,08,08,08,08,08,08,08,08,10,10
10,10,10,08,08,08,08,08,08,08,08,08,08,08,08,08,08,08,08,08,08,10,10
10,10,10,08,08,08,08,08,08,08,08,08,08,08,08,08,08,08,08,08,10,10,10
10,10,10,10,10,08,08,08,08,08,08,08,08,08,08,08,08,08,08,10,10,10,10
10,10,10,10,10,08,08,08,08,08,08,08,08,08,08,08,08,08,10,10,10,10,10
10,10,10,10,10,10,08,08,08,08,08,08,08,08,08,08,08,10,10,10,10,10,10
10,10,10,10,10,10,08,08,08,08,08,08,08,08,08,08,10,10,10,10,10,10,10
10,10,10,10,10,10,10,10,08,08,08,08,08,08,08,08,08,10,10,10,10,10,10
10,10,10,10,10,10,10,10,08,08,08,08,10,10,10,10,08,08,10,10,10,10,10
10,10,10,10,10,10,10,10,10,10,10,10,10,10,10,10,10,10,10,10,10,10,10
10,10,10,10,10,10,10,10,10,10,10,10,10,10,10,10,10,10,10,10,10,10,10
endlayer


# Tower Floor Base (-3)
layer
10,10,10,10,10,10,10,10,10,10,10,10,10,10,10,10,10,10,10,10,10,10,10
10,10,10,10,10,10,10,10,10,10,10,10,10,10,10,10,10,10,10,10,10,10,10
10,10,10,10,10,10,10,10,10,10,10,10,10,10,10,10,10,10,10,10,10,10,10
10,10,10,10,10,10,10,10,10,10,08,10,08,08,10,10,10,10,10,10,10,10,10
10,10,10,10,10,10,10,08,10,08,08,08,08,08,08,10,08,10,10,10,10,10,10
10,10,10,10,10,10,08,08,08,08,08,08,08,08,08,08,10,10,10,10,10,10,10
10,10,10,10,10,10,08,08,08,08,08,08,08,08,08,08,08,08,10,10,10,10,10
10,10,10,10,10,08,08,08,08,08,08,08,08,08,08,08,08,08,10,10,10,10,10
10,10,10,10,08,08,08,08,08,08,08,08,08,08,08,08,08,08,08,10,10,10,10
10,10,10,08,08,08,08,08,08,08,08,08,08,08,08,08,08,08,08,10,10,10,10
10,10,10,08,08,08,08,08,08,08,08,08,08,08,08,08,08,08,08,08,10,10,10
10,10,10,08,08,08,08,08,08,08,08,08,08,08,08,08,08,08,08,08,10,10,10
10,10,10,08,08,08,08,08,08,08,08,08,08,08,08,08,08,08,08,08,10,10,10
10,10,10,08,08,08,08,08,08,08,08,08,08,08,08,08,08,08,08,08,10,10,10
10,10,10,10,08,08,08,08,08,08,08,08,08,08,08,08,08,08,08,10,10,10,10
10,10,10,10,10,08,08,08,08,08,08,08,08,08,08,08,08,08,08,10,10,10,10
10,10,10,10,10,08,08,08,08,08,08,08,08,08,08,08,08,08,10,10,10,10,10
10,10,10,10,10,10,10,08,08,08,08,08,08,08,08,08,08,10,10,10,10,10,10
10,10,10,10,10,10,10,08,08,08,08,08,08,08,08,08,10,10,10,10,10,10,10
10,10,10,10,10,10,10,10,08,08,08,08,08,08,08,10,08,10,10,10,10,10,10
10,10,10,10,10,10,10,10,10,10,08,08,10,10,10,10,08,08,10,10,10,10,10
10,10,10,10,10,10,10,10,10,10,10,10,10,10,10,10,10,10,10,10,10,10,10
10,10,10,10,10,10,10,10,10,10,10,10,10,10,10,10,10,10,10,10,10,10,10
endlayer


# Tower Floor Base (-2)
layer
10,10,10,10,10,10,10,10,10,10,10,10,10,10,10,10,10,10,10,10,10,10,10
10,10,10,10,10,10,10,10,10,10,10,10,10,10,10,10,10,10,10,10,10,10,10
10,10,10,10,10,10,10,10,10,10,10,10,10,10,10,10,10,10,10,10,10,10,10
10,10,10,10,10,10,10,10,10,10,10,10,08,10,10,10,10,10,10,10,10,10,10
10,10,10,10,10,10,10,10,10,08,08,08,08,08,10,10,08,10,10,10,10,10,10
10,10,10,10,10,10,08,08,08,08,08,08,08,08,08,08,10,10,10,10,10,10,10
10,10,10,10,10,10,08,08,08,08,08,08,08,08,08,08,08,10,10,10,10,10,10
10,10,10,10,10,08,08,08,08,08,08,08,08,08,08,08,08,08,10,10,10,10,10
10,10,10,10,10,08,08,08,08,08,08,08,08,08,08,08,08,08,10,10,10,10,10
10,10,10,08,08,08,08,08,08,08,08,08,08,08,08,08,08,08,08,10,10,10,10
10,10,10,08,08,08,08,08,08,08,08,08,08,08,08,08,08,08,08,10,10,10,10
10,10,10,08,08,08,08,08,08,08,08,08,08,08,08,08,08,08,08,08,10,10,10
10,10,10,08,08,08,08,08,08,08,08,08,08,08,08,08,08,08,08,10,10,10,10
10,10,10,10,08,08,08,08,08,08,08,08,08,08,08,08,08,08,08,10,10,10,10
10,10,10,10,10,08,08,08,08,08,08,08,08,08,08,08,08,08,10,10,10,10,10
10,10,10,10,10,08,08,08,08,08,08,08,08,08,08,08,08,08,10,10,10,10,10
10,10,10,10,10,10,08,08,08,08,08,08,08,08,08,08,08,10,10,10,10,10,10
10,10,10,10,10,10,10,08,08,08,08,08,08,08,08,08,08,10,10,10,10,10,10
10,10,10,10,10,10,10,08,08,08,08,08,08,08,10,10,10,10,10,10,10,10,10
10,10,10,10,10,10,10,10,10,10,08,08,08,10,10,10,10,10,10,10,10,10,10
10,10,10,10,10,10,10,10,10,10,10,10,10,10,10,10,08,10,10,10,10,10,10
10,10,10,10,10,10,10,10,10,10,10,10,10,10,10,10,10,10,10,10,10,10,10
10,10,10,10,10,10,10,10,10,10,10,10,10,10,10,10,10,10,10,10,10,10,10
endlayer

# Tower Floor Base (-1)
layer
10,10,10,10,10,10,10,10,10,10,10,10,10,10,10,10,10,10,10,10,10,10,10
10,10,10,10,10,10,10,10,10,10,10,10,10,10,10,10,10,10,10,10,10,10,10
10,10,10,10,10,10,10,10,10,10,10,10,10,10,10,10,10,10,10,10,10,10,10
10,10,10,10,10,10,10,10,10,10,10,10,10,10,10,10,10,10,10,10,10,10,10
10,10,10,10,10,10,10,10,10,01,01,01,02,02,10,10,10,10,10,10,10,10,10
10,10,10,10,10,10,10,01,01,11,11,11,11,11,02,02,10,10,10,10,10,10,10
10,10,10,10,10,10,01,11,11,11,11,11,11,11,11,11,02,10,10,10,10,10,10
10,10,10,10,10,01,11,11,11,11,11,11,11,11,11,11,11,02,10,10,10,10,10
10,10,10,10,10,01,11,11,11,11,11,11,11,11,11,11,11,02,10,10,10,10,10
10,10,10,10,01,11,11,11,11,11,11,11,11,11,11,11,11,11,02,10,10,10,10
10,10,10,10,01,11,11,11,11,11,11,11,11,11,11,11,11,11,02,10,10,10,10
10,10,10,10,02,11,11,11,11,11,11,11,11,11,11,11,11,11,02,10,10,10,10
10,10,10,10,02,11,11,11,11,11,11,11,11,11,11,11,11,11,01,10,10,10,10
10,10,10,10,02,11,11,11,11,11,11,11,11,11,11,11,11,11,01,10,10,10,10
10,10,10,10,10,02,11,11,11,11,11,11,11,11,11,11,11,01,10,10,10,10,10
10,10,10,10,10,02,11,11,11,11,11,11,11,11,11,11,11,01,10,10,10,10,10
10,10,10,10,10,10,02,11,11,11,11,11,11,11,11,11,01,10,10,10,10,10,10
10,10,10,10,10,10,10,02,02,11,11,11,11,11,01,01,10,10,10,10,10,10,10
10,10,10,10,10,10,10,10,10,02,02,01,01,01,10,10,10,10,10,10,10,10,10
10,10,10,10,10,10,10,10,10,10,10,10,10,10,10,10,10,10,10,10,10,10,10
10,10,10,10,10,10,10,10,10,10,10,10,10,10,10,10,10,10,10,10,10,10,10
10,10,10,10,10,10,10,10,10,10,10,10,10,10,10,10,10,10,10,10,10,10,10
10,10,10,10,10,10,10,10,10,10,10,10,10,10,10,10,10,10,10,10,10,10,10
endlayer



# Tower Floor 1 (+1)
layer
0,00,00,00,00,00,00,00,00,00,00,00,00,00,00,00,00,00,00,00,00,00,0
0,00,00,00,00,00,00,00,00,00,00,00,00,00,00,00,00,00,00,00,00,00,0
0,00,00,00,00,00,00,00,00,00,00,00,00,00,00,00,00,00,00,00,00,00,0
0,00,00,00,00,00,00,00,00,00,00,00,00,00,00,00,00,00,00,00,00,00,0
0,00,00,00,00,00,00,00,00,01,01,02,02,02,00,00,00,00,00,00,00,00,0
0,00,00,00,00,00,00,01,01,00,00,00,00,00,02,02,00,00,00,00,00,00,0
0,00,00,00,00,00,01,00,00,00,00,00,00,00,00,00,02,00,00,00,00,00,0
0,00,00,00,00,01,00,00,00,00,00,00,00,00,00,00,00,02,00,00,00,00,0
0,00,00,00,00,01,00,00,00,00,00,00,00,00,00,05,00,02,00,00,00,00,0
0,00,00,00,01,00,00,00,00,00,00,00,00,00,00,04,05,04,02,00,00,00,0
0,00,00,00,01,00,00,00,00,00,00,00,00,00,00,04,04,03,02,00,00,00,0
0,00,00,00,00,00,00,00,00,00,00,00,14,00,00,00,00,00,01,00,00,00,0
0,00,00,00,02,00,00,00,00,00,00,00,00,00,00,00,00,00,01,00,00,00,0
0,00,00,00,02,00,00,00,00,00,00,00,00,00,00,00,00,00,01,00,00,00,0
0,00,00,00,00,02,00,00,00,00,00,00,00,00,00,00,00,01,00,00,00,00,0
0,00,00,00,00,02,00,00,00,00,00,00,00,00,00,00,00,01,00,00,00,00,0
0,00,00,00,00,00,02,00,00,00,00,00,00,00,00,00,01,00,00,00,00,00,0
0,00,00,00,00,00,00,02,02,00,00,00,00,00,01,01,00,00,00,00,00,00,0
0,00,00,00,00,00,00,00,00,02,02,02,01,01,00,00,00,00,00,00,00,00,0
0,00,00,00,00,00,00,00,00,00,00,00,00,00,00,00,00,00,00,00,00,00,0
0,00,00,00,00,00,00,00,00,00,00,00,00,00,00,00,00,00,00,00,00,00,0
0,00,00,00,00,00,00,00,00,00,00,00,00,00,00,00,00,00,00,00,00,00,0
0,00,00,00,00,00,00,00,00,00,00,00,00,00,00,00,00,00,00,00,00,00,0
endlayer

# Tower Floor 1 (+2)
layer
0,00,00,00,00,00,00,00,00,00,00,00,00,00,00,00,00,00,00,00,00,00,0
0,00,00,00,00,00,00,00,00,00,00,00,00,00,00,00,00,00,00,00,00,00,0
0,00,00,00,00,00,00,00,00,00,00,00,00,00,00,00,00,00,00,00,00,00,0
0,00,00,00,00,00,00,00,00,00,00,00,00,00,00,00,00,00,00,00,00,00,0
0,00,00,00,00,00,00,00,00,01,02,02,02,02,00,00,00,00,00,00,00,00,0
0,00,00,00,00,00,00,01,01,00,00,00,00,00,02,02,00,00,00,00,00,00,0
0,00,00,00,00,00,01,00,00,00,00,00,00,00,00,00,02,00,00,00,00,00,0
0,00,00,00,00,01,00,00,00,00,00,00,00,00,00,00,05,02,00,00,00,00,0
0,00,00,00,00,01,00,00,00,00,00,00,00,00,05,04,04,02,00,00,00,00,0
0,00,00,00,01,00,00,00,00,00,00,00,00,00,00,06,03,00,02,00,00,00,0
0,00,00,00,01,00,00,00,00,00,00,00,00,00,00,06,06,00,01,00,00,00,0
0,00,00,00,00,00,00,00,00,00,00,00,00,00,00,00,00,00,01,00,00,00,0
0,00,00,00,01,00,00,00,00,00,00,00,00,00,00,00,00,00,01,00,00,00,0
0,00,00,00,02,00,00,00,00,00,00,00,00,00,00,00,00,00,01,00,00,00,0
0,00,00,00,00,02,00,00,00,00,00,00,00,00,00,00,00,01,00,00,00,00,0
0,00,00,00,00,02,00,00,00,00,00,00,00,00,00,00,00,01,00,00,00,00,0
0,00,00,00,00,00,02,00,00,00,00,00,00,00,00,00,01,00,00,00,00,00,0
0,00,00,00,00,00,00,02,02,00,00,00,00,00,01,01,00,00,00,00,00,00,0
0,00,00,00,00,00,00,00,00,02,02,02,02,01,00,00,00,00,00,00,00,00,0
0,00,00,00,00,00,00,00,00,00,00,00,00,00,00,00,00,00,00,00,00,00,0
0,00,00,00,00,00,00,00,00,00,00,00,00,00,00,00,00,00,00,00,00,00,0
0,00,00,00,00,00,00,00,00,00,00,00,00,00,00,00,00,00,00,00,00,00,0
0,00,00,00,00,00,00,00,00,00,00,00,00,00,00,00,00,00,00,00,00,00,0
endlayer

# Tower Floor 1 (+3)
layer
0,00,00,00,00,00,00,00,00,00,00,00,00,00,00,00,00,00,00,00,00,00,0
0,00,00,00,00,00,00,00,00,00,00,00,00,00,00,00,00,00,00,00,00,00,0
0,00,00,00,00,00,00,00,00,00,00,00,00,00,00,00,00,00,00,00,00,00,0
0,00,00,00,00,00,00,00,00,00,00,00,00,00,00,00,00,00,00,00,00,00,0
0,00,00,00,00,00,00,00,00,02,02,02,02,02,00,00,00,00,00,00,00,00,0
0,00,00,00,00,00,00,01,01,00,00,00,00,00,02,02,00,00,00,00,00,00,0
0,00,00,00,00,00,01,00,00,00,00,00,00,00,00,05,02,00,00,00,00,00,0
0,00,00,00,00,01,00,00,00,00,00,00,00,05,04,04,03,02,00,00,00,00,0
0,00,00,00,00,01,00,00,00,00,00,00,00,00,04,06,00,02,00,00,00,00,0
0,00,00,00,01,00,00,00,00,00,00,00,00,00,00,06,00,00,01,00,00,00,0
0,00,00,00,01,00,00,00,00,00,00,00,00,00,00,00,00,00,01,00,00,00,0
0,00,00,00,01,00,00,00,00,00,00,00,00,00,00,00,00,00,01,00,00,00,0
0,00,00,00,01,00,00,00,00,00,00,00,00,00,00,00,00,00,01,00,00,00,0
0,00,00,00,01,00,00,00,00,00,00,00,00,00,00,00,00,00,01,00,00,00,0
0,00,00,00,00,02,00,00,00,00,00,00,00,00,00,00,00,01,00,00,00,00,0
0,00,00,00,00,02,00,00,00,00,00,00,00,00,00,00,00,01,00,00,00,00,0
0,00,00,00,00,00,02,00,00,00,00,00,00,00,00,00,01,00,00,00,00,00,0
0,00,00,00,00,00,00,02,02,00,00,00,00,00,01,01,00,00,00,00,00,00,0
0,00,00,00,00,00,00,00,00,02,02,02,02,02,00,00,00,00,00,00,00,00,0
0,00,00,00,00,00,00,00,00,00,00,00,00,00,00,00,00,00,00,00,00,00,0
0,00,00,00,00,00,00,00,00,00,00,00,00,00,00,00,00,00,00,00,00,00,0
0,00,00,00,00,00,00,00,00,00,00,00,00,00,00,00,00,00,00,00,00,00,0
0,00,00,00,00,00,00,00,00,00,00,00,00,00,00,00,00,00,00,00,00,00,0
endlayer

# Tower Floor 1 (+4)
layer
0,00,00,00,00,00,00,00,00,00,00,00,00,00,00,00,00,00,00,00,00,00,0
0,00,00,00,00,00,00,00,00,00,00,00,00,00,00,00,00,00,00,00,00,00,0
0,00,00,00,00,00,00,00,00,00,00,00,00,00,00,00,00,00,00,00,00,00,0
0,00,00,00,00,00,00,00,00,00,00,00,00,00,00,00,00,00,00,00,00,00,0
0,00,00,00,00,00,00,00,00,02,02,02,02,02,00,00,00,00,00,00,00,00,0
0,00,00,00,00,00,00,01,02,00,00,00,00,00,02,02,00,00,00,00,00,00,0
0,00,00,00,00,00,01,00,00,00,00,00,00,05,04,03,02,00,00,00,00,00,0
0,00,00,00,00,01,00,00,00,00,00,00,05,04,04,00,00,02,00,00,00,00,0
0,00,00,00,00,01,00,00,00,00,00,00,00,00,06,06,00,01,00,00,00,00,0
0,00,00,00,01,00,00,00,00,00,00,00,00,00,00,00,00,00,01,00,00,00,0
0,00,00,00,01,00,00,00,00,00,00,00,00,00,00,00,00,00,01,00,00,00,0
0,00,00,00,01,00,00,00,00,00,00,00,00,00,00,00,00,00,01,00,00,00,0
0,00,00,00,01,00,00,00,00,00,00,00,00,00,00,00,00,00,01,00,00,00,0
0,00,00,00,01,00,00,00,00,00,00,00,00,00,00,00,00,00,01,00,00,00,0
0,00,00,00,00,01,00,00,00,00,00,00,00,00,00,00,00,01,00,00,00,00,0
0,00,00,00,00,02,00,00,00,00,00,00,00,00,00,00,00,01,00,00,00,00,0
0,00,00,00,00,00,02,00,00,00,00,00,00,00,00,00,01,00,00,00,00,00,0
0,00,00,00,00,00,00,02,02,00,00,00,00,00,02,01,00,00,00,00,00,00,0
0,00,00,00,00,00,00,00,00,02,02,02,02,02,00,00,00,00,00,00,00,00,0
0,00,00,00,00,00,00,00,00,00,00,00,00,00,00,00,00,00,00,00,00,00,0
0,00,00,00,00,00,00,00,00,00,00,00,00,00,00,00,00,00,00,00,00,00,0
0,00,00,00,00,00,00,00,00,00,00,00,00,00,00,00,00,00,00,00,00,00,0
0,00,00,00,00,00,00,00,00,00,00,00,00,00,00,00,00,00,00,00,00,00,0
endlayer

# Tower Floor 1 (+5)
layer
0,00,00,00,00,00,00,00,00,00,00,00,00,00,00,00,00,00,00,00,00,00,0
0,00,00,00,00,00,00,00,00,00,00,00,00,00,00,00,00,00,00,00,00,00,0
0,00,00,00,00,00,00,00,00,00,00,00,00,00,00,00,00,00,00,00,00,00,0
0,00,00,00,00,00,00,00,00,00,00,00,00,00,00,00,00,00,00,00,00,00,0
0,00,00,00,00,00,00,00,00,02,02,02,02,02,00,00,00,00,00,00,00,00,0
0,00,00,00,00,00,00,02,02,00,00,00,05,04,02,02,00,00,00,00,00,00,0
0,00,00,00,00,00,01,00,00,00,00,05,04,03,00,00,02,00,00,00,00,00,0
0,00,00,00,00,01,00,00,00,00,00,00,04,06,06,00,00,01,00,00,00,00,0
0,00,00,00,00,01,00,00,00,00,00,00,00,00,06,00,00,01,00,00,00,00,0
0,00,00,00,01,00,00,00,00,00,00,00,00,00,00,00,00,00,01,00,00,00,0
0,00,00,00,01,00,00,00,00,00,00,00,00,00,00,00,00,00,01,00,00,00,0
0,00,00,00,01,00,00,00,00,00,00,00,00,00,00,00,00,00,01,00,00,00,0
0,00,00,00,01,00,00,00,00,00,00,00,00,00,00,00,00,00,01,00,00,00,0
0,00,00,00,01,00,00,00,00,00,00,00,00,00,00,00,00,00,01,00,00,00,0
0,00,00,00,00,01,00,00,00,00,00,00,00,00,00,00,00,01,00,00,00,00,0
0,00,00,00,00,01,00,00,00,00,00,00,00,00,00,00,00,01,00,00,00,00,0
0,00,00,00,00,00,02,00,00,00,00,00,00,00,00,00,01,00,00,00,00,00,0
0,00,00,00,00,00,00,02,02,00,00,00,00,00,02,02,00,00,00,00,00,00,0
0,00,00,00,00,00,00,00,00,02,02,02,02,02,00,00,00,00,00,00,00,00,0
0,00,00,00,00,00,00,00,00,00,00,00,00,00,00,00,00,00,00,00,00,00,0
0,00,00,00,00,00,00,00,00,00,00,00,00,00,00,00,00,00,00,00,00,00,0
0,00,00,00,00,00,00,00,00,00,00,00,00,00,00,00,00,00,00,00,00,00,0
0,00,00,00,00,00,00,00,00,00,00,00,00,00,00,00,00,00,00,00,00,00,0
endlayer

# Tower Floor 1 (+6)
layer
0,00,00,00,00,00,00,00,00,00,00,00,00,00,00,00,00,00,00,00,00,00,0
0,00,00,00,00,00,00,00,00,00,00,00,00,00,00,00,00,00,00,00,00,00,0
0,00,00,00,00,00,00,00,00,00,00,00,00,00,00,00,00,00,00,00,00,00,0
0,00,00,00,00,00,00,00,00,00,00,00,00,00,00,00,00,00,00,00,00,00,0
0,00,00,00,00,00,00,00,00,02,02,02,02,02,00,00,00,00,00,00,00,00,0
0,00,00,00,00,00,00,02,02,00,05,04,03,00,02,02,00,00,00,00,00,00,0
0,00,00,00,00,00,02,00,00,00,05,04,06,00,00,00,01,00,00,00,00,00,0
0,00,00,00,00,01,00,00,00,00,00,00,06,06,00,00,00,01,00,00,00,00,0
0,00,00,00,00,01,00,00,00,00,00,00,00,00,00,00,00,01,00,00,00,00,0
0,00,00,00,01,00,00,00,00,00,00,00,00,00,00,00,00,00,01,00,00,00,0
0,00,00,00,01,00,00,00,00,00,00,00,00,00,00,00,00,00,01,00,00,00,0
0,00,00,00,01,00,00,00,00,00,00,00,00,00,00,00,00,00,01,00,00,00,0
0,00,00,00,01,00,00,00,00,00,00,00,00,00,00,00,00,00,01,00,00,00,0
0,00,00,00,01,00,00,00,00,00,00,00,00,00,00,00,00,00,01,00,00,00,0
0,00,00,00,00,01,00,00,00,00,00,00,00,00,00,00,00,01,00,00,00,00,0
0,00,00,00,00,01,00,00,00,00,00,00,00,00,00,00,00,01,00,00,00,00,0
0,00,00,00,00,00,01,00,00,00,00,00,00,00,00,00,02,00,00,00,00,00,0
0,00,00,00,00,00,00,02,02,00,00,00,00,00,02,02,00,00,00,00,00,00,0
0,00,00,00,00,00,00,00,00,02,02,02,02,02,00,00,00,00,00,00,00,00,0
0,00,00,00,00,00,00,00,00,00,00,00,00,00,00,00,00,00,00,00,00,00,0
0,00,00,00,00,00,00,00,00,00,00,00,00,00,00,00,00,00,00,00,00,00,0
0,00,00,00,00,00,00,00,00,00,00,00,00,00,00,00,00,00,00,00,00,00,0
0,00,00,00,00,00,00,00,00,00,00,00,00,00,00,00,00,00,00,00,00,00,0
endlayer

# Tower Floor 1 (+7)
layer
0,00,00,00,00,00,00,00,00,00,00,00,00,00,00,00,00,00,00,00,00,00,0
0,00,00,00,00,00,00,00,00,00,00,00,00,00,00,00,00,00,00,00,00,00,0
0,00,00,00,00,00,00,00,00,00,00,00,00,00,00,00,00,00,00,00,00,00,0
0,00,00,00,00,00,00,00,00,00,00,00,00,00,00,00,00,00,00,00,00,00,0
0,00,00,00,00,00,00,00,00,02,02,02,02,02,00,00,00,00,00,00,00,00,0
0,00,00,00,00,00,00,02,02,04,03,00,00,00,02,01,00,00,00,00,00,00,0
0,00,00,00,00,00,02,00,00,05,04,06,06,00,00,00,01,00,00,00,00,00,0
0,00,00,00,00,02,00,00,00,05,04,00,00,00,00,00,00,01,00,00,00,00,0
0,00,00,00,00,01,00,00,00,00,00,00,00,00,00,00,00,01,00,00,00,00,0
0,00,00,00,01,00,00,00,00,00,00,00,00,00,00,00,00,00,01,00,00,00,0
0,00,00,00,01,00,00,00,00,00,00,00,00,00,00,00,00,00,01,00,00,00,0
0,00,00,00,01,00,00,00,00,00,00,00,00,00,00,00,00,00,01,00,00,00,0
0,00,00,00,01,00,00,00,00,00,00,00,00,00,00,00,00,00,01,00,00,00,0
0,00,00,00,01,00,00,00,00,00,00,00,00,00,00,00,00,00,01,00,00,00,0
0,00,00,00,00,01,00,00,00,00,00,00,00,00,00,00,00,01,00,00,00,00,0
0,00,00,00,00,01,00,00,00,00,00,00,00,00,00,00,00,02,00,00,00,00,0
0,00,00,00,00,00,01,00,00,00,00,00,00,00,00,00,02,00,00,00,00,00,0
0,00,00,00,00,00,00,01,02,00,00,00,00,00,02,02,00,00,00,00,00,00,0
0,00,00,00,00,00,00,00,00,02,02,02,02,02,00,00,00,00,00,00,00,00,0
0,00,00,00,00,00,00,00,00,00,00,00,00,00,00,00,00,00,00,00,00,00,0
0,00,00,00,00,00,00,00,00,00,00,00,00,00,00,00,00,00,00,00,00,00,0
0,00,00,00,00,00,00,00,00,00,00,00,00,00,00,00,00,00,00,00,00,00,0
0,00,00,00,00,00,00,00,00,00,00,00,00,00,00,00,00,00,00,00,00,00,0
endlayer

# Tower Floor 1 (+8)
layer
0,00,00,00,00,00,00,00,00,00,00,00,00,00,00,00,00,00,00,00,00,00,0
0,00,00,00,00,00,00,00,00,00,00,00,00,00,00,00,00,00,00,00,00,00,0
0,00,00,00,00,00,00,00,00,00,00,00,00,00,00,00,00,00,00,00,00,00,0
0,00,00,00,00,00,00,00,00,00,00,00,00,00,00,00,00,00,00,00,00,00,0
0,00,00,00,00,00,00,00,00,02,02,02,02,02,00,00,00,00,00,00,00,00,0
0,00,00,00,00,00,00,02,02,00,00,00,00,00,01,01,00,00,00,00,00,00,0
0,00,00,00,00,00,02,05,04,03,06,06,00,00,00,00,01,00,00,00,00,00,0
0,00,00,00,00,02,00,00,04,04,06,00,00,00,00,00,00,01,00,00,00,00,0
0,00,00,00,00,02,00,00,05,00,00,00,00,00,00,00,00,01,00,00,00,00,0
0,00,00,00,01,00,00,00,00,00,00,00,00,00,00,00,00,00,01,00,00,00,0
0,00,00,00,01,00,00,00,00,00,00,00,00,00,00,00,00,00,01,00,00,00,0
0,00,00,00,01,00,00,00,00,00,00,00,00,00,00,00,00,00,01,00,00,00,0
0,00,00,00,01,00,00,00,00,00,00,00,00,00,00,00,00,00,01,00,00,00,0
0,00,00,00,01,00,00,00,00,00,00,00,00,00,00,00,00,00,01,00,00,00,0
0,00,00,00,00,01,00,00,00,00,00,00,00,00,00,00,00,02,00,00,00,00,0
0,00,00,00,00,01,00,00,00,00,00,00,00,00,00,00,00,02,00,00,00,00,0
0,00,00,00,00,00,01,00,00,00,00,00,00,00,00,00,02,00,00,00,00,00,0
0,00,00,00,00,00,00,01,01,00,00,00,00,00,02,02,00,00,00,00,00,00,0
0,00,00,00,00,00,00,00,00,02,02,02,02,02,00,00,00,00,00,00,00,00,0
0,00,00,00,00,00,00,00,00,00,00,00,00,00,00,00,00,00,00,00,00,00,0
0,00,00,00,00,00,00,00,00,00,00,00,00,00,00,00,00,00,00,00,00,00,0
0,00,00,00,00,00,00,00,00,00,00,00,00,00,00,00,00,00,00,00,00,00,0
0,00,00,00,00,00,00,00,00,00,00,00,00,00,00,00,00,00,00,00,00,00,0
endlayer

# Tower Floor 1 (+9)
layer
0,00,00,00,00,00,00,00,00,00,00,00,00,00,00,00,00,00,00,00,00,00,0
0,00,00,00,00,00,00,00,00,00,00,00,00,00,00,00,00,00,00,00,00,00,0
0,00,00,00,00,00,00,00,00,00,00,00,00,00,00,00,00,00,00,00,00,00,0
0,00,00,00,00,00,00,00,00,00,00,00,00,00,00,00,00,00,00,00,00,00,0
0,00,00,00,00,00,00,00,00,02,02,02,02,01,00,00,00,00,00,00,00,00,0
0,00,00,00,00,00,00,02,02,00,00,00,00,00,01,01,00,00,00,00,00,00,0
0,00,00,00,00,00,02,03,00,00,00,00,00,00,00,00,01,00,00,00,00,00,0
0,00,00,00,00,02,05,04,06,06,06,00,00,00,00,00,00,01,00,00,00,00,0
0,00,00,00,00,02,00,04,04,00,00,00,00,00,00,00,00,01,00,00,00,00,0
0,00,00,00,02,00,00,05,00,00,00,00,00,00,00,00,00,00,01,00,00,00,0
0,00,00,00,01,00,00,00,00,00,00,00,00,00,00,00,00,00,01,00,00,00,0
0,00,00,00,01,00,00,00,00,00,00,00,00,00,00,00,00,00,01,00,00,00,0
0,00,00,00,01,00,00,00,00,00,00,00,00,00,00,00,00,00,01,00,00,00,0
0,00,00,00,01,00,00,00,00,00,00,00,00,00,00,00,00,00,02,00,00,00,0
0,00,00,00,00,01,00,00,00,00,00,00,00,00,00,00,00,02,00,00,00,00,0
0,00,00,00,00,01,00,00,00,00,00,00,00,00,00,00,00,02,00,00,00,00,0
0,00,00,00,00,00,01,00,00,00,00,00,00,00,00,00,02,00,00,00,00,00,0
0,00,00,00,00,00,00,01,01,00,00,00,00,00,02,02,00,00,00,00,00,00,0
0,00,00,00,00,00,00,00,00,01,02,02,02,02,00,00,00,00,00,00,00,00,0
0,00,00,00,00,00,00,00,00,00,00,00,00,00,00,00,00,00,00,00,00,00,0
0,00,00,00,00,00,00,00,00,00,00,00,00,00,00,00,00,00,00,00,00,00,0
0,00,00,00,00,00,00,00,00,00,00,00,00,00,00,00,00,00,00,00,00,00,0
0,00,00,00,00,00,00,00,00,00,00,00,00,00,00,00,00,00,00,00,00,00,0
endlayer

# Tower Floor 1 (+10)
layer
0,00,00,00,00,00,00,00,00,00,00,00,00,00,00,00,00,00,00,00,00,00,0
0,00,00,00,00,00,00,00,00,00,00,00,00,00,00,00,00,00,00,00,00,00,0
0,00,00,00,00,00,00,00,00,00,00,00,00,00,00,00,00,00,00,00,00,00,0
0,00,00,00,00,00,00,00,00,00,00,00,00,00,00,00,00,00,00,00,00,00,0
0,00,00,00,00,00,00,00,00,02,02,02,01,01,00,00,00,00,00,00,00,00,0
0,00,00,00,00,00,00,02,02,00,00,00,00,00,01,01,00,00,00,00,00,00,0
0,00,00,00,00,00,02,00,00,00,00,00,00,00,00,00,01,00,00,00,00,00,0
0,00,00,00,00,02,04,00,06,00,00,00,00,00,00,00,00,01,00,00,00,00,0
0,00,00,00,00,02,04,03,06,00,00,00,00,00,00,00,00,01,00,00,00,00,0
0,00,00,00,02,00,05,04,00,00,00,00,00,00,00,00,00,00,01,00,00,00,0
0,00,00,00,02,00,00,05,00,00,00,00,00,00,00,00,00,00,01,00,00,00,0
0,00,00,00,01,00,00,00,00,00,00,00,00,00,00,00,00,00,01,00,00,00,0
0,00,00,00,01,00,00,00,00,00,00,00,00,00,00,00,00,00,02,00,00,00,0
0,00,00,00,01,00,00,00,00,00,00,00,00,00,00,00,00,00,02,00,00,00,0
0,00,00,00,00,01,00,00,00,00,00,00,00,00,00,00,00,02,00,00,00,00,0
0,00,00,00,00,01,00,00,00,00,00,00,00,00,00,00,00,02,00,00,00,00,0
0,00,00,00,00,00,01,00,00,00,00,00,00,00,00,00,02,00,00,00,00,00,0
0,00,00,00,00,00,00,01,01,00,00,00,00,00,02,02,00,00,00,00,00,00,0
0,00,00,00,00,00,00,00,00,01,01,02,02,02,00,00,00,00,00,00,00,00,0
0,00,00,00,00,00,00,00,00,00,00,00,00,00,00,00,00,00,00,00,00,00,0
0,00,00,00,00,00,00,00,00,00,00,00,00,00,00,00,00,00,00,00,00,00,0
0,00,00,00,00,00,00,00,00,00,00,00,00,00,00,00,00,00,00,00,00,00,0
0,00,00,00,00,00,00,00,00,00,00,00,00,00,00,00,00,00,00,00,00,00,0
endlayer

# Tower Floor 2 (+11)
layer
0,00,00,00,00,00,00,00,00,00,00,00,00,00,00,00,00,00,00,00,00,00,0
0,00,00,00,00,00,00,00,00,00,00,00,00,00,00,00,00,00,00,00,00,00,0
0,00,00,00,00,00,00,00,00,00,00,00,00,00,00,00,00,00,00,00,00,00,0
0,00,00,00,00,00,00,00,00,00,00,00,00,00,00,00,00,00,00,00,00,00,0
0,00,00,00,00,00,00,00,00,02,02,01,01,01,00,00,00,00,00,00,00,00,0
0,00,00,00,00,00,00,02,02,11,11,11,11,11,01,01,00,00,00,00,00,00,0
0,00,00,00,00,00,02,00,00,11,11,11,11,11,11,11,01,00,00,00,00,00,0
0,00,00,00,00,02,11,00,11,11,11,11,11,11,11,11,11,01,00,00,00,00,0
0,00,00,00,00,02,11,00,11,11,11,11,11,11,11,11,11,01,00,00,00,00,0
0,00,00,00,02,11,03,00,11,11,11,11,11,11,11,11,11,11,01,00,00,00,0
0,00,00,00,02,11,11,11,11,11,11,11,11,11,11,11,11,11,01,00,00,00,0
0,00,00,00,02,11,11,11,11,11,11,11,11,11,11,11,11,11,02,00,00,00,0
0,00,00,00,01,11,11,11,11,11,11,11,11,11,11,11,11,11,02,00,00,00,0
0,00,00,00,01,11,11,11,11,11,11,11,11,11,11,11,11,11,02,00,00,00,0
0,00,00,00,00,01,11,11,11,11,11,11,11,11,11,11,11,02,00,00,00,00,0
0,00,00,00,00,01,11,11,11,11,11,11,11,11,11,11,11,02,00,00,00,00,0
0,00,00,00,00,00,01,11,11,11,11,11,11,11,11,11,02,00,00,00,00,00,0
0,00,00,00,00,00,00,01,01,11,11,11,11,11,02,02,00,00,00,00,00,00,0
0,00,00,00,00,00,00,00,00,01,01,01,02,02,00,00,00,00,00,00,00,00,0
0,00,00,00,00,00,00,00,00,00,00,00,00,00,00,00,00,00,00,00,00,00,0
0,00,00,00,00,00,00,00,00,00,00,00,00,00,00,00,00,00,00,00,00,00,0
0,00,00,00,00,00,00,00,00,00,00,00,00,00,00,00,00,00,00,00,00,00,0
0,00,00,00,00,00,00,00,00,00,00,00,00,00,00,00,00,00,00,00,00,00,0
endlayer

# Tower Floor 2 (+12)
layer
0,00,00,00,00,00,00,00,00,00,00,00,00,00,00,00,00,00,00,00,00,00,0
0,00,00,00,00,00,00,00,00,00,00,00,00,00,00,00,00,00,00,00,00,00,0
0,00,00,00,00,00,00,00,00,00,00,00,00,00,00,00,00,00,00,00,00,00,0
0,00,00,00,00,00,00,00,00,00,00,00,00,00,00,00,00,00,00,00,00,00,0
0,00,00,00,00,00,00,00,00,00,00,00,00,00,00,00,00,00,00,00,00,00,0
0,00,00,00,00,00,00,00,00,02,01,01,01,01,00,00,00,00,00,00,00,00,0
0,00,00,00,00,00,00,02,02,00,00,15,00,00,01,01,00,00,00,00,00,00,0
0,00,00,00,00,00,02,00,00,00,00,00,00,00,00,00,01,00,00,00,00,00,0
0,00,00,00,00,00,02,00,00,00,00,00,00,00,05,05,01,00,00,00,00,00,0
0,00,00,00,00,02,00,00,00,00,00,00,00,00,04,04,03,01,00,00,00,00,0
0,00,00,00,00,02,00,00,00,00,00,00,00,00,04,04,00,02,00,00,00,00,0
0,00,00,00,00,02,00,00,00,00,00,14,00,00,00,00,00,02,00,00,00,00,0
0,00,00,00,00,02,00,00,00,00,00,00,00,00,00,00,00,02,00,00,00,00,0
0,00,00,00,00,01,00,00,00,00,00,00,00,00,00,00,00,02,00,00,00,00,0
0,00,00,00,00,00,01,00,00,00,00,00,00,00,00,00,02,00,00,00,00,00,0
0,00,00,00,00,00,01,00,00,00,00,00,00,00,00,00,02,00,00,00,00,00,0
0,00,00,00,00,00,00,01,01,00,00,15,00,00,02,02,00,00,00,00,00,00,0
0,00,00,00,00,00,00,00,00,01,01,01,01,02,00,00,00,00,00,00,00,00,0
0,00,00,00,00,00,00,00,00,00,00,00,00,00,00,00,00,00,00,00,00,00,0
0,00,00,00,00,00,00,00,00,00,00,00,00,00,00,00,00,00,00,00,00,00,0
0,00,00,00,00,00,00,00,00,00,00,00,00,00,00,00,00,00,00,00,00,00,0
0,00,00,00,00,00,00,00,00,00,00,00,00,00,00,00,00,00,00,00,00,00,0
0,00,00,00,00,00,00,00,00,00,00,00,00,00,00,00,00,00,00,00,00,00,0
endlayer

# Tower Floor 2 (+13)
layer
0,00,00,00,00,00,00,00,00,00,00,00,00,00,00,00,00,00,00,00,00,00,0
0,00,00,00,00,00,00,00,00,00,00,00,00,00,00,00,00,00,00,00,00,00,0
0,00,00,00,00,00,00,00,00,00,00,00,00,00,00,00,00,00,00,00,00,00,0
0,00,00,00,00,00,00,00,00,00,00,00,00,00,00,00,00,00,00,00,00,00,0
0,00,00,00,00,00,00,00,00,00,00,00,00,00,00,00,00,00,00,00,00,00,0
0,00,00,00,00,00,00,00,00,01,01,01,01,01,00,00,00,00,00,00,00,00,0
0,00,00,00,00,00,00,02,02,00,00,00,00,00,01,01,00,00,00,00,00,00,0
0,00,00,00,00,00,02,00,00,00,00,00,00,00,05,04,01,00,00,00,00,00,0
0,00,00,00,00,00,02,00,00,00,00,00,00,05,04,03,01,00,00,00,00,00,0
0,00,00,00,00,02,00,00,00,00,00,00,00,00,06,00,00,02,00,00,00,00,0
0,00,00,00,00,02,00,00,00,00,00,00,00,00,06,06,00,02,00,00,00,00,0
0,00,00,00,00,02,00,00,00,00,00,00,00,00,00,00,00,02,00,00,00,00,0
0,00,00,00,00,02,00,00,00,00,00,00,00,00,00,00,00,02,00,00,00,00,0
0,00,00,00,00,02,00,00,00,00,00,00,00,00,00,00,00,02,00,00,00,00,0
0,00,00,00,00,00,01,00,00,00,00,00,00,00,00,00,02,00,00,00,00,00,0
0,00,00,00,00,00,01,00,00,00,00,00,00,00,00,00,02,00,00,00,00,00,0
0,00,00,00,00,00,00,01,01,00,00,00,00,00,02,02,00,00,00,00,00,00,0
0,00,00,00,00,00,00,00,00,01,01,01,01,01,00,00,00,00,00,00,00,00,0
0,00,00,00,00,00,00,00,00,00,00,00,00,00,00,00,00,00,00,00,00,00,0
0,00,00,00,00,00,00,00,00,00,00,00,00,00,00,00,00,00,00,00,00,00,0
0,00,00,00,00,00,00,00,00,00,00,00,00,00,00,00,00,00,00,00,00,00,0
0,00,00,00,00,00,00,00,00,00,00,00,00,00,00,00,00,00,00,00,00,00,0
0,00,00,00,00,00,00,00,00,00,00,00,00,00,00,00,00,00,00,00,00,00,0
endlayer

# Tower Floor 2 (+14)
layer
0,00,00,00,00,00,00,00,00,00,00,00,00,00,00,00,00,00,00,00,00,00,0
0,00,00,00,00,00,00,00,00,00,00,00,00,00,00,00,00,00,00,00,00,00,0
0,00,00,00,00,00,00,00,00,00,00,00,00,00,00,00,00,00,00,00,00,00,0
0,00,00,00,00,00,00,00,00,00,00,00,00,00,00,00,00,00,00,00,00,00,0
0,00,00,00,00,00,00,00,00,00,00,00,00,00,00,00,00,00,00,00,00,00,0
0,00,00,00,00,00,00,00,00,01,01,01,01,01,00,00,00,00,00,00,00,00,0
0,00,00,00,00,00,00,02,01,00,00,00,00,05,01,01,00,00,00,00,00,00,0
0,00,00,00,00,00,02,00,00,00,00,00,05,04,03,00,01,00,00,00,00,00,0
0,00,00,00,00,00,02,00,00,00,00,00,04,04,06,00,02,00,00,00,00,00,0
0,00,00,00,00,02,00,00,00,00,00,00,00,00,06,00,00,02,00,00,00,00,0
0,00,00,00,00,02,00,00,00,00,00,00,00,00,00,00,00,02,00,00,00,00,0
0,00,00,00,00,02,00,00,00,00,00,00,00,00,00,00,00,02,00,00,00,00,0
0,00,00,00,00,02,00,00,00,00,00,00,00,00,00,00,00,02,00,00,00,00,0
0,00,00,00,00,02,00,00,00,00,00,00,00,00,00,00,00,02,00,00,00,00,0
0,00,00,00,00,00,02,00,00,00,00,00,00,00,00,00,02,00,00,00,00,00,0
0,00,00,00,00,00,01,00,00,00,00,00,00,00,00,00,02,00,00,00,00,00,0
0,00,00,00,00,00,00,01,01,00,00,00,00,00,01,02,00,00,00,00,00,00,0
0,00,00,00,00,00,00,00,00,01,01,01,01,01,00,00,00,00,00,00,00,00,0
0,00,00,00,00,00,00,00,00,00,00,00,00,00,00,00,00,00,00,00,00,00,0
0,00,00,00,00,00,00,00,00,00,00,00,00,00,00,00,00,00,00,00,00,00,0
0,00,00,00,00,00,00,00,00,00,00,00,00,00,00,00,00,00,00,00,00,00,0
0,00,00,00,00,00,00,00,00,00,00,00,00,00,00,00,00,00,00,00,00,00,0
0,00,00,00,00,00,00,00,00,00,00,00,00,00,00,00,00,00,00,00,00,00,0
endlayer

# Tower Floor 2 (+15)
layer
0,00,00,00,00,00,00,00,00,00,00,00,00,00,00,00,00,00,00,00,00,00,0
0,00,00,00,00,00,00,00,00,00,00,00,00,00,00,00,00,00,00,00,00,00,0
0,00,00,00,00,00,00,00,00,00,00,00,00,00,00,00,00,00,00,00,00,00,0
0,00,00,00,00,00,00,00,00,00,00,00,00,00,00,00,00,00,00,00,00,00,0
0,00,00,00,00,00,00,00,00,00,00,00,00,00,00,00,00,00,00,00,00,00,0
0,00,00,00,00,00,00,00,00,01,01,01,01,01,00,00,00,00,00,00,00,00,0
0,00,00,00,00,00,00,01,01,00,00,05,04,03,01,01,00,00,00,00,00,00,0
0,00,00,00,00,00,02,00,00,00,00,05,04,00,00,00,02,00,00,00,00,00,0
0,00,00,00,00,00,02,00,00,00,00,00,06,06,06,00,02,00,00,00,00,00,0
0,00,00,00,00,02,00,00,00,00,00,00,00,00,00,00,00,02,00,00,00,00,0
0,00,00,00,00,02,00,00,00,00,00,00,00,00,00,00,00,02,00,00,00,00,0
0,00,00,00,00,02,00,00,00,00,00,00,00,00,00,00,00,02,00,00,00,00,0
0,00,00,00,00,02,00,00,00,00,00,00,00,00,00,00,00,02,00,00,00,00,0
0,00,00,00,00,02,00,00,00,00,00,00,00,00,00,00,00,02,00,00,00,00,0
0,00,00,00,00,00,02,00,00,00,00,00,00,00,00,00,02,00,00,00,00,00,0
0,00,00,00,00,00,02,00,00,00,00,00,00,00,00,00,02,00,00,00,00,00,0
0,00,00,00,00,00,00,01,01,00,00,00,00,00,01,01,00,00,00,00,00,00,0
0,00,00,00,00,00,00,00,00,01,01,01,01,01,00,00,00,00,00,00,00,00,0
0,00,00,00,00,00,00,00,00,00,00,00,00,00,00,00,00,00,00,00,00,00,0
0,00,00,00,00,00,00,00,00,00,00,00,00,00,00,00,00,00,00,00,00,00,0
0,00,00,00,00,00,00,00,00,00,00,00,00,00,00,00,00,00,00,00,00,00,0
0,00,00,00,00,00,00,00,00,00,00,00,00,00,00,00,00,00,00,00,00,00,0
0,00,00,00,00,00,00,00,00,00,00,00,00,00,00,00,00,00,00,00,00,00,0
endlayer

# Tower Floor 2 (+16)
layer
0,00,00,00,00,00,00,00,00,00,00,00,00,00,00,00,00,00,00,00,00,00,0
0,00,00,00,00,00,00,00,00,00,00,00,00,00,00,00,00,00,00,00,00,00,0
0,00,00,00,00,00,00,00,00,00,00,00,00,00,00,00,00,00,00,00,00,00,0
0,00,00,00,00,00,00,00,00,00,00,00,00,00,00,00,00,00,00,00,00,00,0
0,00,00,00,00,00,00,00,00,00,00,00,00,00,00,00,00,00,00,00,00,00,0
0,00,00,00,00,00,00,00,00,01,01,01,01,01,00,00,00,00,00,00,00,00,0
0,00,00,00,00,00,00,01,01,05,04,03,00,00,01,02,00,00,00,00,00,00,0
0,00,00,00,00,00,01,00,00,00,04,04,06,00,00,00,02,00,00,00,00,00,0
0,00,00,00,00,00,02,00,00,00,05,00,06,00,00,00,02,00,00,00,00,00,0
0,00,00,00,00,02,00,00,00,00,00,00,00,00,00,00,00,02,00,00,00,00,0
0,00,00,00,00,02,00,00,00,00,00,00,00,00,00,00,00,02,00,00,00,00,0
0,00,00,00,00,02,00,00,00,00,00,00,00,00,00,00,00,02,00,00,00,00,0
0,00,00,00,00,02,00,00,00,00,00,00,00,00,00,00,00,02,00,00,00,00,0
0,00,00,00,00,02,00,00,00,00,00,00,00,00,00,00,00,02,00,00,00,00,0
0,00,00,00,00,00,02,00,00,00,00,00,00,00,00,00,02,00,00,00,00,00,0
0,00,00,00,00,00,02,00,00,00,00,00,00,00,00,00,01,00,00,00,00,00,0
0,00,00,00,00,00,00,02,01,00,00,00,00,00,01,01,00,00,00,00,00,00,0
0,00,00,00,00,00,00,00,00,01,01,01,01,01,00,00,00,00,00,00,00,00,0
0,00,00,00,00,00,00,00,00,00,00,00,00,00,00,00,00,00,00,00,00,00,0
0,00,00,00,00,00,00,00,00,00,00,00,00,00,00,00,00,00,00,00,00,00,0
0,00,00,00,00,00,00,00,00,00,00,00,00,00,00,00,00,00,00,00,00,00,0
0,00,00,00,00,00,00,00,00,00,00,00,00,00,00,00,00,00,00,00,00,00,0
0,00,00,00,00,00,00,00,00,00,00,00,00,00,00,00,00,00,00,00,00,00,0
endlayer

# Tower Floor 2 (+17)
layer
0,00,00,00,00,00,00,00,00,00,00,00,00,00,00,00,00,00,00,00,00,00,0
0,00,00,00,00,00,00,00,00,00,00,00,00,00,00,00,00,00,00,00,00,00,0
0,00,00,00,00,00,00,00,00,00,00,00,00,00,00,00,00,00,00,00,00,00,0
0,00,00,00,00,00,00,00,00,00,00,00,00,00,00,00,00,00,00,00,00,00,0
0,00,00,00,00,00,00,00,00,00,00,00,00,00,00,00,00,00,00,00,00,00,0
0,00,00,00,00,00,00,00,00,01,01,01,01,01,00,00,00,00,00,00,00,00,0
0,00,00,00,00,00,00,01,01,03,00,00,00,00,02,02,00,00,00,00,00,00,0
0,00,00,00,00,00,01,00,05,04,06,06,06,00,00,00,02,00,00,00,00,00,0
0,00,00,00,00,00,01,00,05,04,04,00,00,00,00,00,02,00,00,00,00,00,0
0,00,00,00,00,02,00,00,00,00,00,00,00,00,00,00,00,02,00,00,00,00,0
0,00,00,00,00,02,00,00,00,00,00,00,00,00,00,00,00,02,00,00,00,00,0
0,00,00,00,00,02,00,00,00,00,00,00,00,00,00,00,00,02,00,00,00,00,0
0,00,00,00,00,02,00,00,00,00,00,00,00,00,00,00,00,02,00,00,00,00,0
0,00,00,00,00,02,00,00,00,00,00,00,00,00,00,00,00,02,00,00,00,00,0
0,00,00,00,00,00,02,00,00,00,00,00,00,00,00,00,01,00,00,00,00,00,0
0,00,00,00,00,00,02,00,00,00,00,00,00,00,00,00,01,00,00,00,00,00,0
0,00,00,00,00,00,00,02,02,00,00,00,00,00,01,01,00,00,00,00,00,00,0
0,00,00,00,00,00,00,00,00,01,01,01,01,01,00,00,00,00,00,00,00,00,0
0,00,00,00,00,00,00,00,00,00,00,00,00,00,00,00,00,00,00,00,00,00,0
0,00,00,00,00,00,00,00,00,00,00,00,00,00,00,00,00,00,00,00,00,00,0
0,00,00,00,00,00,00,00,00,00,00,00,00,00,00,00,00,00,00,00,00,00,0
0,00,00,00,00,00,00,00,00,00,00,00,00,00,00,00,00,00,00,00,00,00,0
0,00,00,00,00,00,00,00,00,00,00,00,00,00,00,00,00,00,00,00,00,00,0
endlayer

# Tower Floor 2 (+18)
layer
0,00,00,00,00,00,00,00,00,00,00,00,00,00,00,00,00,00,00,00,00,00,0
0,00,00,00,00,00,00,00,00,00,00,00,00,00,00,00,00,00,00,00,00,00,0
0,00,00,00,00,00,00,00,00,00,00,00,00,00,00,00,00,00,00,00,00,00,0
0,00,00,00,00,00,00,00,00,00,00,00,00,00,00,00,00,00,00,00,00,00,0
0,00,00,00,00,00,00,00,00,00,00,00,00,00,00,00,00,00,00,00,00,00,0
0,00,00,00,00,00,00,00,00,01,01,01,01,02,00,00,00,00,00,00,00,00,0
0,00,00,00,00,00,00,01,01,00,00,00,00,00,02,02,00,00,00,00,00,00,0
0,00,00,00,00,00,01,04,03,00,06,00,00,00,00,00,02,00,00,00,00,00,0
0,00,00,00,00,00,01,05,04,06,06,00,00,00,00,00,02,00,00,00,00,00,0
0,00,00,00,00,01,00,00,05,00,00,00,00,00,00,00,00,02,00,00,00,00,0
0,00,00,00,00,02,00,00,00,00,00,00,00,00,00,00,00,02,00,00,00,00,0
0,00,00,00,00,02,00,00,00,00,00,00,00,00,00,00,00,02,00,00,00,00,0
0,00,00,00,00,02,00,00,00,00,00,00,00,00,00,00,00,02,00,00,00,00,0
0,00,00,00,00,02,00,00,00,00,00,00,00,00,00,00,00,01,00,00,00,00,0
0,00,00,00,00,00,02,00,00,00,00,00,00,00,00,00,01,00,00,00,00,00,0
0,00,00,00,00,00,02,00,00,00,00,00,00,00,00,00,01,00,00,00,00,00,0
0,00,00,00,00,00,00,02,02,00,00,00,00,00,01,01,00,00,00,00,00,00,0
0,00,00,00,00,00,00,00,00,02,01,01,01,01,00,00,00,00,00,00,00,00,0
0,00,00,00,00,00,00,00,00,00,00,00,00,00,00,00,00,00,00,00,00,00,0
0,00,00,00,00,00,00,00,00,00,00,00,00,00,00,00,00,00,00,00,00,00,0
0,00,00,00,00,00,00,00,00,00,00,00,00,00,00,00,00,00,00,00,00,00,0
0,00,00,00,00,00,00,00,00,00,00,00,00,00,00,00,00,00,00,00,00,00,0
0,00,00,00,00,00,00,00,00,00,00,00,00,00,00,00,00,00,00,00,00,00,0
endlayer

# Tower Floor 2 (+19)
layer
0,00,00,00,00,00,00,00,00,00,00,00,00,00,00,00,00,00,00,00,00,00,0
0,00,00,00,00,00,00,00,00,00,00,00,00,00,00,00,00,00,00,00,00,00,0
0,00,00,00,00,00,00,00,00,00,00,00,00,00,00,00,00,00,00,00,00,00,0
0,00,00,00,00,00,00,00,00,00,00,00,00,00,00,00,00,00,00,00,00,00,0
0,00,00,00,00,00,00,00,00,00,00,00,00,00,00,00,00,00,00,00,00,00,0
0,00,00,00,00,00,00,00,00,01,01,01,02,02,00,00,00,00,00,00,00,00,0
0,00,00,00,00,00,00,01,01,00,00,00,00,00,02,02,00,00,00,00,00,00,0
0,00,00,00,00,00,01,04,00,00,00,00,00,00,00,00,02,00,00,00,00,00,0
0,00,00,00,00,00,01,04,00,06,00,00,00,00,00,00,02,00,00,00,00,00,0
0,00,00,00,00,01,05,04,03,04,00,00,00,00,00,00,00,02,00,00,00,00,0
0,00,00,00,00,01,00,05,04,04,00,00,00,00,00,00,00,02,00,00,00,00,0
0,00,00,00,00,02,00,00,05,00,00,00,00,00,00,00,00,02,00,00,00,00,0
0,00,00,00,00,02,00,00,00,00,00,00,00,00,00,00,00,01,00,00,00,00,0
0,00,00,00,00,02,00,00,00,00,00,00,00,00,00,00,00,01,00,00,00,00,0
0,00,00,00,00,00,02,00,00,00,00,00,00,00,00,00,01,00,00,00,00,00,0
0,00,00,00,00,00,02,00,00,00,00,00,00,00,00,00,01,00,00,00,00,00,0
0,00,00,00,00,00,00,02,02,00,00,00,00,00,01,01,00,00,00,00,00,00,0
0,00,00,00,00,00,00,00,00,02,02,01,01,01,00,00,00,00,00,00,00,00,0
0,00,00,00,00,00,00,00,00,00,00,00,00,00,00,00,00,00,00,00,00,00,0
0,00,00,00,00,00,00,00,00,00,00,00,00,00,00,00,00,00,00,00,00,00,0
0,00,00,00,00,00,00,00,00,00,00,00,00,00,00,00,00,00,00,00,00,00,0
0,00,00,00,00,00,00,00,00,00,00,00,00,00,00,00,00,00,00,00,00,00,0
0,00,00,00,00,00,00,00,00,00,00,00,00,00,00,00,00,00,00,00,00,00,0
endlayer

# Tower Floor 3 (+20)
layer
0,00,00,00,00,00,00,00,00,00,00,00,00,00,00,00,00,00,00,00,00,00,0
0,00,00,00,00,00,00,00,00,00,00,00,00,00,00,00,00,00,00,00,00,00,0
0,00,00,00,00,00,00,00,00,00,00,00,00,00,00,00,00,00,00,00,00,00,0
0,00,00,00,00,00,00,00,00,00,00,00,00,00,00,00,00,00,00,00,00,00,0
0,00,00,00,00,00,00,00,00,00,00,00,00,00,00,00,00,00,00,00,00,00,0
0,00,00,00,00,00,00,00,00,01,01,02,02,02,00,00,00,00,00,00,00,00,0
0,00,00,00,00,00,00,01,01,11,11,11,11,11,02,02,00,00,00,00,00,00,0
0,00,00,00,00,00,01,11,00,00,11,11,11,11,11,11,02,00,00,00,00,00,0
0,00,00,00,00,00,01,11,00,11,11,11,11,11,11,11,02,00,00,00,00,00,0
0,00,00,00,00,01,11,00,00,11,11,11,11,11,11,11,11,02,00,00,00,00,0
0,00,00,00,00,01,11,03,11,11,11,11,11,11,11,11,11,02,00,00,00,00,0
0,00,00,00,00,01,11,11,11,11,11,11,11,11,11,11,11,01,00,00,00,00,0
0,00,00,00,00,02,11,11,11,11,11,11,11,11,11,11,11,01,00,00,00,00,0
0,00,00,00,00,02,11,11,11,11,11,11,11,11,11,11,11,01,00,00,00,00,0
0,00,00,00,00,00,02,11,11,11,11,11,11,11,11,11,01,00,00,00,00,00,0
0,00,00,00,00,00,02,11,11,11,11,11,11,11,11,11,01,00,00,00,00,00,0
0,00,00,00,00,00,00,02,02,11,11,11,11,11,01,01,00,00,00,00,00,00,0
0,00,00,00,00,00,00,00,00,02,02,02,01,01,00,00,00,00,00,00,00,00,0
0,00,00,00,00,00,00,00,00,00,00,00,00,00,00,00,00,00,00,00,00,00,0
0,00,00,00,00,00,00,00,00,00,00,00,00,00,00,00,00,00,00,00,00,00,0
0,00,00,00,00,00,00,00,00,00,00,00,00,00,00,00,00,00,00,00,00,00,0
0,00,00,00,00,00,00,00,00,00,00,00,00,00,00,00,00,00,00,00,00,00,0
0,00,00,00,00,00,00,00,00,00,00,00,00,00,00,00,00,00,00,00,00,00,0
endlayer

# Tower Floor 3 (+21)
layer
0,00,00,00,00,00,00,00,00,00,00,00,00,00,00,00,00,00,00,00,00,00,0
0,00,00,00,00,00,00,00,00,00,00,00,00,00,00,00,00,00,00,00,00,00,0
0,00,00,00,00,00,00,00,00,00,00,00,00,00,00,00,00,00,00,00,00,00,0
0,00,00,00,00,00,00,00,00,00,00,00,00,00,00,00,00,00,00,00,00,00,0
0,00,00,00,00,00,00,00,00,00,00,00,00,00,00,00,00,00,00,00,00,00,0
0,00,00,00,00,00,00,00,00,00,00,00,00,00,00,00,00,00,00,00,00,00,0
0,00,00,00,00,00,00,00,00,01,02,02,02,02,00,00,00,00,00,00,00,00,0
0,00,00,00,00,00,00,01,01,00,00,00,00,00,02,02,00,00,00,00,00,00,0
0,00,00,00,00,00,00,01,00,00,00,00,00,00,05,02,00,00,00,00,00,00,0
0,00,00,00,00,00,01,00,00,00,00,00,05,04,04,03,02,00,00,00,00,00,0
0,00,00,00,00,00,01,00,00,00,00,00,00,04,04,00,01,00,00,00,00,00,0
0,00,00,00,00,00,01,00,00,00,00,14,00,00,00,00,01,00,00,00,00,00,0
0,00,00,00,00,00,01,00,00,00,00,00,00,00,00,00,01,00,00,00,00,00,0
0,00,00,00,00,00,02,00,00,00,00,00,00,00,00,00,01,00,00,00,00,00,0
0,00,00,00,00,00,00,02,00,00,00,00,00,00,00,01,00,00,00,00,00,00,0
0,00,00,00,00,00,00,02,02,00,00,15,00,00,01,01,00,00,00,00,00,00,0
0,00,00,00,00,00,00,00,00,02,02,02,02,01,00,00,00,00,00,00,00,00,0
0,00,00,00,00,00,00,00,00,00,00,00,00,00,00,00,00,00,00,00,00,00,0
0,00,00,00,00,00,00,00,00,00,00,00,00,00,00,00,00,00,00,00,00,00,0
0,00,00,00,00,00,00,00,00,00,00,00,00,00,00,00,00,00,00,00,00,00,0
0,00,00,00,00,00,00,00,00,00,00,00,00,00,00,00,00,00,00,00,00,00,0
0,00,00,00,00,00,00,00,00,00,00,00,00,00,00,00,00,00,00,00,00,00,0
0,00,00,00,00,00,00,00,00,00,00,00,00,00,00,00,00,00,00,00,00,00,0
endlayer

# Tower Floor 3 (+22)
layer
0,00,00,00,00,00,00,00,00,00,00,00,00,00,00,00,00,00,00,00,00,00,0
0,00,00,00,00,00,00,00,00,00,00,00,00,00,00,00,00,00,00,00,00,00,0
0,00,00,00,00,00,00,00,00,00,00,00,00,00,00,00,00,00,00,00,00,00,0
0,00,00,00,00,00,00,00,00,00,00,00,00,00,00,00,00,00,00,00,00,00,0
0,00,00,00,00,00,00,00,00,00,00,00,00,00,00,00,00,00,00,00,00,00,0
0,00,00,00,00,00,00,00,00,00,00,00,00,00,00,00,00,00,00,00,00,00,0
0,00,00,00,00,00,00,00,00,02,02,02,02,02,00,00,00,00,00,00,00,00,0
0,00,00,00,00,00,00,01,01,00,00,00,00,05,02,02,00,00,00,00,00,00,0
0,00,00,00,00,00,00,01,00,00,00,05,04,04,03,02,00,00,00,00,00,00,0
0,00,00,00,00,00,01,00,00,00,00,00,04,06,00,00,01,00,00,00,00,00,0
0,00,00,00,00,00,01,00,00,00,00,00,00,06,06,00,01,00,00,00,00,00,0
0,00,00,00,00,00,01,00,00,00,00,00,00,00,00,00,01,00,00,00,00,00,0
0,00,00,00,00,00,01,00,00,00,00,00,00,00,00,00,01,00,00,00,00,00,0
0,00,00,00,00,00,01,00,00,00,00,00,00,00,00,00,01,00,00,00,00,00,0
0,00,00,00,00,00,00,02,00,00,00,00,00,00,00,01,00,00,00,00,00,00,0
0,00,00,00,00,00,00,02,02,00,00,00,00,00,01,01,00,00,00,00,00,00,0
0,00,00,00,00,00,00,00,00,02,02,02,02,02,00,00,00,00,00,00,00,00,0
0,00,00,00,00,00,00,00,00,00,00,00,00,00,00,00,00,00,00,00,00,00,0
0,00,00,00,00,00,00,00,00,00,00,00,00,00,00,00,00,00,00,00,00,00,0
0,00,00,00,00,00,00,00,00,00,00,00,00,00,00,00,00,00,00,00,00,00,0
0,00,00,00,00,00,00,00,00,00,00,00,00,00,00,00,00,00,00,00,00,00,0
0,00,00,00,00,00,00,00,00,00,00,00,00,00,00,00,00,00,00,00,00,00,0
0,00,00,00,00,00,00,00,00,00,00,00,00,00,00,00,00,00,00,00,00,00,0
endlayer

# Tower Floor 3 (+23)
layer
0,00,00,00,00,00,00,00,00,00,00,00,00,00,00,00,00,00,00,00,00,00,0
0,00,00,00,00,00,00,00,00,00,00,00,00,00,00,00,00,00,00,00,00,00,0
0,00,00,00,00,00,00,00,00,00,00,00,00,00,00,00,00,00,00,00,00,00,0
0,00,00,00,00,00,00,00,00,00,00,00,00,00,00,00,00,00,00,00,00,00,0
0,00,00,00,00,00,00,00,00,00,00,00,00,00,00,00,00,00,00,00,00,00,0
0,00,00,00,00,00,00,00,00,00,00,00,00,00,00,00,00,00,00,00,00,00,0
0,00,00,00,00,00,00,00,00,02,02,02,02,02,00,00,00,00,00,00,00,00,0
0,00,00,00,00,00,00,01,02,00,00,05,04,03,02,02,00,00,00,00,00,00,0
0,00,00,00,00,00,00,01,00,00,05,04,06,00,00,01,00,00,00,00,00,00,0
0,00,00,00,00,00,01,00,00,00,00,00,06,06,00,00,01,00,00,00,00,00,0
0,00,00,00,00,00,01,00,00,00,00,00,00,00,00,00,01,00,00,00,00,00,0
0,00,00,00,00,00,01,00,00,00,00,00,00,00,00,00,01,00,00,00,00,00,0
0,00,00,00,00,00,01,00,00,00,00,00,00,00,00,00,01,00,00,00,00,00,0
0,00,00,00,00,00,01,00,00,00,00,00,00,00,00,00,01,00,00,00,00,00,0
0,00,00,00,00,00,00,01,00,00,00,00,00,00,00,01,00,00,00,00,00,00,0
0,00,00,00,00,00,00,02,02,00,00,00,00,00,02,01,00,00,00,00,00,00,0
0,00,00,00,00,00,00,00,00,02,02,02,02,02,00,00,00,00,00,00,00,00,0
0,00,00,00,00,00,00,00,00,00,00,00,00,00,00,00,00,00,00,00,00,00,0
0,00,00,00,00,00,00,00,00,00,00,00,00,00,00,00,00,00,00,00,00,00,0
0,00,00,00,00,00,00,00,00,00,00,00,00,00,00,00,00,00,00,00,00,00,0
0,00,00,00,00,00,00,00,00,00,00,00,00,00,00,00,00,00,00,00,00,00,0
0,00,00,00,00,00,00,00,00,00,00,00,00,00,00,00,00,00,00,00,00,00,0
0,00,00,00,00,00,00,00,00,00,00,00,00,00,00,00,00,00,00,00,00,00,0
endlayer

# Tower Floor 3 (+24)
layer
0,00,00,00,00,00,00,00,00,00,00,00,00,00,00,00,00,00,00,00,00,00,0
0,00,00,00,00,00,00,00,00,00,00,00,00,00,00,00,00,00,00,00,00,00,0
0,00,00,00,00,00,00,00,00,00,00,00,00,00,00,00,00,00,00,00,00,00,0
0,00,00,00,00,00,00,00,00,00,00,00,00,00,00,00,00,00,00,00,00,00,0
0,00,00,00,00,00,00,00,00,00,00,00,00,00,00,00,00,00,00,00,00,00,0
0,00,00,00,00,00,00,00,00,00,00,00,00,00,00,00,00,00,00,00,00,00,0
0,00,00,00,00,00,00,00,00,02,02,02,02,02,00,00,00,00,00,00,00,00,0
0,00,00,00,00,00,00,02,02,05,04,03,00,00,02,01,00,00,00,00,00,00,0
0,00,00,00,00,00,00,01,00,00,04,06,06,00,00,01,00,00,00,00,00,00,0
0,00,00,00,00,00,01,00,00,00,05,00,00,00,00,00,01,00,00,00,00,00,0
0,00,00,00,00,00,01,00,00,00,00,00,00,00,00,00,01,00,00,00,00,00,0
0,00,00,00,00,00,01,00,00,00,00,00,00,00,00,00,01,00,00,00,00,00,0
0,00,00,00,00,00,01,00,00,00,00,00,00,00,00,00,01,00,00,00,00,00,0
0,00,00,00,00,00,01,00,00,00,00,00,00,00,00,00,01,00,00,00,00,00,0
0,00,00,00,00,00,00,01,00,00,00,00,00,00,00,01,00,00,00,00,00,00,0
0,00,00,00,00,00,00,01,02,00,00,00,00,00,02,02,00,00,00,00,00,00,0
0,00,00,00,00,00,00,00,00,02,02,02,02,02,00,00,00,00,00,00,00,00,0
0,00,00,00,00,00,00,00,00,00,00,00,00,00,00,00,00,00,00,00,00,00,0
0,00,00,00,00,00,00,00,00,00,00,00,00,00,00,00,00,00,00,00,00,00,0
0,00,00,00,00,00,00,00,00,00,00,00,00,00,00,00,00,00,00,00,00,00,0
0,00,00,00,00,00,00,00,00,00,00,00,00,00,00,00,00,00,00,00,00,00,0
0,00,00,00,00,00,00,00,00,00,00,00,00,00,00,00,00,00,00,00,00,00,0
0,00,00,00,00,00,00,00,00,00,00,00,00,00,00,00,00,00,00,00,00,00,0
endlayer

# Tower Floor 3 (+25)
layer
0,00,00,00,00,00,00,00,00,00,00,00,00,00,00,00,00,00,00,00,00,00,0
0,00,00,00,00,00,00,00,00,00,00,00,00,00,00,00,00,00,00,00,00,00,0
0,00,00,00,00,00,00,00,00,00,00,00,00,00,00,00,00,00,00,00,00,00,0
0,00,00,00,00,00,00,00,00,00,00,00,00,00,00,00,00,00,00,00,00,00,0
0,00,00,00,00,00,00,00,00,00,00,00,00,00,00,00,00,00,00,00,00,00,0
0,00,00,00,00,00,00,00,00,00,00,00,00,00,00,00,00,00,00,00,00,00,0
0,00,00,00,00,00,00,00,00,02,02,02,02,02,00,00,00,00,00,00,00,00,0
0,00,00,00,00,00,00,02,02,03,00,00,00,00,01,01,00,00,00,00,00,00,0
0,00,00,00,00,00,00,02,05,04,06,06,00,00,00,01,00,00,00,00,00,00,0
0,00,00,00,00,00,01,00,00,04,04,00,00,00,00,00,01,00,00,00,00,00,0
0,00,00,00,00,00,01,00,00,05,00,00,00,00,00,00,01,00,00,00,00,00,0
0,00,00,00,00,00,01,00,00,00,00,00,00,00,00,00,01,00,00,00,00,00,0
0,00,00,00,00,00,01,00,00,00,00,00,00,00,00,00,01,00,00,00,00,00,0
0,00,00,00,00,00,01,00,00,00,00,00,00,00,00,00,01,00,00,00,00,00,0
0,00,00,00,00,00,00,01,00,00,00,00,00,00,00,02,00,00,00,00,00,00,0
0,00,00,00,00,00,00,01,01,00,00,00,00,00,02,02,00,00,00,00,00,00,0
0,00,00,00,00,00,00,00,00,02,02,02,02,02,00,00,00,00,00,00,00,00,0
0,00,00,00,00,00,00,00,00,00,00,00,00,00,00,00,00,00,00,00,00,00,0
0,00,00,00,00,00,00,00,00,00,00,00,00,00,00,00,00,00,00,00,00,00,0
0,00,00,00,00,00,00,00,00,00,00,00,00,00,00,00,00,00,00,00,00,00,0
0,00,00,00,00,00,00,00,00,00,00,00,00,00,00,00,00,00,00,00,00,00,0
0,00,00,00,00,00,00,00,00,00,00,00,00,00,00,00,00,00,00,00,00,00,0
0,00,00,00,00,00,00,00,00,00,00,00,00,00,00,00,00,00,00,00,00,00,0
endlayer

# Tower Floor 3 (+26)
layer
0,00,00,00,00,00,00,00,00,00,00,00,00,00,00,00,00,00,00,00,00,00,0
0,00,00,00,00,00,00,00,00,00,00,00,00,00,00,00,00,00,00,00,00,00,0
0,00,00,00,00,00,00,00,00,00,00,00,00,00,00,00,00,00,00,00,00,00,0
0,00,00,00,00,00,00,00,00,00,00,00,00,00,00,00,00,00,00,00,00,00,0
0,00,00,00,00,00,00,00,00,00,00,00,00,00,00,00,00,00,00,00,00,00,0
0,00,00,00,00,00,00,00,00,00,00,00,00,00,00,00,00,00,00,00,00,00,0
0,00,00,00,00,00,00,00,00,02,02,02,02,01,00,00,00,00,00,00,00,00,0
0,00,00,00,00,00,00,02,02,00,00,00,00,00,01,01,00,00,00,00,00,00,0
0,00,00,00,00,00,00,02,03,00,06,00,00,00,00,01,00,00,00,00,00,00,0
0,00,00,00,00,00,02,00,04,06,06,00,00,00,00,00,01,00,00,00,00,00,0
0,00,00,00,00,00,01,00,04,04,05,05,05,00,00,00,01,00,00,00,00,00,0
0,00,00,00,00,00,01,00,05,05,05,04,05,00,00,00,01,00,00,00,00,00,0
0,00,00,00,00,00,01,00,00,00,05,05,05,00,00,00,01,00,00,00,00,00,0
0,00,00,00,00,00,01,00,00,00,00,00,00,00,00,00,02,00,00,00,00,00,0
0,00,00,00,00,00,00,01,00,00,00,00,00,00,00,02,00,00,00,00,00,00,0
0,00,00,00,00,00,00,01,01,00,00,00,00,00,02,02,00,00,00,00,00,00,0
0,00,00,00,00,00,00,00,00,01,02,02,02,02,00,00,00,00,00,00,00,00,0
0,00,00,00,00,00,00,00,00,00,00,00,00,00,00,00,00,00,00,00,00,00,0
0,00,00,00,00,00,00,00,00,00,00,00,00,00,00,00,00,00,00,00,00,00,0
0,00,00,00,00,00,00,00,00,00,00,00,00,00,00,00,00,00,00,00,00,00,0
0,00,00,00,00,00,00,00,00,00,00,00,00,00,00,00,00,00,00,00,00,00,0
0,00,00,00,00,00,00,00,00,00,00,00,00,00,00,00,00,00,00,00,00,00,0
0,00,00,00,00,00,00,00,00,00,00,00,00,00,00,00,00,00,00,00,00,00,0
endlayer

# Lighthouse Top (+26)
layer
0,00,00,00,00,00,00,00,00,00,00,00,00,00,00,00,00,00,00,00,00,00,0
0,00,00,00,00,00,00,00,00,00,00,00,00,00,00,00,00,00,00,00,00,00,0
0,00,00,00,00,00,00,00,00,00,00,00,00,00,00,00,00,00,00,00,00,00,0
0,00,00,00,00,00,00,00,00,00,00,00,00,00,00,00,00,00,00,00,00,00,0
0,00,00,00,00,00,00,00,00,00,00,00,00,00,00,00,00,00,00,00,00,00,0
0,00,00,00,00,00,00,00,05,05,05,05,05,05,05,00,00,00,00,00,00,00,0
0,00,00,00,00,00,00,05,05,04,04,04,04,04,05,05,00,00,00,00,00,00,0
0,00,00,00,00,00,05,05,04,00,00,00,00,00,04,05,05,00,00,00,00,00,0
0,00,00,00,00,05,05,04,00,00,11,11,11,11,04,04,05,05,00,00,00,00,0
0,00,00,00,00,05,04,04,00,00,11,11,11,11,11,04,04,05,00,00,00,00,0
0,00,00,00,00,05,04,04,03,11,13,13,13,11,11,04,04,05,00,00,00,00,0
0,00,00,00,00,05,04,04,11,11,13,04,13,11,11,04,04,05,00,00,00,00,0
0,00,00,00,00,05,04,04,11,11,13,13,13,11,11,04,04,05,00,00,00,00,0
0,00,00,00,00,05,04,04,11,11,11,11,11,11,11,04,04,05,00,00,00,00,0
0,00,00,00,00,05,05,04,04,11,11,11,11,11,04,04,05,05,00,00,00,00,0
0,00,00,00,00,00,05,05,04,04,04,04,04,04,04,05,05,00,00,00,00,00,0
0,00,00,00,00,00,00,05,05,04,04,04,04,04,05,05,00,00,00,00,00,00,0
0,00,00,00,00,00,00,00,05,05,05,05,05,05,05,00,00,00,00,00,00,00,0
0,00,00,00,00,00,00,00,00,00,00,00,00,00,00,00,00,00,00,00,00,00,0
0,00,00,00,00,00,00,00,00,00,00,00,00,00,00,00,00,00,00,00,00,00,0
0,00,00,00,00,00,00,00,00,00,00,00,00,00,00,00,00,00,00,00,00,00,0
0,00,00,00,00,00,00,00,00,00,00,00,00,00,00,00,00,00,00,00,00,00,0
0,00,00,00,00,00,00,00,00,00,00,00,00,00,00,00,00,00,00,00,00,00,0
endlayer

# Lighthouse Top (+27)
layer
0,00,00,00,00,00,00,00,00,00,00,00,00,00,00,00,00,00,00,00,00,00,0
0,00,00,00,00,00,00,00,00,00,00,00,00,00,00,00,00,00,00,00,00,00,0
0,00,00,00,00,00,00,00,00,00,00,00,00,00,00,00,00,00,00,00,00,00,0
0,00,00,00,00,00,00,00,00,00,00,00,00,00,00,00,00,00,00,00,00,00,0
0,00,00,00,00,00,00,00,00,00,00,00,00,00,00,00,00,00,00,00,00,00,0
0,00,00,00,00,00,00,00,06,06,06,06,06,06,06,00,00,00,00,00,00,00,0
0,00,00,00,00,00,00,06,06,00,00,15,00,00,06,06,00,00,00,00,00,00,0
0,00,00,00,00,00,06,06,00,00,00,00,00,00,00,06,06,00,00,00,00,00,0
0,00,00,00,00,06,06,00,00,00,00,00,00,00,00,00,06,06,00,00,00,00,0
0,00,00,00,00,06,00,00,00,00,12,12,12,00,00,00,00,06,00,00,00,00,0
0,00,00,00,00,06,00,00,00,12,07,07,07,12,00,00,00,06,00,00,00,00,0
0,00,00,00,00,06,15,00,00,12,07,12,07,12,00,00,15,06,00,00,00,00,0
0,00,00,00,00,06,00,00,00,12,07,07,07,12,00,00,00,06,00,00,00,00,0
0,00,00,00,00,06,00,00,00,00,12,12,12,00,00,00,00,06,00,00,00,00,0
0,00,00,00,00,06,06,00,00,00,00,00,00,00,00,00,06,06,00,00,00,00,0
0,00,00,00,00,00,06,06,00,00,00,00,00,00,00,06,06,00,00,00,00,00,0
0,00,00,00,00,00,00,06,06,00,00,15,00,00,06,06,00,00,00,00,00,00,0
0,00,00,00,00,00,00,00,06,06,06,06,06,06,06,00,00,00,00,00,00,00,0
0,00,00,00,00,00,00,00,00,00,00,00,00,00,00,00,00,00,00,00,00,00,0
0,00,00,00,00,00,00,00,00,00,00,00,00,00,00,00,00,00,00,00,00,00,0
0,00,00,00,00,00,00,00,00,00,00,00,00,00,00,00,00,00,00,00,00,00,0
0,00,00,00,00,00,00,00,00,00,00,00,00,00,00,00,00,00,00,00,00,00,0
0,00,00,00,00,00,00,00,00,00,00,00,00,00,00,00,00,00,00,00,00,00,0
endlayer

# Lighthouse Top (+28)
layer
0,00,00,00,00,00,00,00,00,00,00,00,00,00,00,00,00,00,00,00,00,00,0
0,00,00,00,00,00,00,00,00,00,00,00,00,00,00,00,00,00,00,00,00,00,0
0,00,00,00,00,00,00,00,00,00,00,00,00,00,00,00,00,00,00,00,00,00,0
0,00,00,00,00,00,00,00,00,00,00,00,00,00,00,00,00,00,00,00,00,00,0
0,00,00,00,00,00,00,00,00,00,00,00,00,00,00,00,00,00,00,00,00,00,0
0,00,00,00,00,00,00,00,06,06,06,06,06,06,06,00,00,00,00,00,00,00,0
0,00,00,00,00,00,00,06,06,00,00,00,00,00,06,06,00,00,00,00,00,00,0
0,00,00,00,00,00,06,06,00,00,00,00,00,00,00,06,06,00,00,00,00,00,0
0,00,00,00,00,06,06,00,00,00,00,00,00,00,00,00,06,06,00,00,00,00,0
0,00,00,00,00,06,00,00,00,00,12,12,12,00,00,00,00,06,00,00,00,00,0
0,00,00,00,00,06,00,00,00,12,12,07,12,12,00,00,00,06,00,00,00,00,0
0,00,00,00,00,06,00,00,00,12,07,13,07,12,00,00,00,06,00,00,00,00,0
0,00,00,00,00,06,00,00,00,12,12,07,12,12,00,00,00,06,00,00,00,00,0
0,00,00,00,00,06,00,00,00,00,12,12,12,00,00,00,00,06,00,00,00,00,0
0,00,00,00,00,06,06,00,00,00,00,00,00,00,00,00,06,06,00,00,00,00,0
0,00,00,00,00,00,06,06,00,00,00,00,00,00,00,06,06,00,00,00,00,00,0
0,00,00,00,00,00,00,06,06,00,00,00,00,00,06,06,00,00,00,00,00,00,0
0,00,00,00,00,00,00,00,06,06,06,06,06,06,06,00,00,00,00,00,00,00,0
0,00,00,00,00,00,00,00,00,00,00,00,00,00,00,00,00,00,00,00,00,00,0
0,00,00,00,00,00,00,00,00,00,00,00,00,00,00,00,00,00,00,00,00,00,0
0,00,00,00,00,00,00,00,00,00,00,00,00,00,00,00,00,00,00,00,00,00,0
0,00,00,00,00,00,00,00,00,00,00,00,00,00,00,00,00,00,00,00,00,00,0
0,00,00,00,00,00,00,00,00,00,00,00,00,00,00,00,00,00,00,00,00,00,0
endlayer

# Lighthouse Top (+29)
layer
0,00,00,00,00,00,00,00,00,00,00,00,00,00,00,00,00,00,00,00,00,00,0
0,00,00,00,00,00,00,00,00,00,00,00,00,00,00,00,00,00,00,00,00,00,0
0,00,00,00,00,00,00,00,00,00,00,00,00,00,00,00,00,00,00,00,00,00,0
0,00,00,00,00,00,00,00,00,00,00,00,00,00,00,00,00,00,00,00,00,00,0
0,00,00,00,00,00,00,00,00,00,00,00,00,00,00,00,00,00,00,00,00,00,0
0,00,00,00,00,00,00,00,06,06,06,06,06,06,06,00,00,00,00,00,00,00,0
0,00,00,00,00,00,00,06,06,00,00,00,00,00,06,06,00,00,00,00,00,00,0
0,00,00,00,00,00,06,06,00,00,00,00,00,00,00,06,06,00,00,00,00,00,0
0,00,00,00,00,06,06,00,00,00,00,00,00,00,00,00,06,06,00,00,00,00,0
0,00,00,00,00,06,00,00,00,00,12,12,12,00,00,00,00,06,00,00,00,00,0
0,00,00,00,00,06,00,00,00,12,07,07,07,12,00,00,00,06,00,00,00,00,0
0,00,00,00,00,06,00,00,00,12,07,12,07,12,00,00,00,06,00,00,00,00,0
0,00,00,00,00,06,00,00,00,12,07,07,07,12,00,00,00,06,00,00,00,00,0
0,00,00,00,00,06,00,00,00,00,12,12,12,00,00,00,00,06,00,00,00,00,0
0,00,00,00,00,06,06,00,00,00,00,00,00,00,00,00,06,06,00,00,00,00,0
0,00,00,00,00,00,06,06,00,00,00,00,00,00,00,06,06,00,00,00,00,00,0
0,00,00,00,00,00,00,06,06,00,00,00,00,00,06,06,00,00,00,00,00,00,0
0,00,00,00,00,00,00,00,06,06,06,06,06,06,06,00,00,00,00,00,00,00,0
0,00,00,00,00,00,00,00,00,00,00,00,00,00,00,00,00,00,00,00,00,00,0
0,00,00,00,00,00,00,00,00,00,00,00,00,00,00,00,00,00,00,00,00,00,0
0,00,00,00,00,00,00,00,00,00,00,00,00,00,00,00,00,00,00,00,00,00,0
0,00,00,00,00,00,00,00,00,00,00,00,00,00,00,00,00,00,00,00,00,00,0
0,00,00,00,00,00,00,00,00,00,00,00,00,00,00,00,00,00,00,00,00,00,0
endlayer

# Lighthouse Roof (+30)
layer
0,00,00,00,00,00,00,00,00,00,00,00,00,00,00,00,00,00,00,00,00,00,0
0,00,00,00,00,00,00,00,00,00,00,00,00,00,00,00,00,00,00,00,00,00,0
0,00,00,00,00,00,00,00,00,00,00,00,00,00,00,00,00,00,00,00,00,00,0
0,00,00,00,00,00,00,00,00,00,00,00,00,00,00,00,00,00,00,00,00,00,0
0,00,00,00,00,00,00,00,00,00,00,00,00,00,00,00,00,00,00,00,00,00,0
0,00,00,00,00,00,00,00,03,03,03,03,03,03,03,00,00,00,00,00,00,00,0
0,00,00,00,00,00,00,03,03,04,04,04,04,04,03,03,00,00,00,00,00,00,0
0,00,00,00,00,00,03,03,04,05,05,05,05,05,04,03,03,00,00,00,00,00,0
0,00,00,00,00,03,03,04,05,00,00,00,00,00,05,04,03,03,00,00,00,00,0
0,00,00,00,00,03,04,05,00,00,04,04,04,00,00,05,04,03,00,00,00,00,0
0,00,00,00,00,03,04,05,00,04,13,13,13,04,00,05,04,03,00,00,00,00,0
0,00,00,00,00,03,04,05,00,04,13,04,13,04,00,05,04,03,00,00,00,00,0
0,00,00,00,00,03,04,05,00,04,13,13,13,04,00,05,04,03,00,00,00,00,0
0,00,00,00,00,03,04,05,00,00,04,04,04,00,00,05,04,03,00,00,00,00,0
0,00,00,00,00,03,03,04,05,00,00,00,00,00,05,04,03,03,00,00,00,00,0
0,00,00,00,00,00,03,03,04,05,05,05,05,05,04,03,03,00,00,00,00,00,0
0,00,00,00,00,00,00,03,03,04,04,04,04,04,03,03,00,00,00,00,00,00,0
0,00,00,00,00,00,00,00,03,03,03,03,03,03,03,00,00,00,00,00,00,00,0
0,00,00,00,00,00,00,00,00,00,00,00,00,00,00,00,00,00,00,00,00,00,0
0,00,00,00,00,00,00,00,00,00,00,00,00,00,00,00,00,00,00,00,00,00,0
0,00,00,00,00,00,00,00,00,00,00,00,00,00,00,00,00,00,00,00,00,00,0
0,00,00,00,00,00,00,00,00,00,00,00,00,00,00,00,00,00,00,00,00,00,0
0,00,00,00,00,00,00,00,00,00,00,00,00,00,00,00,00,00,00,00,00,00,0
endlayer

# Lighthouse Roof (+31)
layer
0,00,00,00,00,00,00,00,00,00,00,00,00,00,00,00,00,00,00,00,00,00,0
0,00,00,00,00,00,00,00,00,00,00,00,00,00,00,00,00,00,00,00,00,00,0
0,00,00,00,00,00,00,00,00,00,00,00,00,00,00,00,00,00,00,00,00,00,0
0,00,00,00,00,00,00,00,00,00,00,00,00,00,00,00,00,00,00,00,00,00,0
0,00,00,00,00,00,00,00,00,00,00,00,00,00,00,00,00,00,00,00,00,00,0
0,00,00,00,00,00,00,00,00,00,00,00,00,00,00,00,00,00,00,00,00,00,0
0,00,00,00,00,00,00,00,00,00,00,00,00,00,00,00,00,00,00,00,00,00,0
0,00,00,00,00,00,00,00,00,03,03,03,03,03,00,00,00,00,00,00,00,00,0
0,00,00,00,00,00,00,00,03,04,04,04,04,04,03,00,00,00,00,00,00,00,0
0,00,00,00,00,00,00,03,04,04,05,05,05,04,04,03,00,00,00,00,00,00,0
0,00,00,00,00,00,00,03,04,05,04,04,04,05,04,03,00,00,00,00,00,00,0
0,00,00,00,00,00,00,03,04,05,04,04,04,05,04,03,00,00,00,00,00,00,0
0,00,00,00,00,00,00,03,04,05,04,04,04,05,04,03,00,00,00,00,00,00,0
0,00,00,00,00,00,00,03,04,04,05,05,05,04,04,03,00,00,00,00,00,00,0
0,00,00,00,00,00,00,00,03,04,04,04,04,04,03,00,00,00,00,00,00,00,0
0,00,00,00,00,00,00,00,00,03,03,03,03,03,00,00,00,00,00,00,00,00,0
0,00,00,00,00,00,00,00,00,00,00,00,00,00,00,00,00,00,00,00,00,00,0
0,00,00,00,00,00,00,00,00,00,00,00,00,00,00,00,00,00,00,00,00,00,0
0,00,00,00,00,00,00,00,00,00,00,00,00,00,00,00,00,00,00,00,00,00,0
0,00,00,00,00,00,00,00,00,00,00,00,00,00,00,00,00,00,00,00,00,00,0
0,00,00,00,00,00,00,00,00,00,00,00,00,00,00,00,00,00,00,00,00,00,0
0,00,00,00,00,00,00,00,00,00,00,00,00,00,00,00,00,00,00,00,00,00,0
0,00,00,00,00,00,00,00,00,00,00,00,00,00,00,00,00,00,00,00,00,00,0
endlayer

# Lighthouse Roof (+32)
layer
0,00,00,00,00,00,00,00,00,00,00,00,00,00,00,00,00,00,00,00,00,00,0
0,00,00,00,00,00,00,00,00,00,00,00,00,00,00,00,00,00,00,00,00,00,0
0,00,00,00,00,00,00,00,00,00,00,00,00,00,00,00,00,00,00,00,00,00,0
0,00,00,00,00,00,00,00,00,00,00,00,00,00,00,00,00,00,00,00,00,00,0
0,00,00,00,00,00,00,00,00,00,00,00,00,00,00,00,00,00,00,00,00,00,0
0,00,00,00,00,00,00,00,00,00,00,00,00,00,00,00,00,00,00,00,00,00,0
0,00,00,00,00,00,00,00,00,00,00,00,00,00,00,00,00,00,00,00,00,00,0
0,00,00,00,00,00,00,00,00,00,00,00,00,00,00,00,00,00,00,00,00,00,0
0,00,00,00,00,00,00,00,00,00,00,00,00,00,00,00,00,00,00,00,00,00,0
0,00,00,00,00,00,00,00,00,00,03,03,03,00,00,00,00,00,00,00,00,00,0
0,00,00,00,00,00,00,00,00,03,04,04,04,03,00,00,00,00,00,00,00,00,0
0,00,00,00,00,00,00,00,00,03,04,13,04,03,00,00,00,00,00,00,00,00,0
0,00,00,00,00,00,00,00,00,03,04,04,04,03,00,00,00,00,00,00,00,00,0
0,00,00,00,00,00,00,00,00,00,03,03,03,00,00,00,00,00,00,00,00,00,0
0,00,00,00,00,00,00,00,00,00,00,00,00,00,00,00,00,00,00,00,00,00,0
0,00,00,00,00,00,00,00,00,00,00,00,00,00,00,00,00,00,00,00,00,00,0
0,00,00,00,00,00,00,00,00,00,00,00,00,00,00,00,00,00,00,00,00,00,0
0,00,00,00,00,00,00,00,00,00,00,00,00,00,00,00,00,00,00,00,00,00,0
0,00,00,00,00,00,00,00,00,00,00,00,00,00,00,00,00,00,00,00,00,00,0
0,00,00,00,00,00,00,00,00,00,00,00,00,00,00,00,00,00,00,00,00,00,0
0,00,00,00,00,00,00,00,00,00,00,00,00,00,00,00,00,00,00,00,00,00,0
0,00,00,00,00,00,00,00,00,00,00,00,00,00,00,00,00,00,00,00,00,00,0
0,00,00,00,00,00,00,00,00,00,00,00,00,00,00,00,00,00,00,00,00,00,0
endlayer

# Lighthouse Roof (+32)
layer
0,00,00,00,00,00,00,00,00,00,00,00,00,00,00,00,00,00,00,00,00,00,0
0,00,00,00,00,00,00,00,00,00,00,00,00,00,00,00,00,00,00,00,00,00,0
0,00,00,00,00,00,00,00,00,00,00,00,00,00,00,00,00,00,00,00,00,00,0
0,00,00,00,00,00,00,00,00,00,00,00,00,00,00,00,00,00,00,00,00,00,0
0,00,00,00,00,00,00,00,00,00,00,00,00,00,00,00,00,00,00,00,00,00,0
0,00,00,00,00,00,00,00,00,00,00,00,00,00,00,00,00,00,00,00,00,00,0
0,00,00,00,00,00,00,00,00,00,00,00,00,00,00,00,00,00,00,00,00,00,0
0,00,00,00,00,00,00,00,00,00,00,00,00,00,00,00,00,00,00,00,00,00,0
0,00,00,00,00,00,00,00,00,00,00,00,00,00,00,00,00,00,00,00,00,00,0
0,00,00,00,00,00,00,00,00,00,00,00,00,00,00,00,00,00,00,00,00,00,0
0,00,00,00,00,00,00,00,00,00,03,03,03,00,00,00,00,00,00,00,00,00,0
0,00,00,00,00,00,00,00,00,00,03,09,03,00,00,00,00,00,00,00,00,00,0
0,00,00,00,00,00,00,00,00,00,03,03,03,00,00,00,00,00,00,00,00,00,0
0,00,00,00,00,00,00,00,00,00,00,00,00,00,00,00,00,00,00,00,00,00,0
0,00,00,00,00,00,00,00,00,00,00,00,00,00,00,00,00,00,00,00,00,00,0
0,00,00,00,00,00,00,00,00,00,00,00,00,00,00,00,00,00,00,00,00,00,0
0,00,00,00,00,00,00,00,00,00,00,00,00,00,00,00,00,00,00,00,00,00,0
0,00,00,00,00,00,00,00,00,00,00,00,00,00,00,00,00,00,00,00,00,00,0
0,00,00,00,00,00,00,00,00,00,00,00,00,00,00,00,00,00,00,00,00,00,0
0,00,00,00,00,00,00,00,00,00,00,00,00,00,00,00,00,00,00,00,00,00,0
0,00,00,00,00,00,00,00,00,00,00,00,00,00,00,00,00,00,00,00,00,00,0
0,00,00,00,00,00,00,00,00,00,00,00,00,00,00,00,00,00,00,00,00,00,0
0,00,00,00,00,00,00,00,00,00,00,00,00,00,00,00,00,00,00,00,00,00,0
endlayer






























