# QuartzColumns -- made for MC 1.7.10, 15 Oct 2014
# Created by Ruins mod version 13.8 Ingame Parser
# authoring Player: Jordan_Greywolf

biomesToSpawnIn=deep ocean,desert,ocean

weight=1
embed_into_distance=12
acceptable_target_blocks=
unacceptable_target_blocks=flowing_water,water,flowing_lava,lava
dimensions=19,13,13
allowable_overhang=400
max_leveling=0
leveling_buffer=0
preserve_water=1
preserve_lava=0

rule1=0,100,preserveBlock
rule2=0,100,minecraft:quartz_block-2
rule3=1,90,minecraft:quartz_block-1
rule4=1,80,minecraft:quartz_block-2


layer
1,1,1,1,1,2,1,2,1,1,1,1,1
1,1,1,2,1,1,1,1,1,2,1,1,1
1,1,1,1,1,1,1,1,1,1,1,1,1
1,2,1,1,1,1,1,1,1,1,1,2,1
1,1,1,1,1,1,1,1,1,1,1,1,1
2,1,1,1,1,1,1,1,1,1,1,1,2
1,1,1,1,1,1,1,1,1,1,1,1,1
2,1,1,1,1,1,1,1,1,1,1,1,2
1,1,1,1,1,1,1,1,1,1,1,1,1
1,2,1,1,1,1,1,1,1,1,1,2,1
1,1,1,1,1,1,1,1,1,1,1,1,1
1,1,1,2,1,1,1,1,1,2,1,1,1
1,1,1,1,1,2,1,2,1,1,1,1,1
endlayer

layer
1,1,1,1,1,2,1,2,1,1,1,1,1
1,1,1,2,1,1,1,1,1,2,1,1,1
1,1,1,1,1,1,1,1,1,1,1,1,1
1,2,1,1,1,1,1,1,1,1,1,2,1
1,1,1,1,1,1,1,1,1,1,1,1,1
2,1,1,1,1,1,1,1,1,1,1,1,2
1,1,1,1,1,1,1,1,1,1,1,1,1
2,1,1,1,1,1,1,1,1,1,1,1,2
1,1,1,1,1,1,1,1,1,1,1,1,1
1,2,1,1,1,1,1,1,1,1,1,2,1
1,1,1,1,1,1,1,1,1,1,1,1,1
1,1,1,2,1,1,1,1,1,2,1,1,1
1,1,1,1,1,2,1,2,1,1,1,1,1
endlayer

layer
1,1,1,1,1,2,1,2,1,1,1,1,1
1,1,1,2,1,1,1,1,1,2,1,1,1
1,1,1,1,1,1,1,1,1,1,1,1,1
1,2,1,1,1,1,1,1,1,1,1,2,1
1,1,1,1,1,1,1,1,1,1,1,1,1
2,1,1,1,1,1,1,1,1,1,1,1,2
1,1,1,1,1,1,1,1,1,1,1,1,1
2,1,1,1,1,1,1,1,1,1,1,1,2
1,1,1,1,1,1,1,1,1,1,1,1,1
1,2,1,1,1,1,1,1,1,1,1,2,1
1,1,1,1,1,1,1,1,1,1,1,1,1
1,1,1,2,1,1,1,1,1,2,1,1,1
1,1,1,1,1,2,1,2,1,1,1,1,1
endlayer

layer
1,1,1,1,1,2,1,2,1,1,1,1,1
1,1,1,2,1,1,1,1,1,2,1,1,1
1,1,1,1,1,1,1,1,1,1,1,1,1
1,2,1,1,1,1,1,1,1,1,1,2,1
1,1,1,1,1,1,1,1,1,1,1,1,1
2,1,1,1,1,1,1,1,1,1,1,1,2
1,1,1,1,1,1,1,1,1,1,1,1,1
2,1,1,1,1,1,1,1,1,1,1,1,2
1,1,1,1,1,1,1,1,1,1,1,1,1
1,2,1,1,1,1,1,1,1,1,1,2,1
1,1,1,1,1,1,1,1,1,1,1,1,1
1,1,1,2,1,1,1,1,1,2,1,1,1
1,1,1,1,1,2,1,2,1,1,1,1,1
endlayer

layer
1,1,1,1,1,2,1,2,1,1,1,1,1
1,1,1,2,1,1,1,1,1,2,1,1,1
1,1,1,1,1,1,1,1,1,1,1,1,1
1,2,1,1,1,1,1,1,1,1,1,2,1
1,1,1,1,1,1,1,1,1,1,1,1,1
2,1,1,1,1,1,1,1,1,1,1,1,2
1,1,1,1,1,1,1,1,1,1,1,1,1
2,1,1,1,1,1,1,1,1,1,1,1,2
1,1,1,1,1,1,1,1,1,1,1,1,1
1,2,1,1,1,1,1,1,1,1,1,2,1
1,1,1,1,1,1,1,1,1,1,1,1,1
1,1,1,2,1,1,1,1,1,2,1,1,1
1,1,1,1,1,2,1,2,1,1,1,1,1
endlayer

layer
1,1,1,1,1,2,1,2,1,1,1,1,1
1,1,1,2,1,1,1,1,1,2,1,1,1
1,1,1,1,1,1,1,1,1,1,1,1,1
1,2,1,1,1,1,1,1,1,1,1,2,1
1,1,1,1,1,1,1,1,1,1,1,1,1
2,1,1,1,1,1,1,1,1,1,1,1,2
1,1,1,1,1,1,1,1,1,1,1,1,1
2,1,1,1,1,1,1,1,1,1,1,1,2
1,1,1,1,1,1,1,1,1,1,1,1,1
1,2,1,1,1,1,1,1,1,1,1,2,1
1,1,1,1,1,1,1,1,1,1,1,1,1
1,1,1,2,1,1,1,1,1,2,1,1,1
1,1,1,1,1,2,1,2,1,1,1,1,1
endlayer


layer
1,1,1,1,1,2,1,2,1,1,1,1,1
1,1,1,2,1,1,1,1,1,2,1,1,1
1,1,1,1,1,1,1,1,1,1,1,1,1
1,2,1,1,1,1,1,1,1,1,1,2,1
1,1,1,1,1,1,1,1,1,1,1,1,1
2,1,1,1,1,1,1,1,1,1,1,1,2
1,1,1,1,1,1,1,1,1,1,1,1,1
2,1,1,1,1,1,1,1,1,1,1,1,2
1,1,1,1,1,1,1,1,1,1,1,1,1
1,2,1,1,1,1,1,1,1,1,1,2,1
1,1,1,1,1,1,1,1,1,1,1,1,1
1,1,1,2,1,1,1,1,1,2,1,1,1
1,1,1,1,1,2,1,2,1,1,1,1,1
endlayer


layer
1,1,1,1,1,2,1,2,1,1,1,1,1
1,1,1,2,1,1,1,1,1,2,1,1,1
1,1,1,1,1,1,1,1,1,1,1,1,1
1,2,1,1,1,1,1,1,1,1,1,2,1
1,1,1,1,1,1,1,1,1,1,1,1,1
2,1,1,1,1,1,1,1,1,1,1,1,2
1,1,1,1,1,1,1,1,1,1,1,1,1
2,1,1,1,1,1,1,1,1,1,1,1,2
1,1,1,1,1,1,1,1,1,1,1,1,1
1,2,1,1,1,1,1,1,1,1,1,2,1
1,1,1,1,1,1,1,1,1,1,1,1,1
1,1,1,2,1,1,1,1,1,2,1,1,1
1,1,1,1,1,2,1,2,1,1,1,1,1
endlayer


layer
1,1,1,1,1,2,1,2,1,1,1,1,1
1,1,1,2,1,1,1,1,1,2,1,1,1
1,1,1,1,1,1,1,1,1,1,1,1,1
1,2,1,1,1,1,1,1,1,1,1,2,1
1,1,1,1,1,1,1,1,1,1,1,1,1
2,1,1,1,1,1,1,1,1,1,1,1,2
1,1,1,1,1,1,1,1,1,1,1,1,1
2,1,1,1,1,1,1,1,1,1,1,1,2
1,1,1,1,1,1,1,1,1,1,1,1,1
1,2,1,1,1,1,1,1,1,1,1,2,1
1,1,1,1,1,1,1,1,1,1,1,1,1
1,1,1,2,1,1,1,1,1,2,1,1,1
1,1,1,1,1,2,1,2,1,1,1,1,1
endlayer


layer
1,1,1,1,1,2,1,2,1,1,1,1,1
1,1,1,2,1,1,1,1,1,2,1,1,1
1,1,1,1,1,1,1,1,1,1,1,1,1
1,2,1,1,1,1,1,1,1,1,1,2,1
1,1,1,1,1,1,1,1,1,1,1,1,1
2,1,1,1,1,1,1,1,1,1,1,1,2
1,1,1,1,1,1,1,1,1,1,1,1,1
2,1,1,1,1,1,1,1,1,1,1,1,2
1,1,1,1,1,1,1,1,1,1,1,1,1
1,2,1,1,1,1,1,1,1,1,1,2,1
1,1,1,1,1,1,1,1,1,1,1,1,1
1,1,1,2,1,1,1,1,1,2,1,1,1
1,1,1,1,1,2,1,2,1,1,1,1,1
endlayer


layer
1,1,1,1,1,2,1,2,1,1,1,1,1
1,1,1,2,1,1,1,1,1,2,1,1,1
1,1,1,1,1,1,1,1,1,1,1,1,1
1,2,1,1,1,1,1,1,1,1,1,2,1
1,1,1,1,1,1,1,1,1,1,1,1,1
2,1,1,1,1,1,1,1,1,1,1,1,2
1,1,1,1,1,1,1,1,1,1,1,1,1
2,1,1,1,1,1,1,1,1,1,1,1,2
1,1,1,1,1,1,1,1,1,1,1,1,1
1,2,1,1,1,1,1,1,1,1,1,2,1
1,1,1,1,1,1,1,1,1,1,1,1,1
1,1,1,2,1,1,1,1,1,2,1,1,1
1,1,1,1,1,2,1,2,1,1,1,1,1
endlayer


layer
1,1,1,1,1,2,1,2,1,1,1,1,1
1,1,1,2,1,1,1,1,1,2,1,1,1
1,1,1,1,1,1,1,1,1,1,1,1,1
1,2,1,1,1,1,1,1,1,1,1,2,1
1,1,1,1,1,1,1,1,1,1,1,1,1
2,1,1,1,1,1,1,1,1,1,1,1,2
1,1,1,1,1,1,1,1,1,1,1,1,1
2,1,1,1,1,1,1,1,1,1,1,1,2
1,1,1,1,1,1,1,1,1,1,1,1,1
1,2,1,1,1,1,1,1,1,1,1,2,1
1,1,1,1,1,1,1,1,1,1,1,1,1
1,1,1,2,1,1,1,1,1,2,1,1,1
1,1,1,1,1,2,1,2,1,1,1,1,1
endlayer


layer
1,1,1,1,1,2,1,2,1,1,1,1,1
1,1,1,2,1,1,1,1,1,2,1,1,1
1,1,1,1,1,1,1,1,1,1,1,1,1
1,2,1,1,1,1,1,1,1,1,1,2,1
1,1,1,1,1,1,1,1,1,1,1,1,1
2,1,1,1,1,1,1,1,1,1,1,1,2
1,1,1,1,1,1,1,1,1,1,1,1,1
2,1,1,1,1,1,1,1,1,1,1,1,2
1,1,1,1,1,1,1,1,1,1,1,1,1
1,2,1,1,1,1,1,1,1,1,1,2,1
1,1,1,1,1,1,1,1,1,1,1,1,1
1,1,1,2,1,1,1,1,1,2,1,1,1
1,1,1,1,1,2,1,2,1,1,1,1,1
endlayer


layer
1,1,1,1,1,2,1,2,1,1,1,1,1
1,1,1,2,1,1,1,1,1,2,1,1,1
1,1,1,1,1,1,1,1,1,1,1,1,1
1,2,1,1,1,1,1,1,1,1,1,2,1
1,1,1,1,1,1,1,1,1,1,1,1,1
2,1,1,1,1,1,1,1,1,1,1,1,2
1,1,1,1,1,1,1,1,1,1,1,1,1
2,1,1,1,1,1,1,1,1,1,1,1,2
1,1,1,1,1,1,1,1,1,1,1,1,1
1,2,1,1,1,1,1,1,1,1,1,2,1
1,1,1,1,1,1,1,1,1,1,1,1,1
1,1,1,2,1,1,1,1,1,2,1,1,1
1,1,1,1,1,2,1,2,1,1,1,1,1
endlayer


layer
1,1,1,1,1,2,1,2,1,1,1,1,1
1,1,1,2,1,1,1,1,1,2,1,1,1
1,1,1,1,1,1,1,1,1,1,1,1,1
1,2,1,1,1,1,1,1,1,1,1,2,1
1,1,1,1,1,1,1,1,1,1,1,1,1
2,1,1,1,1,1,1,1,1,1,1,1,2
1,1,1,1,1,1,1,1,1,1,1,1,1
2,1,1,1,1,1,1,1,1,1,1,1,2
1,1,1,1,1,1,1,1,1,1,1,1,1
1,2,1,1,1,1,1,1,1,1,1,2,1
1,1,1,1,1,1,1,1,1,1,1,1,1
1,1,1,2,1,1,1,1,1,2,1,1,1
1,1,1,1,1,2,1,2,1,1,1,1,1
endlayer


layer
1,1,1,1,1,2,1,2,1,1,1,1,1
1,1,1,2,1,1,1,1,1,2,1,1,1
1,1,1,1,1,1,1,1,1,1,1,1,1
1,2,1,1,1,1,1,1,1,1,1,2,1
1,1,1,1,1,1,1,1,1,1,1,1,1
2,1,1,1,1,1,1,1,1,1,1,1,2
1,1,1,1,1,1,1,1,1,1,1,1,1
2,1,1,1,1,1,1,1,1,1,1,1,2
1,1,1,1,1,1,1,1,1,1,1,1,1
1,2,1,1,1,1,1,1,1,1,1,2,1
1,1,1,1,1,1,1,1,1,1,1,1,1
1,1,1,2,1,1,1,1,1,2,1,1,1
1,1,1,1,1,2,1,2,1,1,1,1,1
endlayer


layer
0,0,0,0,0,4,0,4,0,0,0,0,0
0,0,0,4,0,0,0,0,0,4,0,0,0
0,0,0,0,0,0,0,0,0,0,0,0,0
0,4,0,0,0,0,0,0,0,0,0,4,0
0,0,0,0,0,0,0,0,0,0,0,0,0
4,0,0,0,0,0,0,0,0,0,0,0,4
0,0,0,0,0,0,0,0,0,0,0,0,0
4,0,0,0,0,0,0,0,0,0,0,0,4
0,0,0,0,0,0,0,0,0,0,0,0,0
0,4,0,0,0,0,0,0,0,0,0,4,0
0,0,0,0,0,0,0,0,0,0,0,0,0
0,0,0,4,0,0,0,0,0,4,0,0,0
0,0,0,0,0,4,0,4,0,0,0,0,0
endlayer

layer
0,0,0,0,0,4,0,4,0,0,0,0,0
0,0,0,4,0,0,0,0,0,4,0,0,0
0,0,0,0,0,0,0,0,0,0,0,0,0
0,4,0,0,0,0,0,0,0,0,0,4,0
0,0,0,0,0,0,0,0,0,0,0,0,0
4,0,0,0,0,0,0,0,0,0,0,0,4
0,0,0,0,0,0,0,0,0,0,0,0,0
4,0,0,0,0,0,0,0,0,0,0,0,4
0,0,0,0,0,0,0,0,0,0,0,0,0
0,4,0,0,0,0,0,0,0,0,0,4,0
0,0,0,0,0,0,0,0,0,0,0,0,0
0,0,0,4,0,0,0,0,0,4,0,0,0
0,0,0,0,0,4,0,4,0,0,0,0,0
endlayer

layer
0,0,0,0,0,4,0,4,0,0,0,0,0
0,0,0,4,0,0,0,0,0,4,0,0,0
0,0,0,0,0,0,0,0,0,0,0,0,0
0,4,0,0,0,0,0,0,0,0,0,4,0
0,0,0,0,0,0,0,0,0,0,0,0,0
4,0,0,0,0,0,0,0,0,0,0,0,4
0,0,0,0,0,0,0,0,0,0,0,0,0
4,0,0,0,0,0,0,0,0,0,0,0,4
0,0,0,0,0,0,0,0,0,0,0,0,0
0,4,0,0,0,0,0,0,0,0,0,4,0
0,0,0,0,0,0,0,0,0,0,0,0,0
0,0,0,4,0,0,0,0,0,4,0,0,0
0,0,0,0,0,4,0,4,0,0,0,0,0
endlayer

layer
0,0,0,0,0,4,0,4,0,0,0,0,0
0,0,0,4,0,0,0,0,0,4,0,0,0
0,0,0,0,0,0,0,0,0,0,0,0,0
0,4,0,0,0,0,0,0,0,0,0,4,0
0,0,0,0,0,0,0,0,0,0,0,0,0
4,0,0,0,0,0,0,0,0,0,0,0,4
0,0,0,0,0,0,0,0,0,0,0,0,0
4,0,0,0,0,0,0,0,0,0,0,0,4
0,0,0,0,0,0,0,0,0,0,0,0,0
0,4,0,0,0,0,0,0,0,0,0,4,0
0,0,0,0,0,0,0,0,0,0,0,0,0
0,0,0,4,0,0,0,0,0,4,0,0,0
0,0,0,0,0,4,0,4,0,0,0,0,0
endlayer

layer
0,0,0,0,0,3,0,3,0,0,0,0,0
0,0,0,3,0,0,0,0,0,3,0,0,0
0,0,0,0,0,0,0,0,0,0,0,0,0
0,3,0,0,0,0,0,0,0,0,0,3,0
0,0,0,0,0,0,0,0,0,0,0,0,0
3,0,0,0,0,0,0,0,0,0,0,0,3
0,0,0,0,0,0,0,0,0,0,0,0,0
3,0,0,0,0,0,0,0,0,0,0,0,3
0,0,0,0,0,0,0,0,0,0,0,0,0
0,3,0,0,0,0,0,0,0,0,0,3,0
0,0,0,0,0,0,0,0,0,0,0,0,0
0,0,0,3,0,0,0,0,0,3,0,0,0
0,0,0,0,0,3,0,3,0,0,0,0,0
endlayer


