
# Ziggurat_Island (9 Apr 2014)
# Updated to MC 1.7.10, 13 Oct 2014
# Created by Ruins mod version 12.3 Ingame Parser
# authoring Player: Jordan_Greywolf

biomesToSpawnIn=beach,bog,gravel beach,forested island,ocean,jungle,stone beach,swampland

weight=1
embed_into_distance=18

acceptable_target_blocks=stone,dirt,grass,sand,gravel,water,flowing_water,clay,sandstone

dimensions=50,36,36
allowable_overhang=500
max_cut_in=0
cut_in_buffer=0
max_leveling=0
leveling_buffer=0
preserve_water=0
preserve_lava=0
preserve_plants=1

rule1=0,100,preserveBlock
rule2=0,100,minecraft:grass-0
rule3=0,100,minecraft:dirt-0
rule4=0,100,minecraft:stone-0
rule5=0,100,minecraft:glowstone-0,gold_ore,iron_ore,diamond_ore,emerald_ore
rule6=0,100,minecraft:vine-1
rule7=0,100,minecraft:vine-2
rule8=0,100,minecraft:vine-4
rule9=0,100,minecraft:vine-8
rule10=0,100,minecraft:vine-0
rule11=0,100,minecraft:vine-9
rule12=0,100,minecraft:vine-12
rule13=0,100,MobSpawner:CaveSpider
rule14=0,100,minecraft:monster_egg-0
rule15=0,100,minecraft:tnt-1
rule16=0,100,minecraft:stonebrick-3
rule17=0,100,minecraft:stonebrick-2
rule18=0,100,minecraft:monster_egg-3
rule19=0,100,minecraft:stonebrick-1
rule20=0,100,minecraft:monster_egg-2
rule21=0,100,minecraft:stonebrick-0
rule22=0,100,minecraft:monster_egg-4
rule23=0,100,minecraft:water-11
rule24=0,100,minecraft:log-3

# Trap disabled (monsters keep setting it off!)
#rule25=0,100,minecraft:stone_pressure_plate-0

rule25=0,100,minecraft:carpet-11

rule26=0,100,minecraft:redstone_wire-0
rule27=2,100,minecraft:lava-0
rule28=0,100,minecraft:tripwire_hook-4
rule29=0,100,minecraft:tripwire-4
rule30=0,100,minecraft:tripwire_hook-6
rule31=0,100,HardChest-4
rule32=0,100,minecraft:water-13
rule33=0,100,minecraft:water-1
rule34=0,100,minecraft:tripwire_hook-7
rule35=0,100,minecraft:water-2
rule36=0,100,MediumChest-2
rule37=0,100,minecraft:water-3
rule38=0,100,MediumChest-3
rule39=0,100,minecraft:tripwire_hook-5
rule40=0,100,MediumChest-5
rule41=0,100,minecraft:monster_egg-5
rule42=0,100,minecraft:cobblestone_wall-1
rule43=0,100,minecraft:stone_brick_stairs-4
rule44=0,100,minecraft:stone_brick_stairs-6
rule45=0,100,minecraft:stone_brick_stairs-7
rule46=0,100,minecraft:stone_brick_stairs-5
rule47=0,100,minecraft:torch-5
rule48=0,100,WallSign:null:null:null:null-3
rule49=0,100,WallSign:null:null:null:null-2
rule50=0,100,WallSign:null:null:null:null-5
rule51=0,100,WallSign:null:null:null:null-4
rule52=0,100,minecraft:tallgrass-1,minecraft:tallgrass-2,minecraft:red_flower-3
rule53=0,100,minecraft:vine-6
rule54=0,100,minecraft:vine-3
rule55=0,100,minecraft:leaves-7
rule56=0,100,minecraft:leaves-3
rule57=0,100,minecraft:stone_brick_stairs-0
rule58=0,100,minecraft:stone_brick_stairs-1
rule59=0,100,minecraft:stone_brick_stairs-2
rule60=0,100,minecraft:stone_brick_stairs-3
rule61=0,100,minecraft:water-0
rule62=0,100,minecraft:water-4
rule63=0,100,minecraft:water-5
rule64=0,100,minecraft:cocoa-8
rule65=0,100,minecraft:cocoa-11
rule66=0,100,minecraft:cocoa-10
rule67=0,100,minecraft:cocoa-9
rule68=0,100,minecraft:stone_slab-13

layer
1,1,1,1,1,1,1,1,1,1,3,3,1,1,2,3,3,3,2,3,2,1,1,1,1,1,3,1,1,2,1,1,1,1,1,1
1,1,1,1,1,1,1,1,1,3,3,3,3,4,4,4,4,4,4,4,3,1,1,1,3,4,4,4,3,3,2,3,1,1,1,1
1,1,1,1,1,1,1,2,4,4,4,4,4,4,4,4,4,4,4,4,4,4,3,4,4,4,4,4,4,4,4,4,3,1,1,1
1,1,1,1,1,1,3,4,4,4,4,4,4,4,4,4,4,4,4,4,4,4,4,4,4,4,4,4,4,4,4,4,4,3,1,1
1,1,1,1,1,2,4,4,4,4,4,4,4,4,4,4,4,4,4,4,4,4,4,4,4,4,4,4,4,4,4,4,4,4,1,1
1,1,1,1,2,4,4,4,4,4,4,4,4,4,4,4,4,4,4,4,4,4,4,4,4,4,4,4,4,4,4,4,4,4,1,1
1,1,1,2,4,4,4,4,4,4,4,4,4,4,4,4,4,4,4,4,4,4,4,4,4,4,4,4,4,4,4,4,4,4,1,1
1,1,1,2,4,4,4,4,4,4,4,4,4,4,4,4,4,4,4,4,4,4,4,4,4,4,4,4,4,4,4,4,4,4,1,1
1,1,1,4,4,4,4,4,4,4,4,4,4,4,4,4,4,4,4,4,4,4,4,4,4,4,4,4,4,4,4,4,4,4,1,1
1,1,2,4,4,4,4,4,4,4,4,4,4,4,4,4,4,4,4,4,4,4,4,4,4,4,4,4,4,4,4,4,4,4,1,1
1,2,4,4,4,4,4,4,4,4,4,4,4,4,4,4,4,4,4,4,4,4,4,4,4,4,4,4,4,4,4,4,4,3,1,1
1,4,4,4,4,4,4,4,4,4,4,4,4,4,4,4,4,4,4,4,4,4,4,4,4,4,4,4,4,4,4,4,4,3,1,1
1,2,2,4,4,4,4,4,4,4,4,4,4,5,4,4,4,4,4,4,4,4,4,4,4,4,4,4,4,4,4,4,4,4,4,3
1,1,1,4,4,4,4,4,4,4,4,4,4,4,4,4,4,4,4,4,4,4,4,4,4,4,4,4,4,4,4,4,4,4,4,3
1,1,1,2,4,4,4,4,4,4,4,4,4,4,4,4,4,4,4,4,4,4,4,4,4,4,4,4,4,4,4,4,4,4,4,3
1,1,1,4,4,4,4,4,4,4,4,4,4,4,4,4,4,4,4,4,4,4,4,4,4,4,4,4,4,4,4,4,4,4,4,1
1,1,1,1,3,4,4,4,4,4,4,4,4,4,4,4,4,4,4,4,4,4,4,4,4,4,4,4,4,4,4,4,4,4,3,1
1,1,1,1,4,4,4,4,4,4,4,4,4,4,4,4,4,4,4,4,4,4,4,4,4,4,4,4,4,4,4,4,4,4,3,1
1,1,1,2,4,4,4,4,4,4,4,4,4,4,4,4,4,4,4,4,4,4,4,4,4,4,4,4,4,4,4,4,4,4,2,1
1,1,1,2,4,4,4,4,4,4,4,4,4,4,4,4,4,4,4,4,4,4,4,4,4,4,4,4,4,4,4,4,4,4,1,1
1,1,2,4,4,4,4,4,4,4,4,4,4,4,4,4,4,4,4,4,4,4,4,4,4,4,4,4,4,4,4,4,4,3,1,1
1,2,4,4,4,4,4,4,4,4,4,4,4,4,4,4,4,4,4,4,4,4,4,4,4,4,4,4,4,4,4,4,4,3,1,1
2,4,4,4,4,4,4,4,4,4,4,4,4,4,4,4,4,4,4,4,4,4,4,4,4,4,4,4,4,4,4,4,4,3,1,1
2,4,4,4,4,4,4,4,0,4,4,4,4,4,4,4,4,4,4,4,4,4,4,4,4,4,4,4,4,4,4,4,4,3,1,1
1,1,4,4,4,4,4,4,4,4,4,4,4,4,4,4,4,4,4,4,4,4,4,4,4,4,4,4,4,4,4,4,4,3,1,1
1,1,2,4,4,4,4,4,4,4,4,4,4,4,4,4,5,4,4,4,4,4,4,4,4,4,4,4,4,4,4,4,4,3,3,1
1,1,1,3,4,4,4,4,4,4,4,4,4,4,4,4,4,4,4,4,4,4,4,4,4,4,4,4,4,4,4,4,4,3,1,1
1,1,1,2,4,4,4,4,4,4,4,4,4,4,4,4,4,4,4,4,4,4,4,4,4,4,4,4,4,4,4,4,4,3,1,1
1,1,1,1,2,4,4,4,4,4,4,4,4,4,4,4,4,4,4,4,4,4,4,4,4,4,4,4,4,4,4,4,3,3,1,1
1,1,1,1,1,2,4,4,4,4,4,4,4,4,4,4,4,4,4,4,4,4,4,4,4,4,4,4,4,4,3,3,3,1,1,1
1,1,1,1,1,1,3,4,4,4,4,4,4,4,4,4,4,4,4,4,4,4,4,4,4,4,4,4,4,3,3,3,1,1,1,1
1,1,1,1,1,1,1,1,3,4,3,1,4,4,4,4,4,4,4,4,4,4,4,4,4,4,4,4,4,3,3,1,1,1,1,1
1,1,1,1,1,1,1,1,1,3,1,1,1,4,4,4,3,4,4,4,4,4,3,4,4,4,4,4,3,1,1,1,1,1,1,1
1,1,1,1,1,1,1,1,1,1,1,1,1,1,1,3,1,1,1,3,4,2,1,3,4,4,4,3,1,1,1,1,1,1,1,1
1,1,1,1,1,1,1,1,1,1,1,1,1,1,1,1,1,1,1,1,3,1,1,1,2,4,2,1,1,1,1,1,1,1,1,1
1,1,1,1,1,1,1,1,1,1,1,1,1,1,1,1,1,1,1,1,1,1,1,1,1,3,1,1,1,1,1,1,1,1,1,1
endlayer

layer
1,1,1,1,1,1,1,1,1,1,1,1,1,1,1,3,3,3,1,2,1,1,1,1,1,1,2,1,1,1,1,1,1,1,1,1
1,1,1,1,1,1,1,1,1,1,3,3,3,4,4,4,4,4,4,4,3,1,1,1,2,3,4,3,2,3,1,2,1,1,1,1
1,1,1,1,1,1,1,1,3,4,4,4,4,4,4,4,4,4,4,4,4,3,3,3,4,4,4,4,4,4,4,3,1,1,1,1
1,1,1,1,1,1,3,4,4,4,4,4,4,4,4,4,4,4,4,4,4,4,4,4,4,4,4,4,4,4,4,4,4,3,1,1
1,1,1,1,1,1,4,4,4,4,4,4,4,4,4,4,4,4,4,4,4,4,4,4,4,4,4,4,4,4,4,4,4,4,1,1
1,1,1,1,1,4,4,4,4,4,4,4,4,0,0,4,4,4,4,4,4,4,4,4,4,4,4,4,4,4,4,4,4,4,1,1
1,1,1,1,3,4,4,4,4,4,4,4,4,0,0,4,4,4,4,4,4,4,4,4,4,4,4,4,4,4,4,4,4,4,1,1
1,1,1,1,4,4,4,4,4,4,4,4,4,4,0,4,4,4,4,4,4,4,4,4,4,4,4,4,4,4,4,4,4,4,1,1
1,1,1,2,4,4,4,4,4,4,4,4,4,4,6,0,0,0,0,0,4,4,4,4,4,4,4,4,4,4,4,4,4,4,1,1
1,1,1,4,4,4,4,4,4,4,4,4,4,0,0,0,0,0,0,0,0,0,0,7,7,0,4,4,4,4,4,4,4,4,1,1
1,1,3,4,4,4,4,4,4,4,4,4,4,4,0,0,4,4,4,4,0,0,0,8,4,4,4,4,4,4,4,4,4,3,1,1
1,3,4,4,4,4,4,4,4,4,4,4,4,4,6,0,0,4,4,4,4,4,0,0,0,0,4,4,4,4,4,4,4,3,1,1
1,1,1,4,4,4,4,4,4,4,4,4,0,7,4,9,9,4,4,4,4,4,4,0,0,0,0,4,4,4,4,4,4,4,4,1
1,1,1,3,4,4,4,4,4,4,4,4,4,0,4,4,4,4,4,4,4,4,4,4,4,9,0,4,4,4,4,4,4,4,4,3
1,1,1,1,4,4,4,4,4,4,4,4,4,4,4,4,4,4,4,4,4,4,4,4,4,4,0,0,4,4,4,4,4,4,4,1
1,1,1,2,4,4,4,4,4,4,4,4,4,4,4,4,4,4,4,4,4,4,4,4,4,4,4,0,0,0,4,4,4,4,4,1
1,1,1,1,2,4,4,4,4,4,4,4,4,4,4,4,4,4,4,4,4,4,4,4,4,4,4,0,4,4,4,4,4,4,3,1
1,1,1,1,3,4,4,4,4,4,4,4,4,4,4,4,4,4,4,4,4,4,4,4,4,4,4,0,0,4,4,4,4,4,3,1
1,1,1,1,4,4,4,4,4,4,4,4,4,4,4,4,4,0,4,4,4,4,4,4,4,4,4,0,4,4,4,4,4,4,1,1
1,1,1,1,4,4,4,4,4,4,4,4,4,4,4,0,0,0,4,4,4,4,4,0,0,0,0,9,4,4,4,4,4,4,1,1
1,1,1,4,4,4,4,4,4,4,4,4,4,0,0,0,4,4,4,4,4,4,0,0,0,4,0,4,4,4,4,4,4,3,1,1
1,1,4,4,4,4,4,4,4,4,4,4,4,0,0,4,4,4,4,4,4,0,0,0,4,4,0,0,4,4,4,4,4,3,1,1
1,4,4,4,4,4,4,4,4,4,4,4,0,0,4,4,4,4,4,4,0,0,0,4,4,4,0,0,4,4,4,4,4,3,1,1
1,3,4,4,4,4,4,4,4,4,4,4,4,0,4,4,4,4,4,0,0,0,4,4,4,4,0,0,4,4,4,4,4,3,1,1
1,1,4,4,4,4,4,4,4,4,4,0,0,0,0,0,0,0,0,0,0,4,4,4,4,4,4,4,4,4,4,4,4,3,1,1
1,1,1,4,4,4,4,4,4,4,4,4,4,4,4,0,0,0,0,4,4,4,4,4,4,4,4,4,4,4,4,4,4,3,1,1
1,1,1,2,4,4,4,4,4,4,4,4,4,4,4,4,4,4,4,4,4,4,4,4,4,4,4,4,4,4,4,4,4,3,1,1
1,1,1,1,4,4,4,4,4,4,4,4,4,4,4,4,4,4,4,4,4,4,4,4,4,4,4,4,4,4,4,4,4,3,1,1
1,1,1,1,1,4,4,4,4,4,4,4,4,4,4,4,4,4,4,4,4,4,4,4,4,4,4,4,4,4,4,4,3,3,1,1
1,1,1,1,1,1,4,4,4,4,4,4,4,4,4,4,4,4,4,4,4,4,4,4,4,4,4,4,4,4,3,3,3,1,1,1
1,1,1,1,1,1,2,4,4,4,4,4,4,4,4,4,4,4,4,4,4,4,4,4,4,4,4,4,4,3,3,3,1,1,1,1
1,1,1,1,1,1,1,1,3,4,3,1,4,4,4,4,4,4,4,4,4,4,4,4,4,4,4,4,3,3,3,1,1,1,1,1
1,1,1,1,1,1,1,1,1,3,1,1,1,3,4,4,3,3,4,4,4,4,2,4,4,4,4,4,3,1,1,1,1,1,1,1
1,1,1,1,1,1,1,1,1,1,1,1,1,1,1,3,1,1,1,3,4,1,1,2,4,4,4,2,1,1,1,1,1,1,1,1
1,1,1,1,1,1,1,1,1,1,1,1,1,1,1,1,1,1,1,1,2,1,1,1,1,3,1,1,1,1,1,1,1,1,1,1
1,1,1,1,1,1,1,1,1,1,1,1,1,1,1,1,1,1,1,1,1,1,1,1,1,2,1,1,1,1,1,1,1,1,1,1
endlayer

layer
1,1,1,1,1,1,1,1,1,1,1,1,1,1,1,3,3,2,1,1,1,1,1,1,1,1,1,1,1,1,1,1,1,1,1,1
1,1,1,1,1,1,1,1,1,1,1,1,3,4,4,4,4,4,4,4,2,1,1,1,1,3,4,2,1,2,1,1,1,1,1,1
1,1,1,1,1,1,1,1,3,4,4,1,4,4,4,4,4,4,4,4,3,3,2,3,4,4,4,4,4,4,2,3,1,1,1,1
1,1,1,1,1,1,3,4,4,4,4,4,4,4,4,4,4,4,4,4,4,4,4,4,4,4,4,4,4,4,4,4,4,1,1,1
1,1,1,1,1,1,4,4,4,4,4,4,4,4,0,4,4,4,4,4,4,4,4,4,4,4,4,4,4,4,4,4,4,4,1,1
1,1,1,1,1,3,4,4,4,4,4,4,4,0,0,4,4,4,4,4,4,4,4,4,4,4,4,4,4,4,4,4,4,4,1,1
1,1,1,1,2,4,4,4,4,4,4,4,4,0,0,0,0,4,4,4,4,4,4,4,4,0,0,0,4,4,4,4,4,4,1,1
1,1,1,1,4,4,4,4,4,4,4,4,4,6,0,0,0,0,0,0,0,4,4,4,5,0,0,4,4,4,4,4,4,4,1,1
1,1,1,1,4,4,4,4,4,4,4,4,0,0,0,0,0,0,0,0,0,0,4,0,0,0,0,4,4,4,4,4,4,4,1,1
1,1,1,4,4,4,4,4,4,4,4,4,0,0,0,0,0,0,0,0,0,0,0,0,0,0,4,4,4,4,4,4,4,4,1,1
1,1,2,4,4,4,4,4,4,4,4,4,4,4,0,0,0,0,0,0,0,0,0,0,0,0,0,4,4,4,4,4,4,3,1,1
1,3,4,4,4,4,4,4,4,4,4,4,4,4,6,0,0,0,0,4,0,0,0,0,0,0,0,0,4,4,4,4,4,3,1,1
1,1,1,3,4,4,4,4,4,4,4,4,0,7,0,0,0,0,4,4,0,4,0,0,0,0,0,8,4,4,4,4,4,4,4,1
1,1,1,2,4,4,4,4,4,4,4,0,0,0,0,0,0,4,4,4,4,4,4,0,0,0,0,0,0,0,4,4,4,4,4,3
1,1,1,1,4,4,4,4,4,4,4,4,4,0,0,4,4,4,4,4,4,4,4,0,0,0,0,0,0,0,4,4,4,4,4,1
1,1,1,1,4,4,4,4,4,4,4,4,4,4,4,4,4,4,4,4,4,4,4,4,6,10,0,0,0,0,0,0,0,4,4,1
1,1,1,1,1,4,4,4,4,4,4,4,4,4,4,4,4,4,0,4,4,4,4,4,4,0,0,0,0,0,4,4,4,4,3,1
1,1,1,1,2,4,4,4,4,4,4,4,4,4,4,0,0,5,4,4,4,4,4,4,4,4,0,0,0,0,4,4,4,4,3,1
1,1,1,1,3,4,4,4,4,4,4,4,4,4,0,0,0,0,4,4,4,4,0,0,0,0,0,0,0,4,4,4,4,4,1,1
1,1,1,1,4,4,4,4,4,4,4,4,4,0,0,0,0,0,4,4,4,0,0,0,0,0,0,0,0,4,4,4,4,4,1,1
1,1,1,4,4,4,4,4,4,4,4,4,0,0,0,0,0,0,4,0,0,0,0,0,0,0,0,0,0,5,4,4,4,3,1,1
1,1,4,4,4,4,4,4,4,4,4,0,0,0,0,0,0,4,0,0,0,0,0,0,4,0,0,0,0,4,4,4,4,3,1,1
1,3,4,4,4,4,4,4,4,4,4,0,0,0,0,0,4,5,4,0,0,0,0,0,4,0,0,0,0,4,4,4,4,3,1,1
1,2,4,4,4,4,4,4,4,4,4,0,0,0,0,0,0,0,0,0,0,0,0,4,4,0,0,0,0,4,4,4,4,3,1,1
1,1,3,4,4,4,4,4,4,4,9,10,0,0,0,0,0,0,0,0,0,0,0,4,4,0,0,0,4,4,4,4,4,3,1,1
1,1,1,3,4,4,4,4,4,4,4,6,0,0,0,0,0,0,0,0,0,0,4,4,4,4,0,4,4,4,4,4,4,3,1,1
1,1,1,1,4,4,4,4,4,4,4,4,4,4,0,0,0,0,0,0,5,4,4,4,4,4,4,4,4,4,4,4,4,3,1,1
1,1,1,1,3,4,4,4,4,4,4,4,4,4,4,4,0,0,0,0,4,4,4,4,4,4,4,4,4,4,4,4,4,3,1,1
1,1,1,1,1,4,4,4,4,4,4,4,4,4,4,4,4,4,4,4,4,4,4,4,4,4,4,4,4,4,4,4,3,3,1,1
1,1,1,1,1,1,4,4,4,4,4,4,4,4,4,4,4,4,4,4,4,4,4,4,4,4,4,4,4,4,3,3,3,1,1,1
1,1,1,1,1,1,1,4,4,4,4,4,4,4,4,4,4,4,4,4,4,4,4,4,4,4,4,4,4,3,3,3,1,1,1,1
1,1,1,1,1,1,1,1,3,4,1,1,3,4,4,4,4,4,4,4,4,4,3,4,4,4,4,4,3,3,3,1,1,1,1,1
1,1,1,1,1,1,1,1,1,1,1,1,1,3,4,4,3,3,3,4,4,3,1,4,4,4,4,3,3,1,1,1,1,1,1,1
1,1,1,1,1,1,1,1,1,1,1,1,1,1,1,3,1,1,1,2,4,1,1,1,3,4,4,1,1,1,1,1,1,1,1,1
1,1,1,1,1,1,1,1,1,1,1,1,1,1,1,1,1,1,1,1,1,1,1,1,1,3,1,1,1,1,1,1,1,1,1,1
1,1,1,1,1,1,1,1,1,1,1,1,1,1,1,1,1,1,1,1,1,1,1,1,1,1,1,1,1,1,1,1,1,1,1,1
endlayer

layer
1,1,1,1,1,1,1,1,1,1,1,1,1,1,1,2,2,1,1,1,1,1,1,1,1,1,1,1,1,1,1,1,1,1,1,1
1,1,1,1,1,1,1,1,1,1,1,1,3,4,4,4,4,4,4,2,1,1,1,1,1,2,3,1,1,1,1,1,1,1,1,1
1,1,1,1,1,1,1,1,3,3,4,1,4,4,4,4,4,4,4,4,3,3,1,3,4,4,4,4,4,3,1,1,1,1,1,1
1,1,1,1,1,1,2,3,4,4,4,1,4,4,4,4,4,4,4,4,4,4,4,4,4,4,4,4,4,4,4,4,3,1,1,1
1,1,1,1,1,1,4,4,4,4,4,4,4,4,4,4,4,4,4,4,4,4,4,4,4,4,4,4,4,4,4,4,4,4,1,1
1,1,1,1,1,2,4,4,4,4,4,4,4,0,0,4,4,4,4,4,4,4,4,4,4,4,4,4,4,4,4,4,4,4,1,1
1,1,1,1,1,4,4,4,4,4,4,4,4,0,0,4,4,4,4,4,4,4,4,4,4,4,4,4,4,4,4,4,4,4,1,1
1,1,1,1,3,4,4,4,4,4,4,4,4,4,4,4,4,4,4,4,4,4,4,4,4,4,4,7,8,4,4,4,4,4,1,1
1,1,1,1,4,4,4,4,4,4,4,4,4,4,4,4,4,4,4,4,4,4,4,4,4,4,4,6,8,4,4,4,4,4,1,1
1,1,1,2,4,4,4,4,4,4,4,4,4,4,4,4,4,4,4,4,4,4,4,4,4,4,4,6,9,4,4,4,4,4,1,1
1,1,1,4,4,4,4,4,4,4,4,4,4,4,4,4,4,4,4,4,4,4,4,4,4,4,4,4,4,4,4,4,4,3,1,1
1,2,3,4,4,4,4,4,4,4,4,4,4,6,7,4,4,4,4,4,4,4,4,4,4,4,4,4,4,4,4,4,4,1,1,1
1,1,1,2,4,4,4,4,4,4,4,4,4,0,0,8,4,4,4,4,4,4,4,4,4,4,4,4,4,4,4,4,4,4,4,1
1,1,1,1,4,4,4,4,4,4,4,4,4,4,4,4,4,4,4,4,4,4,4,4,4,4,4,4,4,4,4,4,4,4,4,3
1,1,1,1,4,4,4,4,4,4,4,4,4,4,4,4,4,4,4,4,4,4,4,4,4,4,4,0,4,4,4,4,4,4,4,1
1,1,1,1,3,4,4,4,4,4,4,4,4,4,4,4,4,5,4,4,4,4,4,4,4,4,4,0,0,0,0,0,0,4,4,1
1,1,1,1,1,4,4,4,4,4,4,4,4,4,4,4,4,5,4,4,4,4,4,4,4,4,4,0,0,4,4,4,4,4,3,1
1,1,1,1,1,4,4,4,4,4,4,4,4,4,4,4,4,4,4,4,4,4,4,4,4,4,4,4,4,4,4,4,4,4,2,1
1,1,1,1,2,4,4,4,4,4,4,4,4,4,4,4,4,4,4,4,4,4,0,4,4,4,4,0,0,4,4,4,4,4,1,1
1,1,1,1,4,4,4,4,4,4,4,4,4,4,4,4,4,4,4,4,4,0,0,0,0,0,0,0,0,4,4,4,4,4,1,1
1,1,1,4,4,4,4,4,4,4,4,4,4,4,0,0,0,4,4,4,4,0,0,0,4,4,4,4,4,4,4,4,4,3,1,1
1,1,3,4,4,4,4,4,4,4,0,4,4,4,0,0,0,4,4,4,4,4,4,4,4,0,0,4,4,4,4,4,4,3,1,1
1,3,4,4,4,4,4,4,4,4,4,4,4,4,4,4,4,4,4,4,4,4,4,4,4,0,0,0,4,4,4,4,4,3,1,1
1,1,3,4,4,4,4,4,4,4,4,4,4,4,4,4,4,4,4,4,4,4,4,4,4,0,0,4,4,4,4,4,4,3,1,1
1,1,2,3,4,4,4,4,4,4,4,4,6,10,4,4,0,10,0,4,4,4,4,4,4,4,4,4,4,4,4,4,4,3,1,1
1,1,1,3,4,4,4,4,4,4,4,4,4,5,4,4,0,9,0,4,4,4,4,4,4,4,4,4,4,4,4,4,4,3,1,1
1,1,1,1,3,4,4,4,4,4,4,4,4,4,4,4,4,4,4,4,4,4,4,4,4,4,4,4,4,4,4,4,4,3,1,1
1,1,1,1,3,4,4,4,4,4,4,4,4,4,4,4,4,4,4,4,4,4,4,4,4,4,4,4,4,4,4,4,4,3,1,1
1,1,1,1,1,3,4,4,4,4,4,4,4,4,4,4,4,4,4,4,4,4,4,4,4,4,4,4,4,4,4,3,3,2,1,1
1,1,1,1,1,1,4,4,4,4,4,4,4,4,4,4,4,4,4,4,4,4,4,4,4,4,4,4,4,4,3,3,3,1,1,1
1,1,1,1,1,1,1,4,4,4,4,4,4,4,4,4,4,4,4,4,4,4,4,4,4,4,4,4,3,3,3,2,1,1,1,1
1,1,1,1,1,1,1,1,1,4,1,1,3,4,4,4,4,4,4,4,4,3,3,4,4,4,4,4,3,3,2,1,1,1,1,1
1,1,1,1,1,1,1,1,1,1,1,1,1,3,3,4,1,3,3,4,4,3,1,4,4,4,4,3,2,1,1,1,1,1,1,1
1,1,1,1,1,1,1,1,1,1,1,1,1,1,1,1,1,1,1,1,3,1,1,1,3,4,3,1,1,1,1,1,1,1,1,1
1,1,1,1,1,1,1,1,1,1,1,1,1,1,1,1,1,1,1,1,1,1,1,1,1,3,1,1,1,1,1,1,1,1,1,1
1,1,1,1,1,1,1,1,1,1,1,1,1,1,1,1,1,1,1,1,1,1,1,1,1,1,1,1,1,1,1,1,1,1,1,1
endlayer

layer
1,1,1,1,1,1,1,1,1,1,1,1,1,1,1,1,1,1,1,1,1,1,1,1,1,1,1,1,1,1,1,1,1,1,1,1
1,1,1,1,1,1,1,1,1,1,1,1,1,4,4,4,4,4,3,1,1,1,1,1,1,1,2,1,1,1,1,1,1,1,1,1
1,1,1,1,1,1,1,1,2,3,3,1,4,4,4,4,4,4,4,3,3,2,1,2,4,4,4,4,3,2,1,1,1,1,1,1
1,1,1,1,1,1,1,3,4,4,4,1,1,4,4,4,4,4,4,4,4,4,3,4,4,4,4,4,4,4,4,3,3,1,1,1
1,1,1,1,1,1,4,4,4,4,4,1,1,4,4,4,4,4,4,4,4,4,4,4,4,4,4,4,4,4,4,4,4,4,1,1
1,1,1,1,1,1,4,4,4,4,4,4,4,5,4,4,4,4,4,4,4,4,4,4,4,4,4,4,0,0,0,4,4,4,1,1
1,1,1,1,1,3,4,4,4,4,4,4,4,4,4,4,4,4,4,4,4,4,4,4,4,4,4,0,0,0,9,4,4,4,1,1
1,1,1,1,2,4,4,4,4,4,4,4,4,4,4,4,4,4,4,4,4,4,4,4,4,4,4,0,0,8,4,4,4,4,1,1
1,1,1,1,3,4,4,4,4,4,4,4,4,4,4,4,4,4,4,4,4,4,4,4,4,4,0,0,0,0,4,4,4,4,1,1
1,1,1,1,4,4,4,4,4,4,4,4,4,4,4,4,4,4,4,4,4,4,4,4,4,4,6,0,9,4,4,4,4,4,1,1
1,1,1,2,4,4,4,4,4,4,4,4,4,6,0,8,4,4,4,4,4,4,4,4,4,4,4,6,4,4,4,4,4,1,1,1
1,1,2,4,4,4,4,4,4,4,4,4,4,6,0,0,0,4,4,4,4,4,4,4,4,4,4,4,4,4,4,4,4,1,1,1
1,1,1,1,4,4,4,4,4,4,4,4,4,4,0,0,0,7,7,0,8,4,4,4,4,4,4,4,4,4,4,4,4,4,4,1
1,1,1,1,4,4,4,4,4,4,4,4,4,4,4,4,11,8,4,0,0,4,4,4,4,4,4,4,4,4,4,4,4,4,4,1
1,1,1,1,3,4,4,4,4,4,4,4,4,4,4,4,4,4,0,0,0,4,4,4,4,4,4,4,4,4,4,4,4,4,4,1
1,1,1,1,2,4,4,4,4,4,4,4,4,4,4,4,4,0,0,0,4,4,4,4,4,4,4,4,4,4,4,0,0,1,4,1
1,1,1,1,1,1,1,1,1,4,4,4,4,4,4,4,0,0,0,9,4,4,4,4,4,4,4,4,4,4,4,4,4,4,3,1
1,1,1,1,1,4,4,4,4,4,4,4,4,4,4,6,0,0,0,4,4,4,4,4,4,4,4,4,4,4,4,4,4,4,1,1
1,1,1,1,1,4,4,4,4,4,4,4,4,4,4,0,8,4,4,4,4,4,4,4,4,4,4,4,4,4,4,4,4,4,1,1
1,1,1,1,2,4,4,4,4,4,4,4,4,4,4,4,8,4,4,4,4,4,4,4,4,4,4,4,4,4,4,4,4,4,1,1
1,1,1,2,4,4,4,4,4,4,4,4,4,4,4,4,4,4,4,4,4,4,4,4,4,4,4,4,4,4,4,4,4,3,1,1
1,1,2,4,4,4,4,4,4,4,4,4,4,4,4,4,4,4,4,4,4,4,4,4,4,4,4,4,4,4,4,4,4,3,1,1
1,2,3,4,4,4,4,4,4,4,4,4,4,4,4,4,4,4,4,4,4,4,4,4,4,4,4,4,4,4,4,4,4,3,1,1
1,1,2,4,4,4,4,4,4,4,4,4,4,4,4,4,4,4,4,4,4,4,4,4,4,4,4,4,4,4,4,4,4,3,1,1
1,1,1,3,4,4,4,4,4,4,4,4,4,4,4,4,4,4,4,4,4,4,4,4,4,4,4,4,4,4,4,4,4,3,1,1
1,1,1,2,3,4,4,4,4,4,4,4,4,4,4,4,4,4,4,4,4,4,4,4,4,4,4,4,4,4,4,4,4,3,1,1
1,1,1,1,3,4,4,4,4,4,4,4,4,4,4,4,4,4,4,4,4,4,4,4,4,4,4,4,4,4,4,4,4,3,1,1
1,1,1,1,3,4,4,4,4,4,4,4,4,4,4,4,4,4,4,4,4,4,4,4,4,4,4,4,4,4,4,4,4,3,1,1
1,1,1,1,1,3,4,4,4,4,4,4,4,4,4,4,4,4,4,4,4,4,4,4,4,4,4,4,4,4,4,3,3,1,1,1
1,1,1,1,1,1,3,4,4,4,4,4,4,4,4,4,4,4,4,4,4,4,4,4,4,4,4,4,4,4,3,3,2,1,1,1
1,1,1,1,1,1,1,4,4,4,4,3,4,4,4,4,4,4,4,4,4,3,4,4,4,4,4,4,3,3,2,1,1,1,1,1
1,1,1,1,1,1,1,1,1,3,1,1,3,4,4,4,4,4,4,4,4,3,3,4,4,4,4,3,3,2,1,1,1,1,1,1
1,1,1,1,1,1,1,1,1,1,1,1,1,3,3,3,1,3,3,3,4,3,1,3,4,4,4,3,1,1,1,1,1,1,1,1
1,1,1,1,1,1,1,1,1,1,1,1,1,1,1,1,1,1,1,1,3,1,1,1,3,4,2,1,1,1,1,1,1,1,1,1
1,1,1,1,1,1,1,1,1,1,1,1,1,1,1,1,1,1,1,1,1,1,1,1,1,2,1,1,1,1,1,1,1,1,1,1
1,1,1,1,1,1,1,1,1,1,1,1,1,1,1,1,1,1,1,1,1,1,1,1,1,1,1,1,1,1,1,1,1,1,1,1
endlayer

layer
1,1,1,1,1,1,1,1,1,1,1,1,1,1,1,1,1,1,1,1,1,1,1,1,1,1,1,1,1,1,1,1,1,1,1,1
1,1,1,1,1,1,1,1,1,1,1,1,1,4,4,4,4,4,2,1,1,1,1,1,1,1,1,1,1,1,1,1,1,1,1,1
1,1,1,1,1,1,1,1,1,2,3,4,4,4,4,4,4,4,4,3,2,1,1,1,4,4,4,4,2,1,1,1,1,1,1,1
1,1,1,1,1,1,1,3,3,4,4,1,1,4,4,4,4,4,4,4,4,4,3,4,4,4,4,4,4,4,3,2,1,1,1,1
1,1,1,1,1,1,4,4,4,4,4,1,1,1,4,4,4,4,4,4,4,4,4,4,4,4,4,4,4,4,4,4,4,3,1,1
1,1,1,1,1,1,4,4,4,4,4,1,1,1,1,1,4,4,4,4,4,4,4,4,4,4,4,4,0,0,0,4,4,4,1,1
1,1,1,1,1,3,4,4,4,4,4,4,1,1,1,1,4,4,4,4,4,4,4,4,4,4,4,0,0,0,0,0,4,4,1,1
1,1,1,1,1,4,4,4,4,4,4,4,4,1,1,1,4,4,4,4,4,4,4,4,4,4,4,0,0,9,9,4,4,4,1,1
1,1,1,1,3,4,4,4,4,4,4,4,4,4,4,4,4,4,4,4,4,4,4,4,4,4,0,0,0,4,4,4,4,4,1,1
1,1,1,1,3,4,4,4,4,4,4,4,0,4,4,4,4,4,4,4,4,4,4,4,4,0,0,0,0,4,4,4,4,4,1,1
1,1,1,1,3,4,4,4,4,4,4,6,0,0,0,8,4,4,4,4,4,4,4,4,0,0,0,0,4,4,4,4,4,1,1,1
1,1,1,3,4,4,4,4,4,4,0,0,0,0,0,0,0,0,7,0,4,4,4,4,6,0,0,4,4,4,4,4,4,1,1,1
1,1,1,1,3,4,4,4,4,4,6,0,4,4,0,0,0,0,0,0,8,4,4,4,4,6,9,4,4,4,4,4,4,4,4,1
1,1,1,1,4,4,4,4,4,4,4,4,4,4,4,6,9,8,4,0,0,0,4,4,4,4,4,4,4,4,4,4,4,4,4,1
1,1,1,1,3,4,4,4,1,1,4,4,4,4,4,4,4,4,0,0,0,8,4,4,4,4,4,4,4,4,4,4,4,4,4,1
1,1,1,1,1,4,4,4,1,1,1,1,4,4,4,4,4,0,0,0,9,0,4,4,4,4,4,4,4,4,4,4,4,1,1,1
1,1,1,1,1,1,1,1,1,1,1,1,4,4,4,4,0,0,0,9,4,4,4,4,4,4,4,4,4,4,4,4,4,4,2,1
1,1,1,1,1,4,4,5,4,4,4,4,4,4,4,6,0,0,0,4,4,4,4,4,4,4,4,4,4,4,4,4,4,4,1,1
1,1,1,1,1,4,4,3,4,4,4,4,4,4,4,0,0,0,5,4,4,4,4,4,4,4,4,4,4,4,4,4,4,4,1,1
1,1,1,1,1,4,4,4,4,4,4,4,4,4,4,0,0,8,4,4,4,4,4,4,4,4,4,4,4,4,4,4,4,4,1,1
1,1,1,1,4,4,4,4,4,4,4,4,4,4,4,4,4,4,4,4,4,4,4,4,4,4,4,4,4,4,4,4,4,3,1,1
1,1,1,2,4,4,4,4,4,4,4,4,4,4,4,4,4,4,4,4,4,4,4,4,4,4,4,4,4,4,4,4,4,3,1,1
1,1,2,4,4,4,4,4,4,4,4,4,4,4,4,4,4,4,4,4,4,4,4,4,4,4,4,4,4,4,4,4,4,3,1,1
1,1,1,3,4,4,4,4,4,4,4,4,4,4,4,4,4,4,4,4,4,4,4,4,4,4,4,4,4,4,4,4,4,3,1,1
1,1,1,3,4,4,4,4,4,4,4,4,4,4,4,4,4,4,4,4,4,4,4,4,4,4,4,4,4,4,4,4,4,3,1,1
1,1,1,1,3,4,4,4,4,4,4,4,4,4,4,4,4,4,4,4,4,4,4,4,4,4,4,4,4,4,4,4,4,3,1,1
1,1,1,1,3,4,0,4,4,4,4,4,4,4,4,4,4,4,4,4,4,4,4,4,4,4,4,4,4,4,4,4,4,3,1,1
1,1,1,1,2,4,4,4,4,4,4,4,4,4,4,4,4,4,4,4,4,4,4,4,4,4,4,4,4,4,4,4,3,3,1,1
1,1,1,1,1,2,4,4,4,4,4,4,4,4,4,4,4,4,4,4,4,4,4,4,4,4,4,4,4,4,3,3,3,1,1,1
1,1,1,1,1,1,3,4,4,4,4,4,4,4,4,4,4,4,4,4,4,4,4,4,4,4,4,4,4,4,3,3,1,1,1,1
1,1,1,1,1,1,1,4,4,4,4,3,4,4,4,4,4,4,4,4,4,3,4,4,4,4,4,4,3,3,1,1,1,1,1,1
1,1,1,1,1,1,1,1,1,3,1,1,2,4,4,4,4,4,4,4,4,3,2,4,4,4,4,3,2,1,1,1,1,1,1,1
1,1,1,1,1,1,1,1,1,1,1,1,1,3,1,3,1,3,2,3,2,2,1,3,4,4,4,2,1,1,1,1,1,1,1,1
1,1,1,1,1,1,1,1,1,1,1,1,1,1,1,1,1,1,1,1,2,1,1,1,2,3,1,1,1,1,1,1,1,1,1,1
1,1,1,1,1,1,1,1,1,1,1,1,1,1,1,1,1,1,1,1,1,1,1,1,1,1,1,1,1,1,1,1,1,1,1,1
1,1,1,1,1,1,1,1,1,1,1,1,1,1,1,1,1,1,1,1,1,1,1,1,1,1,1,1,1,1,1,1,1,1,1,1
endlayer

layer
1,1,1,1,1,1,1,1,1,1,1,1,1,1,1,1,1,1,1,1,1,1,1,1,1,1,1,1,1,1,1,1,1,1,1,1
1,1,1,1,1,1,1,1,1,1,1,1,1,4,4,4,4,4,1,1,1,1,1,1,1,1,1,1,1,1,1,1,1,1,1,1
1,1,1,1,1,1,1,1,1,1,2,3,4,4,4,4,4,4,4,2,1,1,1,1,4,4,4,4,1,1,1,1,1,1,1,1
1,1,1,1,1,1,1,2,3,4,4,4,0,4,4,4,4,4,4,4,4,3,3,2,4,4,4,4,4,3,3,1,1,1,1,1
1,1,1,1,1,1,4,4,4,4,4,0,1,0,4,4,4,4,4,4,4,4,4,4,4,4,4,4,4,4,4,4,3,1,1,1
1,1,1,1,1,1,4,4,4,4,4,0,0,0,0,0,4,4,4,4,4,4,4,4,4,4,4,4,4,0,0,4,4,1,1,1
1,1,1,1,1,3,4,4,4,4,4,0,0,0,0,0,0,4,4,4,4,4,4,4,4,4,4,4,0,0,0,0,4,4,1,1
1,1,1,1,1,4,4,4,4,4,4,4,0,0,0,0,0,4,4,4,4,4,4,4,4,4,4,4,0,0,0,0,4,4,1,1
1,1,1,1,3,4,4,4,4,4,4,4,5,0,0,9,8,4,4,4,4,4,4,4,4,4,0,0,4,9,0,5,4,4,1,1
1,1,1,1,2,4,4,4,4,4,4,4,7,4,4,4,4,4,4,4,4,4,4,4,4,0,0,0,4,4,4,4,4,3,1,1
1,1,1,1,3,4,4,4,4,4,4,6,0,7,0,8,4,4,4,4,4,4,4,4,0,0,0,0,4,4,4,4,4,1,1,1
1,1,1,3,3,4,4,4,0,0,0,0,0,0,0,0,0,4,4,4,4,4,4,0,0,0,0,5,4,4,4,4,4,1,1,1
1,1,1,1,3,4,4,7,0,0,0,0,5,4,4,0,0,4,4,0,8,4,4,0,0,0,0,4,4,4,4,4,4,4,3,1
1,1,1,1,4,0,0,0,0,0,0,4,4,4,4,6,4,4,4,0,0,4,4,6,9,0,4,4,4,4,4,4,4,4,4,1
1,1,1,1,2,4,4,4,0,0,4,7,4,4,4,4,4,4,4,0,0,4,4,4,4,4,4,4,4,4,4,4,4,4,4,1
1,1,1,1,1,4,4,4,0,0,9,8,4,4,4,4,4,4,4,0,9,0,4,4,4,4,4,4,4,4,4,4,4,4,3,1
1,1,1,1,1,2,4,0,0,9,0,12,4,4,4,4,4,4,4,4,4,4,4,4,4,4,4,4,4,4,4,4,4,4,1,1
1,1,1,1,1,2,4,4,4,4,4,9,4,4,4,4,0,0,4,8,4,4,4,4,4,4,4,4,4,4,4,4,4,4,1,1
1,1,1,1,1,4,4,0,4,4,4,4,4,4,4,4,0,0,0,0,4,4,4,4,4,4,4,4,4,4,4,4,4,4,1,1
1,1,1,1,1,4,4,4,4,4,4,4,4,4,4,4,0,9,0,0,0,4,4,4,4,4,4,4,4,4,4,4,4,3,1,1
1,1,1,1,3,4,4,4,4,4,4,4,4,4,4,4,4,4,4,4,0,4,4,4,4,4,4,4,4,4,4,4,4,3,1,1
1,1,1,1,4,4,4,4,4,4,4,4,4,4,4,4,4,4,4,4,0,0,4,4,4,4,4,4,4,4,4,4,4,3,1,1
1,1,1,3,4,4,4,4,4,4,4,4,4,4,4,4,4,4,4,4,4,9,4,4,4,4,4,4,4,4,4,4,4,2,1,1
1,1,1,2,4,4,4,4,4,4,4,4,4,4,4,4,4,4,4,4,4,4,4,4,4,4,4,4,4,4,4,4,3,2,1,1
1,1,1,2,4,4,4,4,4,4,4,4,4,4,4,4,4,4,4,4,4,4,4,4,4,4,4,4,4,4,4,4,4,3,1,1
1,1,1,1,2,4,4,4,4,4,4,4,4,4,4,4,4,4,4,4,4,4,4,4,4,4,4,4,4,4,4,4,4,3,1,1
1,1,1,1,2,4,4,4,4,4,4,4,4,4,4,4,4,4,4,4,4,4,4,4,4,4,4,4,4,4,4,4,4,3,1,1
1,1,1,1,1,4,4,4,4,4,4,4,4,4,4,4,4,4,4,4,4,4,4,4,4,4,4,4,4,4,4,4,3,3,1,1
1,1,1,1,1,1,3,4,4,4,4,4,4,4,4,4,4,4,4,4,4,4,4,4,4,4,4,4,4,4,3,3,3,1,1,1
1,1,1,1,1,1,3,4,4,4,4,4,4,4,4,4,4,4,4,4,4,4,4,4,4,4,4,4,4,3,3,3,1,1,1,1
1,1,1,1,1,1,1,2,4,4,4,3,3,4,4,4,4,4,4,4,4,3,3,4,4,4,4,3,3,2,1,1,1,1,1,1
1,1,1,1,1,1,1,1,1,1,1,1,1,3,4,4,4,4,4,4,3,2,1,4,4,4,4,3,1,1,1,1,1,1,1,1
1,1,1,1,1,1,1,1,1,1,1,1,1,1,1,1,1,2,1,2,1,1,1,2,4,4,3,1,1,1,1,1,1,1,1,1
1,1,1,1,1,1,1,1,1,1,1,1,1,1,1,1,1,1,1,1,1,1,1,1,1,3,1,1,1,1,1,1,1,1,1,1
1,1,1,1,1,1,1,1,1,1,1,1,1,1,1,1,1,1,1,1,1,1,1,1,1,1,1,1,1,1,1,1,1,1,1,1
1,1,1,1,1,1,1,1,1,1,1,1,1,1,1,1,1,1,1,1,1,1,1,1,1,1,1,1,1,1,1,1,1,1,1,1
endlayer

layer
1,1,1,1,1,1,1,1,1,1,1,1,1,1,1,1,1,1,1,1,1,1,1,1,1,1,1,1,1,1,1,1,1,1,1,1
1,1,1,1,1,1,1,1,1,1,1,1,1,3,4,4,4,2,1,1,1,1,1,1,1,1,1,1,1,1,1,1,1,1,1,1
1,1,1,1,1,1,1,1,1,1,1,2,2,4,4,4,4,4,2,1,1,1,1,1,2,4,4,2,1,1,1,1,1,1,1,1
1,1,1,1,1,1,1,1,3,4,4,4,4,4,4,4,4,4,4,4,4,3,2,1,4,4,4,4,3,3,2,1,1,1,1,1
1,1,1,1,1,1,4,4,4,4,4,4,1,4,4,4,4,4,4,4,4,4,4,4,4,4,4,4,4,4,4,3,3,1,1,1
1,1,1,1,1,1,4,4,4,4,4,4,0,0,4,4,4,4,4,4,4,4,4,4,4,4,4,4,4,4,4,4,3,1,1,1
1,1,1,1,1,2,4,4,4,4,5,0,0,0,0,0,0,4,4,4,4,4,4,4,4,4,4,4,4,0,0,4,4,1,1,1
1,1,1,1,1,4,4,4,4,4,4,4,0,0,0,0,0,4,4,4,4,4,4,4,4,4,4,4,4,0,0,4,4,4,1,1
1,1,1,1,2,4,4,4,4,4,4,4,0,0,0,0,0,0,4,4,4,4,4,4,4,4,4,4,6,0,0,4,4,4,1,1
1,1,1,1,1,4,4,4,4,4,4,4,4,4,4,0,0,8,4,4,4,4,4,4,4,4,4,4,9,9,4,4,4,3,1,1
1,1,1,1,2,4,4,4,4,4,4,4,4,4,4,4,9,9,4,4,4,4,4,4,4,0,0,4,4,4,4,4,3,1,1,1
1,1,1,2,3,4,4,4,7,0,0,0,0,4,4,4,4,4,4,4,4,4,4,0,0,0,0,4,4,4,4,4,4,1,1,1
1,1,1,1,2,4,6,7,0,0,0,0,4,4,4,4,4,4,5,4,4,4,4,0,0,0,4,4,4,4,4,4,4,4,2,1
1,1,1,1,5,6,0,0,0,0,0,4,4,4,4,4,4,4,4,4,4,4,6,0,9,0,4,4,4,4,4,4,4,4,4,1
1,1,1,1,1,4,4,9,0,0,4,7,4,4,4,4,4,4,4,4,4,6,0,0,4,4,4,4,4,4,5,4,4,4,4,1
1,1,1,1,1,2,4,4,0,0,9,8,4,4,4,4,4,4,4,4,4,4,4,4,4,4,4,4,4,4,4,4,4,4,2,1
1,1,1,1,1,1,2,4,6,9,4,9,4,4,4,4,4,4,4,4,7,4,4,4,4,4,4,4,4,4,4,4,4,4,1,1
1,1,1,1,1,1,2,4,4,4,4,5,4,4,4,4,4,4,4,0,0,4,4,4,4,4,4,4,4,4,4,4,4,4,1,1
1,1,1,1,1,2,2,3,4,4,4,4,4,4,4,4,0,0,0,0,0,4,4,4,4,4,4,4,4,4,4,4,4,3,1,1
1,1,1,1,1,4,4,4,4,4,4,4,4,4,4,4,0,9,0,0,0,4,4,4,4,4,4,4,4,4,4,4,4,2,1,1
1,1,1,1,2,4,4,4,4,4,4,4,4,4,4,4,4,4,4,0,0,0,4,4,4,4,4,4,4,4,4,4,4,3,1,1
1,1,1,1,2,4,4,4,4,4,4,4,4,4,4,4,4,4,4,0,0,0,0,4,4,4,4,4,4,4,4,4,3,2,1,1
1,1,1,2,4,4,4,4,4,4,4,4,4,4,4,4,4,4,4,0,0,0,9,4,4,4,4,4,4,4,4,4,4,1,1,1
1,1,1,1,4,4,4,4,4,4,4,4,4,4,4,4,4,4,4,4,4,9,4,4,4,4,4,4,4,4,4,4,3,1,1,1
1,1,1,1,2,4,4,4,4,4,4,4,4,4,4,4,4,4,4,4,4,4,4,4,4,4,4,4,4,4,4,4,4,3,1,1
1,1,1,1,1,4,4,4,4,4,4,4,4,4,4,4,4,4,4,4,4,4,4,4,4,4,4,4,4,4,4,4,4,3,1,1
1,1,1,1,1,4,4,4,4,4,4,4,4,4,4,4,4,4,4,4,4,4,4,4,4,4,4,4,4,4,4,4,3,3,1,1
1,1,1,1,1,2,4,4,4,4,4,4,4,4,4,4,4,4,4,4,4,4,4,4,4,4,4,4,4,4,4,4,3,3,1,1
1,1,1,1,1,1,2,4,4,4,4,4,4,4,4,4,4,4,4,4,4,4,4,4,4,4,4,4,4,4,3,3,3,1,1,1
1,1,1,1,1,1,2,3,4,4,4,4,4,4,4,4,4,4,4,4,4,4,4,4,4,4,4,4,4,3,3,3,1,1,1,1
1,1,1,1,1,1,1,1,3,4,3,2,3,4,4,4,4,4,4,4,4,2,2,4,4,4,4,2,2,1,1,1,1,1,1,1
1,1,1,1,1,1,1,1,1,1,1,1,1,3,3,4,4,4,4,4,2,1,1,3,4,4,4,2,1,1,1,1,1,1,1,1
1,1,1,1,1,1,1,1,1,1,1,1,1,1,1,1,1,1,1,1,1,1,1,1,3,4,2,1,1,1,1,1,1,1,1,1
1,1,1,1,1,1,1,1,1,1,1,1,1,1,1,1,1,1,1,1,1,1,1,1,1,2,1,1,1,1,1,1,1,1,1,1
1,1,1,1,1,1,1,1,1,1,1,1,1,1,1,1,1,1,1,1,1,1,1,1,1,1,1,1,1,1,1,1,1,1,1,1
1,1,1,1,1,1,1,1,1,1,1,1,1,1,1,1,1,1,1,1,1,1,1,1,1,1,1,1,1,1,1,1,1,1,1,1
endlayer

layer
1,1,1,1,1,1,1,1,1,1,1,1,1,1,1,1,1,1,1,1,1,1,1,1,1,1,1,1,1,1,1,1,1,1,1,1
1,1,1,1,1,1,1,1,1,1,1,1,1,2,2,3,2,1,1,1,1,1,1,1,1,1,1,1,1,1,1,1,1,1,1,1
1,1,1,1,1,1,1,1,1,1,1,1,1,2,3,3,3,2,1,1,1,1,1,1,1,2,3,1,1,1,1,1,1,1,1,1
1,1,1,1,1,1,1,1,2,2,2,2,1,3,4,4,3,2,3,3,3,3,1,1,2,3,3,3,3,2,1,1,1,1,1,1
1,1,1,1,1,1,2,3,3,3,3,3,0,4,4,4,4,4,3,3,4,4,4,3,3,4,4,3,3,3,3,3,3,1,1,1
1,1,1,1,1,1,2,3,3,3,4,4,5,4,4,4,4,4,4,4,4,4,4,4,4,4,4,4,4,4,3,3,3,1,1,1
1,1,1,1,1,1,3,3,3,4,4,4,4,0,0,4,4,4,4,4,4,4,4,4,4,4,4,4,4,4,4,3,3,1,1,1
1,1,1,1,1,2,3,3,3,4,4,4,4,0,0,0,0,0,4,4,4,4,4,4,4,4,4,4,4,0,4,3,3,3,1,1
1,1,1,1,1,3,3,3,3,4,4,4,4,4,0,0,0,0,4,4,4,4,4,4,4,4,4,6,0,0,4,3,3,3,1,1
1,1,1,1,1,3,3,3,3,4,4,4,4,4,4,0,0,0,0,4,4,4,4,4,4,4,9,0,0,9,4,3,3,3,1,1
1,1,1,1,1,3,3,3,3,4,4,4,4,4,4,0,0,0,0,4,4,4,4,4,4,4,4,9,0,4,4,3,3,1,1,1
1,1,1,1,2,3,3,3,4,4,4,4,4,4,4,4,0,0,0,0,4,4,4,4,4,4,4,4,4,4,4,3,3,1,1,1
1,1,1,1,1,3,4,4,4,0,4,4,4,4,4,4,4,0,0,0,0,4,4,0,0,4,4,4,4,4,4,3,3,3,1,1
1,1,1,1,2,4,4,4,5,0,0,4,4,4,4,4,4,4,0,0,0,0,0,0,0,4,4,4,4,4,1,1,1,2,1,1
1,1,1,1,1,2,3,4,4,4,4,4,4,4,4,4,4,4,4,0,0,0,0,0,4,4,4,4,1,1,1,1,1,3,3,1
1,1,1,1,1,1,3,3,4,4,4,4,4,4,4,4,4,4,4,4,0,0,4,4,4,4,4,4,1,1,4,3,3,3,1,1
1,1,1,1,1,1,1,3,4,4,4,4,4,4,4,4,4,4,4,0,0,0,4,4,4,4,4,4,4,4,4,3,3,2,1,1
1,1,1,1,1,1,1,3,4,4,4,4,4,4,4,4,4,4,4,0,0,4,4,4,4,4,4,4,4,4,4,3,3,2,1,1
1,1,1,1,1,1,1,3,3,4,4,4,4,4,4,4,4,4,4,0,0,4,4,4,4,4,4,4,4,4,4,3,3,2,1,1
1,1,1,1,1,2,3,3,3,4,4,4,4,4,4,4,4,4,4,4,4,4,4,4,4,4,4,4,4,4,4,3,3,1,1,1
1,1,1,1,1,3,3,3,3,4,4,4,4,4,4,4,4,4,4,0,0,0,4,4,4,4,4,4,4,4,4,3,3,2,1,1
1,1,1,1,1,2,3,3,3,4,4,4,4,4,4,4,4,4,4,4,0,0,4,4,4,4,4,4,4,4,4,3,3,1,1,1
1,1,1,1,2,3,3,3,3,4,4,4,4,4,4,4,4,4,4,0,0,0,9,4,4,4,4,4,4,4,4,3,3,1,1,1
1,1,1,1,2,3,3,3,4,4,4,4,4,4,4,4,4,4,4,4,0,0,4,4,4,4,4,4,4,4,4,3,3,1,1,1
1,1,1,1,1,3,3,3,3,4,4,4,4,4,4,4,4,4,4,4,4,9,4,4,4,4,4,4,4,4,4,3,3,3,1,1
1,1,1,1,1,3,3,3,3,4,4,4,4,4,4,4,4,4,4,4,4,4,4,4,4,4,4,4,4,4,4,3,3,3,1,1
1,1,1,1,1,2,3,3,3,4,4,4,4,4,4,4,4,4,4,4,4,4,4,4,4,4,4,4,4,4,4,3,3,1,1,1
1,1,1,1,1,1,3,3,3,4,4,4,4,4,4,4,4,4,4,4,4,4,4,4,4,4,4,4,4,4,4,3,3,1,1,1
1,1,1,1,1,1,1,3,3,3,3,3,3,4,4,4,4,4,4,4,4,4,3,4,4,4,3,3,3,3,3,3,3,1,1,1
1,1,1,1,1,1,1,3,3,3,3,3,3,3,3,4,4,4,4,3,3,3,3,3,3,3,3,3,3,3,3,3,1,1,1,1
1,1,1,1,1,1,1,1,1,3,3,1,3,3,3,3,4,3,3,3,3,1,1,3,3,3,3,1,1,1,1,1,1,1,1,1
1,1,1,1,1,1,1,1,1,1,1,1,1,3,3,3,3,3,3,3,1,1,1,2,3,3,3,1,1,1,1,1,1,1,1,1
1,1,1,1,1,1,1,1,1,1,1,1,1,1,1,1,1,1,1,1,1,1,1,1,2,2,1,1,1,1,1,1,1,1,1,1
1,1,1,1,1,1,1,1,1,1,1,1,1,1,1,1,1,1,1,1,1,1,1,1,1,1,1,1,1,1,1,1,1,1,1,1
1,1,1,1,1,1,1,1,1,1,1,1,1,1,1,1,1,1,1,1,1,1,1,1,1,1,1,1,1,1,1,1,1,1,1,1
1,1,1,1,1,1,1,1,1,1,1,1,1,1,1,1,1,1,1,1,1,1,1,1,1,1,1,1,1,1,1,1,1,1,1,1
endlayer

layer
1,1,1,1,1,1,1,1,1,1,1,1,1,1,1,1,1,1,1,1,1,1,1,1,1,1,1,1,1,1,1,1,1,1,1,1
1,1,1,1,1,1,1,1,1,1,1,1,1,1,1,2,1,1,1,1,1,1,1,1,1,1,1,1,1,1,1,1,1,1,1,1
1,1,1,1,1,1,1,1,1,1,1,1,1,1,2,3,2,1,1,1,1,1,1,1,1,1,2,1,1,1,1,1,1,1,1,1
1,1,1,1,1,1,1,1,1,1,1,1,2,3,3,3,3,1,2,3,3,3,1,1,1,3,3,3,2,1,1,1,1,1,1,1
1,1,1,1,1,1,1,3,3,3,3,3,3,3,3,3,3,3,3,3,3,3,3,3,3,3,3,3,3,3,3,3,3,1,1,1
1,1,1,1,1,1,1,3,3,3,3,3,3,3,3,3,3,3,3,3,3,4,4,4,4,4,4,4,4,3,3,3,3,1,1,1
1,1,1,1,1,1,2,3,3,4,4,4,4,4,4,4,4,4,4,4,4,4,4,4,4,4,4,4,4,4,4,3,3,1,1,1
1,1,1,1,1,1,3,3,3,4,4,4,4,4,4,4,4,0,4,4,4,4,4,4,4,4,4,4,4,0,4,3,3,3,1,1
1,1,1,1,1,2,3,3,3,4,4,4,4,4,4,0,0,0,0,4,4,4,4,4,4,4,0,0,0,0,4,3,3,3,1,1
1,1,1,1,1,2,3,3,3,4,4,4,4,4,4,0,0,0,0,4,4,4,4,4,4,4,0,0,0,0,4,3,3,3,1,1
1,1,1,1,1,2,3,3,3,4,4,4,4,4,4,0,0,0,0,0,4,4,4,4,4,5,0,9,0,4,4,3,3,1,1,1
1,1,1,1,1,2,3,3,3,4,4,4,4,4,4,4,0,0,0,0,4,4,4,4,4,4,0,4,4,4,4,3,3,1,1,1
1,1,1,1,1,2,3,3,3,4,4,4,4,4,4,4,0,0,0,0,0,4,4,4,4,4,0,0,0,4,4,3,3,3,1,1
1,1,1,1,1,3,3,3,3,4,4,4,4,4,4,4,0,0,0,0,0,0,0,4,4,4,0,0,0,0,0,0,1,1,1,1
1,1,1,1,1,1,3,3,3,4,4,4,4,4,4,4,4,4,0,0,0,0,0,4,4,4,4,0,0,0,0,0,0,3,2,1
1,1,1,1,1,1,3,3,4,4,4,4,4,4,4,4,4,4,4,0,0,0,4,4,4,4,4,0,0,0,4,3,3,2,1,1
1,1,1,1,1,1,1,3,3,4,4,4,4,4,4,4,4,4,4,0,0,0,4,4,4,4,4,4,0,13,4,3,3,1,1,1
1,1,1,1,1,1,1,3,3,4,4,4,4,4,4,4,4,4,4,0,0,4,4,4,4,4,4,4,4,4,4,3,3,1,1,1
1,1,1,1,1,1,1,3,3,4,4,4,4,4,4,4,4,4,4,4,4,4,4,4,4,4,4,4,4,4,4,3,3,1,1,1
1,1,1,1,1,1,2,3,3,4,4,4,4,4,4,4,4,4,4,4,4,4,4,4,4,4,4,4,4,4,4,3,3,1,1,1
1,1,1,1,1,2,3,3,3,4,4,4,4,4,4,4,4,4,4,4,4,4,4,4,4,4,4,4,4,4,4,3,3,1,1,1
1,1,1,1,1,1,3,3,3,4,4,4,4,4,4,4,4,4,4,4,4,0,4,4,4,4,4,4,4,4,4,3,3,1,1,1
1,1,1,1,1,2,3,3,3,4,4,4,4,4,4,4,4,4,4,4,0,0,0,4,4,4,4,4,4,4,4,3,3,1,1,1
1,1,1,1,1,3,3,3,4,4,4,4,4,4,4,4,4,4,4,4,0,0,0,4,4,4,4,4,4,4,4,3,3,1,1,1
1,1,1,1,1,2,3,3,3,4,4,4,4,4,4,4,4,4,4,4,0,0,0,0,4,4,4,4,4,4,4,3,3,3,1,1
1,1,1,1,1,3,3,3,3,4,4,4,4,4,4,4,4,4,4,4,4,0,0,4,4,4,4,4,4,4,4,3,3,1,1,1
1,1,1,1,1,1,3,3,3,4,4,4,4,4,4,4,4,4,4,4,4,4,4,4,4,4,4,4,4,4,4,3,3,1,1,1
1,1,1,1,1,1,3,3,3,4,4,4,4,4,4,4,4,4,4,4,4,4,4,4,4,4,4,4,4,4,4,3,3,1,1,1
1,1,1,1,1,1,1,3,3,3,3,3,3,3,3,4,4,4,4,4,4,4,3,3,3,3,3,3,3,3,3,3,3,1,1,1
1,1,1,1,1,1,1,3,3,3,3,3,3,3,3,3,3,3,3,3,3,3,3,3,3,3,3,3,3,3,3,3,1,1,1,1
1,1,1,1,1,1,1,1,1,3,3,1,2,3,3,3,3,3,3,3,2,1,1,2,3,3,3,1,1,1,1,1,1,1,1,1
1,1,1,1,1,1,1,1,1,1,1,1,1,2,2,3,3,3,3,2,1,1,1,1,2,3,3,1,1,1,1,1,1,1,1,1
1,1,1,1,1,1,1,1,1,1,1,1,1,1,1,1,1,1,1,1,1,1,1,1,1,1,1,1,1,1,1,1,1,1,1,1
1,1,1,1,1,1,1,1,1,1,1,1,1,1,1,1,1,1,1,1,1,1,1,1,1,1,1,1,1,1,1,1,1,1,1,1
1,1,1,1,1,1,1,1,1,1,1,1,1,1,1,1,1,1,1,1,1,1,1,1,1,1,1,1,1,1,1,1,1,1,1,1
1,1,1,1,1,1,1,1,1,1,1,1,1,1,1,1,1,1,1,1,1,1,1,1,1,1,1,1,1,1,1,1,1,1,1,1
endlayer

layer
1,1,1,1,1,1,1,1,1,1,1,1,1,1,1,1,1,1,1,1,1,1,1,1,1,1,1,1,1,1,1,1,1,1,1,1
1,1,1,1,1,1,1,1,1,1,1,1,1,1,1,1,1,1,1,1,1,1,1,1,1,1,1,1,1,1,1,1,1,1,1,1
1,1,1,1,1,1,1,1,1,1,1,1,1,1,1,2,1,1,1,1,1,1,1,1,1,1,1,1,1,1,1,1,1,1,1,1
1,1,1,1,1,1,1,1,1,1,1,1,1,2,3,3,2,1,1,3,1,1,1,1,1,3,3,2,1,1,1,1,1,1,1,1
1,1,1,1,1,1,1,3,3,3,2,2,2,2,3,3,3,3,3,3,3,3,3,3,3,3,3,3,3,3,3,3,3,1,1,1
1,1,1,1,1,1,1,3,3,3,3,3,3,3,3,3,3,3,3,3,3,3,3,3,4,3,3,3,3,3,3,3,3,1,1,1
1,1,1,1,1,1,1,3,3,4,4,4,4,4,4,4,4,4,4,4,4,4,4,4,4,4,4,4,4,4,4,3,3,1,1,1
1,1,1,1,1,1,2,3,3,4,4,4,4,4,4,4,4,4,4,4,4,4,4,4,4,4,4,4,4,4,4,3,3,3,1,1
1,1,1,1,1,1,3,3,3,4,4,4,4,4,4,0,0,4,4,4,4,4,4,4,4,4,0,0,4,4,4,3,3,3,1,1
1,1,1,1,1,1,2,3,3,4,4,4,4,4,4,0,0,0,4,4,4,4,4,4,4,0,0,0,0,4,4,3,3,1,1,1
1,1,1,1,1,1,3,3,3,4,4,4,4,4,4,4,0,0,4,4,4,4,4,4,4,0,0,0,4,4,4,3,3,1,1,1
1,1,1,1,1,1,3,3,3,4,4,4,4,4,4,4,4,0,0,4,4,4,4,4,4,0,0,0,4,4,4,3,3,1,1,1
1,1,1,1,1,1,3,3,3,4,4,4,4,4,4,4,4,0,0,0,4,4,4,4,4,4,0,0,0,4,4,3,3,3,1,1
1,1,1,1,1,3,3,3,3,4,4,4,4,4,4,4,4,0,0,0,0,4,4,4,4,4,0,0,0,0,0,0,0,3,1,1
1,1,1,1,1,1,3,3,3,4,4,4,4,4,4,4,4,4,0,0,0,4,4,4,4,4,4,0,0,0,0,0,0,2,1,1
1,1,1,1,1,1,3,3,4,4,4,4,4,4,4,4,4,4,4,4,4,4,4,4,4,4,4,0,0,4,4,3,3,1,1,1
1,1,1,1,1,1,1,3,3,4,4,4,4,4,4,4,4,4,4,4,4,4,4,4,4,4,4,4,0,4,4,3,3,1,1,1
1,1,1,1,1,1,1,3,3,4,14,4,4,4,4,4,4,4,4,4,4,4,4,4,4,4,4,4,4,4,4,3,3,1,1,1
1,1,1,1,1,1,1,3,3,4,4,4,4,4,4,4,4,4,4,4,4,4,4,4,4,4,4,4,4,4,4,3,3,1,1,1
1,1,1,1,1,1,1,3,3,4,4,4,4,4,4,4,4,4,4,4,4,4,4,4,4,4,4,4,4,4,4,3,3,1,1,1
1,1,1,1,1,1,2,3,3,4,4,4,4,4,4,4,4,4,4,4,4,4,4,4,4,4,4,4,4,4,4,3,3,1,1,1
1,1,1,1,1,1,2,3,3,4,4,4,4,4,4,4,4,4,4,4,4,4,4,4,4,4,4,4,4,4,4,3,3,1,1,1
1,1,1,1,1,1,3,3,3,4,4,4,4,4,4,4,4,4,4,4,4,0,4,4,4,4,4,4,4,4,4,3,3,1,1,1
1,1,1,1,1,2,3,3,3,4,4,4,4,4,4,4,4,4,4,4,0,0,0,0,4,4,4,4,4,4,4,3,3,1,1,1
1,1,1,1,1,1,3,3,3,4,4,4,4,4,4,4,4,4,4,4,0,0,0,0,0,4,4,4,4,4,4,3,3,1,1,1
1,1,1,1,1,3,3,3,3,4,4,4,4,4,4,4,4,4,4,4,14,0,0,4,4,4,4,4,4,4,4,3,3,1,1,1
1,1,1,1,1,1,3,3,3,4,4,4,4,4,4,4,4,4,4,4,4,4,13,4,4,4,4,4,4,4,4,3,3,1,1,1
1,1,1,1,1,1,3,3,3,4,4,4,4,4,4,4,4,4,4,4,4,4,4,4,4,4,4,4,4,4,4,3,3,1,1,1
1,1,1,1,1,1,1,3,3,3,3,3,3,3,3,3,4,3,3,3,3,3,3,3,3,3,3,3,3,3,3,3,3,1,1,1
1,1,1,1,1,1,1,3,3,3,3,3,3,3,3,3,3,3,3,3,3,3,3,3,3,3,3,3,3,3,3,3,1,1,1,1
1,1,1,1,1,1,1,1,1,3,1,1,1,3,3,3,3,3,3,2,1,1,1,1,2,3,3,1,1,1,1,1,1,1,1,1
1,1,1,1,1,1,1,1,1,1,1,1,1,1,1,2,3,3,2,1,1,1,1,1,1,2,2,1,1,1,1,1,1,1,1,1
1,1,1,1,1,1,1,1,1,1,1,1,1,1,1,1,1,1,1,1,1,1,1,1,1,1,1,1,1,1,1,1,1,1,1,1
1,1,1,1,1,1,1,1,1,1,1,1,1,1,1,1,1,1,1,1,1,1,1,1,1,1,1,1,1,1,1,1,1,1,1,1
1,1,1,1,1,1,1,1,1,1,1,1,1,1,1,1,1,1,1,1,1,1,1,1,1,1,1,1,1,1,1,1,1,1,1,1
1,1,1,1,1,1,1,1,1,1,1,1,1,1,1,1,1,1,1,1,1,1,1,1,1,1,1,1,1,1,1,1,1,1,1,1
endlayer

layer
1,1,1,1,1,1,1,1,1,1,1,1,1,1,1,1,1,1,1,1,1,1,1,1,1,1,1,1,1,1,1,1,1,1,1,1
1,1,1,1,1,1,1,1,1,1,1,1,1,1,1,1,1,1,1,1,1,1,1,1,1,1,1,1,1,1,1,1,1,1,1,1
1,1,1,1,1,1,1,1,1,1,1,1,1,1,1,1,1,1,1,1,1,1,1,1,1,1,1,1,1,1,1,1,1,1,1,1
1,1,1,1,1,1,1,1,1,1,1,1,1,1,2,3,1,1,1,3,1,1,1,1,1,2,2,1,1,1,1,1,1,1,1,1
1,1,1,1,1,1,1,1,1,1,1,1,1,1,3,3,3,3,3,3,3,3,3,3,3,3,3,3,3,3,3,3,3,1,1,1
1,1,1,1,1,1,1,3,3,3,3,3,3,3,3,3,3,3,3,3,3,3,3,3,3,3,3,3,3,3,3,3,3,1,1,1
1,1,1,1,1,1,1,3,3,4,4,4,4,4,4,4,4,4,4,4,4,4,4,4,4,4,4,4,4,4,4,3,3,1,1,1
1,1,1,1,1,1,1,3,3,4,4,4,4,4,4,4,4,4,15,16,16,15,4,4,4,4,4,4,4,4,4,3,3,3,1,1
1,1,1,1,1,1,2,3,3,4,4,4,4,4,4,4,4,4,4,4,4,4,4,4,4,4,4,4,4,4,4,3,3,1,1,1
1,1,1,1,1,1,1,3,3,4,4,4,4,4,4,4,4,4,4,4,4,4,4,4,4,4,4,4,4,4,4,3,3,1,1,1
1,1,1,1,1,1,3,3,3,4,4,4,4,4,4,4,4,14,4,4,4,4,4,4,4,4,4,4,4,4,4,3,3,1,1,1
1,1,1,1,1,1,3,3,3,4,4,4,4,4,4,4,4,4,4,4,4,4,4,4,4,4,4,4,4,4,4,3,3,1,1,1
1,1,1,1,1,1,3,3,3,4,4,4,4,4,4,4,4,5,4,4,4,4,4,4,4,4,4,4,4,4,4,3,3,2,1,1
1,1,1,1,1,2,3,3,3,4,4,4,4,4,4,4,4,4,4,4,4,4,4,4,4,4,4,4,4,4,4,3,3,3,1,1
1,1,1,1,1,1,3,3,3,4,4,4,4,4,4,4,4,4,4,4,4,4,4,4,4,4,4,4,4,4,4,3,3,1,1,1
1,1,1,1,1,1,2,3,3,4,15,4,4,4,4,4,4,4,4,4,4,4,4,4,4,4,4,4,4,15,4,3,3,1,1,1
1,1,1,1,1,1,1,3,3,4,16,4,4,4,4,4,4,4,4,4,4,4,4,4,4,4,4,4,4,16,4,3,3,1,1,1
1,1,1,1,1,1,1,3,3,4,16,4,4,4,4,4,4,4,4,4,4,4,4,4,4,4,4,4,4,16,4,3,3,1,1,1
1,1,1,1,1,1,1,3,3,4,15,4,4,4,4,4,4,4,4,4,4,4,4,4,4,4,4,4,4,15,4,3,3,1,1,1
1,1,1,1,1,1,1,3,3,4,4,4,4,4,4,4,4,4,4,4,4,4,4,4,4,4,4,4,4,4,4,3,3,1,1,1
1,1,1,1,1,1,1,3,3,4,4,4,4,4,4,4,4,4,4,4,4,4,4,4,4,4,4,4,4,4,4,3,3,1,1,1
1,1,1,1,1,1,1,3,3,4,4,4,4,4,4,4,4,4,4,4,4,4,4,4,4,4,4,4,4,4,4,3,3,1,1,1
1,1,1,1,1,1,2,3,3,4,4,4,4,4,4,4,4,4,4,4,4,4,4,4,4,4,4,4,4,4,4,3,3,1,1,1
1,1,1,1,1,1,2,3,3,4,4,4,4,4,4,4,4,4,14,4,4,14,4,4,4,4,4,4,4,4,4,3,3,1,1,1
1,1,1,1,1,1,3,3,3,4,4,4,4,4,4,4,4,4,4,4,4,4,4,4,4,4,4,4,4,4,4,3,3,1,1,1
1,1,1,1,1,2,3,3,3,4,4,4,4,4,4,4,4,4,4,4,4,4,5,4,4,4,4,4,4,4,4,3,3,1,1,1
1,1,1,1,1,1,3,3,3,4,4,4,4,4,4,4,4,4,15,16,16,15,4,4,4,4,4,4,4,4,4,3,3,1,1,1
1,1,1,1,1,1,2,3,3,4,4,4,4,4,4,4,4,4,4,4,4,4,4,4,4,4,4,4,4,4,4,3,3,1,1,1
1,1,1,1,1,1,1,3,3,3,3,3,3,3,3,3,3,3,3,3,3,3,3,3,3,3,3,3,3,3,3,3,3,1,1,1
1,1,1,1,1,1,1,3,3,3,3,3,3,3,3,3,3,3,3,3,3,3,3,3,3,3,3,3,3,3,3,3,1,1,1,1
1,1,1,1,1,1,1,1,1,1,1,1,1,3,3,2,3,3,3,1,1,1,1,1,1,2,3,1,1,1,1,1,1,1,1,1
1,1,1,1,1,1,1,1,1,1,1,1,1,1,1,1,2,3,1,1,1,1,1,1,1,1,1,1,1,1,1,1,1,1,1,1
1,1,1,1,1,1,1,1,1,1,1,1,1,1,1,1,1,1,1,1,1,1,1,1,1,1,1,1,1,1,1,1,1,1,1,1
1,1,1,1,1,1,1,1,1,1,1,1,1,1,1,1,1,1,1,1,1,1,1,1,1,1,1,1,1,1,1,1,1,1,1,1
1,1,1,1,1,1,1,1,1,1,1,1,1,1,1,1,1,1,1,1,1,1,1,1,1,1,1,1,1,1,1,1,1,1,1,1
1,1,1,1,1,1,1,1,1,1,1,1,1,1,1,1,1,1,1,1,1,1,1,1,1,1,1,1,1,1,1,1,1,1,1,1
endlayer

layer
1,1,1,1,1,1,1,1,1,1,1,1,1,1,1,1,1,1,1,1,1,1,1,1,1,1,1,1,1,1,1,1,1,1,1,1
1,1,1,1,1,1,1,1,1,1,1,1,1,1,1,1,1,1,1,1,1,1,1,1,1,1,1,1,1,1,1,1,1,1,1,1
1,1,1,1,1,1,1,1,1,1,1,1,1,1,1,1,1,1,1,1,1,1,1,1,1,1,1,1,1,1,1,1,1,1,1,1
1,1,1,1,1,1,1,1,1,1,1,1,1,1,1,3,1,1,1,1,1,1,1,1,1,1,1,1,1,1,1,1,1,1,1,1
1,1,1,1,1,1,1,1,1,1,1,1,1,1,3,3,3,3,3,3,3,3,3,3,3,3,3,3,3,3,3,3,3,1,1,1
1,1,1,1,1,1,1,3,3,3,3,3,3,3,3,3,3,3,3,3,3,3,3,3,3,3,3,3,3,3,3,3,3,1,1,1
1,1,1,1,1,1,1,3,3,21,21,17,17,17,22,20,22,21,19,20,21,17,18,20,21,19,20,19,18,17,17,3,3,1,1,1
1,1,1,1,1,1,1,3,3,17,20,17,20,20,22,17,20,22,22,21,21,18,17,21,19,21,18,19,20,22,18,3,3,1,1,1
1,1,1,1,1,1,1,3,3,20,20,21,22,20,19,17,20,20,19,18,22,20,20,20,22,17,20,18,20,20,21,3,3,1,1,1
1,1,1,1,1,1,1,3,3,21,22,21,19,17,22,20,18,20,22,20,17,17,20,19,20,19,22,17,20,20,17,3,3,1,1,1
1,1,1,1,1,1,2,3,3,19,19,22,21,20,18,20,19,15,21,18,17,21,15,21,17,22,20,21,17,17,19,3,3,1,1,1
1,1,1,1,1,1,3,3,3,22,20,18,19,21,20,19,22,18,22,19,17,17,21,19,17,22,17,19,18,17,22,3,3,1,1,1
1,1,1,1,1,1,3,3,3,21,17,21,20,17,20,22,17,5,18,17,22,19,18,20,20,17,17,19,19,17,17,3,3,1,1,1
1,1,1,1,1,1,3,3,3,19,18,21,20,18,21,22,17,22,21,18,20,19,22,19,17,19,18,18,19,21,19,3,3,2,1,1
1,1,1,1,1,1,3,3,3,18,17,22,20,15,18,20,17,19,17,18,18,21,17,19,17,18,15,17,22,20,19,3,3,1,1,1
1,1,1,1,1,1,1,3,3,19,21,22,18,21,22,19,18,18,19,22,19,18,19,21,22,22,21,19,17,17,17,3,3,1,1,1
1,1,1,1,1,1,1,3,3,21,21,22,22,19,21,17,19,18,18,23,23,22,22,17,20,17,22,19,20,21,18,3,3,1,1,1
1,1,1,1,1,1,1,3,3,21,21,20,18,20,21,18,21,22,20,23,23,22,20,21,18,22,17,19,22,21,22,3,3,1,1,1
1,1,1,1,1,1,1,3,3,21,17,20,19,21,21,18,20,17,19,19,19,19,21,18,20,17,21,20,22,21,22,3,3,1,1,1
1,1,1,1,1,1,1,3,3,20,18,17,22,15,17,17,20,19,19,21,22,19,21,22,22,21,15,21,21,21,17,3,3,1,1,1
1,1,1,1,1,1,1,3,3,19,17,18,20,22,18,18,17,20,19,18,19,18,21,20,17,22,21,18,21,19,19,3,3,1,1,1
1,1,1,1,1,1,1,3,3,17,17,20,22,21,19,20,17,22,20,22,22,19,20,17,17,19,20,22,19,20,17,3,3,1,1,1
1,1,1,1,1,1,1,3,3,22,20,19,20,19,17,21,19,19,17,21,18,19,21,21,19,17,19,22,18,18,20,3,3,1,1,1
1,1,1,1,1,1,1,3,3,19,20,18,20,20,19,21,22,15,21,17,20,21,15,21,18,18,18,18,21,17,17,3,3,1,1,1
1,1,1,1,1,1,3,3,3,22,17,20,22,17,17,22,21,17,21,20,22,19,18,21,19,21,21,18,22,20,22,3,3,1,1,1
1,1,1,1,1,1,3,3,3,18,20,17,18,20,19,17,19,18,22,20,17,20,21,22,17,17,18,20,21,18,18,3,3,1,1,1
1,1,1,1,1,1,3,3,3,19,18,18,20,19,18,18,18,20,21,21,21,18,20,20,21,22,22,22,21,20,18,3,3,1,1,1
1,1,1,1,1,1,1,3,3,20,20,22,20,21,18,22,17,19,21,17,19,17,17,18,19,17,19,22,21,20,19,3,3,1,1,1
1,1,1,1,1,1,1,3,3,3,3,3,3,3,3,3,3,3,3,3,3,3,3,3,3,3,3,3,3,3,3,3,3,1,1,1
1,1,1,1,1,1,1,3,3,3,3,3,3,3,3,3,3,3,3,3,3,3,3,3,3,3,3,3,3,3,3,3,1,1,1,1
1,1,1,1,1,1,1,1,1,1,1,1,1,2,3,1,2,3,2,1,1,1,1,1,1,1,2,1,1,1,1,1,1,1,1,1
1,1,1,1,1,1,1,1,1,1,1,1,1,1,1,1,1,2,1,1,1,1,1,1,1,1,1,1,1,1,1,1,1,1,1,1
1,1,1,1,1,1,1,1,1,1,1,1,1,1,1,1,1,1,1,1,1,1,1,1,1,1,1,1,1,1,1,1,1,1,1,1
1,1,1,1,1,1,1,1,1,1,1,1,1,1,1,1,1,1,1,1,1,1,1,1,1,1,1,1,1,1,1,1,1,1,1,1
1,1,1,1,1,1,1,1,1,1,1,1,1,1,1,1,1,1,1,1,1,1,1,1,1,1,1,1,1,1,1,1,1,1,1,1
1,1,1,1,1,1,1,1,1,1,1,1,1,1,1,1,1,1,1,1,1,1,1,1,1,1,1,1,1,1,1,1,1,1,1,1
endlayer

layer
1,1,1,1,1,1,1,1,1,1,1,1,1,1,1,1,1,1,1,1,1,1,1,1,1,1,1,1,1,1,1,1,1,1,1,1
1,1,1,1,1,1,1,1,1,1,1,1,1,1,1,1,1,1,1,1,1,1,1,1,1,1,1,1,1,1,1,1,1,1,1,1
1,1,1,1,1,1,1,1,1,1,1,1,1,1,1,1,1,1,1,1,1,1,1,1,1,1,1,1,1,1,1,1,1,1,1,1
1,1,1,1,1,1,1,1,1,1,1,1,1,1,1,24,1,1,1,1,1,1,1,1,1,1,1,1,1,1,1,1,1,1,1,1
1,1,1,1,1,1,1,1,1,1,1,1,1,1,2,3,3,3,3,3,3,3,3,3,3,3,3,3,3,3,3,3,2,1,1,1
1,1,1,1,1,1,1,2,21,21,21,21,21,21,21,21,21,21,21,21,21,21,21,21,21,21,21,21,21,21,21,21,3,1,1,1
1,1,1,1,1,1,1,2,21,21,20,22,19,17,18,17,18,18,21,22,19,21,20,21,21,22,20,22,18,22,22,21,3,1,1,1
1,1,1,1,1,1,1,2,21,19,0,0,0,0,0,0,0,0,25,0,0,25,0,0,0,0,0,0,0,0,17,21,3,1,1,1
1,1,1,1,1,1,1,2,21,21,0,0,0,0,0,0,0,0,0,0,26,0,0,0,0,0,0,0,0,0,17,21,3,1,1,1
1,1,1,1,1,1,1,3,21,19,0,0,21,17,21,18,22,21,17,26,0,19,17,20,22,18,20,18,0,0,19,21,3,1,1,1
1,1,1,1,1,1,1,3,21,18,0,0,22,27,27,27,27,22,30,29,29,28,21,27,27,27,27,22,0,0,18,21,3,1,1,1
1,1,1,1,1,1,2,3,21,18,0,0,18,27,27,27,27,19,21,31,31,17,18,27,27,27,27,20,0,0,17,21,3,1,1,1
1,1,1,1,1,1,3,3,21,20,0,0,20,27,27,27,27,27,20,18,18,22,27,27,27,27,27,22,0,0,20,21,3,1,1,1
1,1,1,1,1,1,2,3,21,21,0,0,22,27,27,27,27,27,17,32,32,17,27,27,27,27,27,20,0,0,21,21,3,1,1,1
1,1,1,1,1,1,2,3,21,19,0,0,20,18,18,27,27,27,19,33,33,22,27,27,27,17,20,22,0,0,21,21,3,1,1,1
1,1,1,1,1,1,1,3,21,21,25,0,17,34,21,20,22,21,17,35,35,19,21,21,18,17,34,21,0,25,21,21,3,1,1,1
1,1,1,1,1,1,1,3,21,22,0,0,26,29,38,21,32,33,35,37,37,35,33,32,17,36,29,26,0,0,19,21,3,1,1,1
1,1,1,1,1,1,1,3,21,18,0,0,0,29,38,21,32,33,35,37,37,35,33,32,19,36,29,0,0,0,19,21,3,1,1,1
1,1,1,1,1,1,1,3,21,21,25,0,21,39,21,21,17,20,18,35,35,21,17,19,22,21,39,18,0,25,21,21,3,1,1,1
1,1,1,1,1,1,1,3,21,17,0,26,19,19,18,27,27,27,22,33,33,21,27,27,27,20,22,21,0,0,20,21,3,1,1,1
1,1,1,1,1,1,1,3,21,20,0,0,19,27,27,27,27,27,22,32,32,18,27,27,27,27,27,18,0,0,18,21,3,1,1,1
1,1,1,1,1,1,1,3,21,18,0,0,21,27,27,27,27,27,20,22,21,21,27,27,27,27,27,17,0,0,17,21,3,1,1,1
1,1,1,1,1,1,1,3,21,21,0,0,21,27,27,27,27,18,17,40,40,17,17,27,27,27,27,22,0,0,18,21,3,1,1,1
1,1,1,1,1,1,1,3,21,20,0,0,22,27,27,27,27,22,30,29,29,28,21,27,27,27,27,21,0,0,20,21,3,1,1,1
1,1,1,1,1,1,2,3,21,22,0,0,22,22,21,17,19,22,20,26,0,18,22,22,21,21,19,21,0,0,18,21,3,1,1,1
1,1,1,1,1,1,3,3,21,22,0,0,0,0,0,0,0,26,0,0,0,0,0,0,0,0,0,0,0,0,18,21,3,1,1,1
1,1,1,1,1,1,2,3,21,18,0,0,0,0,0,0,0,0,25,0,0,25,0,0,0,0,0,0,0,0,18,21,3,1,1,1
1,1,1,1,1,1,1,3,21,22,20,17,18,22,19,20,18,22,21,20,17,21,19,18,20,22,20,20,21,19,21,21,3,1,1,1
1,1,1,1,1,1,1,3,21,21,21,21,21,21,21,21,21,21,21,21,21,21,21,21,21,21,21,21,21,21,21,21,2,1,1,1
1,1,1,1,1,1,1,2,3,3,3,3,3,3,3,3,3,3,3,3,3,3,3,3,3,3,3,3,3,3,3,3,1,1,1,1
1,1,1,1,1,1,1,1,1,1,1,1,1,1,2,1,1,2,1,1,1,1,1,1,1,1,1,1,1,1,1,1,1,1,1,1
1,1,1,1,1,1,1,1,1,1,1,1,1,1,1,1,1,1,1,1,1,1,1,1,1,1,1,1,1,1,1,1,1,1,1,1
1,1,1,1,1,1,1,1,1,1,1,1,1,1,1,1,1,1,1,1,1,1,1,1,1,1,1,1,1,1,1,1,1,1,1,1
1,1,1,1,1,1,1,1,1,1,1,1,1,1,1,1,1,1,1,1,1,1,1,1,1,1,1,1,1,1,1,1,1,1,1,1
1,1,1,1,1,1,1,1,1,1,1,1,1,1,1,1,1,1,1,1,1,1,1,1,1,1,1,1,1,1,1,1,1,1,1,1
1,1,1,1,1,1,1,1,1,1,1,1,1,1,1,1,1,1,1,1,1,1,1,1,1,1,1,1,1,1,1,1,1,1,1,1
endlayer

layer
1,1,1,1,1,1,1,1,1,1,1,1,1,1,1,1,1,1,1,1,1,1,1,1,1,1,1,1,1,1,1,1,1,1,1,1
1,1,1,1,1,1,1,1,1,1,1,1,1,1,1,1,1,1,1,1,1,1,1,1,1,1,1,1,1,1,1,1,1,1,1,1
1,1,1,1,1,1,1,1,1,1,1,1,1,1,1,1,1,1,1,1,1,1,1,1,1,1,1,1,1,1,1,1,1,1,1,1
1,1,1,1,1,1,1,1,1,1,1,1,1,1,1,24,1,1,1,1,1,1,1,1,1,1,1,1,1,1,1,1,1,1,1,1
1,1,1,1,1,1,1,1,1,1,1,1,1,1,1,2,3,3,3,3,3,3,3,3,2,3,2,3,3,3,3,2,1,1,1,1
1,1,1,1,1,1,1,1,3,3,3,3,3,2,3,3,3,3,3,3,3,3,3,3,3,3,3,3,3,3,3,3,3,1,1,1
1,1,1,1,1,1,1,1,3,22,22,41,22,41,16,16,16,16,17,20,20,19,16,41,41,41,16,17,41,18,17,3,3,1,1,1
1,1,1,1,1,1,1,1,2,18,0,0,0,0,0,0,0,0,0,0,0,0,0,0,0,0,0,0,0,0,20,3,3,1,1,1
1,1,1,1,1,1,1,1,3,41,0,0,0,0,0,0,0,0,0,0,0,0,0,0,0,0,0,0,0,0,16,3,3,1,1,1
1,1,1,1,1,1,1,2,3,22,0,0,42,42,42,42,42,18,19,0,0,21,20,42,42,42,42,42,0,0,18,3,3,1,1,1
1,1,1,1,1,1,1,3,3,41,0,0,42,0,0,0,0,21,16,0,0,16,22,0,0,0,0,42,0,0,16,3,3,1,1,1
1,1,1,1,1,1,1,3,3,16,0,0,42,0,0,0,0,20,21,0,0,19,22,0,0,0,0,42,0,0,41,3,2,1,1,1
1,1,1,1,1,1,2,3,3,16,0,0,42,0,0,0,0,0,0,16,16,0,0,0,0,0,0,42,0,0,16,3,3,1,1,1
1,1,1,1,1,1,1,3,3,41,0,0,42,0,0,0,0,0,0,32,32,0,0,0,0,0,0,42,0,0,16,3,3,1,1,1
1,1,1,1,1,1,1,3,3,16,0,0,19,22,18,0,0,0,42,0,0,42,0,0,0,21,20,20,0,0,41,3,3,1,1,1
1,1,1,1,1,1,1,3,3,17,0,0,19,16,18,0,0,42,18,43,43,18,42,0,0,20,16,19,0,0,19,3,3,1,1,1
1,1,1,1,1,1,1,3,3,17,0,0,0,0,0,16,32,0,45,18,18,44,0,32,16,0,0,0,0,0,20,3,3,1,1,1
1,1,1,1,1,1,1,3,3,18,0,0,0,0,0,16,32,0,45,18,18,44,0,32,16,0,0,0,0,0,17,3,3,1,1,1
1,1,1,1,1,1,1,3,3,18,0,0,20,16,21,0,0,42,18,46,46,22,42,0,0,21,16,22,0,0,18,3,3,1,1,1
1,1,1,1,1,1,1,3,3,41,0,0,17,19,21,0,0,0,42,0,0,42,0,0,0,20,20,18,0,0,41,3,3,1,1,1
1,1,1,1,1,1,1,3,3,41,0,0,42,0,0,0,0,0,0,32,32,0,0,0,0,0,0,42,0,0,16,3,3,1,1,1
1,1,1,1,1,1,1,3,3,16,0,0,42,0,0,0,0,0,0,16,16,0,0,0,0,0,0,42,0,0,16,3,3,1,1,1
1,1,1,1,1,1,1,3,3,41,0,0,42,0,0,0,0,18,17,0,0,21,17,0,0,0,0,42,0,0,16,3,3,1,1,1
1,1,1,1,1,1,1,3,3,16,0,0,42,0,0,0,0,20,16,0,0,16,17,0,0,0,0,42,0,0,41,3,2,1,1,1
1,1,1,1,1,1,1,3,3,21,0,0,42,42,42,42,42,19,21,0,0,21,21,42,42,42,42,42,0,0,17,3,3,1,1,1
1,1,1,1,1,1,3,3,3,16,0,0,0,0,0,0,0,0,0,0,0,0,0,0,0,0,0,0,0,0,16,3,3,1,1,1
1,1,1,1,1,1,1,3,3,21,0,0,0,0,0,0,0,0,0,0,0,0,0,0,0,0,0,0,0,0,19,3,2,1,1,1
1,1,1,1,1,1,1,3,3,22,19,41,20,16,16,16,16,16,19,17,17,22,16,16,16,41,16,22,16,17,19,3,2,1,1,1
1,1,1,1,1,1,1,3,3,3,3,3,3,3,3,3,3,3,3,3,3,3,3,3,3,3,3,3,3,3,3,3,1,1,1,1
1,1,1,1,1,1,1,1,3,3,3,3,3,3,3,3,3,3,3,3,3,3,3,3,3,3,3,3,3,3,3,2,1,1,1,1
1,1,1,1,1,1,1,1,1,1,1,1,1,1,1,1,1,1,1,1,1,1,1,1,1,1,1,1,1,1,1,1,1,1,1,1
1,1,1,1,1,1,1,1,1,1,1,1,1,1,1,1,1,1,1,1,1,1,1,1,1,1,1,1,1,1,1,1,1,1,1,1
1,1,1,1,1,1,1,1,1,1,1,1,1,1,1,1,1,1,1,1,1,1,1,1,1,1,1,1,1,1,1,1,1,1,1,1
1,1,1,1,1,1,1,1,1,1,1,1,1,1,1,1,1,1,1,1,1,1,1,1,1,1,1,1,1,1,1,1,1,1,1,1
1,1,1,1,1,1,1,1,1,1,1,1,1,1,1,1,1,1,1,1,1,1,1,1,1,1,1,1,1,1,1,1,1,1,1,1
1,1,1,1,1,1,1,1,1,1,1,1,1,1,1,1,1,1,1,1,1,1,1,1,1,1,1,1,1,1,1,1,1,1,1,1
endlayer

layer
1,1,1,1,1,1,1,1,1,1,1,1,1,1,1,1,1,1,1,1,1,1,1,1,1,1,1,1,1,1,1,1,1,1,1,1
1,1,1,1,1,1,1,1,1,1,1,1,1,1,1,1,1,1,1,1,1,1,1,1,1,1,1,1,1,1,1,1,1,1,1,1
1,1,1,1,1,1,1,1,1,1,1,1,1,1,1,1,1,1,1,1,1,1,1,1,1,1,1,1,1,1,1,1,1,1,1,1
1,1,1,1,1,1,1,1,1,1,1,1,1,1,1,24,1,1,1,1,1,1,1,1,1,1,1,1,1,1,1,1,1,1,1,1
1,1,1,1,1,1,1,1,1,1,1,1,1,1,1,1,2,3,2,2,3,3,3,2,1,2,1,2,3,3,3,1,1,1,1,1
1,1,1,1,1,1,1,1,24,24,2,2,2,1,2,3,3,3,3,3,3,3,3,3,3,3,3,3,3,3,3,3,2,1,1,1
1,1,1,1,1,1,1,1,2,21,17,16,17,41,18,19,22,16,20,22,17,20,16,22,19,22,16,20,16,20,18,3,3,1,1,1
1,1,1,1,1,1,1,1,1,22,0,0,0,0,0,0,0,0,0,0,0,0,0,0,0,0,0,0,0,0,21,3,2,1,1,1
1,1,1,1,1,1,1,1,2,41,0,0,0,0,0,0,0,0,0,0,0,0,0,0,0,0,0,0,0,0,16,3,3,1,1,1
1,1,1,1,1,1,1,1,3,21,0,0,47,0,0,0,42,42,18,17,20,22,42,42,0,0,0,47,0,0,19,3,2,1,1,1
1,1,1,1,1,1,1,2,3,16,0,0,0,0,0,0,0,0,20,49,48,18,0,0,0,0,0,0,0,0,41,3,2,1,1,1
1,1,1,1,1,1,1,3,3,17,0,0,0,0,0,0,0,0,21,49,48,22,0,0,0,0,0,0,0,0,19,3,1,1,1,1
1,1,1,1,1,1,1,3,3,19,0,0,0,0,0,0,0,0,0,17,18,0,0,0,0,0,0,0,0,0,21,3,2,1,1,1
1,1,1,1,1,1,1,3,3,19,0,0,42,0,0,0,0,0,0,32,32,0,0,0,0,0,0,42,0,0,22,3,3,1,1,1
1,1,1,1,1,1,1,3,3,41,0,0,42,0,0,0,0,0,47,0,0,47,0,0,0,0,0,42,0,0,16,3,3,1,1,1
1,1,1,1,1,1,1,3,3,17,0,0,17,21,22,0,0,47,19,18,18,22,47,0,0,22,19,17,0,0,18,3,3,1,1,1
1,1,1,1,1,1,1,3,3,17,0,0,21,50,50,22,32,0,18,27,27,18,0,32,21,50,50,20,0,0,21,3,3,1,1,1
1,1,1,1,1,1,1,3,3,22,0,0,20,51,51,18,32,0,18,27,27,18,0,32,22,51,51,21,0,0,20,3,3,1,1,1
1,1,1,1,1,1,1,3,3,22,0,0,18,22,17,0,0,47,22,18,18,20,47,0,0,22,21,22,0,0,17,3,3,1,1,1
1,1,1,1,1,1,1,3,3,41,0,0,42,0,0,0,0,0,47,0,0,47,0,0,0,0,0,42,0,0,16,3,3,1,1,1
1,1,1,1,1,1,1,3,3,22,0,0,42,0,0,0,0,0,0,32,32,0,0,0,0,0,0,42,0,0,21,3,3,1,1,1
1,1,1,1,1,1,1,2,3,20,0,0,0,0,0,0,0,0,0,18,18,0,0,0,0,0,0,0,0,0,21,3,3,1,1,1
1,1,1,1,1,1,1,3,3,18,0,0,0,0,0,0,0,0,20,49,48,21,0,0,0,0,0,0,0,0,22,3,3,1,1,1
1,1,1,1,1,1,1,3,3,16,0,0,0,0,0,0,0,0,21,49,48,22,0,0,0,0,0,0,0,0,16,3,1,1,1,1
1,1,1,1,1,1,1,3,3,21,0,0,47,0,0,0,42,42,19,17,17,18,42,42,0,0,0,47,0,0,21,3,2,1,1,1
1,1,1,1,1,1,2,3,3,16,0,0,0,0,0,0,0,0,0,0,0,0,0,0,0,0,0,0,0,0,16,3,3,1,1,1
1,1,1,1,1,1,1,2,3,20,0,0,0,0,0,0,0,0,0,0,0,0,0,0,0,0,0,0,0,0,20,3,1,1,1,1
1,1,1,1,1,1,1,2,3,18,20,41,21,41,17,17,19,41,20,18,18,17,16,19,20,21,16,22,16,21,19,3,1,1,1,1
1,1,1,1,1,1,1,2,3,3,3,3,3,3,3,3,3,3,3,3,3,3,3,3,3,3,3,3,3,3,3,3,1,1,1,1
1,1,1,1,1,1,1,1,2,3,3,3,3,2,3,3,3,3,3,3,3,2,3,3,3,2,2,3,3,2,2,1,1,1,1,1
1,1,1,1,1,1,1,1,1,1,1,1,1,1,1,1,1,1,1,1,1,1,1,1,1,1,1,1,1,1,1,1,1,1,1,1
1,1,1,1,1,1,1,1,1,1,1,1,1,1,1,1,1,1,1,1,1,1,1,1,1,1,1,1,1,1,1,1,1,1,1,1
1,1,1,1,1,1,1,1,1,1,1,1,1,1,1,1,1,1,1,1,1,1,1,1,1,1,1,1,1,1,1,1,1,1,1,1
1,1,1,1,1,1,1,1,1,1,1,1,1,1,1,1,1,1,1,1,1,1,1,1,1,1,1,1,1,1,1,1,1,1,1,1
1,1,1,1,1,1,1,1,1,1,1,1,1,1,1,1,1,1,1,1,1,1,1,1,1,1,1,1,1,1,1,1,1,1,1,1
1,1,1,1,1,1,1,1,1,1,1,1,1,1,1,1,1,1,1,1,1,1,1,1,1,1,1,1,1,1,1,1,1,1,1,1
endlayer

layer
1,1,1,1,1,1,1,1,1,1,1,1,1,1,1,1,1,1,1,1,1,1,1,1,1,1,1,1,1,1,1,1,1,1,1,1
1,1,1,1,1,1,1,1,1,1,1,1,1,1,1,1,1,1,1,1,1,1,1,1,1,1,1,1,1,1,1,1,1,1,1,1
1,1,1,1,1,1,1,1,1,1,1,1,1,1,1,1,1,1,1,1,1,1,1,1,1,1,1,1,1,1,1,1,1,1,1,1
1,1,1,1,1,1,1,1,1,1,1,1,1,1,1,24,1,1,1,1,1,1,1,1,1,1,1,1,1,1,1,1,1,1,1,1
1,1,1,1,1,1,1,1,1,1,1,1,1,1,1,1,1,2,1,1,2,3,2,1,1,1,1,1,3,3,2,1,1,1,1,1
1,1,1,1,1,1,1,1,24,24,1,1,1,1,1,3,3,3,3,3,3,3,3,3,3,2,3,3,3,3,3,3,1,1,1,1
1,1,1,1,1,1,1,1,1,19,18,16,22,41,41,41,17,41,18,21,18,18,41,20,41,41,41,22,41,20,19,3,2,1,1,1
1,1,1,1,1,1,1,1,1,22,0,0,0,0,0,0,0,0,0,0,0,0,0,0,0,0,0,0,0,0,18,3,1,1,1,1
1,1,1,1,1,1,1,1,1,41,0,0,0,0,0,0,0,0,0,0,0,0,0,0,0,0,0,0,0,0,16,3,2,1,1,1
1,1,1,1,1,1,1,1,2,22,0,0,0,0,0,0,0,0,19,18,20,19,0,0,0,0,0,0,0,0,22,3,1,1,1,1
1,1,1,1,1,1,1,1,3,41,0,0,0,0,0,0,0,0,19,27,27,18,0,0,0,0,0,0,0,0,41,3,1,1,1,1
1,1,1,1,1,1,1,3,3,41,0,0,0,0,0,0,0,0,22,27,27,20,0,0,0,0,0,0,0,0,41,3,1,1,1,1
1,1,1,1,1,1,1,3,3,41,0,0,0,0,0,0,0,0,0,18,17,0,0,0,0,0,0,0,0,0,16,3,1,1,1,1
1,1,1,1,1,1,1,2,3,20,0,0,0,0,0,0,0,0,0,32,32,0,0,0,0,0,0,0,0,0,19,3,2,1,1,1
1,1,1,1,1,1,1,3,3,16,0,0,0,0,0,0,0,0,0,0,0,0,0,0,0,0,0,0,0,0,41,3,3,1,1,1
1,1,1,1,1,1,1,2,3,20,0,0,19,19,22,0,0,0,21,18,18,18,0,0,0,17,22,22,0,0,18,3,3,1,1,1
1,1,1,1,1,1,1,3,3,19,0,0,19,27,27,20,32,0,18,0,0,18,0,32,18,27,27,20,0,0,21,3,3,1,1,1
1,1,1,1,1,1,1,3,3,18,0,0,19,27,27,17,32,0,18,0,0,18,0,32,17,27,27,17,0,0,17,3,3,1,1,1
1,1,1,1,1,1,1,2,3,17,0,0,20,20,21,0,0,0,17,18,18,20,0,0,0,18,17,17,0,0,17,3,3,1,1,1
1,1,1,1,1,1,1,3,3,16,0,0,0,0,0,0,0,0,0,0,0,0,0,0,0,0,0,0,0,0,41,3,3,1,1,1
1,1,1,1,1,1,1,3,3,21,0,0,0,0,0,0,0,0,0,32,32,0,0,0,0,0,0,0,0,0,20,3,3,1,1,1
1,1,1,1,1,1,1,1,3,16,0,0,0,0,0,0,0,0,0,21,22,0,0,0,0,0,0,0,0,0,16,3,2,1,1,1
1,1,1,1,1,1,1,2,3,16,0,0,0,0,0,0,0,0,19,27,27,17,0,0,0,0,0,0,0,0,16,3,2,1,1,1
1,1,1,1,1,1,1,3,3,41,0,0,0,0,0,0,0,0,22,27,27,19,0,0,0,0,0,0,0,0,41,3,1,1,1,1
1,1,1,1,1,1,1,3,3,21,0,0,0,0,0,0,0,0,21,22,21,22,0,0,0,0,0,0,0,0,22,3,1,1,1,1
1,1,1,1,1,1,1,2,3,41,0,0,0,0,0,0,0,0,0,0,0,0,0,0,0,0,0,0,0,0,41,3,3,1,1,1
1,1,1,1,1,1,1,1,3,18,0,0,0,0,0,0,0,0,0,0,0,0,0,0,0,0,0,0,0,0,17,3,1,1,1,1
1,1,1,1,1,1,1,1,3,19,18,41,21,16,41,41,21,41,17,17,17,20,41,19,41,16,16,22,16,22,18,3,1,1,1,1
1,1,1,1,1,1,1,1,3,3,3,3,3,3,3,3,3,3,3,3,3,3,3,3,3,3,3,3,3,3,3,3,1,1,1,1
1,1,1,1,1,1,1,1,1,2,3,2,2,1,2,3,2,2,2,3,2,1,2,3,2,1,1,2,3,1,1,1,1,1,1,1
1,1,1,1,1,1,1,1,1,1,1,1,1,1,1,1,1,1,1,1,1,1,1,1,1,1,1,1,1,1,1,1,1,1,1,1
1,1,1,1,1,1,1,1,1,1,1,1,1,1,1,1,1,1,1,1,1,1,1,1,1,1,1,1,1,1,1,1,1,1,1,1
1,1,1,1,1,1,1,1,1,1,1,1,1,1,1,1,1,1,1,1,1,1,1,1,1,1,1,1,1,1,1,1,1,1,1,1
1,1,1,1,1,1,1,1,1,1,1,1,1,1,1,1,1,1,1,1,1,1,1,1,1,1,1,1,1,1,1,1,1,1,1,1
1,1,1,1,1,1,1,1,1,1,1,1,1,1,1,1,1,1,1,1,1,1,1,1,1,1,1,1,1,1,1,1,1,1,1,1
1,1,1,1,1,1,1,1,1,1,1,1,1,1,1,1,1,1,1,1,1,1,1,1,1,1,1,1,1,1,1,1,1,1,1,1
endlayer

layer
1,1,1,1,1,1,1,1,1,1,1,1,1,1,1,1,1,1,1,1,1,1,1,1,1,1,1,1,1,1,1,1,1,1,1,1
1,1,1,1,1,1,1,1,1,1,1,1,1,1,1,1,1,1,1,1,1,1,1,1,1,1,1,1,1,1,1,1,1,1,1,1
1,1,1,1,1,1,1,1,1,1,1,1,1,1,1,1,1,1,1,1,1,1,1,1,1,1,1,1,1,1,1,1,1,1,1,1
1,1,1,1,1,1,1,1,1,1,1,1,1,1,1,24,1,1,1,1,1,1,1,1,1,1,1,1,1,1,1,1,1,1,1,1
1,1,1,1,1,1,1,1,24,24,1,1,1,1,1,1,1,1,1,1,1,3,1,1,1,1,1,1,3,3,1,1,1,1,1,1
1,1,1,1,1,1,1,1,24,24,1,1,1,1,1,2,3,3,3,3,3,3,3,3,3,1,2,3,3,3,3,3,1,1,1,1
1,1,1,1,1,1,1,1,1,22,21,16,21,19,21,16,22,16,17,22,18,21,41,21,16,22,19,17,16,21,17,3,1,1,1,1
1,1,1,1,1,1,1,1,1,22,0,0,0,0,0,0,0,0,0,0,0,0,0,0,0,0,0,0,0,0,21,2,1,1,1,1
1,1,1,1,1,1,1,1,1,41,0,0,0,0,0,0,0,0,0,0,0,0,0,0,0,0,0,0,0,0,16,3,1,1,1,1
1,1,1,1,1,1,1,1,1,22,0,0,0,0,0,0,0,0,18,18,18,18,0,0,0,0,0,0,0,0,20,3,1,1,1,1
1,1,1,1,1,1,1,1,3,22,0,0,0,0,0,0,0,0,17,0,0,18,0,0,0,0,0,0,0,0,20,3,1,1,1,1
1,1,1,1,1,1,1,2,3,21,0,0,0,0,0,0,0,0,22,0,0,21,0,0,0,0,0,0,0,0,19,3,1,1,1,1
1,1,1,1,1,1,1,3,3,41,0,0,0,0,0,0,0,0,0,21,22,0,0,0,0,0,0,0,0,0,16,3,1,1,1,1
1,1,1,1,1,1,1,1,3,22,0,0,0,0,0,0,0,0,0,32,32,0,0,0,0,0,0,0,0,0,20,3,1,1,1,1
1,1,1,1,1,1,1,2,3,41,0,0,0,0,0,0,0,0,0,0,0,0,0,0,0,0,0,0,0,0,41,3,3,1,1,1
1,1,1,1,1,1,1,1,3,19,0,0,18,21,18,0,0,0,20,0,0,19,0,0,0,18,22,20,0,0,19,3,2,1,1,1
1,1,1,1,1,1,1,3,3,22,0,0,17,0,0,19,32,0,0,0,0,0,0,32,20,0,0,20,0,0,20,3,2,1,1,1
1,1,1,1,1,1,1,3,3,18,0,0,20,0,0,21,32,0,0,0,0,0,0,32,19,0,0,21,0,0,18,3,2,1,1,1
1,1,1,1,1,1,1,1,3,17,0,0,20,21,21,0,0,0,22,0,0,17,0,0,0,21,19,17,0,0,19,3,2,1,1,1
1,1,1,1,1,1,1,2,3,41,0,0,0,0,0,0,0,0,0,0,0,0,0,0,0,0,0,0,0,0,41,3,3,1,1,1
1,1,1,1,1,1,1,2,3,19,0,0,0,0,0,0,0,0,0,32,32,0,0,0,0,0,0,0,0,0,20,3,2,1,1,1
1,1,1,1,1,1,1,1,3,16,0,0,0,0,0,0,0,0,0,20,17,0,0,0,0,0,0,0,0,0,41,3,1,1,1,1
1,1,1,1,1,1,1,1,3,17,0,0,0,0,0,0,0,0,20,0,0,20,0,0,0,0,0,0,0,0,18,3,1,1,1,1
1,1,1,1,1,1,1,3,3,17,0,0,0,0,0,0,0,0,20,0,0,22,0,0,0,0,0,0,0,0,18,3,1,1,1,1
1,1,1,1,1,1,1,3,3,19,0,0,0,0,0,0,0,0,18,20,19,20,0,0,0,0,0,0,0,0,20,3,1,1,1,1
1,1,1,1,1,1,1,1,3,16,0,0,0,0,0,0,0,0,0,0,0,0,0,0,0,0,0,0,0,0,16,3,3,1,1,1
1,1,1,1,1,1,1,1,3,18,0,0,0,0,0,0,0,0,0,0,0,0,0,0,0,0,0,0,0,0,22,3,1,1,1,1
1,1,1,1,1,1,1,1,2,20,21,41,20,20,22,41,20,16,20,17,20,20,16,19,16,21,21,18,16,19,18,2,1,1,1,1
1,1,1,1,1,1,1,1,2,3,3,3,3,3,3,3,3,3,3,3,3,3,3,3,3,3,3,3,3,3,3,2,1,1,1,1
1,1,1,1,1,1,1,1,1,1,2,1,1,1,1,3,1,1,1,3,1,1,1,2,1,1,1,1,3,1,1,1,1,1,1,1
1,1,1,1,1,1,1,1,1,1,1,1,1,1,1,1,1,1,1,1,1,1,1,1,1,1,1,1,1,1,1,1,1,1,1,1
1,1,1,1,1,1,1,1,1,1,1,1,1,1,1,1,1,1,1,1,1,1,1,1,1,1,1,1,1,1,1,1,1,1,1,1
1,1,1,1,1,1,1,1,1,1,1,1,1,1,1,1,1,1,1,1,1,1,1,1,1,1,1,1,1,1,1,1,1,1,1,1
1,1,1,1,1,1,1,1,1,1,1,1,1,1,1,1,1,1,1,1,1,1,1,1,1,1,1,1,1,1,1,1,1,1,1,1
1,1,1,1,1,1,1,1,1,1,1,1,1,1,1,1,1,1,1,1,1,1,1,1,1,1,1,1,1,1,1,1,1,1,1,1
1,1,1,1,1,1,1,1,1,1,1,1,1,1,1,1,1,1,1,1,1,1,1,1,1,1,1,1,1,1,1,1,1,1,1,1
endlayer

layer
0,0,0,0,0,0,0,0,0,0,0,0,0,0,0,0,0,0,0,0,0,0,0,0,0,0,0,0,0,0,0,0,0,0,0,0
0,0,0,0,0,0,0,0,0,0,0,0,0,0,0,0,0,0,0,0,0,0,0,0,0,0,0,0,0,0,0,0,0,0,0,0
0,0,0,0,0,0,0,0,0,0,0,0,0,0,0,9,0,0,0,0,0,0,0,0,0,0,0,0,0,0,0,0,0,0,0,0
0,0,0,0,0,0,0,0,9,9,0,0,0,0,8,24,0,0,0,0,0,9,0,0,0,0,0,0,9,9,0,0,0,0,0,0
0,0,0,0,0,0,0,8,24,24,6,0,0,0,0,0,0,0,0,9,9,3,11,9,9,0,0,8,3,3,6,9,0,0,0,0
0,0,0,0,0,0,0,8,24,24,11,9,9,9,9,8,2,3,2,3,3,3,2,2,3,6,52,2,3,3,2,24,6,0,0,0
0,0,0,0,0,0,0,0,53,17,21,41,16,16,16,16,21,16,18,17,21,20,16,17,41,41,41,41,41,22,21,2,6,0,0,0
0,0,0,0,0,0,0,0,8,21,0,0,0,0,0,0,0,0,0,0,0,0,0,0,0,0,0,0,0,0,21,52,0,0,0,0
0,0,0,0,0,0,0,0,8,16,0,0,0,0,0,0,0,0,0,0,0,0,0,0,0,0,0,0,0,0,41,2,0,0,0,0
0,0,0,0,0,0,0,0,8,16,0,0,0,0,0,0,0,0,17,17,22,18,0,0,0,0,0,0,0,0,41,3,6,0,0,0
0,0,0,0,0,0,0,0,2,16,0,0,0,0,0,0,0,0,0,18,17,0,0,0,0,0,0,0,0,0,16,2,6,0,0,0
0,0,0,0,0,0,0,52,3,16,0,0,0,0,0,0,0,0,0,18,22,0,0,0,0,0,0,0,0,0,41,2,0,0,0,0
0,0,0,0,0,0,0,2,3,16,0,0,0,0,0,0,0,0,0,20,21,0,0,0,0,0,0,0,0,0,16,2,0,0,0,0
0,0,0,0,0,0,0,8,3,21,0,0,0,0,0,0,0,0,0,32,32,0,0,0,0,0,0,0,0,0,17,3,6,0,0,0
0,0,0,0,0,0,0,52,3,41,0,0,0,0,0,0,0,0,0,0,0,0,0,0,0,0,0,0,0,0,41,3,2,0,0,0
0,0,0,0,0,0,0,8,3,20,0,0,20,0,0,0,0,0,20,0,0,17,0,0,0,0,0,18,0,0,22,3,52,0,0,0
0,0,0,0,0,0,0,2,3,20,0,0,22,21,19,22,32,0,0,0,0,0,0,32,19,20,19,18,0,0,22,3,52,0,0,0
0,0,0,0,0,0,0,2,3,18,0,0,18,20,20,19,32,0,0,0,0,0,0,32,19,22,21,19,0,0,19,3,52,0,0,0
0,0,0,0,0,0,0,8,3,22,0,0,18,0,0,0,0,0,18,0,0,19,0,0,0,0,0,19,0,0,18,3,52,0,0,0
0,0,0,0,0,0,0,52,3,41,0,0,0,0,0,0,0,0,0,0,0,0,0,0,0,0,0,0,0,0,41,3,24,6,0,0
0,0,0,0,0,0,0,52,2,21,0,0,0,0,0,0,0,0,0,32,32,0,0,0,0,0,0,0,0,0,21,3,52,0,0,0
0,0,0,0,0,0,0,0,2,16,0,0,0,0,0,0,0,0,0,22,21,0,0,0,0,0,0,0,0,0,41,3,6,0,0,0
0,0,0,0,0,0,0,9,2,16,0,0,0,0,0,0,0,0,0,17,20,0,0,0,0,0,0,0,0,0,41,2,0,0,0,0
0,0,0,0,0,0,8,3,3,16,0,0,0,0,0,0,0,0,0,22,22,0,0,0,0,0,0,0,0,0,16,2,0,0,0,0
0,0,0,0,0,0,8,3,3,41,0,0,0,0,0,0,0,0,19,20,17,22,0,0,0,0,0,0,0,0,16,2,9,0,0,0
0,0,0,0,0,0,0,7,3,16,0,0,0,0,0,0,0,0,0,0,0,0,0,0,0,0,0,0,0,0,16,2,24,6,0,0
0,0,0,0,0,0,0,0,2,20,0,0,0,0,0,0,0,0,0,0,0,0,0,0,0,0,0,0,0,0,18,2,54,0,0,0
0,0,0,0,0,0,0,0,52,20,18,16,16,41,16,41,18,16,22,18,20,17,16,21,16,16,16,41,41,22,17,52,0,0,0,0
0,0,0,0,0,0,0,0,52,3,3,3,2,3,3,3,3,2,3,3,3,3,3,2,3,3,2,3,3,2,2,52,0,0,0,0
0,0,0,0,0,0,0,0,0,7,52,7,0,7,7,24,7,0,7,24,7,7,7,52,7,7,0,7,24,0,7,0,0,0,0,0
0,0,0,0,0,0,0,0,0,0,0,0,0,0,0,7,0,0,0,7,0,0,0,0,0,0,0,0,7,0,0,0,0,0,0,0
0,0,0,0,0,0,0,0,0,0,0,0,0,0,0,0,0,0,0,0,0,0,0,0,0,0,0,0,0,0,0,0,0,0,0,0
0,0,0,0,0,0,0,0,0,0,0,0,0,0,0,0,0,0,0,0,0,0,0,0,0,0,0,0,0,0,0,0,0,0,0,0
0,0,0,0,0,0,0,0,0,0,0,0,0,0,0,0,0,0,0,0,0,0,0,0,0,0,0,0,0,0,0,0,0,0,0,0
0,0,0,0,0,0,0,0,0,0,0,0,0,0,0,0,0,0,0,0,0,0,0,0,0,0,0,0,0,0,0,0,0,0,0,0
0,0,0,0,0,0,0,0,0,0,0,0,0,0,0,0,0,0,0,0,0,0,0,0,0,0,0,0,0,0,0,0,0,0,0,0
endlayer

layer
0,0,0,0,0,0,0,0,0,0,0,0,0,0,0,0,0,0,0,0,0,0,0,0,0,0,0,0,0,0,0,0,0,0,0,0
0,0,0,0,0,0,0,0,0,0,0,0,0,0,0,0,0,0,0,0,0,0,0,0,0,0,0,0,0,0,0,0,0,0,0,0
0,0,0,0,0,0,0,0,0,0,0,0,0,0,0,9,0,0,0,0,0,0,0,0,0,0,0,0,0,0,0,0,0,0,0,0
0,0,0,0,0,0,0,0,9,9,0,0,0,0,8,24,0,0,0,0,0,9,0,0,0,0,0,0,9,9,0,0,0,0,0,0
0,0,0,0,0,0,0,8,24,24,6,0,0,0,0,0,0,0,0,9,9,24,6,0,9,0,0,8,3,3,6,9,0,0,0,0
0,0,0,0,0,0,0,8,24,24,11,9,9,9,9,0,8,24,52,2,2,2,52,52,3,6,0,52,3,3,52,24,6,0,0,0
0,0,0,0,0,0,0,0,53,20,19,17,17,20,21,18,17,18,20,22,18,18,18,18,19,18,19,17,17,17,17,52,0,0,0,0
0,0,0,0,0,0,0,0,8,19,0,0,0,0,0,0,0,0,0,0,0,0,0,0,0,0,0,0,0,0,21,6,0,0,0,0
0,0,0,0,0,0,0,0,8,19,0,0,0,0,0,0,0,0,0,0,0,0,0,0,0,0,0,0,0,0,17,52,0,0,0,0
0,0,0,0,0,0,0,0,8,18,0,0,0,0,0,0,0,0,17,21,21,17,0,0,0,0,0,0,0,0,22,3,6,0,0,0
0,0,0,0,0,0,0,0,52,22,0,0,0,0,0,0,0,0,0,0,0,0,0,0,0,0,0,0,0,0,18,52,0,0,0,0
0,0,0,0,0,0,0,0,2,17,0,0,0,0,0,0,0,0,0,0,0,0,0,0,0,0,0,0,0,0,19,6,0,0,0,0
0,0,0,0,0,0,0,52,3,22,0,0,0,0,0,0,0,0,0,0,0,0,0,0,0,0,0,0,0,0,22,52,0,0,0,0
0,0,0,0,0,0,0,8,3,17,0,0,0,0,0,0,0,0,0,32,32,0,0,0,0,0,0,0,0,0,20,2,6,0,0,0
0,0,0,0,0,0,0,0,2,22,0,0,0,0,0,0,0,0,0,0,0,0,0,0,0,0,0,0,0,0,20,3,52,0,0,0
0,0,0,0,0,0,0,8,2,19,0,0,22,0,0,0,0,0,21,0,0,19,0,0,0,0,0,22,0,0,20,2,6,0,0,0
0,0,0,0,0,0,0,52,2,17,0,0,22,0,0,0,32,0,0,0,0,0,0,32,0,0,0,17,0,0,22,2,0,0,0,0
0,0,0,0,0,0,0,52,2,21,0,0,22,0,0,0,32,0,0,0,0,0,0,32,0,0,0,17,0,0,19,2,6,0,0,0
0,0,0,0,0,0,0,8,2,19,0,0,18,0,0,0,0,0,20,0,0,20,0,0,0,0,0,22,0,0,22,2,0,0,0,0
0,0,0,0,0,0,0,0,2,22,0,0,0,0,0,0,0,0,0,0,0,0,0,0,0,0,0,0,0,0,19,2,24,6,0,0
0,0,0,0,0,0,0,0,52,21,0,0,0,0,0,0,0,0,0,32,32,0,0,0,0,0,0,0,0,0,17,2,55,0,0,0
0,0,0,0,0,0,0,0,52,22,0,0,0,0,0,0,0,0,0,0,0,0,0,0,0,0,0,0,0,0,20,3,6,0,0,0
0,0,0,0,0,0,0,9,52,21,0,0,0,0,0,0,0,0,0,0,0,0,0,0,0,0,0,0,0,0,20,52,0,0,0,0
0,0,0,0,0,0,8,3,3,21,0,0,0,0,0,0,0,0,0,0,0,0,0,0,0,0,0,0,0,0,21,52,0,0,0,0
0,0,0,0,0,0,8,3,3,22,0,0,0,0,0,0,0,0,18,18,20,18,0,0,0,0,0,0,0,0,21,52,9,0,0,0
0,0,0,0,0,0,0,7,2,20,0,0,0,0,0,0,0,0,0,0,0,0,0,0,0,0,0,0,0,0,18,52,24,6,0,0
0,0,0,0,0,0,0,0,52,18,0,0,0,0,0,0,0,0,0,0,0,0,0,0,0,0,0,0,0,0,20,52,7,0,0,0
0,0,0,0,0,0,0,0,8,22,19,20,18,21,18,21,22,19,22,19,17,18,21,17,20,21,21,18,21,20,18,6,0,0,0,0
0,0,0,0,0,0,0,0,0,24,2,2,52,2,2,2,2,52,2,2,2,2,2,52,2,3,56,2,2,56,56,0,0,0,0,0
0,0,0,0,0,0,0,0,0,7,7,7,0,7,7,24,7,0,7,24,7,7,7,0,7,7,56,56,24,56,56,0,0,0,0,0
0,0,0,0,0,0,0,0,0,0,0,0,0,0,0,7,0,0,0,7,0,0,0,0,0,0,56,56,56,56,56,0,0,0,0,0
0,0,0,0,0,0,0,0,0,0,0,0,0,0,0,0,0,0,0,0,0,0,0,0,0,0,0,56,56,56,56,0,0,0,0,0
0,0,0,0,0,0,0,0,0,0,0,0,0,0,0,0,0,0,0,0,0,0,0,0,0,0,0,0,0,0,0,0,0,0,0,0
0,0,0,0,0,0,0,0,0,0,0,0,0,0,0,0,0,0,0,0,0,0,0,0,0,0,0,0,0,0,0,0,0,0,0,0
0,0,0,0,0,0,0,0,0,0,0,0,0,0,0,0,0,0,0,0,0,0,0,0,0,0,0,0,0,0,0,0,0,0,0,0
0,0,0,0,0,0,0,0,0,0,0,0,0,0,0,0,0,0,0,0,0,0,0,0,0,0,0,0,0,0,0,0,0,0,0,0
endlayer

layer
0,0,0,0,0,0,0,0,0,0,0,0,0,0,0,0,0,0,0,0,0,0,0,0,0,0,0,0,0,0,0,0,0,0,0,0
0,0,0,0,0,0,0,0,0,0,0,0,0,56,56,56,56,56,0,0,0,0,0,0,0,0,0,0,0,0,0,0,0,0,0,0
0,0,0,0,0,0,0,0,0,0,0,0,0,56,56,56,56,56,0,0,0,0,0,0,0,0,0,0,0,0,0,0,0,0,0,0
0,0,0,0,0,0,0,0,9,9,0,0,0,56,56,24,56,56,0,0,0,9,0,0,0,0,0,0,9,9,0,0,0,0,0,0
0,0,0,0,0,0,0,8,24,24,6,0,0,56,56,56,56,56,0,0,0,24,6,0,9,0,0,8,24,24,6,9,0,0,0,0
0,0,0,0,0,0,0,8,24,24,6,0,0,56,56,56,56,24,11,52,52,52,0,0,24,6,0,8,24,24,6,24,6,0,0,0
0,0,0,0,0,0,0,0,7,7,0,9,0,9,0,0,0,0,16,57,57,41,0,9,0,0,9,0,7,7,0,7,0,0,0,0
0,0,0,0,0,0,0,0,0,0,18,21,17,22,22,20,20,19,18,22,19,18,18,19,21,20,20,18,20,20,0,0,0,0,0,0
0,0,0,0,0,0,0,0,0,8,21,17,19,18,19,19,20,21,17,22,18,21,20,20,17,17,17,20,17,21,6,0,0,0,0,0
0,0,0,0,0,0,0,0,0,0,22,19,22,17,18,19,22,17,21,18,17,17,18,22,22,17,19,22,22,17,0,24,6,0,0,0
0,0,0,0,0,0,0,0,0,0,22,21,21,21,0,0,0,0,0,58,58,0,0,0,0,0,17,22,18,22,0,0,0,0,0,0
0,0,0,0,0,0,0,0,52,9,20,21,20,0,0,0,0,0,0,58,58,0,0,0,0,0,0,21,19,17,6,0,0,0,0,0
0,0,0,0,0,0,0,8,3,3,18,22,21,0,0,0,0,0,0,58,58,0,0,0,0,0,0,18,20,17,0,0,0,0,0,0
0,0,0,0,0,0,0,8,3,3,17,17,20,0,0,0,0,0,0,32,32,0,0,0,0,0,0,20,20,21,6,9,0,0,0,0
0,0,0,0,0,0,0,0,52,7,19,19,20,0,0,0,0,0,0,0,0,0,0,0,0,0,0,19,20,20,0,24,6,0,0,0
0,0,0,0,0,0,0,0,52,41,19,18,20,0,0,0,0,0,21,0,0,21,0,0,0,0,0,22,18,22,41,52,0,0,0,0
0,0,0,0,0,0,0,0,52,60,22,21,17,59,59,59,32,0,0,0,0,0,0,32,60,60,60,19,18,20,59,52,0,0,0,0
0,0,0,0,0,0,0,0,52,60,21,20,20,59,59,59,32,0,0,0,0,0,0,32,60,60,60,22,19,21,59,52,0,0,0,0
0,0,0,0,0,0,0,0,52,41,18,21,22,0,0,0,0,0,19,0,0,18,0,0,0,0,0,20,17,22,41,52,55,0,0,0
0,0,0,0,0,0,0,0,52,0,20,19,18,0,0,0,0,0,0,0,0,0,0,0,0,0,0,22,21,21,0,55,24,55,0,0
0,0,0,0,0,0,0,0,0,0,20,17,20,0,0,0,0,0,0,32,32,0,0,0,0,0,0,18,17,17,55,55,55,0,0,0
0,0,0,0,0,0,0,0,0,8,18,17,17,0,0,0,0,0,0,57,57,0,0,0,0,0,0,20,18,22,55,24,6,0,0,0
0,0,0,0,0,0,0,9,9,0,20,17,22,0,0,0,0,0,0,57,57,0,0,0,0,0,0,19,17,20,55,55,0,0,0,0
0,0,0,0,0,0,8,24,24,6,19,17,21,19,0,0,0,0,0,57,57,0,0,0,0,0,17,19,20,17,0,0,0,0,0,0
0,0,0,0,0,0,8,24,24,6,19,18,17,19,18,17,22,17,21,21,17,17,17,17,19,22,18,17,22,17,0,0,9,0,0,0
0,0,0,0,0,0,0,7,52,0,21,19,22,21,18,19,21,17,19,20,21,22,17,22,21,20,20,22,20,22,0,8,24,6,0,0
0,0,0,0,0,0,0,0,0,8,19,20,21,17,17,21,22,22,20,17,18,19,21,22,20,22,18,21,18,21,0,0,7,0,0,0
0,0,0,0,0,0,0,0,0,55,55,0,0,0,0,0,0,0,16,58,58,16,0,7,55,55,0,56,56,56,56,0,0,0,0,0
0,0,0,0,0,0,0,0,55,24,52,52,0,52,52,52,52,0,52,52,52,52,52,0,52,24,56,56,56,56,56,0,0,0,0,0
0,0,0,0,0,0,0,0,0,55,0,0,0,0,0,24,0,0,0,24,0,0,0,0,0,7,56,56,24,56,56,0,0,0,0,0
0,0,0,0,0,0,0,0,0,0,0,0,0,0,0,7,0,0,0,7,0,0,0,0,0,0,56,56,56,56,56,0,0,0,0,0
0,0,0,0,0,0,0,0,0,0,0,0,0,0,0,10,0,0,0,0,0,0,0,0,0,0,0,56,56,56,0,0,0,0,0,0
0,0,0,0,0,0,0,0,0,0,0,0,0,0,0,0,0,0,0,0,0,0,0,0,0,0,0,0,0,0,0,0,0,0,0,0
0,0,0,0,0,0,0,0,0,0,0,0,0,0,0,0,0,0,0,0,0,0,0,0,0,0,0,0,0,0,0,0,0,0,0,0
0,0,0,0,0,0,0,0,0,0,0,0,0,0,0,0,0,0,0,0,0,0,0,0,0,0,0,0,0,0,0,0,0,0,0,0
0,0,0,0,0,0,0,0,0,0,0,0,0,0,0,0,0,0,0,0,0,0,0,0,0,0,0,0,0,0,0,0,0,0,0,0
endlayer

layer
0,0,0,0,0,0,0,0,0,0,0,0,0,0,0,0,0,0,0,0,0,0,0,0,0,0,0,0,0,0,0,0,0,0,0,0
0,0,0,0,0,0,0,0,0,0,0,0,0,0,56,56,56,56,0,0,0,0,0,0,0,0,0,0,0,0,0,0,0,0,0,0
0,0,0,0,0,0,0,0,0,0,0,0,0,56,56,56,56,56,0,0,0,0,0,0,0,0,0,0,0,0,0,0,0,0,0,0
0,0,0,0,0,0,0,0,9,9,0,0,0,56,56,24,56,56,0,0,0,9,0,0,0,0,0,0,9,9,0,0,0,0,0,0
0,0,0,0,0,0,0,8,24,24,6,0,0,56,56,56,56,56,0,0,0,24,6,0,9,0,0,8,24,24,6,55,0,0,0,0
0,0,0,0,0,0,0,8,24,24,6,0,0,56,56,56,56,24,6,0,0,0,0,0,24,6,0,8,24,24,6,24,55,0,0,0
0,0,0,0,0,0,0,0,7,7,0,0,0,0,0,0,0,0,9,0,0,0,0,0,0,0,0,0,7,7,0,7,0,0,0,0
0,0,0,0,0,0,0,0,0,0,0,0,9,9,0,9,0,8,41,57,57,16,0,9,0,9,0,0,0,0,56,56,56,0,0,0
0,0,0,0,0,0,0,0,0,0,0,20,19,19,18,19,17,22,18,61,61,19,19,22,22,21,22,21,18,56,56,56,56,56,0,0
0,0,0,0,0,0,0,0,0,0,0,22,18,21,19,22,19,22,41,33,33,16,18,17,18,22,20,20,20,56,56,24,56,56,0,0
0,0,0,0,0,0,0,0,0,0,0,17,21,19,0,0,0,0,42,35,35,42,0,0,0,0,20,21,18,56,56,56,56,56,0,0
0,0,0,0,0,0,0,0,9,9,0,19,22,0,0,0,0,0,42,37,37,42,0,0,0,0,0,17,22,56,56,56,56,56,0,0
0,0,0,0,0,0,0,8,24,24,6,18,21,0,0,0,0,0,42,62,62,42,0,0,0,0,0,19,17,0,0,0,0,0,0,0
0,0,0,0,0,0,0,8,24,24,6,21,21,0,0,0,0,0,0,63,63,0,0,0,0,0,0,21,19,0,0,9,0,0,0,0
0,0,0,0,0,0,0,0,7,7,0,21,18,0,0,0,0,0,0,0,0,0,0,0,0,0,0,19,20,0,0,24,6,0,0,0
0,0,0,0,0,0,0,0,0,0,41,17,41,42,42,42,0,0,21,0,0,17,0,0,42,42,42,16,21,41,6,0,0,0,0,0
0,0,0,0,0,0,0,0,0,0,60,61,33,35,37,62,63,0,0,0,0,0,0,63,62,37,35,33,61,59,0,0,0,0,0,0
0,0,0,0,0,0,0,0,0,0,60,61,33,35,37,62,63,0,0,0,0,0,0,63,62,37,35,33,61,59,0,0,0,0,0,0
0,0,0,0,0,0,0,0,0,0,16,18,16,42,42,42,0,0,19,0,0,17,0,0,42,42,42,41,18,41,6,0,9,0,0,0
0,0,0,0,0,0,0,0,0,0,7,18,17,0,0,0,0,0,0,0,0,0,0,0,0,0,0,17,18,6,0,0,24,64,0,0
0,0,0,0,0,0,0,0,0,0,8,22,19,0,0,0,0,0,0,63,63,0,0,0,0,0,0,18,22,6,0,0,7,0,0,0
0,0,0,0,0,0,0,0,0,0,0,21,17,0,0,0,0,0,42,62,62,42,0,0,0,0,0,19,21,0,55,24,6,0,0,0
0,0,0,0,0,0,0,9,9,0,0,18,19,0,0,0,0,0,42,37,37,42,0,0,0,0,0,18,18,0,0,55,0,0,0,0
0,0,0,0,0,0,8,24,24,6,0,19,21,18,0,0,0,0,42,35,35,42,0,0,0,0,20,19,17,0,0,0,0,0,0,0
0,0,0,0,0,0,8,24,24,6,0,17,19,18,18,20,18,20,41,33,33,41,20,21,19,21,17,20,20,0,0,0,55,0,0,0
0,0,0,0,0,0,0,7,7,0,0,21,19,20,20,22,20,17,19,61,61,19,19,21,22,21,19,18,18,0,0,8,24,6,0,0
0,0,0,0,0,0,0,0,0,55,0,0,0,0,0,0,0,0,41,58,58,16,0,0,0,55,0,0,0,0,0,0,7,0,0,0
0,0,0,0,0,0,0,0,0,55,55,0,0,0,56,56,56,56,56,56,56,56,0,0,55,55,55,0,0,0,0,0,0,0,0,0
0,0,0,0,0,0,0,0,55,24,55,0,0,56,56,56,56,56,56,56,56,56,0,0,8,24,6,56,56,0,0,0,0,0,0,0
0,0,0,0,0,0,0,0,0,7,0,0,0,56,56,24,56,56,56,24,56,56,0,0,0,7,0,56,24,56,0,0,0,0,0,0
0,0,0,0,0,0,0,0,0,0,0,0,0,56,56,56,56,56,56,56,56,56,0,0,0,0,0,56,56,56,0,0,0,0,0,0
0,0,0,0,0,0,0,0,0,0,0,0,0,56,56,56,56,56,56,56,56,0,0,0,0,0,0,0,0,0,0,0,0,0,0,0
0,0,0,0,0,0,0,0,0,0,0,0,0,0,0,0,0,0,0,0,0,0,0,0,0,0,0,0,0,0,0,0,0,0,0,0
0,0,0,0,0,0,0,0,0,0,0,0,0,0,0,0,0,0,0,0,0,0,0,0,0,0,0,0,0,0,0,0,0,0,0,0
0,0,0,0,0,0,0,0,0,0,0,0,0,0,0,0,0,0,0,0,0,0,0,0,0,0,0,0,0,0,0,0,0,0,0,0
0,0,0,0,0,0,0,0,0,0,0,0,0,0,0,0,0,0,0,0,0,0,0,0,0,0,0,0,0,0,0,0,0,0,0,0
endlayer

layer
0,0,0,0,0,0,0,0,0,0,0,0,0,0,0,0,0,0,0,0,0,0,0,0,0,0,0,0,0,0,0,0,0,0,0,0
0,0,0,0,0,0,0,0,0,0,0,0,0,0,0,0,0,0,0,0,0,0,0,0,0,0,0,0,0,0,0,0,0,0,0,0
0,0,0,0,0,0,0,0,0,0,0,0,0,0,0,56,56,0,0,0,0,0,0,0,0,0,0,0,0,0,0,0,0,0,0,0
0,0,0,0,0,0,0,0,9,9,0,0,0,0,56,24,56,0,0,0,0,9,0,0,0,0,0,0,9,65,0,0,0,0,0,0
0,0,0,0,0,0,0,8,24,24,6,0,0,0,56,56,56,0,0,0,0,24,6,0,9,0,0,8,24,24,6,9,0,0,0,0
0,0,0,0,0,0,0,8,24,24,6,0,0,0,0,0,0,24,0,0,0,0,0,0,24,55,0,8,24,24,6,24,64,0,0,0
0,0,0,0,0,0,0,0,7,7,0,0,0,0,0,0,0,0,0,0,0,0,0,0,0,0,0,0,7,7,0,7,0,0,0,0
0,0,0,0,0,0,0,0,0,0,0,0,0,0,0,0,0,0,0,0,0,0,0,0,0,0,0,0,0,56,56,56,56,0,0,0
0,0,0,0,0,0,0,0,0,0,0,0,0,0,9,0,0,0,41,57,57,41,0,0,9,0,0,0,0,56,56,56,56,56,0,0
0,0,0,0,0,0,0,0,0,0,0,0,21,17,18,22,22,22,22,19,19,21,17,19,17,21,18,22,0,56,56,24,56,56,0,0
0,0,0,0,0,0,0,0,0,0,0,0,18,22,0,0,0,0,0,46,46,0,0,0,0,0,19,18,0,56,56,56,56,56,0,0
0,0,0,0,0,0,0,0,9,9,0,8,19,0,0,0,0,0,0,46,46,0,0,0,0,0,0,18,0,0,56,56,56,0,0,0
0,0,0,0,0,0,0,8,24,24,6,0,20,0,0,0,0,0,47,46,46,47,0,0,0,0,0,17,0,0,0,0,0,0,0,0
0,0,0,0,0,0,0,8,24,24,6,8,17,0,0,0,0,0,0,0,0,0,0,0,0,0,0,21,0,0,0,9,0,0,0,0
0,0,0,0,0,0,0,0,7,7,0,0,17,0,0,0,0,0,0,0,0,0,0,0,0,0,0,18,0,0,0,24,6,0,0,0
0,0,0,0,0,0,0,0,0,0,0,16,18,0,0,47,0,0,22,0,0,18,0,0,47,0,0,19,41,0,0,55,0,0,0,0
0,0,0,0,0,0,0,0,0,0,0,60,20,44,44,44,0,0,0,0,0,0,0,0,45,45,45,19,59,0,0,0,0,0,0,0
0,0,0,0,0,0,0,0,0,0,0,60,19,44,44,44,0,0,0,0,0,0,0,0,45,45,45,17,59,0,0,0,0,0,0,0
0,0,0,0,0,0,0,0,0,0,8,41,19,0,0,47,0,0,20,0,0,20,0,0,47,0,0,21,41,0,0,0,9,0,0,0
0,0,0,0,0,0,0,0,0,0,0,0,21,0,0,0,0,0,0,0,0,0,0,0,0,0,0,22,0,0,0,66,24,6,0,0
0,0,0,0,0,0,0,0,0,0,0,0,19,0,0,0,0,0,0,0,0,0,0,0,0,0,0,21,0,0,0,55,7,0,0,0
0,0,0,0,0,0,0,0,0,0,0,0,19,0,0,0,0,0,47,43,43,47,0,0,0,0,0,19,0,0,66,24,64,0,0,0
0,0,0,0,0,0,0,9,9,0,0,8,20,0,0,0,0,0,0,43,43,0,0,0,0,0,0,20,0,0,0,0,0,0,0,0
0,0,0,0,0,0,8,24,24,6,0,0,18,18,0,0,0,0,0,43,43,0,0,0,0,0,19,19,6,0,0,0,0,0,0,0
0,0,0,0,0,0,8,24,24,6,0,0,20,22,22,18,19,22,18,21,22,17,18,19,21,17,17,22,0,0,0,0,9,0,0,0
0,0,0,0,0,0,0,7,7,0,0,0,0,7,0,0,0,0,16,58,58,41,0,0,0,0,0,0,0,0,0,55,24,6,0,0
0,0,0,0,0,0,0,0,0,0,0,0,0,0,0,0,0,0,0,0,0,0,0,0,0,0,0,0,0,0,0,0,67,0,0,0
0,0,0,0,0,0,0,0,0,55,0,0,0,56,56,56,56,56,56,56,56,0,0,0,0,55,0,0,0,0,0,0,0,0,0,0
0,0,0,0,0,0,0,0,55,24,0,0,0,56,56,56,56,56,56,56,56,56,0,0,8,24,6,0,56,0,0,0,0,0,0,0
0,0,0,0,0,0,0,0,0,7,0,0,0,56,56,24,56,56,56,24,56,56,0,0,0,7,0,56,56,56,0,0,0,0,0,0
0,0,0,0,0,0,0,0,0,0,0,0,0,56,56,56,56,56,56,56,56,56,0,0,0,0,0,0,56,0,0,0,0,0,0,0
0,0,0,0,0,0,0,0,0,0,0,0,0,0,56,56,56,56,56,56,56,0,0,0,0,0,0,0,0,0,0,0,0,0,0,0
0,0,0,0,0,0,0,0,0,0,0,0,0,0,0,0,0,0,0,0,0,0,0,0,0,0,0,0,0,0,0,0,0,0,0,0
0,0,0,0,0,0,0,0,0,0,0,0,0,0,0,0,0,0,0,0,0,0,0,0,0,0,0,0,0,0,0,0,0,0,0,0
0,0,0,0,0,0,0,0,0,0,0,0,0,0,0,0,0,0,0,0,0,0,0,0,0,0,0,0,0,0,0,0,0,0,0,0
0,0,0,0,0,0,0,0,0,0,0,0,0,0,0,0,0,0,0,0,0,0,0,0,0,0,0,0,0,0,0,0,0,0,0,0
endlayer

layer
0,0,0,0,0,0,0,0,0,0,0,0,0,0,0,0,0,0,0,0,0,0,0,0,0,0,0,0,0,0,0,0,0,0,0,0
0,0,0,0,0,0,0,0,0,0,0,0,0,0,0,0,0,0,0,0,0,0,0,0,0,0,0,0,0,0,0,0,0,0,0,0
0,0,0,0,0,0,0,0,0,0,0,0,0,0,0,56,0,0,0,0,0,0,0,0,0,0,0,0,0,0,0,0,0,0,0,0
0,0,0,0,0,0,0,0,9,9,0,0,0,0,56,56,56,56,56,56,0,0,56,56,56,56,0,0,9,9,0,0,0,0,0,0
0,0,0,0,0,0,0,8,24,24,6,0,0,0,0,56,56,56,56,56,0,24,56,56,56,56,0,8,24,24,6,9,0,0,0,0
0,0,0,0,0,0,0,8,24,24,6,0,0,0,0,56,56,24,56,56,0,0,56,56,24,56,0,8,24,24,6,24,0,0,0,0
0,0,0,0,0,0,0,0,7,7,0,0,0,0,0,56,56,56,56,56,0,0,56,56,56,56,0,0,7,7,0,67,0,0,0,0
0,0,0,0,0,0,0,0,0,0,0,0,0,0,0,0,56,56,56,0,0,0,56,56,56,56,0,0,0,0,0,0,0,0,0,0
0,0,0,0,0,0,0,0,0,0,0,0,0,0,0,0,0,0,0,0,0,0,0,0,0,0,0,0,0,0,0,56,0,0,0,0
0,0,0,0,0,0,0,0,0,0,0,0,0,0,0,9,9,0,41,57,57,16,0,0,0,9,0,0,0,0,56,24,56,0,0,0
0,0,0,0,0,0,0,0,0,0,0,0,8,22,20,21,21,22,17,16,16,21,21,22,18,21,19,0,0,0,56,56,56,0,0,0
0,0,0,0,0,0,0,0,9,9,0,0,0,20,19,0,0,0,0,0,0,0,0,0,0,17,20,0,0,0,0,0,0,0,0,0
0,0,0,0,0,0,0,8,24,24,6,0,0,21,0,0,0,0,0,0,0,0,0,0,0,0,21,0,0,0,0,0,0,0,0,0
0,0,0,0,0,0,0,8,24,24,6,0,8,18,0,0,0,0,0,0,0,0,0,0,0,0,22,6,0,0,0,65,0,0,0,0
0,0,0,0,0,0,0,0,7,7,0,0,9,18,0,0,0,0,0,0,0,0,0,0,0,0,22,0,0,0,66,24,6,0,0,0
0,0,0,0,0,0,0,0,0,0,0,8,16,21,0,0,0,0,22,18,18,17,0,0,0,0,18,16,0,0,0,0,0,0,0,0
0,0,0,0,0,0,0,0,0,0,0,0,60,41,0,0,0,0,18,49,50,18,0,0,0,0,41,59,0,0,0,0,0,0,0,0
0,0,0,0,0,0,0,0,0,0,0,0,60,16,0,0,0,0,18,51,48,18,0,0,0,0,16,59,0,0,0,0,0,0,0,0
0,0,0,0,0,0,0,0,0,0,0,0,41,17,0,0,0,0,21,18,18,17,0,0,0,0,17,41,0,0,0,0,9,0,0,0
0,0,0,0,0,0,0,0,0,0,0,0,0,21,0,0,0,0,0,0,0,0,0,0,0,0,17,7,0,0,0,0,24,6,0,0
0,0,0,0,0,0,0,0,0,0,0,0,0,19,0,0,0,0,0,0,0,0,0,0,0,0,21,0,0,0,0,0,7,0,0,0
0,0,0,0,0,0,0,0,0,0,0,0,0,18,0,0,0,0,0,0,0,0,0,0,0,0,21,6,0,0,0,24,6,0,0,0
0,0,0,0,0,0,0,9,9,0,0,0,0,19,19,0,0,0,0,0,0,0,0,0,0,22,21,0,0,0,0,0,0,0,0,0
0,0,0,0,0,0,8,24,24,6,0,0,8,21,20,18,18,22,21,16,41,21,19,20,19,22,21,6,0,0,0,0,0,0,0,0
0,0,0,0,0,0,8,24,24,6,0,0,0,0,0,7,0,0,16,58,58,41,0,7,0,0,0,0,0,0,0,0,9,0,0,0
0,0,0,0,0,0,0,7,7,0,0,0,0,0,0,0,0,0,0,0,0,7,0,0,0,0,0,0,0,0,0,66,24,6,0,0
0,0,0,0,0,0,0,56,56,56,56,56,0,0,0,0,0,0,0,0,0,0,0,0,0,0,0,0,0,0,0,0,7,0,0,0
0,0,0,0,0,0,0,56,56,56,56,56,0,0,0,0,0,0,0,0,0,0,0,0,0,0,0,0,0,0,0,0,0,0,0,0
0,0,0,0,0,0,0,56,56,24,56,56,0,0,56,56,56,0,56,56,0,0,0,0,8,24,64,0,0,0,0,0,0,0,0,0
0,0,0,0,0,0,0,56,56,56,56,56,0,0,56,24,56,0,56,24,56,0,0,0,0,7,0,0,0,0,0,0,0,0,0,0
0,0,0,0,0,0,0,56,56,56,56,0,0,0,0,56,56,0,0,56,0,0,0,0,0,0,0,0,0,0,0,0,0,0,0,0
0,0,0,0,0,0,0,0,0,0,0,0,0,0,0,0,0,0,0,0,0,0,0,0,0,0,0,0,0,0,0,0,0,0,0,0
0,0,0,0,0,0,0,0,0,0,0,0,0,0,0,0,0,0,0,0,0,0,0,0,0,0,0,0,0,0,0,0,0,0,0,0
0,0,0,0,0,0,0,0,0,0,0,0,0,0,0,0,0,0,0,0,0,0,0,0,0,0,0,0,0,0,0,0,0,0,0,0
0,0,0,0,0,0,0,0,0,0,0,0,0,0,0,0,0,0,0,0,0,0,0,0,0,0,0,0,0,0,0,0,0,0,0,0
0,0,0,0,0,0,0,0,0,0,0,0,0,0,0,0,0,0,0,0,0,0,0,0,0,0,0,0,0,0,0,0,0,0,0,0
endlayer

layer
0,0,0,0,0,0,0,0,0,0,0,0,0,0,0,0,0,0,0,0,0,0,0,0,0,0,0,0,0,0,0,0,0,0,0,0
0,0,0,0,0,0,0,0,0,0,0,0,0,0,0,0,0,0,0,0,0,0,0,0,0,0,0,0,0,0,0,0,0,0,0,0
0,0,0,0,0,0,0,0,0,0,0,0,0,0,0,0,0,0,0,0,0,0,0,0,0,0,0,0,0,0,0,0,0,0,0,0
0,0,0,0,0,0,0,0,9,9,0,0,0,0,0,0,56,56,56,0,0,65,56,56,56,56,56,0,9,9,0,0,0,0,0,0
0,0,0,0,0,0,0,8,24,24,6,0,0,0,0,56,56,56,56,56,0,24,56,56,56,56,56,8,24,24,6,9,0,0,0,0
0,0,0,0,0,0,0,8,24,24,6,0,0,0,0,56,56,24,56,56,0,0,56,56,24,56,56,8,24,24,6,24,0,0,0,0
0,0,0,0,0,0,0,0,7,7,0,0,0,0,0,56,56,56,56,56,0,0,56,56,56,56,56,0,7,7,0,0,0,0,0,0
0,0,0,0,0,0,0,0,0,0,0,0,0,0,0,56,56,56,56,0,0,0,0,56,56,56,0,0,0,0,0,0,0,0,0,0
0,0,0,0,0,0,0,0,0,0,0,0,0,0,0,0,0,0,0,0,0,0,0,0,0,0,0,0,0,0,0,56,0,0,0,0
0,0,0,0,0,0,0,0,0,0,0,0,0,0,0,0,0,0,0,0,0,0,0,0,0,0,0,0,0,0,56,56,56,0,0,0
0,0,0,0,0,0,0,0,0,0,0,0,0,0,9,0,9,0,41,57,57,41,0,9,0,0,0,0,0,0,0,56,0,0,0,0
0,0,0,0,0,0,0,0,9,9,0,0,0,0,21,19,22,20,17,19,17,22,21,17,18,21,6,0,0,0,0,0,0,0,0,0
0,0,0,0,0,0,0,8,24,24,6,0,0,8,18,20,0,0,0,0,0,0,0,0,21,21,0,0,0,0,0,0,0,0,0,0
0,0,0,0,0,0,0,8,24,24,6,0,0,0,18,0,0,0,0,0,0,0,0,0,0,17,0,0,0,0,0,0,0,0,0,0
0,0,0,0,0,0,0,0,7,7,0,0,0,8,18,0,0,0,0,0,0,0,0,0,0,17,0,0,0,0,0,24,6,10,0,0
0,0,0,0,0,0,0,0,0,0,0,0,0,41,21,0,0,0,17,18,18,20,0,0,0,21,16,6,0,0,0,0,0,0,0,0
0,0,0,0,0,0,0,0,0,0,0,0,0,60,20,0,0,0,18,61,61,18,0,0,0,20,59,0,0,0,0,0,0,0,0,0
0,0,0,0,0,0,0,0,0,0,0,0,0,60,18,0,0,0,18,61,61,18,0,0,0,17,59,0,0,0,0,0,0,0,0,0
0,0,0,0,0,0,0,0,0,0,0,0,8,16,21,0,0,0,22,18,18,20,0,0,0,17,41,0,0,0,0,0,9,0,0,0
0,0,0,0,0,0,0,0,0,0,0,0,0,0,20,0,0,0,0,0,0,0,0,0,0,19,0,0,0,0,0,0,24,6,0,0
0,0,0,0,0,0,0,0,0,0,0,0,0,8,17,0,0,0,0,0,0,0,0,0,0,22,6,0,0,0,0,0,7,10,0,0
0,0,0,0,0,0,0,0,0,0,0,0,0,0,17,20,0,0,0,0,0,0,0,0,19,17,0,0,0,0,0,24,0,0,0,0
0,0,0,0,0,0,0,9,9,0,0,0,0,0,22,18,17,22,21,22,18,17,20,22,18,22,0,0,0,0,0,0,0,0,0,0
0,0,0,0,0,0,8,24,24,6,0,0,0,0,0,0,0,7,16,58,58,41,0,0,0,0,0,0,0,0,0,0,0,0,0,0
0,0,0,0,0,0,8,24,24,6,0,0,0,0,0,0,0,0,7,0,0,0,0,0,0,0,0,0,0,0,0,0,55,0,0,0
0,0,0,0,0,0,0,7,7,0,0,0,0,0,0,0,0,0,0,0,0,0,0,0,0,0,0,0,0,0,0,8,24,64,0,0
0,0,0,0,0,0,0,0,56,56,56,56,0,0,0,0,0,0,0,0,0,0,0,0,0,0,0,0,0,0,0,0,7,0,0,0
0,0,0,0,0,0,0,56,56,56,56,56,0,0,0,0,0,0,0,0,0,0,0,0,0,0,0,0,0,0,0,0,10,0,0,0
0,0,0,0,0,0,0,56,56,24,56,56,0,0,0,56,0,0,0,56,0,0,0,0,0,24,0,0,0,0,0,0,0,0,0,0
0,0,0,0,0,0,0,56,56,56,56,56,0,0,56,56,56,0,56,56,56,0,0,0,0,0,0,0,0,0,0,0,0,0,0,0
0,0,0,0,0,0,0,56,56,56,56,56,0,0,0,56,0,0,0,56,0,0,0,0,0,0,0,0,0,0,0,0,0,0,0,0
0,0,0,0,0,0,0,0,0,0,0,0,0,0,0,0,0,0,0,0,0,0,0,0,0,0,0,0,0,0,0,0,0,0,0,0
0,0,0,0,0,0,0,0,0,0,0,0,0,0,0,0,0,0,0,0,0,0,0,0,0,0,0,0,0,0,0,0,0,0,0,0
0,0,0,0,0,0,0,0,0,0,0,0,0,0,0,0,0,0,0,0,0,0,0,0,0,0,0,0,0,0,0,0,0,0,0,0
0,0,0,0,0,0,0,0,0,0,0,0,0,0,0,0,0,0,0,0,0,0,0,0,0,0,0,0,0,0,0,0,0,0,0,0
0,0,0,0,0,0,0,0,0,0,0,0,0,0,0,0,0,0,0,0,0,0,0,0,0,0,0,0,0,0,0,0,0,0,0,0
endlayer

layer
0,0,0,0,0,0,0,0,0,0,0,0,0,0,0,0,0,0,0,0,0,0,0,0,0,0,0,0,0,0,0,0,0,0,0,0
0,0,0,0,0,0,0,0,0,0,0,0,0,0,0,0,0,0,0,0,0,0,0,0,0,0,0,0,0,0,0,0,0,0,0,0
0,0,0,0,0,0,0,0,0,0,0,0,0,0,0,0,0,0,0,0,0,0,0,0,0,0,0,0,0,0,0,0,0,0,0,0
0,0,0,0,0,0,0,0,9,9,0,0,0,0,0,0,0,0,0,0,0,0,0,0,0,0,0,0,9,9,0,0,0,0,0,0
0,0,0,0,0,0,0,8,24,24,6,0,0,0,0,0,56,56,0,0,0,24,0,0,56,0,0,8,24,24,6,65,0,0,0,0
0,0,0,0,0,0,0,8,24,24,6,0,0,0,0,0,56,24,56,0,0,0,0,56,24,56,0,8,24,24,6,24,0,0,0,0
0,0,0,0,0,0,0,0,7,7,0,0,0,0,0,0,56,56,0,0,0,0,0,56,56,56,0,0,7,7,0,0,0,0,0,0
0,0,0,0,0,0,0,0,0,0,0,0,0,0,0,0,0,0,0,0,0,0,0,0,0,0,0,0,0,0,0,0,0,0,0,0
0,0,0,0,0,0,0,0,0,0,0,0,0,0,0,0,0,0,0,0,0,0,0,0,0,0,0,0,0,0,0,0,0,0,0,0
0,0,0,0,0,0,0,0,0,0,0,0,0,0,0,0,0,0,0,0,0,0,0,0,0,0,0,0,0,0,0,0,0,0,0,0
0,0,0,0,0,0,0,0,0,0,0,0,0,0,0,0,0,0,9,0,0,0,0,0,0,0,0,0,0,0,0,0,0,0,0,0
0,0,0,0,0,0,0,0,9,9,0,0,0,0,0,0,9,0,16,57,57,41,0,0,9,0,0,0,0,0,0,0,0,0,0,0
0,0,0,0,0,0,0,8,24,24,6,0,0,0,0,22,22,19,21,22,18,21,19,22,20,0,0,0,0,0,56,56,56,0,0,0
0,0,0,0,0,0,0,8,24,24,6,0,0,0,8,17,21,0,0,0,0,0,0,19,20,6,0,0,0,56,56,56,56,56,0,0
0,0,0,0,0,0,0,0,7,7,0,0,0,0,8,20,0,0,0,0,0,0,0,0,18,0,0,0,0,56,56,24,56,56,0,0
0,0,0,0,0,0,0,0,0,0,0,0,0,8,41,20,0,0,19,0,0,21,0,0,17,16,6,0,0,56,56,56,56,56,0,0
0,0,0,0,0,0,0,0,0,0,0,0,0,0,60,18,0,0,0,0,0,0,0,0,17,59,0,0,0,0,56,56,56,56,0,0
0,0,0,0,0,0,0,0,0,0,0,0,0,0,60,17,0,0,0,0,0,0,0,0,22,59,0,0,0,0,0,56,56,56,0,0
0,0,0,0,0,0,0,0,0,0,0,0,0,0,41,21,0,0,17,0,0,21,0,0,17,16,0,0,0,0,56,56,56,56,56,0
0,0,0,0,0,0,0,0,0,0,0,0,0,0,7,18,0,0,0,0,0,0,0,0,18,7,0,0,0,0,56,56,24,56,56,0
0,0,0,0,0,0,0,0,0,0,0,0,0,0,0,17,22,0,0,0,0,0,0,22,19,0,0,0,0,0,56,56,56,56,56,0
0,0,0,0,0,0,0,0,0,0,0,0,0,0,0,21,22,18,22,22,17,18,18,17,20,6,0,0,0,0,0,24,56,56,0,0
0,0,0,0,0,0,0,9,9,0,0,0,0,0,0,7,0,0,41,58,58,41,6,7,0,0,0,0,0,0,0,0,0,0,0,0
0,0,0,0,0,0,8,24,24,6,0,0,0,0,0,0,0,0,7,0,0,0,0,0,0,0,0,0,0,0,0,56,56,56,0,0
0,0,0,0,0,0,8,24,24,6,0,0,0,0,0,0,0,0,0,0,0,0,0,0,0,0,0,0,0,0,56,56,56,56,56,0
0,0,0,0,0,0,0,7,7,0,0,0,0,0,0,0,0,0,0,0,0,0,0,0,0,0,0,0,0,0,56,56,24,56,56,0
0,0,0,0,0,0,0,0,0,0,0,0,0,0,0,0,0,0,0,0,0,0,0,56,56,56,56,0,0,0,56,56,56,56,56,0
0,0,0,0,0,0,0,0,56,56,56,0,0,0,0,0,0,0,0,0,0,0,0,56,56,56,56,56,0,0,0,56,56,56,56,0
0,0,0,0,0,0,0,0,56,24,56,0,0,0,0,0,0,0,0,0,0,0,0,56,56,24,56,56,0,0,0,0,0,0,0,0
0,0,0,0,0,0,0,0,56,56,56,0,0,0,0,0,0,0,0,0,0,0,0,56,56,56,56,56,0,0,0,0,0,0,0,0
0,0,0,0,0,0,0,0,0,0,0,0,0,0,0,0,0,0,0,0,0,0,0,56,56,56,56,0,0,0,0,0,0,0,0,0
0,0,0,0,0,0,0,0,0,0,0,0,0,0,0,0,0,0,0,0,0,0,0,0,0,0,0,0,0,0,0,0,0,0,0,0
0,0,0,0,0,0,0,0,0,0,0,0,0,0,0,0,0,0,0,0,0,0,0,0,0,0,0,0,0,0,0,0,0,0,0,0
0,0,0,0,0,0,0,0,0,0,0,0,0,0,0,0,0,0,0,0,0,0,0,0,0,0,0,0,0,0,0,0,0,0,0,0
0,0,0,0,0,0,0,0,0,0,0,0,0,0,0,0,0,0,0,0,0,0,0,0,0,0,0,0,0,0,0,0,0,0,0,0
0,0,0,0,0,0,0,0,0,0,0,0,0,0,0,0,0,0,0,0,0,0,0,0,0,0,0,0,0,0,0,0,0,0,0,0
endlayer

layer
0,0,0,0,0,0,0,0,0,0,0,0,0,0,0,0,0,0,0,0,0,0,0,0,0,0,0,0,0,0,0,0,0,0,0,0
0,0,0,0,0,0,0,0,0,0,0,0,0,0,0,0,0,0,0,0,0,0,0,0,0,0,0,0,0,0,0,0,0,0,0,0
0,0,0,0,0,0,0,0,0,0,0,0,0,0,0,0,0,0,0,0,0,0,0,0,0,0,0,0,0,0,0,0,0,0,0,0
0,0,0,0,0,0,0,0,9,9,0,0,0,0,0,0,0,0,0,0,0,0,0,0,0,0,0,0,9,9,56,56,56,56,0,0
0,0,0,0,0,0,0,8,24,24,6,0,0,0,0,0,0,56,0,0,0,24,0,0,56,0,0,66,24,24,6,56,56,56,0,0
0,0,0,0,0,0,0,8,24,24,6,0,0,0,0,0,56,56,56,0,0,0,0,56,56,56,0,8,24,24,56,24,56,56,0,0
0,0,0,0,0,0,0,0,7,7,0,0,0,0,0,0,0,56,0,0,0,0,0,0,56,0,0,0,7,7,56,56,56,56,0,0
0,0,0,0,0,0,0,0,0,0,0,0,0,0,0,0,0,0,0,0,0,0,0,0,0,0,0,0,0,56,56,56,56,56,0,0
0,0,0,0,0,0,0,0,0,0,0,0,0,0,0,0,0,0,0,0,0,0,0,0,0,0,0,0,0,0,0,0,0,0,0,0
0,0,0,0,0,0,0,0,0,0,0,0,0,0,0,0,0,0,0,0,0,0,0,0,0,0,0,0,0,0,0,0,0,0,0,0
0,0,0,0,0,0,0,0,0,0,0,0,0,0,0,0,0,0,0,0,0,0,0,0,0,0,0,0,0,0,0,0,0,0,0,0
0,0,0,0,0,0,0,0,9,9,0,0,0,0,0,0,0,0,0,0,0,9,0,0,0,0,0,0,0,0,0,0,0,0,0,0
0,0,0,0,0,0,0,8,24,24,6,0,0,0,0,0,0,8,41,57,57,16,6,0,0,0,0,0,0,56,56,56,56,0,0,0
0,0,0,0,0,0,0,8,24,24,6,0,0,0,0,8,19,20,18,19,20,17,21,19,0,0,0,0,0,56,56,56,56,56,0,0
0,0,0,0,0,0,0,0,7,7,0,0,0,0,0,0,22,17,0,0,0,0,22,22,0,0,0,0,0,56,56,24,56,56,0,0
0,0,0,0,0,0,0,0,0,0,0,0,0,0,0,41,18,0,20,18,18,20,0,21,16,0,0,0,0,56,56,56,56,56,0,0
0,0,0,0,0,0,0,0,0,0,0,0,0,0,0,60,19,0,18,50,48,18,0,19,59,0,0,0,0,56,56,56,56,0,0,0
0,0,0,0,0,0,0,0,0,0,0,0,0,0,0,60,17,0,18,49,51,18,0,19,59,0,0,0,0,0,0,56,56,56,56,0
0,0,0,0,0,0,0,0,0,0,0,0,0,0,0,41,22,0,20,18,18,20,0,18,41,6,0,0,0,0,56,56,56,56,56,0
0,0,0,0,0,0,0,0,0,0,0,0,0,0,0,0,19,22,0,0,0,0,17,22,0,0,0,0,0,0,56,56,24,56,56,0
0,0,0,0,0,0,0,0,0,0,0,0,0,0,0,8,21,19,22,20,20,20,20,17,6,0,0,0,0,56,56,56,56,56,56,0
0,0,0,0,0,0,0,0,0,0,0,0,0,0,0,0,0,0,41,58,58,41,0,0,0,0,0,0,0,56,56,24,56,56,56,0
0,0,0,0,0,0,0,9,9,0,0,0,0,0,0,0,0,0,0,0,0,0,0,0,0,0,0,0,0,56,56,56,56,56,0,0
0,0,0,0,0,0,8,24,24,6,0,0,0,0,0,0,0,0,0,0,0,0,0,0,0,0,0,0,0,0,56,56,56,56,56,0
0,0,0,0,0,0,8,24,24,6,0,0,0,0,0,0,0,0,0,0,0,0,0,0,0,0,0,0,0,0,56,56,56,56,56,0
0,0,0,0,0,0,0,7,7,0,0,0,0,0,0,0,0,0,0,0,0,0,0,0,0,0,0,0,0,0,56,56,24,56,56,0
0,0,0,0,0,0,0,0,0,0,0,0,0,0,0,0,0,0,0,0,0,0,0,0,56,56,56,56,0,0,56,56,56,56,56,0
0,0,0,0,0,0,0,0,0,56,0,0,0,0,0,0,0,0,0,0,0,0,0,56,56,56,56,56,0,0,0,56,56,56,56,0
0,0,0,0,0,0,0,0,56,56,56,0,0,0,0,0,0,0,0,0,0,0,0,56,56,24,56,56,0,0,0,0,0,0,0,0
0,0,0,0,0,0,0,0,0,56,0,0,0,0,0,0,0,0,0,0,0,0,0,56,56,56,56,56,0,0,0,0,0,0,0,0
0,0,0,0,0,0,0,0,0,0,0,0,0,0,0,0,0,0,0,0,0,0,0,0,56,56,56,0,0,0,0,0,0,0,0,0
0,0,0,0,0,0,0,0,0,0,0,0,0,0,0,0,0,0,0,0,0,0,0,0,0,0,0,0,0,0,0,0,0,0,0,0
0,0,0,0,0,0,0,0,0,0,0,0,0,0,0,0,0,0,0,0,0,0,0,0,0,0,0,0,0,0,0,0,0,0,0,0
0,0,0,0,0,0,0,0,0,0,0,0,0,0,0,0,0,0,0,0,0,0,0,0,0,0,0,0,0,0,0,0,0,0,0,0
0,0,0,0,0,0,0,0,0,0,0,0,0,0,0,0,0,0,0,0,0,0,0,0,0,0,0,0,0,0,0,0,0,0,0,0
0,0,0,0,0,0,0,0,0,0,0,0,0,0,0,0,0,0,0,0,0,0,0,0,0,0,0,0,0,0,0,0,0,0,0,0
endlayer

layer
0,0,0,0,0,0,0,0,0,0,0,0,0,0,0,0,0,0,0,0,0,0,0,0,0,0,0,0,0,0,0,0,0,0,0,0
0,0,0,0,0,0,0,0,0,0,0,0,0,0,0,0,0,0,0,0,0,0,0,0,0,0,0,0,0,0,0,0,0,0,0,0
0,0,0,0,0,0,0,0,0,0,0,0,0,0,0,0,0,0,0,0,56,56,56,56,0,0,0,0,0,0,0,0,0,0,0,0
0,0,0,0,0,0,0,0,9,9,0,0,0,0,0,0,0,0,0,56,56,56,56,56,0,0,0,0,9,9,56,56,56,0,0,0
0,0,0,0,0,0,0,8,24,24,6,0,0,0,0,0,0,0,0,56,56,24,56,56,0,0,0,8,24,24,6,56,56,56,0,0
0,0,0,0,0,0,0,8,24,24,64,0,0,0,0,0,0,0,0,56,56,56,56,56,0,0,0,8,24,24,6,24,56,56,0,0
0,0,0,0,0,0,0,0,7,7,0,0,0,0,0,0,0,0,0,0,56,56,56,0,0,0,0,0,7,7,56,56,56,56,0,0
0,0,0,0,0,0,0,0,0,0,0,0,0,0,0,0,0,0,0,0,0,0,0,0,0,0,0,0,0,0,56,56,56,56,0,0
0,0,0,0,0,0,0,0,0,0,0,0,0,0,0,0,0,0,0,0,0,0,0,0,0,0,0,0,0,0,0,0,0,0,0,0
0,0,0,0,0,0,0,0,0,0,0,0,0,0,0,0,0,0,0,0,0,0,0,0,0,0,0,0,0,0,0,0,0,0,0,0
0,0,0,0,0,0,0,0,0,0,0,0,0,0,0,0,0,0,0,0,0,0,0,0,0,0,0,0,0,0,0,0,0,0,0,0
0,0,0,0,0,0,0,0,9,9,0,0,0,0,0,0,0,0,0,0,0,0,0,0,0,0,0,0,0,0,0,0,0,0,0,0
0,0,0,0,0,0,0,8,24,24,6,0,0,0,0,0,0,0,9,0,0,9,0,0,0,0,0,0,0,0,0,0,0,0,0,0
0,0,0,0,0,0,0,8,24,24,6,0,0,0,0,0,0,0,16,57,57,41,0,0,0,0,0,0,0,0,56,56,0,0,0,0
0,0,0,0,0,0,0,0,7,7,0,0,0,0,0,0,0,22,21,20,20,19,20,6,0,0,0,0,0,0,56,24,56,0,0,0
0,0,0,0,0,0,0,0,0,0,0,0,0,0,0,0,16,17,19,18,22,18,20,41,0,0,0,0,0,0,0,56,0,0,0,0
0,0,0,0,0,0,0,0,0,0,0,0,0,0,0,0,60,21,22,61,61,18,17,59,0,0,0,0,0,0,0,0,0,0,0,0
0,0,0,0,0,0,0,0,0,0,0,0,0,0,0,0,60,22,22,61,61,20,18,59,0,0,0,0,0,0,0,0,0,0,0,0
0,0,0,0,0,0,0,0,0,0,0,0,0,0,0,0,16,21,22,19,19,21,18,16,0,0,0,0,0,0,0,0,56,56,0,0
0,0,0,0,0,0,0,0,0,0,0,0,0,0,0,0,8,21,18,20,17,22,18,0,0,0,0,0,0,0,56,56,24,56,0,0
0,0,0,0,0,0,0,0,0,0,0,0,0,0,0,0,0,7,16,58,58,41,0,0,0,0,0,0,0,56,56,56,56,56,0,0
0,0,0,0,0,0,0,0,0,0,0,0,0,0,0,0,0,0,0,0,0,7,0,0,0,0,0,0,0,56,56,24,56,56,0,0
0,0,0,0,0,0,0,9,9,0,0,0,0,0,0,0,0,0,0,0,0,0,0,0,0,0,0,0,0,56,56,56,56,56,0,0
0,0,0,0,0,0,66,24,24,6,0,0,0,0,0,0,0,0,0,0,0,0,0,0,0,0,0,0,0,56,56,56,56,0,0,0
0,0,0,0,0,0,8,24,24,6,0,0,0,0,0,0,0,0,0,0,0,0,0,0,0,0,0,0,0,0,0,56,56,0,0,0
0,0,0,0,0,0,0,7,7,0,0,0,0,0,0,0,0,0,0,0,0,0,0,0,0,0,0,0,0,0,0,56,24,56,0,0
0,0,0,0,0,0,0,0,0,0,0,0,0,0,0,0,0,0,0,0,0,0,0,0,0,0,0,0,0,0,0,0,56,0,0,0
0,0,0,0,0,0,0,0,0,0,0,0,0,0,0,0,0,0,0,0,0,0,0,0,56,56,0,0,0,0,0,0,0,0,0,0
0,0,0,0,0,0,0,0,0,0,0,0,0,0,0,0,0,0,0,0,0,0,0,0,56,24,56,0,0,0,0,0,0,0,0,0
0,0,0,0,0,0,0,0,0,0,0,0,0,0,0,0,0,0,0,0,0,0,0,0,0,56,0,0,0,0,0,0,0,0,0,0
0,0,0,0,0,0,0,0,0,0,0,0,0,0,0,0,0,0,0,0,0,0,0,0,0,0,0,0,0,0,0,0,0,0,0,0
0,0,0,0,0,0,0,0,0,0,0,0,0,0,0,0,0,0,0,0,0,0,0,0,0,0,0,0,0,0,0,0,0,0,0,0
0,0,0,0,0,0,0,0,0,0,0,0,0,0,0,0,0,0,0,0,0,0,0,0,0,0,0,0,0,0,0,0,0,0,0,0
0,0,0,0,0,0,0,0,0,0,0,0,0,0,0,0,0,0,0,0,0,0,0,0,0,0,0,0,0,0,0,0,0,0,0,0
0,0,0,0,0,0,0,0,0,0,0,0,0,0,0,0,0,0,0,0,0,0,0,0,0,0,0,0,0,0,0,0,0,0,0,0
0,0,0,0,0,0,0,0,0,0,0,0,0,0,0,0,0,0,0,0,0,0,0,0,0,0,0,0,0,0,0,0,0,0,0,0
endlayer

layer
0,0,0,0,0,0,0,0,0,0,0,0,0,0,0,0,0,0,0,0,0,0,0,0,0,0,0,0,0,0,0,0,0,0,0,0
0,0,0,0,0,0,0,0,0,0,0,0,0,0,0,0,0,0,0,0,0,0,0,0,0,0,0,0,0,0,0,0,0,0,0,0
0,0,0,0,0,0,0,0,0,0,0,0,0,0,0,0,0,0,0,56,56,56,56,0,0,0,0,0,0,0,0,0,0,0,0,0
0,0,0,0,0,0,0,0,9,9,0,0,0,0,0,0,0,0,0,56,56,56,56,56,0,0,0,0,9,9,0,0,0,0,0,0
0,0,0,0,0,0,0,8,24,24,6,0,0,0,0,0,0,0,0,56,56,24,56,56,0,0,0,8,24,24,56,56,0,0,0,0
0,0,0,0,0,0,0,8,24,24,6,0,0,0,0,0,0,0,0,56,56,56,56,56,0,0,0,8,24,24,6,24,56,0,0,0
0,0,0,0,0,0,0,0,0,7,0,0,0,0,0,0,0,0,0,0,56,56,56,0,0,0,0,0,7,7,56,56,56,0,0,0
0,0,0,0,0,0,0,0,0,0,0,0,0,0,0,0,0,0,0,0,0,0,0,0,0,0,0,0,0,0,0,0,0,0,0,0
0,0,0,0,0,0,0,0,0,0,0,0,0,0,0,0,0,0,0,0,0,0,0,0,0,0,0,0,0,0,0,0,0,0,0,0
0,0,0,0,0,0,0,0,0,0,0,0,0,0,0,0,0,0,0,0,0,0,0,0,0,0,0,0,0,0,0,0,0,0,0,0
0,0,0,0,0,0,0,0,0,0,0,0,0,0,0,0,0,0,0,0,0,0,0,0,0,0,0,0,0,0,0,0,0,0,0,0
0,0,0,0,0,0,0,0,9,9,0,0,0,0,0,0,0,0,0,0,0,0,0,0,0,0,0,0,0,0,0,0,0,0,0,0
0,0,0,0,0,0,0,8,24,24,6,0,0,0,0,0,0,0,0,0,0,0,0,0,0,0,0,0,0,0,0,0,0,0,0,0
0,0,0,0,0,0,0,8,24,24,6,0,0,0,0,0,0,0,0,0,0,0,0,0,0,0,0,0,0,0,0,56,0,0,0,0
0,0,0,0,0,0,0,0,7,7,0,0,0,0,0,0,0,0,9,0,0,9,0,0,0,0,0,0,0,0,56,56,56,0,0,0
0,0,0,0,0,0,0,0,0,0,0,0,0,0,0,0,0,8,19,0,26,21,6,0,0,0,0,0,0,0,0,56,0,0,0,0
0,0,0,0,0,0,0,0,0,0,0,0,0,0,0,0,0,26,0,0,0,0,26,0,0,0,0,0,0,0,0,0,0,0,0,0
0,0,0,0,0,0,0,0,0,0,0,0,0,0,0,0,0,0,26,0,0,0,0,0,0,0,0,0,0,0,0,0,0,0,0,0
0,0,0,0,0,0,0,0,0,0,0,0,0,0,0,0,0,8,22,0,0,22,6,0,0,0,0,0,0,0,0,0,56,0,0,0
0,0,0,0,0,0,0,0,0,0,0,0,0,0,0,0,0,0,7,26,0,7,0,0,0,0,0,0,0,0,0,56,56,56,0,0
0,0,0,0,0,0,0,0,0,0,0,0,0,0,0,0,0,0,0,0,0,0,0,0,0,0,0,0,0,0,0,56,56,0,0,0
0,0,0,0,0,0,0,0,0,0,0,0,0,0,0,0,0,0,0,0,0,0,0,0,0,0,0,0,0,0,56,24,56,0,0,0
0,0,0,0,0,0,0,9,9,0,0,0,0,0,0,0,0,0,0,0,0,0,0,0,0,0,0,0,0,0,0,56,56,0,0,0
0,0,0,0,0,0,8,24,24,6,0,0,0,0,0,0,0,0,0,0,0,0,0,0,0,0,0,0,0,0,0,0,0,0,0,0
0,0,0,0,0,0,8,24,24,6,0,0,0,0,0,0,0,0,0,0,0,0,0,0,0,0,0,0,0,0,0,0,56,0,0,0
0,0,0,0,0,0,0,7,7,0,0,0,0,0,0,0,0,0,0,0,0,0,0,0,0,0,0,0,0,0,0,56,56,56,0,0
0,0,0,0,0,0,0,0,0,0,0,0,0,0,0,0,0,0,0,0,0,0,0,0,0,0,0,0,0,0,0,0,56,0,0,0
0,0,0,0,0,0,0,0,0,0,0,0,0,0,0,0,0,0,0,0,0,0,0,0,0,56,0,0,0,0,0,0,0,0,0,0
0,0,0,0,0,0,0,0,0,0,0,0,0,0,0,0,0,0,0,0,0,0,0,0,56,56,56,0,0,0,0,0,0,0,0,0
0,0,0,0,0,0,0,0,0,0,0,0,0,0,0,0,0,0,0,0,0,0,0,0,0,56,0,0,0,0,0,0,0,0,0,0
0,0,0,0,0,0,0,0,0,0,0,0,0,0,0,0,0,0,0,0,0,0,0,0,0,0,0,0,0,0,0,0,0,0,0,0
0,0,0,0,0,0,0,0,0,0,0,0,0,0,0,0,0,0,0,0,0,0,0,0,0,0,0,0,0,0,0,0,0,0,0,0
0,0,0,0,0,0,0,0,0,0,0,0,0,0,0,0,0,0,0,0,0,0,0,0,0,0,0,0,0,0,0,0,0,0,0,0
0,0,0,0,0,0,0,0,0,0,0,0,0,0,0,0,0,0,0,0,0,0,0,0,0,0,0,0,0,0,0,0,0,0,0,0
0,0,0,0,0,0,0,0,0,0,0,0,0,0,0,0,0,0,0,0,0,0,0,0,0,0,0,0,0,0,0,0,0,0,0,0
0,0,0,0,0,0,0,0,0,0,0,0,0,0,0,0,0,0,0,0,0,0,0,0,0,0,0,0,0,0,0,0,0,0,0,0
endlayer

layer
0,0,0,0,0,0,0,0,0,0,0,0,0,0,0,0,0,0,0,0,0,0,0,0,0,0,0,0,0,0,0,0,0,0,0,0
0,0,0,0,0,0,0,0,0,0,0,0,0,0,0,0,0,0,0,0,0,0,0,0,0,0,0,0,0,0,0,0,0,0,0,0
0,0,0,0,0,0,0,0,0,0,0,0,0,0,0,0,0,0,0,0,0,0,0,0,0,0,0,0,0,0,0,0,0,0,0,0
0,0,0,0,0,0,0,0,65,9,0,0,0,0,0,0,0,0,0,0,56,56,0,0,0,0,0,0,9,9,0,0,0,0,0,0
0,0,0,0,0,0,0,0,24,24,6,0,0,0,0,0,0,0,0,0,56,24,56,0,0,0,0,8,24,24,6,56,0,0,0,0
0,0,0,0,0,0,0,8,24,24,6,0,0,0,0,0,0,0,0,0,56,56,0,0,0,0,0,8,24,24,6,56,56,0,0,0
0,0,0,0,0,0,0,0,67,7,0,0,0,0,0,0,0,0,0,0,0,0,0,0,0,0,0,0,7,67,0,56,0,0,0,0
0,0,0,0,0,0,0,0,0,0,0,0,0,0,0,0,0,0,0,0,0,0,0,0,0,0,0,0,0,0,0,0,0,0,0,0
0,0,0,0,0,0,0,0,0,0,0,0,0,0,0,0,0,0,0,0,0,0,0,0,0,0,0,0,0,0,0,0,0,0,0,0
0,0,0,0,0,0,0,0,0,0,0,0,0,0,0,0,0,0,0,0,0,0,0,0,0,0,0,0,0,0,0,0,0,0,0,0
0,0,0,0,0,0,0,0,0,0,0,0,0,0,0,0,0,0,0,0,0,0,0,0,0,0,0,0,0,0,0,0,0,0,0,0
0,0,0,0,0,0,0,0,9,9,0,0,0,0,0,0,0,0,0,0,0,0,0,0,0,0,0,0,0,0,0,0,0,0,0,0
0,0,0,0,0,0,0,8,24,24,6,0,0,0,0,0,0,0,0,0,0,0,0,0,0,0,0,0,0,0,0,0,0,0,0,0
0,0,0,0,0,0,0,8,24,24,6,0,0,0,0,0,0,0,0,0,0,0,0,0,0,0,0,0,0,0,0,0,0,0,0,0
0,0,0,0,0,0,0,0,7,7,0,0,0,0,0,0,0,0,9,0,0,9,0,0,0,0,0,0,0,0,0,0,0,0,0,0
0,0,0,0,0,0,0,0,0,0,0,0,0,0,0,0,0,8,16,0,0,16,6,0,0,0,0,0,0,0,0,0,0,0,0,0
0,0,0,0,0,0,0,0,0,0,0,0,0,0,0,0,0,0,0,0,0,0,0,0,0,0,0,0,0,0,0,0,0,0,0,0
0,0,0,0,0,0,0,0,0,0,0,0,0,0,0,0,0,0,0,0,0,0,0,0,0,0,0,0,0,0,0,0,0,0,0,0
0,0,0,0,0,0,0,0,0,0,0,0,0,0,0,0,0,8,16,0,0,41,6,0,0,0,0,0,0,0,0,0,0,0,0,0
0,0,0,0,0,0,0,0,0,0,0,0,0,0,0,0,0,0,7,0,0,7,0,0,0,0,0,0,0,0,0,0,0,0,0,0
0,0,0,0,0,0,0,0,0,0,0,0,0,0,0,0,0,0,0,0,0,0,0,0,0,0,0,0,0,0,0,56,0,0,0,0
0,0,0,0,0,0,0,0,0,0,0,0,0,0,0,0,0,0,0,0,0,0,0,0,0,0,0,0,0,0,56,56,56,0,0,0
0,0,0,0,0,0,0,9,9,0,0,0,0,0,0,0,0,0,0,0,0,0,0,0,0,0,0,0,0,0,0,56,0,0,0,0
0,0,0,0,0,0,8,24,24,6,0,0,0,0,0,0,0,0,0,0,0,0,0,0,0,0,0,0,0,0,0,0,0,0,0,0
0,0,0,0,0,0,8,24,24,6,0,0,0,0,0,0,0,0,0,0,0,0,0,0,0,0,0,0,0,0,0,0,0,0,0,0
0,0,0,0,0,0,0,7,67,0,0,0,0,0,0,0,0,0,0,0,0,0,0,0,0,0,0,0,0,0,0,0,0,0,0,0
0,0,0,0,0,0,0,0,0,0,0,0,0,0,0,0,0,0,0,0,0,0,0,0,0,0,0,0,0,0,0,0,0,0,0,0
0,0,0,0,0,0,0,0,0,0,0,0,0,0,0,0,0,0,0,0,0,0,0,0,0,0,0,0,0,0,0,0,0,0,0,0
0,0,0,0,0,0,0,0,0,0,0,0,0,0,0,0,0,0,0,0,0,0,0,0,0,0,0,0,0,0,0,0,0,0,0,0
0,0,0,0,0,0,0,0,0,0,0,0,0,0,0,0,0,0,0,0,0,0,0,0,0,0,0,0,0,0,0,0,0,0,0,0
0,0,0,0,0,0,0,0,0,0,0,0,0,0,0,0,0,0,0,0,0,0,0,0,0,0,0,0,0,0,0,0,0,0,0,0
0,0,0,0,0,0,0,0,0,0,0,0,0,0,0,0,0,0,0,0,0,0,0,0,0,0,0,0,0,0,0,0,0,0,0,0
0,0,0,0,0,0,0,0,0,0,0,0,0,0,0,0,0,0,0,0,0,0,0,0,0,0,0,0,0,0,0,0,0,0,0,0
0,0,0,0,0,0,0,0,0,0,0,0,0,0,0,0,0,0,0,0,0,0,0,0,0,0,0,0,0,0,0,0,0,0,0,0
0,0,0,0,0,0,0,0,0,0,0,0,0,0,0,0,0,0,0,0,0,0,0,0,0,0,0,0,0,0,0,0,0,0,0,0
0,0,0,0,0,0,0,0,0,0,0,0,0,0,0,0,0,0,0,0,0,0,0,0,0,0,0,0,0,0,0,0,0,0,0,0
endlayer

layer
0,0,0,0,0,0,0,0,0,0,0,0,0,0,0,0,0,0,0,0,0,0,0,0,0,0,0,0,0,0,0,0,0,0,0,0
0,0,0,0,0,0,0,0,0,0,0,0,0,0,0,0,0,0,0,0,0,0,0,0,0,0,0,0,0,0,0,0,0,0,0,0
0,0,0,0,0,0,0,0,0,0,0,0,0,0,0,0,0,0,0,0,0,0,0,0,0,0,0,0,0,0,0,0,0,0,0,0
0,0,0,0,0,0,0,0,0,24,0,0,0,0,0,0,0,0,0,0,0,56,0,0,0,0,0,0,9,9,0,0,0,0,0,0
0,0,0,0,0,0,0,0,24,24,6,0,0,0,0,0,0,0,0,0,56,56,56,0,0,0,0,8,24,24,6,0,0,0,0,0
0,0,0,0,0,0,0,8,24,24,6,0,0,0,0,0,0,0,0,0,0,56,0,0,0,0,0,8,24,24,6,0,0,0,0,0
0,0,0,0,0,0,0,0,7,7,0,0,0,0,0,0,0,0,0,0,0,0,0,0,0,0,0,0,7,7,0,0,0,0,0,0
0,0,0,0,0,0,0,0,0,0,0,0,0,0,0,0,0,0,0,0,0,0,0,0,0,0,0,0,0,0,0,0,0,0,0,0
0,0,0,0,0,0,0,0,0,0,0,0,0,0,0,0,0,0,0,0,0,0,0,0,0,0,0,0,0,0,0,0,0,0,0,0
0,0,0,0,0,0,0,0,0,0,0,0,0,0,0,0,0,0,0,0,0,0,0,0,0,0,0,0,0,0,0,0,0,0,0,0
0,0,0,0,0,0,0,0,0,0,0,0,0,0,0,0,0,0,0,0,0,0,0,0,0,0,0,0,0,0,0,0,0,0,0,0
0,0,0,0,0,0,0,0,9,9,0,0,0,0,0,0,0,0,0,0,0,0,0,0,0,0,0,0,0,0,0,0,0,0,0,0
0,0,0,0,0,0,0,8,24,24,6,0,0,0,0,0,0,0,0,0,0,0,0,0,0,0,0,0,0,0,0,0,0,0,0,0
0,0,0,0,0,0,0,8,24,24,6,0,0,0,0,0,0,0,0,0,0,0,0,0,0,0,0,0,0,0,0,0,0,0,0,0
0,0,0,0,0,0,0,0,7,0,0,0,0,0,0,0,0,0,0,0,0,0,0,0,0,0,0,0,0,0,0,0,0,0,0,0
0,0,0,0,0,0,0,0,0,0,0,0,0,0,0,0,0,0,57,57,57,59,0,0,0,0,0,0,0,0,0,0,0,0,0,0
0,0,0,0,0,0,0,0,0,0,0,0,0,0,0,0,0,0,60,68,68,59,0,0,0,0,0,0,0,0,0,0,0,0,0,0
0,0,0,0,0,0,0,0,0,0,0,0,0,0,0,0,0,0,60,68,68,59,0,0,0,0,0,0,0,0,0,0,0,0,0,0
0,0,0,0,0,0,0,0,0,0,0,0,0,0,0,0,0,0,60,58,58,58,0,0,0,0,0,0,0,0,0,0,0,0,0,0
0,0,0,0,0,0,0,0,0,0,0,0,0,0,0,0,0,0,0,0,0,0,0,0,0,0,0,0,0,0,0,0,0,0,0,0
0,0,0,0,0,0,0,0,0,0,0,0,0,0,0,0,0,0,0,0,0,0,0,0,0,0,0,0,0,0,0,0,0,0,0,0
0,0,0,0,0,0,0,0,0,0,0,0,0,0,0,0,0,0,0,0,0,0,0,0,0,0,0,0,0,0,0,0,0,0,0,0
0,0,0,0,0,0,0,9,9,0,0,0,0,0,0,0,0,0,0,0,0,0,0,0,0,0,0,0,0,0,0,0,0,0,0,0
0,0,0,0,0,0,8,24,24,6,0,0,0,0,0,0,0,0,0,0,0,0,0,0,0,0,0,0,0,0,0,0,0,0,0,0
0,0,0,0,0,0,8,24,24,6,0,0,0,0,0,0,0,0,0,0,0,0,0,0,0,0,0,0,0,0,0,0,0,0,0,0
0,0,0,0,0,0,0,7,7,0,0,0,0,0,0,0,0,0,0,0,0,0,0,0,0,0,0,0,0,0,0,0,0,0,0,0
0,0,0,0,0,0,0,0,0,0,0,0,0,0,0,0,0,0,0,0,0,0,0,0,0,0,0,0,0,0,0,0,0,0,0,0
0,0,0,0,0,0,0,0,0,0,0,0,0,0,0,0,0,0,0,0,0,0,0,0,0,0,0,0,0,0,0,0,0,0,0,0
0,0,0,0,0,0,0,0,0,0,0,0,0,0,0,0,0,0,0,0,0,0,0,0,0,0,0,0,0,0,0,0,0,0,0,0
0,0,0,0,0,0,0,0,0,0,0,0,0,0,0,0,0,0,0,0,0,0,0,0,0,0,0,0,0,0,0,0,0,0,0,0
0,0,0,0,0,0,0,0,0,0,0,0,0,0,0,0,0,0,0,0,0,0,0,0,0,0,0,0,0,0,0,0,0,0,0,0
0,0,0,0,0,0,0,0,0,0,0,0,0,0,0,0,0,0,0,0,0,0,0,0,0,0,0,0,0,0,0,0,0,0,0,0
0,0,0,0,0,0,0,0,0,0,0,0,0,0,0,0,0,0,0,0,0,0,0,0,0,0,0,0,0,0,0,0,0,0,0,0
0,0,0,0,0,0,0,0,0,0,0,0,0,0,0,0,0,0,0,0,0,0,0,0,0,0,0,0,0,0,0,0,0,0,0,0
0,0,0,0,0,0,0,0,0,0,0,0,0,0,0,0,0,0,0,0,0,0,0,0,0,0,0,0,0,0,0,0,0,0,0,0
0,0,0,0,0,0,0,0,0,0,0,0,0,0,0,0,0,0,0,0,0,0,0,0,0,0,0,0,0,0,0,0,0,0,0,0
endlayer

layer
0,0,0,0,0,0,0,0,0,56,0,0,0,0,0,0,0,0,0,0,0,0,0,0,0,0,0,0,0,0,0,0,0,0,0,0
0,0,0,0,0,0,0,0,56,56,56,0,0,0,0,0,0,0,0,0,0,0,0,0,0,0,0,0,0,0,0,0,0,0,0,0
0,0,0,0,0,0,0,56,56,24,56,56,0,0,0,0,0,0,0,0,0,0,0,0,0,0,0,0,0,0,0,0,0,0,0,0
0,0,0,0,0,0,0,0,56,56,56,0,0,0,0,0,0,0,0,0,0,0,0,0,0,0,0,0,9,9,0,0,0,0,0,0
0,0,0,0,0,0,0,0,24,24,6,0,0,0,0,0,0,0,0,0,0,0,0,0,0,0,0,8,24,24,6,0,0,0,0,0
0,0,0,0,0,0,0,8,24,24,0,0,0,0,0,0,0,0,0,0,0,0,0,0,0,0,0,8,24,24,6,0,0,0,0,0
0,0,0,0,0,0,0,0,7,7,0,0,0,0,0,0,0,0,0,0,0,0,0,0,0,0,0,24,7,7,0,0,0,0,0,0
0,0,0,0,0,0,0,0,0,0,0,0,0,0,0,0,0,0,0,0,0,0,0,0,0,0,0,0,0,0,0,0,0,0,0,0
0,0,0,0,0,0,0,0,0,0,0,0,0,0,0,0,0,0,0,0,0,0,0,0,0,0,0,0,0,0,0,0,0,0,0,0
0,0,0,0,0,0,0,0,0,0,0,0,0,0,0,0,0,0,0,0,0,0,0,0,0,0,0,0,0,0,0,0,0,0,0,0
0,0,0,0,0,0,0,0,0,0,0,0,0,0,0,0,0,0,0,0,0,0,0,0,0,0,0,0,0,0,0,0,0,0,0,0
0,0,0,0,0,0,0,0,9,9,0,0,0,0,0,0,0,0,0,0,0,0,0,0,0,0,0,0,0,0,0,0,0,0,0,0
0,0,0,0,0,0,0,8,24,24,6,0,0,0,0,0,0,0,0,0,0,0,0,0,0,0,0,0,0,0,0,0,0,0,0,0
0,0,0,0,0,0,0,8,24,24,6,0,0,0,0,0,0,0,0,0,0,0,0,0,0,0,0,0,0,0,0,0,0,0,0,0
0,0,0,0,0,0,0,0,7,67,0,0,0,0,0,0,0,0,0,0,0,0,0,0,0,0,0,0,0,0,0,0,0,0,0,0
0,0,0,0,0,0,0,0,0,0,0,0,0,0,0,0,0,0,45,43,43,43,0,0,0,0,0,0,0,0,0,0,0,0,0,0
0,0,0,0,0,0,0,0,0,0,0,0,0,0,0,0,0,0,45,41,16,44,0,0,0,0,0,0,0,0,0,0,0,0,0,0
0,0,0,0,0,0,0,0,0,0,0,0,0,0,0,0,0,0,45,16,41,44,0,0,0,0,0,0,0,0,0,0,0,0,0,0
0,0,0,0,0,0,0,0,0,0,0,0,0,0,0,0,0,0,46,46,46,46,0,0,0,0,0,0,0,0,0,0,0,0,0,0
0,0,0,0,0,0,0,0,0,0,0,0,0,0,0,0,0,0,0,0,0,0,0,0,0,0,0,0,0,0,0,0,0,0,0,0
0,0,0,0,0,0,0,0,0,0,0,0,0,0,0,0,0,0,0,0,0,0,0,0,0,0,0,0,0,0,0,0,0,0,0,0
0,0,0,0,0,0,0,0,0,0,0,0,0,0,0,0,0,0,0,0,0,0,0,0,0,0,0,0,0,0,0,0,0,0,0,0
0,0,0,0,0,0,0,9,9,0,0,0,0,0,0,0,0,0,0,0,0,0,0,0,0,0,0,0,0,0,0,0,0,0,0,0
0,0,0,0,0,0,8,24,24,6,0,0,0,0,0,0,0,0,0,0,0,0,0,0,0,0,0,0,0,0,0,0,0,0,0,0
0,0,0,0,0,0,8,24,24,6,0,0,0,0,0,0,0,0,0,0,0,0,0,0,0,0,0,0,0,0,0,0,0,0,0,0
0,0,0,0,0,0,0,7,7,0,0,0,0,0,0,0,0,0,0,0,0,0,0,0,0,0,0,0,0,0,0,0,0,0,0,0
0,0,0,0,0,0,0,0,0,0,0,0,0,0,0,0,0,0,0,0,0,0,0,0,0,0,0,0,0,0,0,0,0,0,0,0
0,0,0,0,0,0,0,0,0,0,0,0,0,0,0,0,0,0,0,0,0,0,0,0,0,0,0,0,0,0,0,0,0,0,0,0
0,0,0,0,0,0,0,0,0,0,0,0,0,0,0,0,0,0,0,0,0,0,0,0,0,0,0,0,0,0,0,0,0,0,0,0
0,0,0,0,0,0,0,0,0,0,0,0,0,0,0,0,0,0,0,0,0,0,0,0,0,0,0,0,0,0,0,0,0,0,0,0
0,0,0,0,0,0,0,0,0,0,0,0,0,0,0,0,0,0,0,0,0,0,0,0,0,0,0,0,0,0,0,0,0,0,0,0
0,0,0,0,0,0,0,0,0,0,0,0,0,0,0,0,0,0,0,0,0,0,0,0,0,0,0,0,0,0,0,0,0,0,0,0
0,0,0,0,0,0,0,0,0,0,0,0,0,0,0,0,0,0,0,0,0,0,0,0,0,0,0,0,0,0,0,0,0,0,0,0
0,0,0,0,0,0,0,0,0,0,0,0,0,0,0,0,0,0,0,0,0,0,0,0,0,0,0,0,0,0,0,0,0,0,0,0
0,0,0,0,0,0,0,0,0,0,0,0,0,0,0,0,0,0,0,0,0,0,0,0,0,0,0,0,0,0,0,0,0,0,0,0
0,0,0,0,0,0,0,0,0,0,0,0,0,0,0,0,0,0,0,0,0,0,0,0,0,0,0,0,0,0,0,0,0,0,0,0
endlayer

layer
0,0,0,0,0,56,56,56,56,56,56,56,56,0,0,0,0,0,0,0,0,0,0,0,0,0,0,0,0,0,0,0,0,0,0,0
0,0,0,0,56,56,56,56,56,56,56,56,56,56,0,0,0,0,0,0,0,0,0,0,0,0,0,0,0,0,0,0,0,0,0,0
0,0,0,0,56,56,56,56,56,56,56,56,56,56,0,0,0,0,0,0,0,0,0,0,0,0,0,0,0,0,0,0,0,0,0,0
0,0,0,0,56,56,56,56,56,56,56,56,56,56,0,0,0,0,0,0,0,0,0,0,0,0,0,0,9,9,0,0,0,0,0,0
0,0,0,56,56,56,56,56,24,24,56,56,56,56,56,0,0,0,0,0,0,0,0,0,0,0,0,8,24,24,6,0,0,0,0,0
0,0,0,56,56,56,56,56,24,24,56,56,56,56,56,0,0,0,0,0,0,0,0,0,0,0,0,8,24,24,6,0,0,0,0,0
0,0,0,0,56,56,56,56,56,56,56,56,56,56,0,0,0,0,0,0,0,0,0,0,0,0,24,0,7,7,0,0,0,0,0,0
0,0,0,0,56,56,56,56,56,56,56,56,56,56,0,0,0,0,0,0,0,0,0,0,0,24,0,0,0,0,0,0,0,0,0,0
0,0,0,0,56,56,56,56,56,56,56,56,56,56,0,0,0,0,0,0,0,0,0,0,0,0,0,0,0,0,0,0,0,0,0,0
0,0,0,0,0,56,56,56,56,56,56,56,56,0,0,0,0,0,0,0,0,0,0,0,0,0,0,0,0,0,0,0,0,0,0,0
0,0,0,0,0,0,0,0,56,56,0,0,0,0,0,0,0,0,0,0,0,0,0,0,0,0,0,0,0,0,0,0,0,0,0,0
0,0,0,0,0,0,0,0,9,9,0,0,0,0,0,0,0,0,0,0,0,0,0,0,0,0,0,0,0,0,0,0,0,0,0,0
0,0,0,0,0,0,0,8,24,24,6,0,0,0,0,0,0,0,0,0,0,0,0,0,0,0,0,0,0,0,0,0,0,0,0,0
0,0,0,0,0,0,0,8,24,24,6,0,0,0,0,0,0,0,0,0,0,0,0,0,0,0,0,0,0,0,0,0,0,0,0,0
0,0,0,0,0,0,0,0,7,7,0,0,0,0,0,0,0,0,0,0,0,0,0,0,0,0,0,0,0,0,0,0,0,0,0,0
0,0,0,0,0,0,0,0,0,0,0,0,0,0,0,0,0,0,0,0,0,0,0,0,0,0,0,0,0,0,0,0,0,0,0,0
0,0,0,0,0,0,0,0,0,0,0,0,0,0,0,0,0,0,0,0,0,0,0,0,0,0,0,0,0,0,0,0,0,0,0,0
0,0,0,0,0,0,0,0,0,0,0,0,0,0,0,0,0,0,0,0,0,0,0,0,0,0,0,0,0,0,0,0,0,0,0,0
0,0,0,0,0,0,0,0,0,0,0,0,0,0,0,0,0,0,0,0,0,0,0,0,0,0,0,0,0,0,0,0,0,0,0,0
0,0,0,0,0,0,0,0,0,0,0,0,0,0,0,0,0,0,0,0,0,0,0,0,0,0,0,0,0,0,0,0,0,0,0,0
0,0,0,0,0,0,0,0,0,0,0,0,0,0,0,0,0,0,0,0,0,0,0,0,0,0,0,0,0,0,0,0,0,0,0,0
0,0,0,0,0,0,0,0,0,0,0,0,0,0,0,0,0,0,0,0,0,0,0,0,0,0,0,0,0,0,0,0,0,0,0,0
0,0,0,0,0,0,0,9,9,0,0,0,0,0,0,0,0,0,0,0,0,0,0,0,0,0,0,0,0,0,0,0,0,0,0,0
0,0,0,0,0,0,8,24,24,6,0,0,0,0,0,0,0,0,0,0,0,0,0,0,0,0,0,0,0,0,0,0,0,0,0,0
0,0,0,0,0,0,8,24,24,6,0,0,0,0,0,0,0,0,0,0,0,0,0,0,0,0,0,0,0,0,0,0,0,0,0,0
0,0,0,0,0,0,0,7,7,0,0,0,0,0,0,0,0,0,0,0,0,0,0,0,0,0,0,0,0,0,0,0,0,0,0,0
0,0,0,0,0,0,0,0,0,0,0,0,0,0,0,0,0,0,0,0,0,0,0,0,0,0,0,0,0,0,0,0,0,0,0,0
0,0,0,0,0,0,0,0,0,0,0,0,0,0,0,0,0,0,0,0,0,0,0,0,0,0,0,0,0,0,0,0,0,0,0,0
0,0,0,0,0,0,0,0,0,0,0,0,0,0,0,0,0,0,0,0,0,0,0,0,0,0,0,0,0,0,0,0,0,0,0,0
0,0,0,0,0,0,0,0,0,0,0,0,0,0,0,0,0,0,0,0,0,0,0,0,0,0,0,0,0,0,0,0,0,0,0,0
0,0,0,0,0,0,0,0,0,0,0,0,0,0,0,0,0,0,0,0,0,0,0,0,0,0,0,0,0,0,0,0,0,0,0,0
0,0,0,0,0,0,0,0,0,0,0,0,0,0,0,0,0,0,0,0,0,0,0,0,0,0,0,0,0,0,0,0,0,0,0,0
0,0,0,0,0,0,0,0,0,0,0,0,0,0,0,0,0,0,0,0,0,0,0,0,0,0,0,0,0,0,0,0,0,0,0,0
0,0,0,0,0,0,0,0,0,0,0,0,0,0,0,0,0,0,0,0,0,0,0,0,0,0,0,0,0,0,0,0,0,0,0,0
0,0,0,0,0,0,0,0,0,0,0,0,0,0,0,0,0,0,0,0,0,0,0,0,0,0,0,0,0,0,0,0,0,0,0,0
0,0,0,0,0,0,0,0,0,0,0,0,0,0,0,0,0,0,0,0,0,0,0,0,0,0,0,0,0,0,0,0,0,0,0,0
endlayer

layer
0,0,0,0,0,0,0,0,56,56,0,0,0,0,0,0,0,0,0,0,0,0,0,0,0,0,0,0,0,0,0,0,0,0,0,0
0,0,0,0,0,0,56,56,56,56,56,56,0,0,0,0,0,0,0,0,0,0,0,0,0,0,0,0,0,0,0,0,0,0,0,0
0,0,0,0,0,56,56,56,56,56,56,56,56,0,0,0,0,0,0,0,0,0,0,0,0,0,0,0,0,0,0,0,0,0,0,0
0,0,0,0,0,56,56,56,56,56,56,56,56,0,0,0,0,0,0,0,0,0,0,0,0,0,0,0,9,9,0,0,0,0,0,0
0,0,0,0,56,56,56,56,56,24,56,56,56,56,0,0,0,0,0,0,0,0,0,0,0,0,0,8,24,24,6,0,0,0,0,0
0,0,0,0,56,56,56,56,56,56,56,56,56,56,0,0,0,0,0,0,0,0,0,0,0,56,0,8,24,24,6,0,0,0,0,0
0,0,0,0,0,56,56,56,56,56,56,56,56,0,0,0,0,0,0,0,0,0,0,0,56,56,56,0,7,7,0,0,0,0,0,0
0,0,0,0,0,56,56,56,56,56,56,56,56,0,0,0,0,0,0,0,0,0,0,56,56,24,56,56,0,0,0,0,0,0,0,0
0,0,0,0,0,0,56,56,56,56,56,56,0,0,0,0,0,0,0,0,0,0,0,0,56,56,56,0,0,0,0,0,0,0,0,0
0,0,0,0,0,0,0,0,56,56,0,0,0,0,0,0,0,0,0,0,0,0,0,0,0,56,0,0,0,0,0,0,0,0,0,0
0,0,0,0,0,0,0,0,0,0,0,0,0,0,0,0,0,0,0,0,0,0,0,0,0,0,0,0,0,0,0,0,0,0,0,0
0,0,0,0,0,0,0,0,9,9,0,0,0,0,0,0,0,0,0,0,0,0,0,0,0,0,0,0,0,0,0,0,0,0,0,0
0,0,0,0,0,0,0,8,24,24,6,0,0,0,0,0,0,0,0,0,0,0,0,0,0,0,0,0,0,0,0,0,0,0,0,0
0,0,0,0,0,0,0,8,24,24,6,0,0,0,0,0,0,0,0,0,0,0,0,0,0,0,0,0,0,0,0,0,0,0,0,0
0,0,0,0,0,0,0,0,7,7,0,0,0,0,0,0,0,0,0,0,0,0,0,0,0,0,0,0,0,0,0,0,0,0,0,0
0,0,0,0,0,0,0,0,0,0,0,0,0,0,0,0,0,0,0,0,0,0,0,0,0,0,0,0,0,0,0,0,0,0,0,0
0,0,0,0,0,0,0,0,0,0,0,0,0,0,0,0,0,0,0,0,0,0,0,0,0,0,0,0,0,0,0,0,0,0,0,0
0,0,0,0,0,0,0,0,0,0,0,0,0,0,0,0,0,0,0,0,0,0,0,0,0,0,0,0,0,0,0,0,0,0,0,0
0,0,0,0,0,0,0,0,0,0,0,0,0,0,0,0,0,0,0,0,0,0,0,0,0,0,0,0,0,0,0,0,0,0,0,0
0,0,0,0,0,0,0,0,0,0,0,0,0,0,0,0,0,0,0,0,0,0,0,0,0,0,0,0,0,0,0,0,0,0,0,0
0,0,0,0,0,0,0,0,0,0,0,0,0,0,0,0,0,0,0,0,0,0,0,0,0,0,0,0,0,0,0,0,0,0,0,0
0,0,0,0,0,0,0,0,0,0,0,0,0,0,0,0,0,0,0,0,0,0,0,0,0,0,0,0,0,0,0,0,0,0,0,0
0,0,0,0,0,0,0,9,9,0,0,0,0,0,0,0,0,0,0,0,0,0,0,0,0,0,0,0,0,0,0,0,0,0,0,0
0,0,0,0,0,0,8,24,24,6,0,0,0,0,0,0,0,0,0,0,0,0,0,0,0,0,0,0,0,0,0,0,0,0,0,0
0,0,0,0,0,0,8,24,24,6,0,0,0,0,0,0,0,0,0,0,0,0,0,0,0,0,0,0,0,0,0,0,0,0,0,0
0,0,0,0,0,0,0,7,7,0,0,0,0,0,0,0,0,0,0,0,0,0,0,0,0,0,0,0,0,0,0,0,0,0,0,0
0,0,0,0,0,0,0,0,0,0,0,0,0,0,0,0,0,0,0,0,0,0,0,0,0,0,0,0,0,0,0,0,0,0,0,0
0,0,0,0,0,0,0,0,0,0,0,0,0,0,0,0,0,0,0,0,0,0,0,0,0,0,0,0,0,0,0,0,0,0,0,0
0,0,0,0,0,0,0,0,0,0,0,0,0,0,0,0,0,0,0,0,0,0,0,0,0,0,0,0,0,0,0,0,0,0,0,0
0,0,0,0,0,0,0,0,0,0,0,0,0,0,0,0,0,0,0,0,0,0,0,0,0,0,0,0,0,0,0,0,0,0,0,0
0,0,0,0,0,0,0,0,0,0,0,0,0,0,0,0,0,0,0,0,0,0,0,0,0,0,0,0,0,0,0,0,0,0,0,0
0,0,0,0,0,0,0,0,0,0,0,0,0,0,0,0,0,0,0,0,0,0,0,0,0,0,0,0,0,0,0,0,0,0,0,0
0,0,0,0,0,0,0,0,0,0,0,0,0,0,0,0,0,0,0,0,0,0,0,0,0,0,0,0,0,0,0,0,0,0,0,0
0,0,0,0,0,0,0,0,0,0,0,0,0,0,0,0,0,0,0,0,0,0,0,0,0,0,0,0,0,0,0,0,0,0,0,0
0,0,0,0,0,0,0,0,0,0,0,0,0,0,0,0,0,0,0,0,0,0,0,0,0,0,0,0,0,0,0,0,0,0,0,0
0,0,0,0,0,0,0,0,0,0,0,0,0,0,0,0,0,0,0,0,0,0,0,0,0,0,0,0,0,0,0,0,0,0,0,0
endlayer

layer
0,0,0,0,0,0,0,0,0,0,0,0,0,0,0,0,0,0,0,0,0,0,0,0,0,0,0,0,0,0,0,0,0,0,0,0
0,0,0,0,0,0,0,0,56,56,0,0,0,0,0,0,0,0,0,0,0,0,0,0,0,0,0,0,0,0,0,0,0,0,0,0
0,0,0,0,0,0,56,56,56,56,56,56,0,0,0,0,0,0,0,0,0,0,0,0,0,0,0,0,0,0,0,0,0,0,0,0
0,0,0,0,0,0,56,56,56,56,56,56,0,0,0,0,0,0,0,0,0,0,0,0,0,0,0,0,9,9,0,0,0,0,0,0
0,0,0,0,0,56,56,56,56,56,56,56,56,0,0,0,0,0,0,0,0,0,0,0,0,0,0,8,24,24,6,0,0,0,0,0
0,0,0,0,0,56,56,56,56,56,56,56,56,0,0,0,0,0,0,0,0,0,0,0,0,0,0,24,24,24,6,0,0,0,0,0
0,0,0,0,0,0,56,56,56,56,56,56,0,0,0,0,0,0,0,0,0,0,0,0,0,56,0,0,7,7,0,0,0,0,0,0
0,0,0,0,0,0,56,56,56,56,56,56,0,0,0,0,0,0,0,0,0,0,0,0,56,56,56,0,0,0,0,0,0,0,0,0
0,0,0,0,0,0,0,0,56,56,0,0,0,0,0,0,0,0,0,0,0,0,0,0,0,56,0,0,0,0,0,0,0,0,0,0
0,0,0,0,0,0,0,0,0,0,0,0,0,0,0,0,0,0,0,0,0,0,0,0,0,0,0,0,0,0,0,0,0,0,0,0
0,0,0,0,0,0,0,0,0,0,0,0,0,0,0,0,0,0,0,0,0,0,0,0,0,0,0,0,0,0,0,0,0,0,0,0
0,0,0,0,0,0,0,0,9,9,0,0,0,0,0,0,0,0,0,0,0,0,0,0,0,0,0,0,0,0,0,0,0,0,0,0
0,0,0,0,0,0,0,8,24,24,6,0,0,0,0,0,0,0,0,0,0,0,0,0,0,0,0,0,0,0,0,0,0,0,0,0
0,0,0,0,0,0,0,8,24,24,6,0,0,0,0,0,0,0,0,0,0,0,0,0,0,0,0,0,0,0,0,0,0,0,0,0
0,0,0,0,0,0,0,0,7,7,0,0,0,0,0,0,0,0,0,0,0,0,0,0,0,0,0,0,0,0,0,0,0,0,0,0
0,0,0,0,0,0,0,0,0,0,0,0,0,0,0,0,0,0,0,0,0,0,0,0,0,0,0,0,0,0,0,0,0,0,0,0
0,0,0,0,0,0,0,0,0,0,0,0,0,0,0,0,0,0,0,0,0,0,0,0,0,0,0,0,0,0,0,0,0,0,0,0
0,0,0,0,0,0,0,0,0,0,0,0,0,0,0,0,0,0,0,0,0,0,0,0,0,0,0,0,0,0,0,0,0,0,0,0
0,0,0,0,0,0,0,0,0,0,0,0,0,0,0,0,0,0,0,0,0,0,0,0,0,0,0,0,0,0,0,0,0,0,0,0
0,0,0,0,0,0,0,0,0,0,0,0,0,0,0,0,0,0,0,0,0,0,0,0,0,0,0,0,0,0,0,0,0,0,0,0
0,0,0,0,0,0,0,0,0,0,0,0,0,0,0,0,0,0,0,0,0,0,0,0,0,0,0,0,0,0,0,0,0,0,0,0
0,0,0,0,0,0,0,0,0,0,0,0,0,0,0,0,0,0,0,0,0,0,0,0,0,0,0,0,0,0,0,0,0,0,0,0
0,0,0,0,0,0,0,9,0,0,0,0,0,0,0,0,0,0,0,0,0,0,0,0,0,0,0,0,0,0,0,0,0,0,0,0
0,0,0,0,0,0,8,24,24,6,0,0,0,0,0,0,0,0,0,0,0,0,0,0,0,0,0,0,0,0,0,0,0,0,0,0
0,0,0,0,0,0,8,24,24,6,0,0,0,0,0,0,0,0,0,0,0,0,0,0,0,0,0,0,0,0,0,0,0,0,0,0
0,0,0,0,0,0,0,7,7,0,0,0,0,0,0,0,0,0,0,0,0,0,0,0,0,0,0,0,0,0,0,0,0,0,0,0
0,0,0,0,0,0,0,0,0,0,0,0,0,0,0,0,0,0,0,0,0,0,0,0,0,0,0,0,0,0,0,0,0,0,0,0
0,0,0,0,0,0,0,0,0,0,0,0,0,0,0,0,0,0,0,0,0,0,0,0,0,0,0,0,0,0,0,0,0,0,0,0
0,0,0,0,0,0,0,0,0,0,0,0,0,0,0,0,0,0,0,0,0,0,0,0,0,0,0,0,0,0,0,0,0,0,0,0
0,0,0,0,0,0,0,0,0,0,0,0,0,0,0,0,0,0,0,0,0,0,0,0,0,0,0,0,0,0,0,0,0,0,0,0
0,0,0,0,0,0,0,0,0,0,0,0,0,0,0,0,0,0,0,0,0,0,0,0,0,0,0,0,0,0,0,0,0,0,0,0
0,0,0,0,0,0,0,0,0,0,0,0,0,0,0,0,0,0,0,0,0,0,0,0,0,0,0,0,0,0,0,0,0,0,0,0
0,0,0,0,0,0,0,0,0,0,0,0,0,0,0,0,0,0,0,0,0,0,0,0,0,0,0,0,0,0,0,0,0,0,0,0
0,0,0,0,0,0,0,0,0,0,0,0,0,0,0,0,0,0,0,0,0,0,0,0,0,0,0,0,0,0,0,0,0,0,0,0
0,0,0,0,0,0,0,0,0,0,0,0,0,0,0,0,0,0,0,0,0,0,0,0,0,0,0,0,0,0,0,0,0,0,0,0
0,0,0,0,0,0,0,0,0,0,0,0,0,0,0,0,0,0,0,0,0,0,0,0,0,0,0,0,0,0,0,0,0,0,0,0
endlayer

layer
0,0,0,0,0,0,0,0,0,0,0,0,0,0,0,0,0,0,0,0,0,0,0,0,0,0,0,0,0,0,0,0,0,0,0,0
0,0,0,0,0,0,0,0,0,0,0,0,0,0,0,0,0,0,0,0,0,0,0,0,0,0,0,0,0,0,0,0,0,0,0,0
0,0,0,0,0,0,0,0,0,0,0,0,0,0,0,0,0,0,0,0,0,0,0,0,0,0,0,0,0,0,0,0,0,0,0,0
0,0,0,0,0,0,0,0,0,0,0,0,0,0,0,0,0,0,0,0,0,0,0,0,0,0,0,0,9,9,0,0,0,0,0,0
0,0,0,0,0,0,0,0,0,0,0,0,0,0,0,0,0,0,0,0,0,0,0,0,0,0,0,8,24,24,6,0,0,0,0,0
0,0,0,0,0,0,0,0,0,0,0,0,0,0,0,0,0,0,0,0,0,0,0,0,0,0,0,8,24,24,6,0,0,0,0,0
0,0,0,0,0,0,0,0,0,0,0,0,0,0,0,0,0,0,0,0,0,0,0,0,0,24,24,0,7,7,0,0,0,0,0,0
0,0,0,0,0,0,0,0,0,0,0,0,0,0,0,0,0,0,0,0,0,0,0,0,0,0,0,0,0,0,0,0,0,0,0,0
0,0,0,0,0,0,0,0,0,0,0,0,0,0,0,0,0,0,0,0,0,0,0,0,0,0,0,0,0,0,0,0,0,0,0,0
0,0,0,0,0,0,0,0,0,0,0,0,0,0,0,0,0,0,0,0,0,0,0,0,0,0,0,0,0,0,0,0,0,0,0,0
0,0,0,0,0,0,0,0,0,0,0,0,0,0,0,0,0,0,0,0,0,0,0,0,0,0,0,0,0,0,0,0,0,0,0,0
0,0,0,0,0,0,0,0,9,9,0,0,0,0,0,0,0,0,0,0,0,0,0,0,0,0,0,0,0,0,0,0,0,0,0,0
0,0,0,0,0,0,0,8,24,24,6,0,0,0,0,0,0,0,0,0,0,0,0,0,0,0,0,0,0,0,0,0,0,0,0,0
0,0,0,0,0,0,0,8,24,24,6,0,0,0,0,0,0,0,0,0,0,0,0,0,0,0,0,0,0,0,0,0,0,0,0,0
0,0,0,0,0,0,0,24,7,7,0,0,0,0,0,0,0,0,0,0,0,0,0,0,0,0,0,0,0,0,0,0,0,0,0,0
0,0,0,0,0,0,0,0,0,0,0,0,0,0,0,0,0,0,0,0,0,0,0,0,0,0,0,0,0,0,0,0,0,0,0,0
0,0,0,0,0,0,0,0,0,0,0,0,0,0,0,0,0,0,0,0,0,0,0,0,0,0,0,0,0,0,0,0,0,0,0,0
