# HauntedHouse (15 May 2014)
# Updated to MC 1.7.10, 10 Oct 2014, 28 Oct 2014
# Created by Ruins mod version 13.8 Ingame Parser
# authoring Player: Jordan_Greywolf

biomesToSpawnIn=autumn woods,birch forest,bog,deadlands,dead forest,enchanted forest,flower forest,forest,green swampland,ominous woods,swampland,taiga,wasteland,woodland,woodlands
weight=1

embed_into_distance=3
acceptable_target_blocks=
unacceptable_target_blocks=flowing_water,water,flowing_lava,lava
dimensions=26,13,17
allowable_overhang=0
max_leveling=3
leveling_buffer=0
preserve_water=0
preserve_lava=0
preserve_plants=1

rule1=0,100,minecraft:dirt-0
rule2=0,100,minecraft:double_stone_slab-0
rule3=0,100,minecraft:stonebrick-0

# Floor/Path
rule4=0,100,minecraft:mossy_cobblestone-0,minecraft:cobblestone-0

# Creepy Crawler Command Block
rule5=0,100,CommandBlock:RUINSTRIGGER /setblock ~0 ~1 ~0 mob_spawner 0 replace {EntityId:CaveSpider,SpawnData:{Equipment:[{Count:1,id:web},{},{},{},{}],CustomName:Creepy Crawler,DropChances:[0.2F,0.0F,0.0F,0.0F,0.0F],ActiveEffects:[{Id:14,Amplifier:1,Duration:999999}],Silent:1}}:@

rule6=0,100,HardChest,ChestGenHook:dungeonChest:2

# Pumpkin Servant Command Block
rule7=0,100,CommandBlock:RUINSTRIGGER /setblock ~0 ~1 ~0 mob_spawner 0 replace {EntityId:Skeleton,SpawnData:{DropChances:[0.3F,0.2F,0.2F,0.2F,0.2F],ActiveEffects:[{Id:1,Amplifier:0,Duration:99999,Ambient:1},{Id:8,Amplifier:7,Duration:99999,Ambient:1},{Id:18,Amplifier:0,Duration:99999,Ambient:1}],CustomName:"Pumpkin Servant",Equipment:[{Count:1,id:268,tag:{display:{color:0,Name:Pumpkin Patch Sword},ench:[{id:16,lvl:5},{id:19,lvl:5},{Count:1,id:20,lvl:5}]}},{id:301,tag:{display:{Name:Dark Boots,color:0}}},{Count:1,id:300,tag:{display:{Name:Dark Pants,color:0}}},{Count:1,id:299,tag:{display:{Name:Dark Tunic,color:0}}},{Count:1,id:86,tag:{display:{Name:Enchanted Pumpkin},ench:[{id:0,lvl:5},{id:5,lvl:15},{id:6,lvl:1},{id:3,lvl:4}]}}]}}:@

rule8=0,100,minecraft:web-0
rule9=0,100,minecraft:brick_block-0
rule10=0,100,minecraft:lit_furnace-3
rule11=0,100,minecraft:stone_brick_stairs-2
rule12=0,100,minecraft:stone_brick_stairs-7
rule13=0,100,minecraft:grass-0

# Tallgrass, etc.
rule14=0,100,minecraft:tallgrass-1,minecraft:tallgrass-2,minecraft:web

rule15=0,100,minecraft:iron_bars-0
rule16=0,100,minecraft:wooden_slab-9

# Special Plants
rule17=0,100,minecraft:tallgrass-0,minecraft:red_flower-1,minecraft:red_flower-2,minecraft:red_flower-3,minecraft:red_flower-4,minecraft:red_flower-5,minecraft:red_flower-6,minecraft:red_flower-8

# Chiseled Stone Brick
rule18=0,100,minecraft:stonebrick-3

rule19=0,100,minecraft:stone_brick_stairs-3

# Red/Black Tile Floor
rule20=0,100,minecraft:stained_hardened_clay-15
rule21=0,100,minecraft:stained_hardened_clay-14

rule22=0,100,minecraft:fence-0
rule23=0,100,minecraft:netherrack-0

# Skullz!
rule24=0,100,minecraft:skull,minecraft:skull-1,minecraft:skull-2,minecraft:skull-3

rule25=0,100,minecraft:planks-1
rule26=0,100,minecraft:flower_pot-11
rule27=0,100,minecraft:stone_brick_stairs-6
rule28=2,100,WallSign:null:null:null:null-4

# Flower Pot
rule29=0,100,minecraft:flower_pot-1,minecraft:flower_pot-2,minecraft:flower_pot-3,minecraft:flower_pot-4,minecraft:flower_pot-5,minecraft:flower_pot-6,minecraft:flower_pot-7,minecraft:flower_pot-8,minecraft:flower_pot-9,minecraft:flower_pot-10,minecraft:flower_pot-11,minecraft:flower_pot-12,minecraft:flower_pot-13

rule30=0,100,minecraft:fire-15
rule31=0,100,minecraft:oak_stairs-2
rule32=1,100,minecraft:wooden_door-1
rule33=2,100,WallSign:null:null:null:null-5
rule34=0,100,minecraft:redstone_lamp-0
rule35=2,100,minecraft:redstone_torch-5
rule36=1,100,minecraft:wooden_door-8
rule37=0,100,minecraft:brick_stairs-3
rule38=0,100,minecraft:wooden_slab-8
rule39=0,100,minecraft:brick_stairs-0
rule40=0,100,minecraft:brick_stairs-1
rule41=1,100,minecraft:wooden_door-2
rule42=0,100,minecraft:lit_furnace-3

# Wicked Witch Command Block!
rule43=0,100,CommandBlock:RUINSTRIGGER /summon Witch ~0 ~1 ~0 {AbsorptionAmount:10,PersistenceRequired:1}:@

rule44=1,100,minecraft:wooden_door-0
rule45=2,100,minecraft:ladder-3
rule46=0,100,minecraft:nether_brick_stairs-0
rule47=0,100,minecraft:nether_brick_stairs-5
rule48=0,100,minecraft:nether_brick_stairs-4
rule49=0,100,minecraft:nether_brick_stairs-1
rule50=0,100,minecraft:nether_brick-0
rule51=0,100,minecraft:stone_slab-8
rule52=0,100,minecraft:stone_slab-0
rule53=0,100,ChestGenHook:dungeonChest:5-5
rule54=0,100,ChestGenHook:dungeonChest:5-4
rule55=0,100,minecraft:stone_slab-6

layer
1,1,1,1,1,1,1,1,1,1,1,1,1,1,1,1,1
1,1,1,1,1,1,1,1,1,1,1,1,1,1,1,1,1
1,1,1,1,1,1,2,3,3,3,3,3,3,3,2,1,1
1,1,1,1,1,1,3,4,4,4,4,4,4,4,3,1,1
1,1,1,1,1,1,3,4,4,4,4,4,4,4,3,1,1
1,1,1,1,1,1,3,4,4,4,4,4,4,4,3,1,1
1,1,1,1,1,1,3,4,4,4,4,4,4,4,3,1,1
1,1,1,1,1,1,3,4,4,4,4,4,4,4,3,1,1
1,1,1,1,1,1,3,4,4,4,4,4,4,4,3,1,1
1,1,1,1,1,1,3,4,4,4,4,4,4,4,3,1,1
1,1,1,1,1,1,2,3,3,3,3,3,3,3,2,1,1
1,1,1,1,1,1,1,1,1,1,1,1,1,1,1,1,1
1,1,1,1,1,1,1,1,1,1,1,1,1,1,1,1,1
endlayer

layer
1,1,1,1,1,1,1,1,1,1,1,1,1,1,1,1,1
1,1,1,1,1,1,1,1,1,1,1,1,1,1,1,1,1
1,1,1,1,1,1,2,3,3,3,3,3,3,3,2,1,1
1,1,1,1,1,1,3,8,7,3,0,0,6,8,3,1,1
1,1,1,1,1,1,3,0,8,3,3,0,3,3,3,1,1
1,1,1,1,1,1,3,0,3,3,0,0,0,0,9,9,1
1,1,1,1,1,1,3,0,0,0,0,0,0,0,10,9,1
1,1,1,1,1,1,3,0,0,3,0,0,0,0,9,9,1
1,1,1,1,1,1,3,8,8,3,3,0,3,3,3,1,1
1,1,1,1,1,1,3,6,7,12,11,0,0,7,3,1,1
1,1,1,1,1,1,2,3,3,3,3,3,3,3,2,1,1
1,1,1,1,1,1,1,1,1,1,1,1,1,1,1,1,1
1,1,1,1,1,1,1,1,1,1,1,1,1,1,1,1,1
endlayer

layer
13,13,13,13,13,13,13,13,13,13,13,13,13,13,13,13,13
13,13,13,13,13,13,13,13,13,13,13,13,13,13,13,13,13
13,13,13,13,13,13,2,3,3,3,3,3,3,3,2,13,13
13,13,13,13,13,13,3,0,8,3,0,0,0,8,3,13,13
13,13,13,13,1,1,3,0,0,3,3,0,3,3,3,13,13
13,13,13,1,1,1,3,0,3,3,0,0,0,0,9,9,13
4,4,4,1,1,1,3,0,0,0,0,0,0,0,9,9,13
13,13,13,1,1,1,3,0,0,3,0,0,0,0,9,9,13
13,13,13,13,1,1,3,8,8,3,3,0,3,3,3,13,13
13,13,13,13,13,13,3,8,12,11,0,0,0,0,3,13,13
13,13,13,13,13,13,2,3,3,3,3,3,3,3,2,13,13
13,13,13,13,13,13,13,13,13,13,13,13,13,13,13,13,13
13,13,13,13,13,13,13,13,13,13,13,13,13,13,13,13,13
endlayer

layer
14,14,14,14,14,14,14,14,14,14,14,14,14,14,14,14,14
14,14,14,14,14,14,14,14,14,14,14,14,14,14,14,14,14
15,15,15,15,15,15,2,3,3,3,3,3,3,3,2,14,0
15,17,17,17,17,17,3,16,16,3,16,16,16,16,3,14,14
15,17,17,17,3,3,3,16,16,3,3,3,3,3,3,17,17
15,17,17,3,18,18,3,3,3,3,16,16,16,16,9,9,17
0,0,0,19,18,18,3,16,16,3,16,16,16,16,9,9,17
15,17,17,3,18,18,3,16,16,3,16,16,16,16,9,9,17
15,17,17,17,3,3,3,16,16,3,3,3,3,3,3,17,17
15,17,17,17,17,17,3,12,11,0,0,0,16,16,3,14,14
15,15,15,15,15,15,2,3,3,3,3,3,3,3,2,14,14
0,0,0,14,14,14,14,14,14,14,14,14,14,14,14,14,0
0,0,0,0,0,0,0,14,14,14,14,14,14,14,14,14,14
endlayer

layer
0,0,0,0,0,0,0,0,0,0,0,0,0,0,0,0,0
0,0,0,0,0,0,0,0,0,0,0,0,0,0,0,0,0
0,0,0,0,0,0,2,3,3,3,3,3,3,3,2,0,0
0,0,0,0,0,0,3,20,21,20,21,20,21,20,3,0,0
0,0,0,0,3,3,3,21,20,21,20,21,20,21,3,0,0
0,0,0,22,18,18,3,20,21,20,21,20,21,9,9,9,0
0,0,0,0,19,18,3,21,20,21,20,21,20,9,23,9,0
24,0,0,22,18,18,3,20,21,20,21,20,21,9,9,9,0
0,0,0,0,3,3,3,21,20,21,20,21,20,21,3,0,0
0,0,0,0,0,0,3,11,0,0,0,20,21,20,3,0,0
0,0,0,0,0,0,2,3,3,3,3,3,3,3,2,0,0
0,0,0,0,0,0,0,0,0,0,0,0,0,0,0,0,0
0,0,0,0,0,0,0,0,0,0,0,0,0,0,0,0,0
endlayer

layer
0,0,0,0,0,0,0,0,0,0,0,0,0,0,0,0,0
0,0,0,0,0,0,0,0,0,0,0,0,0,0,0,0,0
0,0,0,0,0,0,2,25,25,25,25,25,25,25,2,0,0
0,0,0,0,0,0,25,0,19,27,0,0,0,26,25,0,0
0,0,0,0,22,22,25,0,0,0,0,0,0,0,25,0,0
0,0,0,22,22,29,25,0,0,0,0,28,0,15,9,9,0
0,0,0,0,0,0,32,0,0,0,0,31,0,15,30,9,0
0,0,0,22,22,29,25,0,0,0,0,33,0,15,9,9,0
0,0,0,0,22,22,25,0,15,15,15,15,0,0,25,0,0
0,0,0,0,0,0,25,0,0,0,0,15,0,26,25,0,0
0,0,0,0,0,0,2,25,25,25,25,25,25,25,2,0,0
0,0,0,0,0,0,0,0,0,0,0,0,0,0,0,0,0
0,0,0,0,0,0,0,0,0,0,0,0,0,0,0,0,0
endlayer

layer
0,0,0,0,0,0,0,0,0,0,0,0,0,0,0,0,0
0,0,0,0,0,0,0,0,0,0,0,0,0,0,0,0,0
0,0,0,0,0,0,2,25,34,25,34,25,34,25,2,0,0
0,0,0,0,0,0,25,0,0,19,27,0,0,0,25,0,0
0,0,0,0,0,0,34,0,0,0,0,0,0,0,34,0,0
0,0,0,35,0,0,25,0,0,0,0,0,0,15,9,9,0
0,0,0,0,0,0,36,0,0,0,0,24,0,0,0,9,0
0,0,0,35,0,0,25,0,0,0,0,0,0,15,9,9,0
0,0,0,0,0,0,34,0,0,0,0,0,0,0,34,0,0
0,0,0,0,0,0,25,0,0,0,0,0,0,0,25,0,0
0,0,0,0,0,0,2,25,34,25,34,25,34,25,2,0,0
0,0,0,0,0,0,0,0,0,0,0,0,0,0,0,0,0
0,0,0,0,0,0,0,0,0,0,0,0,0,0,0,0,0
endlayer

layer
0,0,0,0,0,0,0,0,0,0,0,0,0,0,0,0,0
0,0,0,0,0,0,0,0,0,0,0,0,0,0,0,0,0
0,0,0,0,0,0,2,25,34,25,34,25,34,25,2,0,0
0,0,0,0,0,0,25,0,0,0,19,27,0,0,25,0,0
0,0,0,0,0,0,34,0,0,0,0,0,0,0,34,0,0
0,0,0,0,0,0,25,0,0,0,0,0,0,37,9,9,0
0,0,0,0,0,0,34,0,0,0,0,0,0,37,0,9,0
0,0,0,0,0,0,25,0,0,0,0,0,0,37,9,9,0
0,0,0,0,0,0,34,0,0,0,0,0,0,0,34,0,0
0,0,0,0,0,0,25,8,0,0,0,0,0,8,25,0,0
0,0,0,0,0,0,2,25,34,25,34,25,34,25,2,0,0
0,0,0,0,0,0,0,0,0,0,0,0,0,0,0,0,0
0,0,0,0,0,0,0,0,0,0,0,0,0,0,0,0,0
endlayer

layer
0,0,0,0,0,0,0,0,0,0,0,0,0,0,0,0,0
0,0,0,0,0,0,38,0,0,0,0,0,0,0,38,0,0
0,0,0,0,0,38,2,25,25,25,25,25,25,25,2,38,0
0,0,0,0,0,0,25,0,8,8,0,19,27,8,25,0,0
0,0,0,0,0,0,25,0,0,0,0,0,0,0,25,0,0
0,0,0,0,0,0,25,0,0,0,0,0,0,0,9,39,0
0,0,0,0,0,0,25,0,0,0,0,0,0,0,9,9,0
0,0,0,0,0,0,25,0,0,0,0,0,0,0,9,40,0
0,0,0,0,0,0,25,8,0,0,0,0,0,0,25,0,0
0,0,0,0,0,0,25,8,8,0,0,0,8,8,25,0,0
0,0,0,0,0,38,2,25,25,25,25,25,25,25,2,38,0
0,0,0,0,0,0,38,0,0,0,0,0,0,0,38,0,0
0,0,0,0,0,0,0,0,0,0,0,0,0,0,0,0,0
endlayer

layer
0,0,0,0,0,0,0,0,0,2,38,2,0,0,0,0,0
0,0,0,0,0,2,25,25,25,25,25,25,25,25,25,2,0
0,0,0,0,0,25,20,21,20,21,20,21,20,21,20,25,0
0,0,0,0,0,25,21,20,21,8,8,0,19,20,21,25,0
0,0,0,0,0,25,20,21,20,21,20,21,20,21,20,25,0
0,0,0,0,0,25,21,20,21,20,21,20,21,20,21,25,0
0,0,0,0,0,25,20,21,20,21,20,21,20,21,20,9,0
0,0,0,0,0,25,21,20,21,20,21,20,21,20,21,25,0
0,0,0,0,0,25,20,21,20,21,20,21,20,21,20,25,0
0,0,0,0,0,25,21,20,21,20,21,20,21,20,21,25,0
0,0,0,0,0,25,20,21,20,21,20,21,20,21,20,25,0
0,0,0,0,0,2,25,25,25,25,25,25,25,25,25,2,0
0,0,0,0,0,0,0,0,0,2,38,2,0,0,0,0,0
endlayer

layer
0,0,0,0,0,0,0,0,0,15,15,15,0,0,0,0,0
0,0,0,0,0,2,25,25,25,25,41,25,25,25,25,2,0
0,0,0,0,0,25,8,8,0,0,0,0,0,8,8,25,0
0,0,0,0,0,25,8,0,0,0,0,0,0,0,8,25,0
0,0,0,0,0,25,0,0,0,0,0,0,0,0,0,25,0
0,0,0,0,0,25,0,0,0,0,0,0,0,0,8,25,0
0,0,0,0,0,25,0,0,0,0,43,0,0,0,42,9,0
0,0,0,0,0,25,0,0,0,0,0,0,0,0,8,25,0
0,0,0,0,0,25,0,0,0,0,0,0,0,0,0,25,0
0,0,0,0,0,25,8,0,0,0,0,0,0,0,8,25,0
0,0,0,0,0,25,8,8,0,0,0,0,0,8,8,25,0
0,0,0,0,0,2,25,25,25,25,44,25,25,25,25,2,0
0,0,0,0,0,0,0,0,0,15,15,15,0,0,0,0,0
endlayer

layer
0,0,0,0,0,0,0,0,0,0,0,0,0,0,0,0,0
0,0,0,0,0,2,25,34,34,25,36,25,34,34,25,2,0
0,0,0,0,0,25,8,0,0,0,0,0,0,0,8,25,0
0,0,0,0,0,34,0,0,0,0,0,0,0,0,0,34,0
0,0,0,0,0,34,0,0,0,0,0,0,0,0,0,34,0
0,0,0,0,0,25,0,0,0,0,0,0,0,0,0,25,0
0,0,0,0,0,34,0,0,0,0,0,0,0,0,45,9,0
0,0,0,0,0,25,0,0,0,0,0,0,0,0,0,25,0
0,0,0,0,0,34,0,0,0,0,0,0,0,0,0,34,0
0,0,0,0,0,34,0,0,0,0,0,0,0,0,0,34,0
0,0,0,0,0,25,8,0,0,0,0,0,0,0,8,25,0
0,0,0,0,0,2,25,34,34,25,36,25,34,34,25,2,0
0,0,0,0,0,0,0,0,0,0,0,0,0,0,0,0,0
endlayer

layer
0,0,0,0,0,0,0,0,0,0,0,0,0,0,0,0,0
0,0,0,0,0,2,25,34,34,25,34,25,34,34,25,2,0
0,0,0,0,0,25,0,0,0,0,0,0,0,0,0,25,0
0,0,0,0,0,34,0,0,0,0,0,0,0,0,0,34,0
0,0,0,0,0,34,0,0,0,0,0,0,0,0,0,34,0
0,0,0,0,0,25,0,0,0,0,0,0,0,0,0,25,0
0,0,0,0,0,34,0,0,0,0,0,0,0,0,45,9,0
0,0,0,0,0,25,0,0,0,0,0,0,0,0,0,25,0
0,0,0,0,0,34,0,0,0,0,0,0,0,0,0,34,0
0,0,0,0,0,34,0,0,0,0,0,0,0,0,0,34,0
0,0,0,0,0,25,0,0,0,0,0,0,0,0,0,25,0
0,0,0,0,0,2,25,34,34,25,34,25,34,34,25,2,0
0,0,0,0,0,0,0,0,0,0,0,0,0,0,0,0,0
endlayer

layer
0,0,0,0,46,46,46,46,46,46,46,46,46,46,46,46,46
0,0,0,0,47,2,25,25,25,25,25,25,25,25,25,2,47
0,0,0,0,0,25,0,0,0,0,0,0,0,0,0,25,0
0,0,0,0,0,25,0,0,0,0,0,0,0,0,0,25,0
0,0,0,0,0,25,0,0,0,0,0,0,0,0,0,25,0
0,0,0,0,0,25,0,0,0,0,0,0,0,0,0,25,0
0,0,0,0,0,25,0,0,0,0,0,0,0,0,45,9,0
0,0,0,0,0,25,0,0,0,0,0,0,0,0,0,25,0
0,0,0,0,0,25,0,0,0,0,0,0,0,0,0,25,0
0,0,0,0,0,25,0,0,0,0,0,0,0,0,0,25,0
0,0,0,0,0,25,0,0,0,0,0,0,0,0,0,25,0
0,0,0,0,48,2,25,25,25,25,25,25,25,25,25,2,48
0,0,0,0,49,49,49,49,49,49,49,49,49,49,49,49,49
endlayer

layer
0,0,0,0,0,0,0,0,0,0,0,0,0,0,0,0,0
0,0,0,0,50,50,50,50,50,50,50,50,50,50,50,50,50
0,0,0,0,0,2,2,51,51,51,51,51,51,51,2,2,0
0,0,0,0,0,2,2,51,51,51,51,51,51,51,2,2,0
0,0,0,0,0,25,52,52,52,52,52,52,52,52,52,25,0
0,0,0,0,0,25,0,0,0,0,0,0,0,0,0,25,0
0,0,0,0,0,34,0,0,0,0,0,0,0,0,45,9,0
0,0,0,0,0,25,0,0,0,0,0,0,0,0,0,25,0
0,0,0,0,0,25,52,52,52,52,52,52,52,52,52,25,0
0,0,0,0,0,2,2,51,51,51,51,51,51,51,2,2,0
0,0,0,0,0,2,2,51,51,51,51,51,51,51,2,2,0
0,0,0,0,50,50,50,50,50,50,50,50,50,50,50,50,50
0,0,0,0,0,0,0,0,0,0,0,0,0,0,0,0,0
endlayer

layer
0,0,0,0,0,0,0,0,0,0,0,0,0,0,0,0,0
0,0,0,0,50,50,50,50,50,50,50,50,50,50,50,50,50
0,0,0,0,0,25,50,50,50,50,50,50,50,50,50,25,0
0,0,0,0,0,25,53,0,0,0,1,0,0,0,53,25,0
0,0,0,0,0,25,0,0,0,0,0,0,0,0,0,25,0
0,0,0,0,0,25,0,0,0,0,0,0,0,0,0,25,0
0,0,0,0,0,34,0,0,0,0,0,0,0,0,45,9,0
0,0,0,0,0,25,0,0,0,0,0,0,0,0,0,25,0
0,0,0,0,0,25,0,0,0,0,0,0,0,0,0,25,0
0,0,0,0,0,25,54,0,0,0,1,0,0,0,54,25,0
0,0,0,0,0,25,50,50,50,50,50,50,50,50,50,25,0
0,0,0,0,50,50,50,50,50,50,50,50,50,50,50,50,50
0,0,0,0,0,0,0,0,0,0,0,0,0,0,0,0,0
endlayer

layer
0,0,0,0,0,0,0,0,0,0,0,0,0,0,0,0,0
0,0,0,0,46,46,46,46,46,46,46,46,46,46,46,46,46
0,0,0,0,47,50,50,50,50,50,50,50,50,50,50,50,47
0,0,0,0,0,25,0,0,0,0,5,0,0,0,0,25,0
0,0,0,0,0,34,0,0,0,0,0,0,0,0,0,34,0
0,0,0,0,0,34,0,0,0,0,0,0,0,0,0,34,0
0,0,0,0,0,25,0,0,0,0,0,0,0,0,45,9,0
0,0,0,0,0,34,0,0,0,0,0,0,0,0,0,34,0
0,0,0,0,0,34,0,0,0,0,0,0,0,0,0,34,0
0,0,0,0,0,25,0,0,0,0,5,0,0,0,0,25,0
0,0,0,0,48,50,50,50,50,50,50,50,50,50,50,50,48
0,0,0,0,49,49,49,49,49,49,49,49,49,49,49,49,49
0,0,0,0,0,0,0,0,0,0,0,0,0,0,0,0,0
endlayer

layer
0,0,0,0,0,0,0,0,0,0,0,0,0,0,0,0,0
0,0,0,0,0,0,0,0,0,0,0,0,0,0,0,0,0
0,0,0,0,50,50,50,50,50,50,50,50,50,50,50,50,50
0,0,0,0,0,25,0,0,0,0,0,0,0,0,0,25,0
0,0,0,0,0,34,0,0,0,0,0,0,0,0,0,34,0
0,0,0,0,0,34,0,0,0,0,0,0,0,0,0,34,0
0,0,0,0,0,25,0,0,0,0,0,0,0,0,45,9,0
0,0,0,0,0,34,0,0,0,0,0,0,0,0,0,34,0
0,0,0,0,0,34,0,0,0,0,0,0,0,0,0,34,0
0,0,0,0,0,25,0,0,0,0,0,0,0,0,0,25,0
0,0,0,0,50,50,50,50,50,50,50,50,50,50,50,50,50
0,0,0,0,0,0,0,0,0,0,0,0,0,0,0,0,0
0,0,0,0,0,0,0,0,0,0,0,0,0,0,0,0,0
endlayer

layer
0,0,0,0,0,0,0,0,0,0,0,0,0,0,0,0,0
0,0,0,0,0,0,0,0,0,0,0,0,0,0,0,0,0
0,0,0,0,50,50,50,50,50,50,50,50,50,50,50,50,50
0,0,0,0,0,25,0,0,8,8,8,0,0,0,0,25,0
0,0,0,0,0,34,0,0,0,0,8,8,8,8,8,34,0
0,0,0,0,0,25,0,0,0,0,0,0,0,0,0,25,0
0,0,0,0,0,25,0,0,0,0,0,0,0,0,45,9,0
0,0,0,0,0,25,0,0,0,0,0,0,8,8,8,25,0
0,0,0,0,0,34,0,0,0,0,0,8,0,0,8,34,0
0,0,0,0,0,25,0,0,8,8,8,8,0,0,0,25,0
0,0,0,0,50,50,50,50,50,50,50,50,50,50,50,50,50
0,0,0,0,0,0,0,0,0,0,0,0,0,0,0,0,0
0,0,0,0,0,0,0,0,0,0,0,0,0,0,0,0,0
endlayer

layer
0,0,0,0,0,0,0,0,0,0,0,0,0,0,0,0,0
0,0,0,0,0,0,0,0,0,0,0,0,0,0,0,0,0
0,0,0,0,46,46,46,46,46,46,46,46,46,46,46,46,46
0,0,0,0,47,50,50,50,50,50,50,50,50,50,50,50,47
0,0,0,0,0,25,0,0,0,0,8,8,0,0,8,25,0
0,0,0,0,0,25,0,0,0,0,0,0,0,0,0,25,0
0,0,0,0,0,25,0,0,0,0,0,0,0,0,45,9,0
0,0,0,0,0,25,0,0,0,0,0,8,8,0,0,25,0
0,0,0,0,0,25,0,0,0,0,0,8,0,0,8,25,0
0,0,0,0,48,50,50,50,50,50,50,50,50,50,50,50,48
0,0,0,0,49,49,49,49,49,49,49,49,49,49,49,49,49
0,0,0,0,0,0,0,0,0,0,0,0,0,0,0,0,0
0,0,0,0,0,0,0,0,0,0,0,0,0,0,0,0,0
endlayer

layer
0,0,0,0,0,0,0,0,0,0,0,0,0,0,0,0,0
0,0,0,0,0,0,0,0,0,0,0,0,0,0,0,0,0
0,0,0,0,0,0,0,0,0,0,0,0,0,0,0,0,0
0,0,0,0,46,46,46,46,46,46,46,46,46,46,46,46,46
0,0,0,0,47,50,50,50,50,50,50,50,50,50,50,50,47
0,0,0,0,0,25,0,0,0,0,8,0,0,0,0,25,0
0,0,0,0,0,25,0,0,0,0,0,0,0,0,45,9,0
0,0,0,0,0,25,0,0,0,0,8,0,8,0,0,25,0
0,0,0,0,48,50,50,50,50,50,50,50,50,50,50,50,48
0,0,0,0,49,49,49,49,49,49,49,49,49,49,49,49,49
0,0,0,0,0,0,0,0,0,0,0,0,0,0,0,0,0
0,0,0,0,0,0,0,0,0,0,0,0,0,0,0,0,0
0,0,0,0,0,0,0,0,0,0,0,0,0,0,0,0,0
endlayer

layer
0,0,0,0,0,0,0,0,0,0,0,0,0,0,0,0,0
0,0,0,0,0,0,0,0,0,0,0,0,0,0,0,0,0
0,0,0,0,0,0,0,0,0,0,0,0,0,0,0,0,0
0,0,0,0,0,0,0,0,0,0,0,0,0,0,0,0,0
0,0,0,0,46,46,46,46,46,46,46,46,46,46,46,46,46
0,0,0,0,47,50,50,50,50,50,50,50,50,50,50,50,47
0,0,0,0,0,25,0,0,0,0,0,0,0,0,0,9,0
0,0,0,0,48,50,50,50,50,50,50,50,50,50,50,50,48
0,0,0,0,49,49,49,49,49,49,49,49,49,49,49,49,49
0,0,0,0,0,0,0,0,0,0,0,0,0,0,0,0,0
0,0,0,0,0,0,0,0,0,0,0,0,0,0,0,0,0
0,0,0,0,0,0,0,0,0,0,0,0,0,0,0,0,0
0,0,0,0,0,0,0,0,0,0,0,0,0,0,0,0,0
endlayer

layer
0,0,0,0,0,0,0,0,0,0,0,0,0,0,0,0,0
0,0,0,0,0,0,0,0,0,0,0,0,0,0,0,0,0
0,0,0,0,0,0,0,0,0,0,0,0,0,0,0,0,0
0,0,0,0,0,0,0,0,0,0,0,0,0,0,0,0,0
0,0,0,0,0,0,0,0,0,0,0,0,0,0,0,0,0
0,0,0,0,55,55,55,55,55,55,55,55,55,55,55,55,55
0,0,0,0,50,50,50,50,50,50,50,50,50,50,50,9,50
0,0,0,0,55,55,55,55,55,55,55,55,55,55,55,55,55
0,0,0,0,0,0,0,0,0,0,0,0,0,0,0,0,0
0,0,0,0,0,0,0,0,0,0,0,0,0,0,0,0,0
0,0,0,0,0,0,0,0,0,0,0,0,0,0,0,0,0
0,0,0,0,0,0,0,0,0,0,0,0,0,0,0,0,0
0,0,0,0,0,0,0,0,0,0,0,0,0,0,0,0,0
endlayer

layer
0,0,0,0,0,0,0,0,0,0,0,0,0,0,0,0,0
0,0,0,0,0,0,0,0,0,0,0,0,0,0,0,0,0
0,0,0,0,0,0,0,0,0,0,0,0,0,0,0,0,0
0,0,0,0,0,0,0,0,0,0,0,0,0,0,0,0,0
0,0,0,0,0,0,0,0,0,0,0,0,0,0,0,0,0
0,0,0,0,0,0,0,0,0,0,0,0,0,0,0,0,0
0,0,0,0,15,15,15,15,15,15,15,15,15,15,15,9,15
0,0,0,0,0,0,0,0,0,0,0,0,0,0,0,0,0
0,0,0,0,0,0,0,0,0,0,0,0,0,0,0,0,0
0,0,0,0,0,0,0,0,0,0,0,0,0,0,0,0,0
0,0,0,0,0,0,0,0,0,0,0,0,0,0,0,0,0
0,0,0,0,0,0,0,0,0,0,0,0,0,0,0,0,0
0,0,0,0,0,0,0,0,0,0,0,0,0,0,0,0,0
endlayer

layer
0,0,0,0,0,0,0,0,0,0,0,0,0,0,0,0,0
0,0,0,0,0,0,0,0,0,0,0,0,0,0,0,0,0
0,0,0,0,0,0,0,0,0,0,0,0,0,0,0,0,0
0,0,0,0,0,0,0,0,0,0,0,0,0,0,0,0,0
0,0,0,0,0,0,0,0,0,0,0,0,0,0,0,0,0
0,0,0,0,0,0,0,0,0,0,0,0,0,0,0,0,0
0,0,0,0,0,0,0,0,0,0,15,0,0,0,0,9,0
0,0,0,0,0,0,0,0,0,0,0,0,0,0,0,0,0
0,0,0,0,0,0,0,0,0,0,0,0,0,0,0,0,0
0,0,0,0,0,0,0,0,0,0,0,0,0,0,0,0,0
0,0,0,0,0,0,0,0,0,0,0,0,0,0,0,0,0
0,0,0,0,0,0,0,0,0,0,0,0,0,0,0,0,0
0,0,0,0,0,0,0,0,0,0,0,0,0,0,0,0,0
endlayer

layer
0,0,0,0,0,0,0,0,0,0,0,0,0,0,0,0,0
0,0,0,0,0,0,0,0,0,0,0,0,0,0,0,0,0
0,0,0,0,0,0,0,0,0,0,0,0,0,0,0,0,0
0,0,0,0,0,0,0,0,0,0,0,0,0,0,0,0,0
0,0,0,0,0,0,0,0,0,0,0,0,0,0,0,0,0
0,0,0,0,0,0,0,0,0,0,15,0,0,0,0,0,0
0,0,0,0,0,0,0,0,0,15,15,15,0,0,0,2,0
0,0,0,0,0,0,0,0,0,0,15,0,0,0,0,0,0
0,0,0,0,0,0,0,0,0,0,0,0,0,0,0,0,0
0,0,0,0,0,0,0,0,0,0,0,0,0,0,0,0,0
0,0,0,0,0,0,0,0,0,0,0,0,0,0,0,0,0
0,0,0,0,0,0,0,0,0,0,0,0,0,0,0,0,0
0,0,0,0,0,0,0,0,0,0,0,0,0,0,0,0,0
endlayer

