# SmallQuartzShrine
# 24 Apr 2014; updated to MC 1.7.10, 13 Oct 2014
# Created by Ruins mod version 12.3 Ingame Parser
# authoring Player: Jordan_Greywolf
# (hacked from "SkyQuartzShrine" top layers)

biomesToSpawnIn=forest,foresthills,flower forest,roofed forest,sunflower plains

weight=1
embed_into_distance=0

unacceptable_target_blocks=lava
dimensions=12,11,11
allowable_overhang=0
max_cut_in=0
cut_in_buffer=0
max_leveling=6
leveling_buffer=0
preserve_water=0
preserve_lava=0
preserve_plants=1

rule1=0,100,minecraft:glowstone-0
rule2=0,0,minecraft:water-7
rule3=0,0,minecraft:water-6
rule4=0,0,minecraft:water-5
rule5=0,0,minecraft:water-9
rule6=0,100,minecraft:water-1
rule7=0,100,minecraft:water-2
rule8=0,0,minecraft:water-3
rule9=0,0,minecraft:water-4
rule10=0,100,minecraft:quartz_block-2
rule11=0,100,minecraft:stone-0
rule12=0,100,minecraft:quartz_block-1
rule13=0,100,minecraft:dirt-0
rule14=0,100,minecraft:water-0
rule15=0,100,minecraft:grass-0
rule16=0,100,minecraft:tallgrass-2,minecraft:tallgrass-1,minecraft:red_flower,minecraft:yellow_flower,minecraft:red_flower-1,minecraft:red_flower-2,minecraft:red_flower-3,minecraft:red_flower-4,preserveBlock,preserveBlock
rule17=0,100,minecraft:water-11
rule18=0,100,minecraft:quartz_block-0
rule19=0,100,minecraft:water-10
rule20=0,100,minecraft:stone_slab-7
rule21=0,100,minecraft:snow_layer-0

rule22=0,100,minecraft:flowing_water

layer
0,0,0,0,15,15,15,0,0,0,0
2,0,0,15,11,11,11,15,0,0,0
3,0,15,11,11,11,11,11,15,0,0
4,15,11,11,11,11,11,11,11,15,0
15,11,11,13,11,11,11,11,11,11,15
15,11,11,11,11,1,14,19,11,11,15
15,11,11,11,11,11,11,11,11,11,15
5,15,11,11,11,11,11,11,11,15,0
8,0,15,11,11,11,11,11,15,0,0
9,0,0,15,11,11,11,15,0,0,0
0,0,0,0,15,15,15,0,0,0,0
endlayer

layer
0,0,0,0,16,16,16,0,0,0,0
0,0,0,16,20,20,20,16,0,0,0
0,0,16,20,18,18,18,20,16,0,0
0,16,20,18,18,18,18,18,20,16,0
16,20,18,18,15,14,15,18,18,20,16
16,20,18,18,14,14,6,7,18,20,16
16,20,18,18,15,14,15,18,18,20,16
0,16,20,18,18,18,18,18,20,16,0
0,0,16,20,18,18,18,20,16,0,0
0,0,0,16,20,20,20,16,0,0,0
0,0,0,0,16,16,16,0,0,0,0
endlayer

layer
0,0,0,0,0,0,0,0,0,0,0
0,0,0,0,0,0,0,0,0,0,0
0,0,0,0,10,0,10,0,0,0,0
0,0,0,0,0,0,0,0,0,0,0
0,0,10,0,16,0,16,0,10,0,0
0,0,0,0,0,0,0,0,0,0,0
0,0,10,0,16,0,16,0,10,0,0
0,0,0,0,0,0,0,0,0,0,0
0,0,0,0,10,0,10,0,0,0,0
0,0,0,0,0,0,0,0,0,0,0
0,0,0,0,0,0,0,0,0,0,0
endlayer

layer
0,0,0,0,0,0,0,0,0,0,0
0,0,0,0,0,0,0,0,0,0,0
0,0,0,0,10,0,10,0,0,0,0
0,0,0,0,0,0,0,0,0,0,0
0,0,10,0,0,0,0,0,10,0,0
0,0,0,0,0,0,0,0,0,0,0
0,0,10,0,0,0,0,0,10,0,0
0,0,0,0,0,0,0,0,0,0,0
0,0,0,0,10,0,10,0,0,0,0
0,0,0,0,0,0,0,0,0,0,0
0,0,0,0,0,0,0,0,0,0,0
endlayer

layer
0,0,0,0,0,0,0,0,0,0,0
0,0,0,0,0,0,0,0,0,0,0
0,0,0,0,10,0,10,0,0,0,0
0,0,0,0,0,0,0,0,0,0,0
0,0,10,0,0,0,0,0,10,0,0
0,0,0,0,0,0,0,0,0,0,0
0,0,10,0,0,0,0,0,10,0,0
0,0,0,0,0,0,0,0,0,0,0
0,0,0,0,10,0,10,0,0,0,0
0,0,0,0,0,0,0,0,0,0,0
0,0,0,0,0,0,0,0,0,0,0
endlayer

layer
0,0,0,0,0,0,0,0,0,0,0
0,0,0,0,0,0,0,0,0,0,0
0,0,0,0,10,0,10,0,0,0,0
0,0,0,0,0,0,0,0,0,0,0
0,0,10,0,0,0,0,0,10,0,0
0,0,0,0,0,0,0,0,0,0,0
0,0,10,0,0,0,0,0,10,0,0
0,0,0,0,0,0,0,0,0,0,0
0,0,0,0,10,0,10,0,0,0,0
0,0,0,0,0,0,0,0,0,0,0
0,0,0,0,0,0,0,0,0,0,0
endlayer

layer
0,0,0,0,0,0,0,0,0,0,0
0,0,0,0,0,0,0,0,0,0,0
0,0,0,0,12,0,12,0,0,0,0
0,0,0,0,0,0,0,0,0,0,0
0,0,12,0,0,0,0,0,12,0,0
0,0,0,0,0,0,0,0,0,0,0
0,0,12,0,0,0,0,0,12,0,0
0,0,0,0,0,0,0,0,0,0,0
0,0,0,0,12,0,12,0,0,0,0
0,0,0,0,0,0,0,0,0,0,0
0,0,0,0,0,0,0,0,0,0,0
endlayer

layer
0,0,0,0,0,0,0,0,0,0,0
0,0,0,0,18,18,18,0,0,0,0
0,0,0,18,18,18,18,18,0,0,0
0,0,18,18,18,18,18,18,18,0,0
0,18,18,18,0,0,0,18,18,18,0
0,18,18,18,0,0,0,18,18,18,0
0,18,18,18,0,0,0,18,18,18,0
0,0,18,18,18,18,18,18,18,0,0
0,0,0,18,18,18,18,18,0,0,0
0,0,0,0,18,18,18,0,0,0,0
0,0,0,0,0,0,0,0,0,0,0
endlayer

layer
0,0,0,0,0,0,0,0,0,0,0
0,0,0,0,20,20,20,0,0,0,0
0,0,0,20,18,18,18,20,0,0,0
0,0,20,18,0,0,0,18,20,0,0
0,20,18,0,0,0,0,0,18,20,0
0,20,18,0,0,0,0,0,18,20,0
0,20,18,0,0,0,0,0,18,20,0
0,0,20,18,0,0,0,18,20,0,0
0,0,0,20,18,18,18,20,0,0,0
0,0,0,0,20,20,20,0,0,0,0
0,0,0,0,0,0,0,0,0,0,0
endlayer

layer
0,0,0,0,0,0,0,0,0,0,0
0,0,0,0,0,0,0,0,0,0,0
0,0,0,0,20,18,20,0,0,0,0
0,0,0,18,18,18,18,18,0,0,0
0,0,20,18,0,0,0,18,20,0,0
0,0,18,18,0,0,0,18,18,0,0
0,0,20,18,0,0,0,18,20,0,0
0,0,0,18,18,18,18,18,0,0,0
0,0,0,0,20,18,20,0,0,0,0
0,0,0,0,0,0,0,0,0,0,0
0,0,0,0,0,0,0,0,0,0,0
endlayer

layer
0,0,0,0,0,0,0,0,0,0,0
0,0,0,0,0,0,0,0,0,0,0
0,0,0,0,0,0,0,0,0,0,0
0,0,0,20,18,18,18,20,0,0,0
0,0,0,18,18,18,18,18,0,0,0
0,0,0,18,18,1,18,18,0,0,0
0,0,0,18,18,18,18,18,0,0,0
0,0,0,20,18,18,18,20,0,0,0
0,0,0,0,0,0,0,0,0,0,0
0,0,0,0,0,0,0,0,0,0,0
0,0,0,0,0,0,0,0,0,0,0
endlayer

layer
0,0,0,0,0,0,0,0,0,0,0
0,0,0,0,0,0,0,0,0,0,0
0,0,0,0,0,0,0,0,0,0,0
0,0,0,0,0,20,0,0,0,0,0
0,0,0,0,20,18,20,0,0,0,0
0,0,0,20,18,18,18,20,0,0,0
0,0,0,0,20,18,20,0,0,0,0
0,0,0,0,0,20,0,0,0,0,0
0,0,0,0,0,0,0,0,0,0,0
0,0,0,0,0,0,0,0,0,0,0
0,0,0,0,0,0,0,0,0,0,0
endlayer

