
# TreeGnarled (Oak)
# 11 Mar 2014; updated to MC 1.7.10, 10 Oct 2014
# Created by Ruins mod version 12.3 Ingame Parser
# authoring Player: Jordan_Greywolf

biomesToSpawnIn=cold taiga,enchanted forest,extreme hills,extreme hills edge,extreme hills m,extreme hills+,extreme hills+ m,flower forest,forest,foresthills,mega taiga,mega taiga hills,oak savanna,plains,roofed forest,roofed forest m,taiga,taiga m,taigahills,twilight clearing,twilight forest

weight=1
embed_into_distance=4

unacceptable_target_blocks=lava,flowing_lava

dimensions=12,13,13
allowable_overhang=50
max_cut_in=0
cut_in_buffer=0
max_leveling=0
leveling_buffer=0
preserve_water=0
preserve_lava=0
preserve_plants=1

rule1=0,100,PreserveBlock
rule2=0,100,minecraft:log-12
rule3=0,100,minecraft:leaves-0

layer
1,1,1,1,1,1,1,1,1,1,1,1,1
1,1,1,1,1,1,1,1,1,1,1,1,1
1,1,1,1,1,1,1,1,1,1,1,1,1
1,1,1,2,1,1,1,1,1,1,1,1,1
1,1,1,1,1,1,1,1,1,1,1,1,1
1,1,1,1,1,1,1,1,1,1,1,1,1
1,1,1,1,1,1,1,1,1,1,1,1,1
1,1,1,1,1,1,1,1,1,1,1,1,1
1,1,1,1,1,1,1,1,1,1,1,1,1
1,1,2,1,1,1,1,1,2,1,1,1,1
1,1,1,1,1,1,1,1,1,1,1,1,1
1,1,1,1,1,1,1,1,1,1,1,1,1
1,1,1,1,1,1,1,1,1,1,1,1,1
endlayer

layer
1,1,1,1,1,1,1,1,1,1,1,1,1
1,1,1,1,1,1,1,1,1,1,1,1,1
1,1,1,1,1,1,1,1,1,1,1,1,1
1,1,1,2,1,1,1,1,1,1,1,1,1
1,1,1,1,2,1,1,1,1,2,1,1,1
1,1,1,1,1,1,2,1,1,1,1,1,1
1,1,1,1,1,1,1,1,1,1,1,1,1
1,1,1,1,1,1,1,1,1,1,1,1,1
1,1,1,2,1,1,1,2,1,1,1,1,1
1,1,2,1,1,1,1,1,2,1,1,1,1
1,1,1,1,1,1,1,1,1,1,1,1,1
1,1,1,1,1,1,1,1,1,1,1,1,1
1,1,1,1,1,1,1,1,1,1,1,1,1
endlayer

layer
1,1,1,1,1,1,1,1,1,1,1,1,1
1,1,1,1,1,1,1,1,1,1,1,1,1
1,1,1,1,1,1,1,1,1,1,1,1,1
1,1,1,1,1,1,1,1,1,1,1,1,1
1,1,1,1,2,1,1,1,2,1,1,1,1
1,1,1,1,2,1,2,1,1,1,1,1,1
1,1,1,1,2,1,1,1,1,1,1,1,1
1,1,1,1,1,1,1,2,1,1,1,1,1
1,1,1,2,1,1,1,2,1,1,1,1,1
1,1,1,1,1,1,1,1,1,1,1,1,1
1,1,1,1,1,1,1,1,1,1,1,1,1
1,1,1,1,1,1,1,1,1,1,1,1,1
1,1,1,1,1,1,1,1,1,1,1,1,1
endlayer

layer
1,1,1,1,1,1,1,1,1,1,1,1,1
1,1,1,1,1,1,1,1,1,1,1,1,1
1,1,1,1,1,1,1,1,1,1,1,1,1
1,1,1,1,1,1,1,1,1,1,1,1,1
1,1,1,1,1,1,2,2,2,1,1,1,1
1,1,1,1,2,2,2,2,1,1,1,1,1
1,1,1,1,2,2,2,2,1,1,1,1,1
1,1,1,1,2,1,2,2,1,1,1,1,1
1,1,1,2,1,1,1,2,1,1,1,1,1
1,1,1,1,1,1,1,1,1,1,1,1,1
1,1,1,1,1,1,1,1,1,1,1,1,1
1,1,1,1,1,1,1,1,1,1,1,1,1
1,1,1,1,1,1,1,1,1,1,1,1,1
endlayer

layer
1,1,1,1,1,1,1,1,1,1,1,1,1
1,1,1,1,1,0,0,1,1,1,1,1,1
1,1,1,1,1,0,0,0,0,0,1,1,1
1,1,1,1,0,0,0,0,3,0,0,1,1
1,1,1,0,0,0,2,0,2,3,0,1,1
1,1,1,0,2,2,0,2,2,0,0,1,1
1,1,1,0,2,2,0,2,0,0,0,1,1
1,1,1,1,2,2,0,2,0,0,1,1,1
1,1,1,1,1,0,0,0,0,1,1,1,1
1,1,1,1,1,0,0,0,0,1,1,1,1
1,1,1,1,1,1,1,1,1,1,1,1,1
1,1,1,1,1,1,1,1,1,1,1,1,1
1,1,1,1,1,1,1,1,1,1,1,1,1
endlayer

layer
1,1,1,1,1,0,0,1,1,1,1,1,1
1,1,1,1,0,0,0,0,0,0,1,1,1
1,1,1,0,0,0,0,0,0,0,0,1,1
1,1,0,0,0,0,0,3,3,3,0,0,1
1,1,0,0,0,0,2,3,3,3,0,0,1
1,0,0,0,0,2,0,2,2,3,0,0,0
1,1,0,0,2,2,0,2,0,0,0,0,1
1,1,1,0,2,0,0,0,0,0,0,1,1
1,1,1,0,0,0,0,0,0,0,1,1,1
1,1,1,0,0,0,0,0,0,0,1,1,1
1,1,1,1,1,0,0,0,0,1,1,1,1
1,1,1,1,1,1,0,0,1,1,1,1,1
1,1,1,1,1,1,1,1,1,1,1,1,1
endlayer

layer
1,1,1,1,0,0,0,0,0,1,1,1,1
1,1,1,0,0,0,0,0,0,0,0,1,1
1,1,0,0,0,0,0,0,0,0,0,0,1
1,0,0,0,0,0,0,0,3,0,0,0,0
0,0,0,0,0,2,2,3,3,3,0,0,0
0,0,0,0,0,2,2,2,3,0,0,0,0
1,0,0,0,2,2,2,2,0,0,0,0,0
1,1,0,0,2,0,0,0,0,0,0,0,1
1,0,0,0,0,0,0,0,0,0,0,1,1
1,1,0,0,0,0,0,0,0,0,0,1,1
1,1,1,0,0,0,0,0,0,0,1,1,1
1,1,1,1,0,0,0,0,0,1,1,1,1
1,1,1,1,1,1,0,0,1,1,1,1,1
endlayer

layer
1,1,1,0,0,0,0,0,0,0,0,1,1
1,1,0,0,0,0,0,0,0,0,0,0,1
1,0,0,0,0,0,0,0,0,0,0,0,0
0,0,0,0,0,0,0,0,0,0,0,0,0
0,0,0,0,0,2,2,0,0,0,0,0,0
0,0,0,0,0,2,2,2,0,0,0,0,0
0,0,0,0,0,2,2,2,0,0,0,0,0
1,0,0,0,2,0,0,0,2,0,0,0,0
1,0,0,0,0,0,0,0,0,0,0,0,0
0,0,0,0,0,0,0,0,0,0,0,0,1
1,0,0,0,0,0,0,0,0,0,0,0,1
1,1,0,0,0,0,0,0,0,0,0,1,1
1,1,1,1,0,0,0,0,0,0,1,1,1
endlayer

layer
1,1,0,0,0,0,0,0,0,0,0,0,1
1,0,0,0,0,0,0,0,0,0,0,0,0
0,0,0,0,0,0,0,0,0,3,0,0,0
0,0,0,3,3,0,3,0,0,3,0,0,0
0,0,3,3,3,2,2,0,2,0,0,0,0
0,0,0,3,3,2,2,2,0,0,0,0,0
0,0,0,0,0,0,2,0,0,0,0,0,0
0,0,3,0,2,0,0,0,2,0,0,0,0
0,3,3,2,0,0,0,0,0,2,0,0,0
0,0,3,0,0,0,0,0,3,3,3,0,0
0,0,0,0,0,0,0,0,3,3,3,0,0
1,0,0,0,0,0,0,0,0,3,0,0,1
1,1,0,0,0,0,0,0,0,0,0,1,1
endlayer

layer
1,0,0,0,0,0,0,0,0,3,0,0,0
0,0,0,0,0,0,0,0,3,3,3,0,0
0,0,0,3,3,3,0,3,3,2,3,3,0
0,0,3,3,3,3,3,3,3,2,3,3,0
0,3,3,2,2,2,3,3,2,3,3,0,0
0,0,3,3,3,3,3,3,3,3,0,0,0
0,0,3,3,3,3,0,0,3,3,0,0,0
0,3,3,3,3,0,0,0,3,3,3,0,0
3,3,2,2,3,3,0,3,3,2,3,3,0
0,3,3,3,3,0,0,3,3,2,3,3,0
0,0,3,3,0,0,0,3,3,2,3,3,0
0,0,0,0,0,0,0,0,3,3,3,0,0
1,0,0,0,0,0,0,0,0,3,0,0,1
endlayer

layer
0,0,0,0,0,0,0,0,0,0,0,0,0
0,0,0,0,0,0,0,0,0,3,0,0,0
0,0,0,0,0,0,0,0,3,3,3,0,0
0,0,0,3,3,3,0,0,3,3,3,0,0
0,0,3,3,3,3,3,3,3,3,0,0,0
0,0,0,3,3,3,0,0,3,0,0,0,0
0,0,0,0,0,0,0,0,0,0,0,0,0
0,0,3,3,0,0,0,0,0,3,0,0,0
0,3,3,3,3,0,0,0,3,3,3,0,0
0,3,3,2,3,3,0,0,3,3,3,0,0
0,0,3,3,3,0,0,0,3,3,3,0,0
0,0,0,3,0,0,0,0,0,3,0,0,0
0,0,0,0,0,0,0,0,0,0,0,0,0
endlayer

layer
0,0,0,0,0,0,0,0,0,0,0,0,0
0,0,0,0,0,0,0,0,0,0,0,0,0
0,0,0,0,0,0,0,0,0,0,0,0,0
0,0,0,0,0,0,0,0,0,0,0,0,0
0,0,0,0,0,0,0,0,0,0,0,0,0
0,0,0,0,0,0,0,0,0,0,0,0,0
0,0,0,0,0,0,0,0,0,0,0,0,0
0,0,0,0,0,0,0,0,0,0,0,0,0
0,0,0,3,0,0,0,0,0,0,0,0,0
0,0,3,3,3,0,0,0,0,0,0,0,0
0,0,0,3,0,0,0,0,0,0,0,0,0
0,0,0,0,0,0,0,0,0,0,0,0,0
0,0,0,0,0,0,0,0,0,0,0,0,0
endlayer

