
# ForestPool
# 7 Mar 2014; updated to MC 1.7.10, 9 Oct 2014
# Created by Ruins mod version 12.3 Ingame Parser
# authoring Player: Jordan_Greywolf

biomesToSpawnIn=enchanted forest,extreme hills edge,flower forest,forest,foresthills,oak savanna,plains,sunflower plains,taiga,taigahills,twilight clearing

weight=1
embed_into_distance=4
#acceptable_target_blocks=stone,grass,dirt,sand,snow,snow_layer
unacceptable_target_blocks=lava,flowing_lava
dimensions=13,12,12
allowable_overhang=15
max_cut_in=0
cut_in_buffer=0
max_leveling=0
leveling_buffer=0
preserve_water=0
preserve_lava=0
preserve_plants=1

rule1=0,100,preserveBlock
rule2=0,100,minecraft:log-0
rule3=0,100,minecraft:dirt-0
rule4=0,100,minecraft:flowing_water
rule5=0,100,minecraft:grass-0
rule6=0,100,minecraft:log-8
rule7=0,100,minecraft:log-4
rule8=0,100,minecraft:log-12
rule9=0,100,minecraft:tallgrass-1,minecraft:tallgrass-1,minecraft:tallgrass-2,0,minecraft:red_flower,minecraft:yellow_flower
rule10=0,100,minecraft:leaves-0

layer
1,1,1,1,1,1,1,1,1,1,1,1
1,2,1,1,1,1,1,1,1,1,1,1
1,1,1,1,3,1,3,3,3,1,1,1
1,1,1,1,3,3,3,4,2,3,1,1
1,1,1,3,3,4,4,3,3,1,1,1
1,1,1,3,3,4,4,4,3,1,1,1
1,1,1,3,4,4,4,3,3,1,1,1
1,1,3,3,4,4,4,3,1,1,1,1
1,1,3,3,3,3,3,3,1,1,1,1
1,1,2,1,1,1,3,1,1,1,1,1
1,1,1,1,1,1,1,1,1,1,1,1
1,1,1,1,1,1,1,1,1,1,1,1
endlayer

layer
1,1,1,1,1,1,1,1,1,2,1,1
1,2,1,1,1,1,3,1,1,1,1,1
1,1,1,3,3,1,2,5,2,1,1,1
1,1,3,3,4,3,4,4,2,2,1,1
1,1,3,3,4,4,4,4,3,1,1,1
1,1,3,4,4,4,4,4,3,3,1,1
1,1,3,4,4,4,4,4,3,1,1,1
1,1,3,4,4,4,4,4,3,1,1,1
1,1,3,4,4,4,4,3,3,1,1,1
1,2,2,3,3,3,3,3,1,1,1,1
1,1,2,1,1,3,1,1,1,1,1,1
1,1,1,1,1,1,1,1,1,1,1,1
endlayer

layer
1,2,1,1,1,1,1,3,1,2,1,1
2,2,3,1,3,1,3,3,3,1,1,1
1,3,3,3,3,3,2,1,2,2,1,1
1,3,3,3,4,4,4,4,2,2,2,1
1,1,3,4,4,4,4,4,3,3,3,1
1,3,3,4,4,4,4,4,3,3,3,1
1,1,3,4,4,4,4,4,4,3,1,1
1,3,4,4,4,4,4,4,4,3,1,1
1,3,4,4,4,4,4,4,4,3,1,1
1,2,2,4,4,4,4,3,3,1,1,1
1,2,2,2,3,3,3,1,1,1,1,1
1,1,1,1,1,3,1,1,1,1,1,1
endlayer

layer
2,2,5,5,1,1,1,5,5,2,1,1
2,2,6,5,4,5,5,5,5,2,1,1
5,7,5,5,4,6,2,2,2,2,5,1
1,5,5,5,4,4,4,4,2,2,2,1
1,5,5,4,4,4,4,4,7,2,5,5
1,4,4,4,4,4,4,4,5,5,5,5
5,5,4,4,4,4,4,4,4,5,5,5
5,7,4,4,4,4,4,4,4,4,1,1
5,7,5,4,4,4,4,4,4,5,5,1
5,2,2,5,4,4,4,4,5,5,1,1
1,2,2,2,5,4,4,5,5,1,1,1
1,7,5,5,5,5,1,5,1,1,1,1
endlayer

layer
2,2,9,9,0,0,0,9,9,8,0,0
2,2,0,9,0,9,9,9,9,2,0,0
0,8,9,9,0,0,8,2,2,2,9,0
0,9,9,9,0,0,0,0,2,2,8,0
0,9,9,0,0,0,0,0,0,2,9,9
0,0,0,0,0,0,0,0,9,9,9,9
9,9,0,0,0,0,0,0,0,9,9,9
9,0,0,0,0,0,0,0,0,0,0,0
9,8,9,0,0,0,0,0,0,9,9,0
9,2,2,9,0,0,0,0,9,9,0,0
0,2,2,8,9,0,0,9,9,0,0,0
0,0,9,9,9,9,0,9,0,0,0,0
endlayer

layer
8,2,0,0,0,0,0,0,0,0,0,0
2,2,0,0,0,0,0,0,0,8,0,0
0,0,0,0,0,0,0,8,2,2,0,0
0,0,0,0,0,0,0,0,2,2,0,0
0,0,0,0,0,0,0,0,0,8,0,0
0,0,0,0,0,0,0,0,0,0,0,0
0,0,0,0,0,0,0,0,0,0,0,0
0,0,0,0,0,0,0,0,0,0,0,0
0,0,0,0,0,0,0,0,0,0,0,0
0,2,2,0,0,0,0,0,0,0,0,0
0,2,2,0,0,0,0,0,0,0,0,0
0,0,0,0,0,0,0,0,0,0,0,0
endlayer

layer
10,8,0,0,0,0,0,0,0,0,0,0
8,2,8,0,0,0,0,0,0,0,0,0
0,8,0,0,0,0,0,0,2,8,0,0
0,0,0,0,0,0,0,0,2,2,0,0
0,0,0,0,0,0,0,0,0,0,0,0
0,0,0,0,0,0,0,0,0,0,0,0
0,0,0,0,0,0,0,0,0,0,0,0
0,0,0,0,0,0,0,0,0,0,0,0
0,0,0,0,0,0,0,0,0,0,0,0
0,2,2,10,0,0,0,0,0,0,0,0
0,8,2,0,0,0,0,0,0,0,0,0
0,0,0,0,0,0,0,0,0,0,0,0
endlayer

layer
0,10,0,0,0,0,0,0,0,0,0,0
10,2,2,0,10,0,0,0,0,0,0,0
10,8,0,10,10,10,0,0,2,0,0,0
0,7,0,0,10,0,0,0,2,8,0,0
0,8,0,0,0,0,0,0,0,0,0,0
0,0,0,0,0,0,0,0,0,0,0,0
0,0,0,0,0,0,0,0,0,0,0,0
0,0,0,0,0,0,0,0,0,0,0,0
0,0,0,10,0,0,0,0,0,0,0,0
0,2,2,10,10,0,0,0,0,0,0,0
0,0,8,10,0,0,0,0,0,0,0,0
0,0,0,0,0,0,0,0,0,0,0,0
endlayer

layer
0,0,10,0,0,0,0,0,0,0,0,0
0,2,8,6,10,0,0,0,0,0,0,0
0,0,0,10,6,10,0,0,8,0,0,0
0,0,0,10,10,10,0,0,8,0,0,0
10,10,10,0,0,0,0,0,7,0,0,0
10,7,10,0,0,0,0,0,7,0,0,0
10,10,10,0,0,0,0,10,10,10,0,0
0,0,0,0,0,0,0,0,10,0,0,0
10,10,8,8,0,0,0,0,0,0,0,0
10,8,8,8,10,0,0,0,0,0,0,0
10,10,10,0,0,0,0,0,0,0,0,0
0,0,0,0,0,0,0,0,0,0,0,0
endlayer

layer
0,0,0,0,0,0,0,0,10,10,0,0
0,8,10,0,10,0,0,10,10,10,10,0
0,10,2,10,10,10,10,6,10,10,10,0
0,10,10,10,10,10,0,10,10,10,0,0
0,10,10,10,0,10,0,0,10,10,0,0
10,10,10,0,10,10,10,0,10,10,10,0
0,10,10,10,10,10,10,10,7,10,10,0
10,10,10,8,0,10,0,10,10,10,10,0
10,10,10,8,8,10,10,10,0,0,0,0
10,10,10,10,10,0,0,0,0,0,0,0
0,0,0,0,0,0,0,0,0,0,0,0
0,0,0,0,0,0,0,0,0,0,0,0
endlayer

layer
0,0,0,0,0,0,0,0,0,0,0,0
0,0,10,10,0,0,0,0,10,10,0,0
0,10,2,10,0,10,10,10,10,10,0,0
0,10,10,10,10,10,8,10,0,0,0,0
0,0,10,10,10,10,10,10,0,0,0,0
0,0,10,10,7,10,10,10,10,0,0,0
0,0,0,10,7,10,10,10,10,10,0,0
0,0,10,10,10,10,10,10,10,0,0,0
0,0,10,10,10,6,10,10,0,0,0,0
0,0,0,10,10,10,10,10,0,0,0,0
0,0,0,0,0,10,10,0,0,0,0,0
0,0,0,0,0,0,0,0,0,0,0,0
endlayer

layer
0,0,0,0,0,0,0,0,0,0,0,0
0,0,10,10,0,0,0,0,0,0,0,0
0,10,10,10,0,10,10,10,0,0,0,0
0,10,10,10,10,10,10,10,0,0,0,0
0,0,0,10,10,10,10,10,0,0,0,0
0,0,0,0,10,10,10,10,0,0,0,0
0,0,0,0,10,10,10,0,0,0,0,0
0,0,0,10,10,10,10,0,0,0,0,0
0,0,0,10,10,10,10,0,0,0,0,0
0,0,0,0,10,10,10,0,0,0,0,0
0,0,0,0,0,0,0,0,0,0,0,0
0,0,0,0,0,0,0,0,0,0,0,0
endlayer

layer
0,0,0,0,0,0,0,0,0,0,0,0
0,0,0,0,0,0,0,0,0,0,0,0
0,0,10,0,0,0,10,0,0,0,0,0
0,0,10,0,0,10,10,10,0,0,0,0
0,0,0,0,0,0,10,0,0,0,0,0
0,0,0,0,10,0,0,0,0,0,0,0
0,0,0,0,0,0,0,0,0,0,0,0
0,0,0,0,0,0,0,0,0,0,0,0
0,0,0,0,10,10,10,0,0,0,0,0
0,0,0,0,0,10,0,0,0,0,0,0
0,0,0,0,0,0,0,0,0,0,0,0
0,0,0,0,0,0,0,0,0,0,0,0
endlayer

