
# Wood House Foundation (28 Mar 2014; MC 1.5.*)
# Updated to MC 1.7.10, 11 Oct 2014
# authoring Player: Jordan_Greywolf

biomesToSpawnIn=birch forest,dead forest,field,forest,frost forest,jungle,lavender fields,meadow,orchard,plains,prairie,savanna,spruce forest,snow forest,snowy forest,snowy coniferous forest,snowy dead forest,snowy rainforest,tundra

weight=1
embed_into_distance=4

acceptable_target_blocks=1,2,3,4,5,7,12,13,24,31,32,37,38,39,40,78,79,80,82,87,88,89,254,903,908,909,911,922,958,966,971,1003,1004,1005,1014,1101,1102,1182,1226,1233,1239,1241,1290,1317,1318,1319,1320,2011

dimensions=9,8,7
allowable_overhang=50
max_cut_in=0
cut_in_buffer=0
max_leveling=0
leveling_buffer=0
preserve_water=0
preserve_lava=0
preserve_plants=1

#Terrain Blending
rule01=0,100,PreserveBlock

#Stone Floor
rule02=0,100,minecraft:stone

#Foundation (mossy cobblestone)
rule03=0,100,minecraft:mossy_cobblestone

#Intact Fireplace (brick)
rule04=0,100,minecraft:brick_block

#Ruined Chimney (brick)
rule05=1,75,minecraft:brick_block

#Fireplace Slope - ascend E
rule06=0,100,minecraft:brick_stairs-0

#Fireplace Slope - ascend W
rule07=0,100,minecraft:brick_stairs-1

#Decayed Floor (spruce plank/grass)
rule08=0,100,minecraft:planks-1,minecraft:wooden_slab-1,minecraft:grass

#Fireplace Base (netherrack)
rule09=0,100,minecraft:netherrack

#Buried Treasure/Trouble
rule10=0,100,MobSpawner:Creeper,MediumChest,minecraft:emerald_ore,minecraft:tnt-1,minecraft:bookshelf,minecraft:iron_ore

#Ruined Cobble (mossy/cobblestone)
rule11=1,75,minecraft:cobblestone,minecraft:mossy_cobblestone

#Ruined Wood (oak)
rule12=1,75,minecraft:planks-0

# ------------------------------

# Basement Floor (-4)
layer
01,01,04,04,04,01,01
03,03,04,04,04,03,03
03,02,02,02,02,02,03
03,02,02,02,02,02,03
03,02,02,02,02,02,03
03,02,02,02,02,02,03
03,02,02,02,02,02,03
03,03,03,03,03,03,03
endlayer


# Basement (-3)
layer
01,01,04,04,04,01,01
03,03,04,04,04,03,03
03,01,04,10,04,01,03
03,01,01,01,01,01,03
03,10,01,00,01,10,03
03,01,00,01,00,01,03
03,01,01,10,01,01,03
03,03,03,03,03,03,03
endlayer


# Basement (-2)
layer
01,01,04,04,04,01,01
03,03,04,04,04,03,03
03,01,04,01,04,01,03
03,01,01,01,01,01,03
03,01,01,00,01,01,03
03,01,00,01,00,01,03
03,01,01,01,01,01,03
03,03,03,03,03,03,03
endlayer


# Floor (-1)
layer
01,01,04,04,04,01,01
03,03,04,09,04,03,03
03,08,04,04,04,08,03
03,08,08,08,08,08,03
03,08,08,08,08,08,03
03,08,08,08,08,08,03
03,08,08,08,08,08,03
03,03,03,03,03,03,03
endlayer

# Aboveground (1)
layer
01,01,04,04,04,01,01
11,12,04,01,04,12,11
12,00,00,01,00,00,12
12,00,00,00,00,00,12
12,01,00,00,00,01,12
01,01,00,00,00,01,01
12,01,00,00,00,01,12
11,12,12,12,12,12,11
endlayer

# Aboveground (2)
layer
01,01,04,04,04,01,01
11,12,04,01,04,12,11
12,00,00,00,00,00,12
00,00,00,00,00,00,00
12,00,00,00,00,00,12
01,00,00,00,00,00,01
12,00,00,00,00,00,12
11,12,12,12,12,12,11
endlayer

# Aboveground (3)
layer
01,01,06,04,07,01,01
11,12,04,04,04,12,11
12,00,00,00,00,00,12
00,00,00,00,00,00,00
12,00,00,00,00,00,12
00,00,00,00,00,00,00
12,00,00,00,00,00,12
11,12,12,12,12,12,11
endlayer

# Aboveground (4)
layer
01,00,00,05,00,00,01
11,12,12,05,12,12,11
12,00,00,00,00,00,12
00,00,00,00,00,00,00
12,00,00,00,00,00,12
00,00,00,00,00,00,00
12,00,00,00,00,00,12
11,12,12,12,12,12,11
endlayer

# Aboveground (5)
layer
00,00,00,05,00,00,00
11,00,00,05,00,00,11
00,00,00,00,00,00,00
00,00,00,00,00,00,00
00,00,00,00,00,00,00
00,00,00,00,00,00,00
00,00,00,00,00,00,00
11,00,00,00,00,00,11
endlayer


