
# Lodge_1v7v10 
# 15 Mar 2014 -- updated to 1.7.10 - 7 Oct 2014
# Created by Ruins mod version 12.3 Ingame Parser
# authoring Player: Jordan_Greywolf

biomesToSpawnIn=birch forest,birch forest hills,birch forest hills m,birch forest m,cold taiga,cold taiga hills,cold taiga m,dark forest,enchanted forest,extreme hills edge,extreme hills,extreme hills m,extreme hills+,extreme hills+ m,flower forest,forest,highlands,highlands center,ice plains,mega spruce taiga,mega taiga,mega taiga hills,oak savanna,roofed forest,snowy forest,snow forest,taiga,taiga m,taigahills

weight=1
embed_into_distance=5

# acceptable_target_blocks=stone,grass,dirt,sand,gravel,snow,snow_layer,clay
unacceptable_target_blocks=lava,flowing_lava,water,flowing_water

dimensions=16,19,10
allowable_overhang=15
max_cut_in=0
cut_in_buffer=0
max_leveling=0
leveling_buffer=0
preserve_water=0
preserve_lava=0
preserve_plants=1

rule1=0,100,PreserveBlock
rule2=0,100,minecraft:mossy_cobblestone-0,minecraft:cobblestone-0
rule3=0,100,minecraft:netherrack-0
rule4=0,100,minecraft:log-1
rule5=0,100,minecraft:planks-1
rule6=0,100,minecraft:planks-2
rule7=0,100,minecraft:stone_slab-3
rule8=0,100,minecraft:fire-15
rule9=0,100,minecraft:oak_stairs-0
rule10=0,100,minecraft:iron_bars-0
rule11=0,100,minecraft:oak_stairs-2
rule12=0,100,minecraft:cobblestone_wall-1
rule13=0,100,minecraft:oak_stairs-3
rule14=0,100,minecraft:bookshelf-0
rule15=0,100,minecraft:flower_pot-1,minecraft:flower_pot-0
rule16=0,100,minecraft:web-0
rule17=0,100,minecraft:spruce_stairs-3
rule18=0,100,minecraft:fence-0
rule19=0,100,minecraft:spruce_stairs-2
rule20=0,100,minecraft:oak_stairs-1
rule21=1,100,minecraft:wooden_door-2
rule22=0,100,minecraft:stone_stairs-2
rule23=0,100,minecraft:stone_stairs-3
rule24=0,100,minecraft:carpet-14
rule25=0,100,minecraft:carpet-0
rule26=1,100,minecraft:wooden_door-9
rule27=1,100,minecraft:wooden_door-8
rule28=0,100,minecraft:stone_stairs-6
rule29=0,100,minecraft:stone_stairs-7
rule30=0,100,minecraft:log-9
rule31=0,100,minecraft:log-5
rule32=0,100,Skull:0:6-1
rule33=1,100,minecraft:redstone_torch-5
rule34=0,100,minecraft:stonebrick-3
rule35=0,100,minecraft:stone_stairs-0

layer
1,1,1,2,2,2,2,1,1,1
1,1,1,2,3,3,2,1,1,1
1,4,2,2,2,2,2,2,4,1
1,2,4,2,2,2,2,4,2,1
1,2,6,5,6,5,6,5,2,1
1,2,5,6,5,6,5,6,2,1
1,2,6,5,6,5,6,5,2,1
1,2,5,6,5,6,5,6,2,1
1,2,6,5,6,5,6,5,2,1
1,2,5,6,5,6,5,6,2,1
1,2,6,5,6,5,6,5,2,1
1,2,5,6,5,6,5,6,2,1
1,2,6,5,6,5,6,5,2,1
1,2,5,6,5,6,5,6,2,1
1,2,6,5,6,5,6,5,2,1
1,2,4,6,5,6,5,4,2,1
1,4,2,2,2,2,2,2,4,1
1,1,1,1,2,2,1,1,1,1
1,1,1,1,2,2,1,1,1,1
endlayer

layer
1,1,1,2,2,2,2,1,1,1
1,1,1,2,3,3,2,1,1,1
1,4,2,2,2,2,2,2,4,1
1,2,4,2,2,2,2,4,2,1
1,2,0,0,0,0,0,0,2,1
1,2,0,0,0,0,0,0,2,1
1,2,0,0,0,0,0,0,2,1
1,2,0,0,0,0,0,0,2,1
1,2,0,0,0,0,0,0,2,1
1,2,0,0,0,0,0,0,2,1
1,2,0,0,0,0,0,0,2,1
1,2,0,0,0,0,0,0,2,1
1,2,0,0,0,0,0,0,2,1
1,2,0,0,0,0,0,0,2,1
1,2,0,0,0,0,0,0,2,1
1,2,0,0,0,0,0,0,2,1
1,4,2,2,2,2,2,2,4,1
1,1,1,1,2,2,1,1,1,1
1,1,1,1,2,2,1,1,1,1
endlayer

layer
1,1,1,2,2,2,2,1,1,1
1,1,1,2,3,3,2,1,1,1
1,4,2,2,2,2,2,2,4,1
1,2,4,2,2,2,2,4,2,1
1,2,0,0,0,0,0,0,2,1
1,2,0,0,0,0,0,0,2,1
1,2,0,0,0,0,0,0,2,1
1,2,0,0,0,0,0,0,2,1
1,2,0,0,0,0,0,0,2,1
1,2,0,0,0,0,0,0,2,1
1,2,0,0,0,0,0,0,2,1
1,2,0,0,0,0,0,0,2,1
1,2,0,0,0,0,0,0,2,1
1,2,0,0,0,0,0,0,2,1
1,2,0,0,0,0,0,0,2,1
1,2,0,0,0,0,0,0,2,1
1,4,2,2,2,2,2,2,4,1
1,1,1,1,2,2,1,1,1,1
1,1,1,1,2,2,1,1,1,1
endlayer


layer
1,1,1,2,2,2,2,1,1,1
1,1,1,2,3,3,2,1,1,1
1,4,2,2,2,2,2,2,4,1
1,2,4,2,2,2,2,4,2,1
1,2,0,0,0,0,0,0,2,1
1,2,0,0,0,0,0,0,2,1
1,2,0,0,0,0,0,0,2,1
1,2,0,0,0,0,0,0,2,1
1,2,0,0,0,0,0,0,2,1
1,2,0,0,0,0,0,0,2,1
1,2,0,0,0,0,0,0,2,1
1,2,0,0,0,0,0,0,2,1
1,2,0,0,0,0,0,0,2,1
1,2,0,0,0,0,0,0,2,1
1,2,0,0,0,0,0,0,2,1
1,2,0,0,0,0,0,0,2,1
1,4,2,2,2,2,2,2,4,1
1,1,1,1,2,2,1,1,1,1
1,1,1,1,1,1,1,1,1,1
endlayer


layer
1,1,1,2,2,2,2,1,1,1
1,1,1,2,3,3,2,1,1,1
1,4,2,2,2,2,2,2,4,1
1,2,4,2,2,2,2,4,2,1
1,2,6,5,6,5,6,5,2,1
1,2,5,6,5,6,5,6,2,1
1,2,6,5,6,5,6,5,2,1
1,2,5,6,5,6,5,6,2,1
1,2,6,5,6,5,6,5,2,1
1,4,5,6,5,6,5,6,4,1
1,2,6,5,6,5,6,5,2,1
1,2,5,6,5,6,5,6,2,1
1,2,6,5,6,5,6,5,2,1
1,2,5,6,5,6,5,6,2,1
1,2,6,5,6,5,6,5,2,1
1,2,4,6,5,6,5,4,2,1
1,4,2,2,2,2,2,2,4,1
1,1,1,1,7,7,1,1,1,1
1,1,1,1,7,7,1,1,1,1
endlayer

layer
1,1,1,2,2,2,2,1,1,1
1,1,1,2,8,8,2,1,1,1
1,4,9,2,10,10,2,9,4,1
1,13,4,12,0,0,12,4,11,1
1,13,14,0,0,0,0,14,11,1
1,13,14,0,0,0,0,14,11,1
1,13,15,0,0,0,0,15,11,1
0,13,0,0,0,0,0,0,11,0
0,13,16,19,18,18,17,16,11,0
0,4,0,0,18,18,0,0,4,0
0,13,16,19,18,18,17,16,11,0
0,13,0,0,18,18,0,0,11,0
1,13,16,19,18,18,17,16,11,1
1,13,0,0,0,0,0,0,11,1
1,13,0,0,0,0,0,0,11,1
1,13,4,0,0,0,0,4,11,1
1,4,20,4,21,21,4,20,4,1
1,1,1,0,0,0,0,1,1,1
1,1,1,1,0,0,1,1,1,1
endlayer

layer
1,1,1,23,2,2,22,1,1,1
1,1,0,2,0,0,2,0,1,1
1,4,9,2,10,10,2,9,4,1
1,13,4,0,0,0,0,4,11,1
0,13,14,0,0,0,0,14,11,0
0,13,14,0,0,0,0,14,11,0
0,13,16,0,0,0,0,16,11,0
0,13,0,0,0,0,0,0,11,0
0,13,0,0,24,24,0,0,11,0
0,4,0,0,25,25,0,0,4,0
0,13,0,0,24,24,0,0,11,0
0,13,0,0,25,25,0,0,11,0
0,13,0,0,24,24,0,0,11,0
0,13,0,0,0,0,0,0,11,0
0,13,0,0,0,0,0,0,11,1
1,13,4,18,0,0,18,4,11,1
1,4,20,4,27,26,4,20,4,1
1,1,0,18,0,0,18,0,1,1
1,1,1,0,0,0,0,1,1,1
endlayer

layer
1,1,0,29,2,2,28,0,1,1
1,0,0,2,0,0,2,0,0,1
0,4,30,2,28,29,2,30,4,1
0,31,4,0,0,0,0,4,31,0
0,31,16,0,0,0,0,16,31,0
0,31,16,0,0,0,0,32,31,0
0,31,0,0,0,0,0,0,31,0
0,31,0,0,0,0,0,0,31,0
0,31,0,0,0,0,0,0,31,0
0,4,0,0,0,0,0,0,4,0
0,31,0,0,0,0,0,0,31,0
0,31,0,0,0,0,0,0,31,0
0,31,0,0,0,0,0,0,31,0
0,31,0,0,0,0,0,0,31,0
0,31,0,0,0,0,0,0,31,0
0,31,4,33,0,0,33,4,31,1
0,4,30,30,30,30,30,30,4,1
1,0,0,33,0,0,33,0,0,1
1,1,0,0,0,0,0,0,1,1
endlayer

layer
1,0,0,2,2,2,2,0,0,1
0,0,0,2,0,0,2,0,0,0
18,4,9,34,2,2,34,9,4,18
0,13,4,0,0,0,0,4,11,0
0,4,16,0,0,0,0,16,4,0
0,18,0,0,0,0,0,0,18,0
0,18,16,0,0,0,0,0,18,0
0,4,0,0,0,0,0,0,4,0
0,18,0,0,0,0,0,0,18,0
18,4,0,0,0,0,0,0,4,18
0,18,0,0,0,0,0,0,18,0
0,4,0,0,0,0,0,0,4,0
0,18,0,0,0,0,0,0,18,0
0,18,0,0,0,0,0,0,18,0
0,4,16,0,0,0,0,16,4,0
0,13,4,0,0,0,0,4,11,0
18,4,20,4,20,20,4,20,4,18
0,0,0,0,0,0,0,0,0,0
1,0,0,0,0,0,0,0,0,1
endlayer

layer
0,0,0,35,35,35,35,0,0,0
0,18,0,2,0,0,2,0,18,0
17,31,30,4,2,2,4,30,31,19
17,31,4,16,0,0,16,4,31,19
17,31,16,0,0,0,0,16,31,19
17,31,16,0,0,0,0,16,31,19
17,31,16,0,0,0,0,16,31,19
17,31,16,0,0,0,0,16,31,19
17,31,16,0,18,18,0,16,31,19
17,31,16,18,18,18,18,16,31,19
17,31,16,0,18,18,0,16,31,19
17,31,16,0,0,0,0,16,31,19
17,31,16,0,0,0,0,16,31,19
17,31,16,0,0,0,0,16,31,19
17,31,16,0,0,0,0,16,31,19
17,31,4,16,0,0,16,4,31,19
17,31,30,4,20,20,4,30,31,19
0,18,0,0,0,0,0,0,18,0
0,0,0,0,0,0,0,0,0,0
endlayer

layer
0,0,18,0,0,0,0,18,0,0
0,17,31,23,2,2,22,31,19,0
0,17,31,30,2,2,30,31,19,0
0,17,31,16,16,16,16,31,19,0
0,17,31,16,0,0,16,31,19,0
0,17,31,16,0,0,16,31,19,0
0,17,31,16,0,0,16,31,19,0
0,17,31,16,0,0,16,31,19,0
0,17,31,0,33,33,16,31,19,0
0,17,31,33,18,18,33,31,19,0
0,17,31,16,33,33,16,31,19,0
0,17,31,16,0,0,16,31,19,0
0,17,31,16,0,0,16,31,19,0
0,17,31,16,0,0,16,31,19,0
0,17,31,16,0,0,16,31,19,0
0,17,31,16,16,16,16,31,19,0
0,17,31,30,20,20,30,31,19,0
0,17,31,0,0,0,0,31,19,0
0,0,18,0,0,0,0,18,0,0
endlayer

layer
0,0,17,31,0,0,31,19,0,0
0,0,17,31,2,2,31,19,0,0
0,0,17,31,30,30,31,19,0,0
0,0,17,31,16,16,31,19,0,0
0,0,17,31,16,16,31,19,0,0
0,0,17,31,16,16,31,19,0,0
0,0,17,31,16,16,31,19,0,0
0,0,17,31,16,16,31,19,0,0
0,0,17,31,16,16,31,19,0,0
0,0,17,31,18,18,31,19,0,0
0,0,17,31,16,16,31,19,0,0
0,0,17,31,16,16,31,19,0,0
0,0,17,31,16,16,31,19,0,0
0,0,17,31,16,16,31,19,0,0
0,0,17,31,16,16,31,19,0,0
0,0,17,31,16,16,31,19,0,0
0,0,17,31,30,30,31,19,0,0
0,0,17,31,0,0,31,19,0,0
0,0,17,31,0,0,31,19,0,0
endlayer

layer
0,0,0,17,31,31,19,0,0,0
0,0,0,17,2,2,19,0,0,0
0,0,0,17,31,31,19,0,0,0
0,0,0,17,31,31,19,0,0,0
0,0,0,17,31,31,19,0,0,0
0,0,0,17,31,31,19,0,0,0
0,0,0,17,31,31,19,0,0,0
0,0,0,17,31,31,19,0,0,0
0,0,0,17,31,31,19,0,0,0
0,0,0,17,31,31,19,0,0,0
0,0,0,17,31,31,19,0,0,0
0,0,0,17,31,31,19,0,0,0
0,0,0,17,31,31,19,0,0,0
0,0,0,17,31,31,19,0,0,0
0,0,0,17,31,31,19,0,0,0
0,0,0,17,31,31,19,0,0,0
0,0,0,17,31,31,19,0,0,0
0,0,0,17,31,31,19,0,0,0
0,0,0,17,31,31,19,0,0,0
endlayer

layer
0,0,0,0,17,19,0,0,0,0
0,0,0,0,2,2,0,0,0,0
0,0,0,0,17,19,0,0,0,0
0,0,0,0,17,19,0,0,0,0
0,0,0,0,17,19,0,0,0,0
0,0,0,0,17,19,0,0,0,0
0,0,0,0,17,19,0,0,0,0
0,0,0,0,17,19,0,0,0,0
0,0,0,0,17,19,0,0,0,0
0,0,0,0,17,19,0,0,0,0
0,0,0,0,17,19,0,0,0,0
0,0,0,0,17,19,0,0,0,0
0,0,0,0,17,19,0,0,0,0
0,0,0,0,17,19,0,0,0,0
0,0,0,0,17,19,0,0,0,0
0,0,0,0,17,19,0,0,0,0
0,0,0,0,17,19,0,0,0,0
0,0,0,0,17,19,0,0,0,0
0,0,0,0,17,19,0,0,0,0
endlayer

layer
0,0,0,0,0,0,0,0,0,0
0,0,0,0,2,2,0,0,0,0
0,0,0,0,0,0,0,0,0,0
0,0,0,0,0,0,0,0,0,0
0,0,0,0,0,0,0,0,0,0
0,0,0,0,0,0,0,0,0,0
0,0,0,0,0,0,0,0,0,0
0,0,0,0,0,0,0,0,0,0
0,0,0,0,0,0,0,0,0,0
0,0,0,0,0,0,0,0,0,0
0,0,0,0,0,0,0,0,0,0
0,0,0,0,0,0,0,0,0,0
0,0,0,0,0,0,0,0,0,0
0,0,0,0,0,0,0,0,0,0
0,0,0,0,0,0,0,0,0,0
0,0,0,0,0,0,0,0,0,0
0,0,0,0,0,0,0,0,0,0
0,0,0,0,0,0,0,0,0,0
0,0,0,0,0,0,0,0,0,0
endlayer

layer
0,0,0,0,0,0,0,0,0,0
0,0,0,0,12,12,0,0,0,0
0,0,0,0,0,0,0,0,0,0
0,0,0,0,0,0,0,0,0,0
0,0,0,0,0,0,0,0,0,0
0,0,0,0,0,0,0,0,0,0
0,0,0,0,0,0,0,0,0,0
0,0,0,0,0,0,0,0,0,0
0,0,0,0,0,0,0,0,0,0
0,0,0,0,0,0,0,0,0,0
0,0,0,0,0,0,0,0,0,0
0,0,0,0,0,0,0,0,0,0
0,0,0,0,0,0,0,0,0,0
0,0,0,0,0,0,0,0,0,0
0,0,0,0,0,0,0,0,0,0
0,0,0,0,0,0,0,0,0,0
0,0,0,0,0,0,0,0,0,0
0,0,0,0,0,0,0,0,0,0
0,0,0,0,0,0,0,0,0,0
endlayer

