
# Menhir_Fountain
# 11 Mar 2014; updated to MC 1.7.10, 10 Oct 2014
# Created by Ruins mod version 12.3 Ingame Parser
# authoring Player: Jordan_Greywolf

biomesToSpawnIn=birch forest,birch forest hills,birch forest hills m,birch forest m,extreme hills edge,flower forest,forest,foresthills,highlands,highlands center,oak savanna,plains,roofed forest,roofed forest m,savanna,savanna m,savanna plateau,savanna plateau m,swampland,swampland m

weight=1
embed_into_distance=2

unacceptable_target_blocks=water,flowing_water,lava,flowing_lava
#acceptable_target_blocks=stone,grass,dirt,sand,gravel,snow_layer,clay

dimensions=7,13,13
allowable_overhang=0
max_cut_in=0
cut_in_buffer=0
max_leveling=8
leveling_buffer=0
preserve_water=0
preserve_lava=0
preserve_plants=1

rule1=0,100,PreserveBlock

# Pave Stones (and dirt/gravel)
rule2=0,100,minecraft:stone-0,minecraft:grass-0,minecraft:gravel-0

# Decorative Circle
rule3=0,100,minecraft:stonebrick-3

# Fountain
rule4=0,100,minecraft:flowing_water

# Column
rule5=1,100,minecraft:cobblestone-0,minecraft:mossy_cobblestone-0

# Keystone
rule6=0,100,minecraft:mossy_cobblestone-0,minecraft:cobblestone-0,minecraft:gravel-0

layer
1,1,1,1,1,2,2,2,1,1,1,1,1
1,1,1,2,2,2,2,2,2,2,1,1,1
1,1,2,2,2,3,3,3,2,2,2,1,1
1,2,2,2,3,4,4,4,3,2,2,2,1
1,2,2,3,4,4,4,4,4,3,2,2,1
2,2,3,4,4,4,4,4,4,4,3,2,2
2,2,3,4,4,4,2,4,4,4,3,2,2
2,2,3,4,4,4,4,4,4,4,3,2,2
1,2,2,3,4,4,4,4,4,3,2,2,1
1,2,2,2,3,4,4,4,3,2,2,2,1
1,1,2,2,2,3,3,3,2,2,2,1,1
1,1,1,2,2,2,2,2,2,2,1,1,1
1,1,1,1,1,2,2,2,1,1,1,1,1
endlayer


layer
1,1,1,1,1,2,2,2,1,1,1,1,1
1,1,1,2,2,2,2,2,2,2,1,1,1
1,1,2,2,2,3,3,3,2,2,2,1,1
1,2,2,2,3,4,4,4,3,2,2,2,1
1,2,2,3,4,4,4,4,4,3,2,2,1
2,2,3,4,4,4,4,4,4,4,3,2,2
2,2,3,4,4,4,2,4,4,4,3,2,2
2,2,3,4,4,4,4,4,4,4,3,2,2
1,2,2,3,4,4,4,4,4,3,2,2,1
1,2,2,2,3,4,4,4,3,2,2,2,1
1,1,2,2,2,3,3,3,2,2,2,1,1
1,1,1,2,2,2,2,2,2,2,1,1,1
1,1,1,1,1,2,2,2,1,1,1,1,1
endlayer

layer
1,1,1,1,1,5,1,5,1,1,1,1,1
1,1,1,5,1,0,1,0,1,5,1,1,1
1,1,1,1,0,0,0,0,0,1,1,1,1
1,5,1,0,0,0,0,0,0,0,1,5,1
1,1,0,0,0,0,0,0,0,0,0,1,1
5,0,0,0,0,0,0,0,0,0,0,0,5
1,1,0,0,0,0,2,0,0,0,0,1,1
5,0,0,0,0,0,0,0,0,0,0,0,5
1,1,0,0,0,0,0,0,0,0,0,1,1
1,5,1,0,0,0,0,0,0,0,1,5,1
1,1,1,1,0,0,0,0,0,1,1,1,1
1,1,1,5,1,0,1,0,1,5,1,1,1
1,1,1,1,1,5,1,5,1,1,1,1,1
endlayer

layer
1,1,1,1,1,5,1,5,1,1,1,1,1
1,1,1,5,0,0,0,0,0,5,1,1,1
1,1,1,0,0,0,0,0,0,0,1,1,1
1,5,0,0,0,0,0,0,0,0,0,5,1
1,0,0,0,0,0,0,0,0,0,0,0,1
5,0,0,0,0,0,0,0,0,0,0,0,5
1,0,0,0,0,0,2,0,0,0,0,0,1
5,0,0,0,0,0,0,0,0,0,0,0,5
1,0,0,0,0,0,0,0,0,0,0,0,1
1,5,0,0,0,0,0,0,0,0,0,5,1
1,1,1,0,0,0,0,0,0,0,1,1,1
1,1,1,5,0,0,0,0,0,5,1,1,1
1,1,1,1,1,5,1,5,1,1,1,1,1
endlayer

layer
1,1,1,1,1,5,6,5,1,1,1,1,1
1,1,1,5,0,0,0,0,0,5,1,1,1
1,1,6,0,0,0,0,0,0,0,6,1,1
1,5,0,0,0,0,0,0,0,0,0,5,1
1,0,0,0,0,0,0,0,0,0,0,0,1
5,0,0,0,0,0,0,0,0,0,0,0,5
6,0,0,0,0,0,2,0,0,0,0,0,6
5,0,0,0,0,0,0,0,0,0,0,0,5
1,0,0,0,0,0,0,0,0,0,0,0,1
1,5,0,0,0,0,0,0,0,0,0,5,1
1,1,6,0,0,0,0,0,0,0,6,1,1
1,1,1,5,0,0,0,0,0,5,1,1,1
1,1,1,1,1,5,6,5,1,1,1,1,1
endlayer

layer
1,1,1,1,0,0,0,0,0,1,1,1,1
1,1,1,0,0,0,0,0,0,0,1,1,1
1,1,0,0,0,0,0,0,0,0,0,1,1
1,0,0,0,0,0,0,0,0,0,0,0,1
0,0,0,0,0,0,4,0,0,0,0,0,0
0,0,0,0,0,0,0,0,0,0,0,0,0
0,0,0,0,4,0,4,0,4,0,0,0,0
0,0,0,0,0,0,0,0,0,0,0,0,0
0,0,0,0,0,0,4,0,0,0,0,0,0
1,0,0,0,0,0,0,0,0,0,0,0,1
1,1,0,0,0,0,0,0,0,0,0,1,1
1,1,1,0,0,0,0,0,0,0,1,1,1
1,1,1,1,0,0,0,0,0,1,1,1,1
endlayer

layer
1,1,1,0,0,0,0,0,0,0,1,1,1
1,1,0,0,0,0,0,0,0,0,0,1,1
1,0,0,0,0,0,0,0,0,0,0,0,1
0,0,0,0,0,0,0,0,0,0,0,0,0
0,0,0,0,0,0,0,0,0,0,0,0,0
0,0,0,0,0,0,4,0,0,0,0,0,0
0,0,0,0,0,4,0,4,0,0,0,0,0
0,0,0,0,0,0,4,0,0,0,0,0,0
0,0,0,0,0,0,0,0,0,0,0,0,0
0,0,0,0,0,0,0,0,0,0,0,0,0
1,0,0,0,0,0,0,0,0,0,0,0,1
1,1,0,0,0,0,0,0,0,0,0,1,1
1,1,1,0,0,0,0,0,0,0,1,1,1
endlayer

