# Raised Railroad Ruin
# Created by Ruins mod version 13.8 Ingame Parser
# authoring Player: Jordan_Greywolf

biomesToSpawnIn=extreme hills,extreme hills edge,extreme hills+,extreme hills m,extreme hills+ m,forest,mesa,plains

weight=1
embed_into_distance=1
acceptable_target_blocks=
unacceptable_target_blocks=
dimensions=7,41,5
allowable_overhang=0
max_leveling=5
leveling_buffer=0
preserve_water=1
preserve_lava=1
preserve_plants=1

rule1=0,100,preserveBlock
rule2=0,100,minecraft:stonebrick-0,minecraft:stonebrick-0,minecraft:stonebrick-1,minecraft:stonebrick-2
rule3=0,100,minecraft:stonebrick-3
rule4=0,100,minecraft:stone_brick_stairs-4
rule5=0,100,minecraft:stone_brick_stairs-6
rule6=0,100,minecraft:stone_brick_stairs-7
rule7=0,100,minecraft:stone_brick_stairs-5
rule8=0,100,minecraft:redstone_block-0
rule9=0,100,minecraft:rail-1
rule10=0,90,minecraft:cobblestone_wall-0,minecraft:cobblestone_wall-0,minecraft:cobblestone_wall-1
rule11=0,100,minecraft:golden_rail-9
rule12=3,100,minecraft:cobblestone_wall-0,minecraft:cobblestone_wall-0,minecraft:cobblestone_wall-1

layer
1,1,1,1,1
1,1,1,1,1
1,1,1,1,1
1,2,1,2,1
1,1,1,1,1
1,1,1,1,1
1,1,1,1,1
1,1,1,1,1
1,1,1,1,1
1,1,1,1,1
1,2,1,2,1
1,1,1,1,1
1,1,1,1,1
1,1,1,1,1
1,1,1,1,1
1,1,1,1,1
1,1,1,1,1
1,2,1,2,1
1,1,1,1,1
1,1,1,1,1
1,1,1,1,1
1,1,1,1,1
1,1,1,1,1
1,1,1,1,1
1,2,1,2,1
1,1,1,1,1
1,1,1,1,1
1,1,1,1,1
1,1,1,1,1
1,1,1,1,1
1,1,1,1,1
1,2,1,2,1
1,1,1,1,1
1,1,1,1,1
1,1,1,1,1
1,1,1,1,1
1,1,1,1,1
1,1,1,1,1
1,2,1,2,1
1,1,1,1,1
1,1,1,1,1
endlayer

layer
0,0,0,0,0
0,0,0,0,0
0,0,0,0,0
0,2,0,2,0
0,0,0,0,0
0,0,0,0,0
0,0,0,0,0
0,0,0,0,0
0,0,0,0,0
0,0,0,0,0
0,2,0,2,0
0,0,0,0,0
0,0,0,0,0
0,0,0,0,0
0,0,0,0,0
0,0,0,0,0
0,0,0,0,0
0,2,0,2,0
0,0,0,0,0
0,0,0,0,0
0,0,0,0,0
0,0,0,0,0
0,0,0,0,0
0,0,0,0,0
0,2,0,2,0
0,0,0,0,0
0,0,0,0,0
0,0,0,0,0
0,0,0,0,0
0,0,0,0,0
0,0,0,0,0
0,2,0,2,0
0,0,0,0,0
0,0,0,0,0
0,0,0,0,0
0,0,0,0,0
0,0,0,0,0
0,0,0,0,0
0,2,0,2,0
0,0,0,0,0
0,0,0,0,0
endlayer

layer
0,0,0,0,0
0,0,0,0,0
0,0,0,0,0
0,3,0,3,0
0,0,0,0,0
0,0,0,0,0
0,0,0,0,0
0,0,0,0,0
0,0,0,0,0
0,0,0,0,0
0,2,0,2,0
0,0,0,0,0
0,0,0,0,0
0,0,0,0,0
0,0,0,0,0
0,0,0,0,0
0,0,0,0,0
0,2,0,2,0
0,0,0,0,0
0,0,0,0,0
0,0,0,0,0
0,0,0,0,0
0,0,0,0,0
0,0,0,0,0
0,2,0,2,0
0,0,0,0,0
0,0,0,0,0
0,0,0,0,0
0,0,0,0,0
0,0,0,0,0
0,0,0,0,0
0,2,0,2,0
0,0,0,0,0
0,0,0,0,0
0,0,0,0,0
0,0,0,0,0
0,0,0,0,0
0,0,0,0,0
0,2,0,2,0
0,0,0,0,0
0,0,0,0,0
endlayer

layer
0,0,0,0,0
0,0,0,0,0
0,4,0,4,0
6,2,2,2,5
0,7,0,7,0
0,0,0,0,0
0,0,0,0,0
0,0,0,0,0
0,0,0,0,0
0,4,0,4,0
6,3,2,3,5
0,7,0,7,0
0,0,0,0,0
0,0,0,0,0
0,0,0,0,0
0,0,0,0,0
0,4,0,4,0
6,3,2,3,5
0,7,0,7,0
0,0,0,0,0
0,0,0,0,0
0,0,0,0,0
0,0,0,0,0
0,4,0,4,0
6,3,2,3,5
0,7,0,7,0
0,0,0,0,0
0,0,0,0,0
0,0,0,0,0
0,0,0,0,0
0,4,0,4,0
6,3,2,3,5
0,7,0,7,0
0,0,0,0,0
0,0,0,0,0
0,0,0,0,0
0,0,0,0,0
0,4,0,4,0
6,3,2,3,5
0,7,0,7,0
0,0,0,0,0
endlayer

layer
0,0,2,0,0
6,2,2,2,0
2,2,2,2,2
3,8,2,8,3
2,2,2,2,2
6,2,2,2,5
6,2,2,2,5
6,2,2,2,5
6,2,2,2,5
2,2,2,2,2
3,8,2,8,3
2,2,2,2,2
6,2,2,2,5
6,2,2,2,5
6,2,2,2,5
6,2,2,2,5
2,2,2,2,2
3,8,2,8,3
2,2,2,2,2
6,2,2,2,5
6,2,2,2,5
6,2,2,2,5
6,2,2,2,5
2,2,2,2,2
3,8,2,8,3
2,2,2,2,2
6,2,2,2,5
6,2,2,2,5
6,2,2,2,5
6,2,2,2,5
2,2,2,2,2
3,8,2,8,3
2,2,2,2,2
6,2,2,2,5
6,2,2,2,5
6,2,2,2,5
6,2,2,2,5
2,2,2,2,2
3,8,2,8,3
2,2,2,2,0
6,0,2,0,0
endlayer

layer
0,0,0,0,0
10,9,0,9,0
10,9,0,9,10
10,11,0,11,10
10,9,0,9,10
10,9,0,9,10
10,9,0,9,10
10,9,0,9,10
10,9,0,9,10
10,9,0,9,10
10,11,0,11,10
10,9,0,9,10
10,9,0,9,10
10,9,0,9,10
10,9,0,9,10
10,9,0,9,10
10,9,0,9,10
10,11,0,11,10
10,9,0,9,10
10,9,0,9,10
10,9,0,9,10
10,9,0,9,10
10,9,0,9,10
10,9,0,9,10
10,11,0,11,10
10,9,0,9,10
10,9,0,9,10
10,9,0,9,10
10,9,0,9,10
10,9,0,9,10
10,9,0,9,10
10,11,0,11,10
10,9,0,9,10
10,9,0,9,10
10,9,0,9,10
10,9,0,9,10
10,9,0,9,10
10,9,0,9,10
10,11,0,11,10
10,9,0,9,0
10,0,0,0,0
endlayer

layer
0,0,0,0,0
12,0,0,0,0
12,0,0,0,12
12,0,0,0,12
12,0,0,0,12
12,0,0,0,12
12,0,0,0,12
12,0,0,0,12
12,0,0,0,12
12,0,0,0,12
12,0,0,0,12
12,0,0,0,12
12,0,0,0,12
12,0,0,0,12
12,0,0,0,12
12,0,0,0,12
12,0,0,0,12
12,0,0,0,12
12,0,0,0,12
12,0,0,0,12
12,0,0,0,12
12,0,0,0,12
12,0,0,0,12
12,0,0,0,12
12,0,0,0,12
12,0,0,0,12
12,0,0,0,12
12,0,0,0,12
12,0,0,0,12
12,0,0,0,12
12,0,0,0,12
12,0,0,0,12
12,0,0,0,12
12,0,0,0,12
12,0,0,0,12
12,0,0,0,12
12,0,0,0,12
12,0,0,0,12
12,0,0,0,12
12,0,0,0,0
12,0,0,0,0
endlayer



