# StatueQuartz - 16 Apr 2014
# Updated to MC 1.7.10, 13 Oct 2014
# StatueQuartz
# Updated to MC 1.7.10, 15 Oct 2014
# Created by Ruins mod version 12.3 Ingame Parser
# authoring Player: Jordan_Greywolf

biomestospawnin=autumn hills,autumn woods,cherry blossom grove,desert,enchanted forest,green hills,forest,foresthills,jungle,junglehills,ominous woods,pasture,plains,prairie,savanna
weight=1
embed_into_distance=1

unacceptable_target_blocks=lava
dimensions=9,7,7
allowable_overhang=45
max_cut_in=0
cut_in_buffer=0
max_leveling=12
leveling_buffer=0
preserve_water=0
preserve_lava=0
preserve_plants=1

rule1=0,100,minecraft:quartz_block-2
rule2=0,100,minecraft:quartz_block-0
rule3=0,100,minecraft:quartz_stairs-2
rule4=0,100,minecraft:quartz_stairs-0
rule5=0,100,minecraft:water-0
rule6=0,100,minecraft:quartz_stairs-3
rule7=0,100,minecraft:quartz_stairs-1
rule8=0,100,minecraft:stone_slab-7
rule9=0,100,minecraft:quartz_stairs-7
rule10=0,100,minecraft:quartz_stairs-6

layer
1,1,1,1,1,1,1
1,2,2,2,2,2,1
1,2,2,2,2,2,1
1,2,2,2,2,2,1
1,2,2,2,2,2,1
1,2,2,2,2,2,1
1,1,1,1,1,1,1
endlayer

layer
4,4,4,4,4,4,3
6,5,5,5,5,5,3
6,5,1,1,1,5,3
6,5,1,1,1,5,3
6,5,1,1,1,5,3
6,5,5,5,5,5,3
6,7,7,7,7,7,7
endlayer

layer
0,0,0,0,0,0,0
0,0,0,0,0,0,0
0,0,0,0,0,0,0
0,0,2,2,3,5,0
0,0,0,0,0,0,0
0,0,0,0,0,0,0
0,0,0,0,0,0,0
endlayer

layer
0,0,0,0,0,0,0
0,0,0,0,0,0,0
0,0,0,0,0,0,0
0,0,2,2,0,5,0
0,0,0,0,0,0,0
0,0,0,0,0,0,0
0,0,0,0,0,0,0
endlayer

layer
0,0,0,0,0,0,0
0,0,0,0,0,0,0
0,0,0,0,0,0,0
0,0,6,2,0,5,0
0,0,0,0,0,0,0
0,0,0,0,0,0,0
0,0,0,0,0,0,0
endlayer

layer
0,0,0,0,0,0,0
0,0,0,0,0,0,0
0,0,0,9,8,0,0
0,0,0,2,10,1,0
0,0,0,9,8,0,0
0,0,0,0,0,0,0
0,0,0,0,0,0,0
endlayer

layer
0,0,0,0,0,0,0
0,0,0,0,0,0,0
0,0,0,4,0,0,0
0,0,0,2,3,0,0
0,0,0,7,0,0,0
0,0,0,0,0,0,0
0,0,0,0,0,0,0
endlayer

layer
0,0,0,0,0,0,0
0,0,0,0,0,0,0
0,0,0,0,0,0,0
0,0,0,2,0,0,0
0,0,0,0,0,0,0
0,0,0,0,0,0,0
0,0,0,0,0,0,0
endlayer

layer
0,0,0,0,0,0,0
0,0,0,0,0,0,0
0,0,0,0,0,0,0
0,0,0,6,0,0,0
0,0,0,0,0,0,0
0,0,0,0,0,0,0
0,0,0,0,0,0,0
endlayer

