# VillageChurchFancy -- a fancier (but spider-infested) church
# 22 Sep 2014 -- Minecraft 1.7.10
# Created by Ruins mod version 13.8 Ingame Parser
# authoring Player: Jordan_Greywolf

biomesToSpawnIn=plains,savanna,savanna plateau,extreme hills,extreme hills edge,forest

weight=1
embed_into_distance=5

unacceptable_target_blocks=flowing_water,water,flowing_lava,lava

dimensions=26,7,11
allowable_overhang=0
max_leveling=5
leveling_buffer=0
preserve_water=0
preserve_lava=0
preserve_plants=1

# Terrain Blending
rule1=0,100,preserveBlock

rule2=0,100,minecraft:cobblestone-0
rule3=0,100,minecraft:stonebrick-3

# Monsters
rule4=0,100,MobSpawner:CaveSpider

rule5=0,100,minecraft:stone_stairs-3
rule6=0,100,minecraft:web-0
rule7=0,100,minecraft:oak_stairs-2
rule8=0,100,minecraft:log-0
rule9=1,100,minecraft:wooden_door-1
rule10=2,100,minecraft:ladder-4

# Stained Glass Windows
rule11=0,100,minecraft:stained_glass_pane-1,minecraft:stained_glass_pane-2,minecraft:stained_glass_pane-3,minecraft:stained_glass_pane-4,minecraft:stained_glass_pane-5,minecraft:stained_glass_pane-6,minecraft:stained_glass_pane-7,minecraft:stained_glass_pane-8,minecraft:stained_glass_pane-9,minecraft:stained_glass_pane-10,minecraft:stained_glass_pane-11

rule12=0,100,minecraft:oak_stairs-1

rule13=1,100,minecraft:wooden_door-8
rule14=0,100,minecraft:oak_stairs-0
rule15=0,100,minecraft:oak_stairs-5
rule16=0,100,minecraft:wooden_slab-8
rule17=0,100,ChestGenHook:dungeonChest:5-2
rule18=0,100,minecraft:oak_stairs-4
rule19=0,100,minecraft:wooden_slab-0
rule20=0,100,minecraft:cobblestone_wall-0

# Church Bell
rule21=0,100,minecraft:noteblock-0

rule22=0,100,minecraft:oak_stairs-3
rule23=0,100,minecraft:fence-0
rule24=0,100,minecraft:oak_stairs-7
rule25=0,100,minecraft:oak_stairs-6
rule26=0,100,minecraft:planks-0

# Sealed Upper Windows
rule27=0,100,minecraft:double_stone_slab

layer
1,1,1,1,1,1,1,1,1,1,1
1,2,2,2,2,2,2,2,2,2,1
1,2,2,2,2,2,2,2,2,2,1
2,2,2,2,2,2,2,2,2,2,1
1,2,2,2,2,2,2,2,2,2,1
1,2,2,2,2,2,2,2,2,2,1
1,1,1,1,1,1,1,1,1,1,1
endlayer

layer
1,1,1,1,1,1,1,1,1,1,1
1,2,2,2,2,2,2,2,2,2,1
1,2,2,2,2,2,2,2,2,2,1
2,2,2,2,2,2,2,2,2,2,1
1,2,2,2,2,2,2,2,2,2,1
1,2,2,2,2,2,2,2,2,2,1
1,1,1,1,1,1,1,1,1,1,1
endlayer

layer
1,1,1,1,1,1,1,1,1,1,1
1,2,2,2,2,2,2,2,2,2,1
1,2,2,2,2,2,2,2,2,2,1
2,2,2,2,2,2,2,2,2,2,1
1,2,2,2,2,2,2,2,2,2,1
1,2,2,2,2,2,2,2,2,2,1
1,1,1,1,1,1,1,1,1,1,1
endlayer

layer
1,1,1,1,1,1,1,1,1,1,1
1,2,2,2,2,2,2,2,2,2,1
1,2,2,2,2,2,2,2,2,2,1
2,2,2,2,2,2,2,2,2,2,1
1,2,2,2,2,2,2,2,2,2,1
1,2,2,2,2,2,2,2,2,2,1
1,1,1,1,1,1,1,1,1,1,1
endlayer


layer
1,1,1,1,1,1,1,1,1,1,1
1,2,2,2,2,2,2,2,2,2,1
1,2,2,2,2,2,2,2,2,2,1
2,2,2,2,2,2,2,2,2,2,1
1,2,2,2,2,2,2,2,2,2,1
1,2,2,2,2,2,2,2,2,2,1
1,1,1,1,1,1,1,1,1,1,1
endlayer

layer
1,1,1,1,1,1,1,1,1,1,1
1,3,2,2,2,2,2,2,2,3,1
1,2,2,2,2,2,2,2,2,2,1
5,2,2,2,2,2,4,2,2,2,1
1,2,2,2,2,2,2,2,2,2,1
1,3,2,2,2,2,2,2,2,3,1
1,1,1,1,1,1,1,1,1,1,1
endlayer

layer
1,0,0,0,0,0,0,0,0,0,1
0,0,2,2,2,2,2,2,2,0,0
0,2,7,7,0,6,5,2,2,2,0
0,9,0,0,0,0,8,2,2,2,0
0,2,7,7,10,6,5,2,2,2,0
0,0,2,2,2,2,2,2,2,0,0
1,0,0,0,0,0,0,0,0,0,1
endlayer

layer
0,0,0,0,0,0,0,0,0,0,0
0,0,2,11,2,11,2,11,2,0,0
0,2,0,0,0,0,6,0,12,2,0
0,13,0,0,0,0,8,0,6,2,0
0,2,0,0,10,0,6,0,14,2,0
0,0,2,11,2,11,2,11,2,0,0
0,0,0,0,0,0,0,0,0,0,0
endlayer

layer
0,0,0,0,0,0,0,0,0,0,0
0,0,2,11,2,11,2,11,2,0,0
0,2,6,0,6,0,6,0,6,2,0
0,2,6,0,0,0,0,0,0,11,0
0,2,6,0,10,0,6,0,6,2,0
0,0,2,11,2,11,2,11,2,0,0
0,0,0,0,0,0,0,0,0,0,0
endlayer

layer
14,14,14,14,14,14,14,14,14,14,14
0,3,2,2,2,2,2,2,2,3,0
0,2,2,2,2,2,6,6,6,2,0
0,2,2,2,2,2,0,0,0,11,0
0,2,2,2,10,2,6,6,6,2,0
0,3,2,2,2,2,2,2,2,3,0
12,12,12,12,12,12,12,12,12,12,12
endlayer

layer
0,0,0,0,0,0,0,0,0,0,0
14,14,2,2,2,14,14,14,14,14,14
16,2,4,6,6,2,15,15,15,2,15
16,2,17,6,0,2,16,16,16,2,16
16,2,6,0,10,2,18,18,18,2,18
12,12,2,2,2,12,12,12,12,12,12
0,0,0,0,0,0,0,0,0,0,0
endlayer

layer
0,0,0,0,0,0,0,0,0,0,0
0,0,2,27,2,0,0,0,0,0,0
19,2,6,6,6,2,19,19,19,19,19
19,27,6,0,0,27,19,19,19,19,19
19,2,6,0,10,2,19,19,19,19,19
0,0,2,27,2,0,0,0,0,0,0
0,0,0,0,0,0,0,0,0,0,0
endlayer

layer
0,0,0,0,0,0,0,0,0,0,0
0,0,2,27,2,0,0,0,0,0,0
0,2,6,0,6,2,0,0,0,0,0
0,27,0,0,0,27,0,0,0,0,0
0,2,0,0,10,2,0,0,0,0,0
0,0,2,27,2,0,0,0,0,0,0
0,0,0,0,0,0,0,0,0,0,0
endlayer

layer
0,0,0,0,0,0,0,0,0,0,0
0,0,2,2,2,0,0,0,0,0,0
0,2,6,6,6,2,0,0,0,0,0
0,2,6,6,6,2,0,0,0,0,0
0,2,6,0,10,2,0,0,0,0,0
0,0,2,2,2,0,0,0,0,0,0
0,0,0,0,0,0,0,0,0,0,0
endlayer

layer
0,0,0,0,0,0,0,0,0,0,0
0,3,2,2,2,3,0,0,0,0,0
0,2,2,2,2,2,0,0,0,0,0
0,2,2,2,2,2,0,0,0,0,0
0,2,2,2,10,2,0,0,0,0,0
0,3,2,2,2,3,0,0,0,0,0
0,0,0,0,0,0,0,0,0,0,0
endlayer

layer
0,0,0,0,0,0,0,0,0,0,0
0,0,2,20,2,0,0,0,0,0,0
0,2,0,0,0,2,0,0,0,0,0
0,20,0,0,0,20,0,0,0,0,0
0,2,0,0,0,2,0,0,0,0,0
0,0,2,20,2,0,0,0,0,0,0
0,0,0,0,0,0,0,0,0,0,0
endlayer

layer
0,0,0,0,0,0,0,0,0,0,0
0,0,2,0,2,0,0,0,0,0,0
0,2,0,0,0,2,0,0,0,0,0
0,0,0,0,0,0,0,0,0,0,0
0,2,0,0,0,2,0,0,0,0,0
0,0,2,0,2,0,0,0,0,0,0
0,0,0,0,0,0,0,0,0,0,0
endlayer

layer
0,0,0,0,0,0,0,0,0,0,0
0,0,2,6,2,0,0,0,0,0,0
0,2,6,0,6,2,0,0,0,0,0
0,6,0,21,0,6,0,0,0,0,0
0,2,6,0,6,2,0,0,0,0,0
0,0,2,6,2,0,0,0,0,0,0
0,0,0,0,0,0,0,0,0,0,0
endlayer

layer
0,22,14,14,14,7,0,0,0,0,0
14,22,2,2,2,14,14,0,0,0,0
22,2,2,6,2,2,7,0,0,0,0
22,2,6,23,6,2,7,0,0,0,0
22,2,2,6,2,2,7,0,0,0,0
12,12,2,2,2,7,12,0,0,0,0
0,22,12,12,12,7,0,0,0,0,0
endlayer

layer
0,0,0,0,0,0,0,0,0,0,0
0,0,22,14,7,0,0,0,0,0,0
0,14,22,15,14,14,0,0,0,0,0
0,22,25,23,24,7,0,0,0,0,0
0,12,12,18,7,12,0,0,0,0,0
0,0,22,12,7,0,0,0,0,0,0
0,0,0,0,0,0,0,0,0,0,0
endlayer

layer
0,0,0,0,0,0,0,0,0,0,0
0,0,0,0,0,0,0,0,0,0,0
0,0,0,14,0,0,0,0,0,0,0
0,0,22,26,7,0,0,0,0,0,0
0,0,0,12,0,0,0,0,0,0,0
0,0,0,0,0,0,0,0,0,0,0
0,0,0,0,0,0,0,0,0,0,0
endlayer

layer
0,0,0,0,0,0,0,0,0,0,0
0,0,0,0,0,0,0,0,0,0,0
0,0,0,0,0,0,0,0,0,0,0
0,0,0,26,0,0,0,0,0,0,0
0,0,0,0,0,0,0,0,0,0,0
0,0,0,0,0,0,0,0,0,0,0
0,0,0,0,0,0,0,0,0,0,0
endlayer

layer
0,0,0,0,0,0,0,0,0,0,0
0,0,0,0,0,0,0,0,0,0,0
0,0,0,0,0,0,0,0,0,0,0
0,0,0,26,0,0,0,0,0,0,0
0,0,0,0,0,0,0,0,0,0,0
0,0,0,0,0,0,0,0,0,0,0
0,0,0,0,0,0,0,0,0,0,0
endlayer

layer
0,0,0,0,0,0,0,0,0,0,0
0,0,0,0,0,0,0,0,0,0,0
0,0,0,0,0,0,0,0,0,0,0
0,0,0,23,0,0,0,0,0,0,0
0,0,0,0,0,0,0,0,0,0,0
0,0,0,0,0,0,0,0,0,0,0
0,0,0,0,0,0,0,0,0,0,0
endlayer

layer
0,0,0,0,0,0,0,0,0,0,0
0,0,0,0,0,0,0,0,0,0,0
0,0,0,0,0,0,0,0,0,0,0
0,0,0,23,0,0,0,0,0,0,0
0,0,0,0,0,0,0,0,0,0,0
0,0,0,0,0,0,0,0,0,0,0
0,0,0,0,0,0,0,0,0,0,0
endlayer

layer
0,0,0,0,0,0,0,0,0,0,0
0,0,0,0,0,0,0,0,0,0,0
0,0,0,0,0,0,0,0,0,0,0
0,0,0,23,0,0,0,0,0,0,0
0,0,0,0,0,0,0,0,0,0,0
0,0,0,0,0,0,0,0,0,0,0
0,0,0,0,0,0,0,0,0,0,0
endlayer

