# Desert Mini Village
# MC 1.7.10; 26 Oct 2014
# Created by Ruins mod version 13.8 Ingame Parser
# authoring Player: Jordan_Greywolf

biomesToSpawnIn=desert,desert m,desert oil field,deserthills,dunes,lush desert,oasis,mountainous desert

unique=1
# Note: This is deliberately set to Unique to spawn only once per biome
# on account of play balance and spawn-lag concerns.

weight=1
embed_into_distance=1
acceptable_target_blocks=
unacceptable_target_blocks=
dimensions=13,36,36
allowable_overhang=25
max_leveling=5
leveling_buffer=0
preserve_water=0
preserve_lava=0
preserve_plants=1

rule1=0,100,minecraft:sandstone-2
rule2=0,100,minecraft:sandstone-0

# Random village one-time spawner
rule3=0,100,CommandBlock:RUINSTRIGGER /summon Villager ~0 ~2 ~0:@

# Chiseled Quartz Block (pool bottom)
rule4=0,100,minecraft:quartz_block-1

# Fruit Vendor one-time spawner
rule5=0,100,CommandBlock:RUINSTRIGGER /summon Villager ~0 ~2 ~0 {Profession:0,CustomName:FRUIT VENDOR,CustomNameVisible:1,Offers:{Recipes:[{maxUses:8,buy:{id:388,Count:1},sell:{id:86,Count:4}},{maxUses:8,buy:{id:388,Count:1},sell:{id:103,Count:4}},{maxUses:8,buy:{id:388,Count:1},sell:{id:260,Count:6}},{maxUses:8,buy:{id:382,Count:4},sell:{id:388,Count:1}}]}}:@

# Antiquities Merchant one-time spawner
rule6=0,100,CommandBlock:RUINSTRIGGER /summon Villager ~0 ~2 ~0 {Profession:1,CustomName:ANTIQUES MERCHANT,CustomNameVisible:1,Offers:{Recipes:[{maxUses:5,buy:{id:388,Count:25},sell:{id:52,Count:1}},{maxUses:1000,buy:{id:54,Count:64},sell:{id:388,Count:1}},{maxUses:10,buy:{id:111,Count:24},sell:{id:388,Count:1}},{maxUses:10,buy:{id:372,Count:64},sell:{id:388,Count:1}},{maxUses:1000,buy:{id:388,Count:1},sell:{id:123,Count:1}},{maxUses:1000,buy:{id:388,Count:4},sell:{id:322,Damage:1,Count:1}},{maxUses:100,buy:{id:388,Count:10},sell:{id:347,Count:1}},{maxUses:1000,buy:{id:403,Count:1},sell:{id:371,Count:1}},{maxUses:1000,buy:{id:388,Count:1},sell:{id:321,Count:10}}]}}:@

# Swift Horse one-time spawner
rule7=0,100,CommandBlock:RUINSTRIGGER /summon EntityHorse ~0 ~2 ~0 {Tame:1,Type:0,AbsorptionAmount:10,Attributes:[{Name:generic.maxHealth,Base:50},{Name:horse.jumpStrength,Base:1.5},{Name:generic.movementSpeed,Base:0.4}],PersistenceRequired:1}:@

# Hostler one-time spawner
rule8=0,100,CommandBlock:RUINSTRIGGER /summon Villager ~0 ~2 ~0 {Profession:0,CustomName:HOSTLER,CustomNameVisible:1,Offers:{Recipes:[{maxUses:1000,buy:{id:388,Count:1},sell:{id:170,Count:1}},{maxUses:50,buy:{id:417,Count:1},sell:{id:265,Count:4}},{maxUses:50,buy:{id:418,Count:1},sell:{id:266,Count:3}},{maxUses:50,buy:{id:419,Count:1},sell:{id:264,Count:2}},{maxUses:4,buy:{id:329,Count:1},sell:{id:334,Count:2}},{maxUses:100,buy:{id:388,Count:8},sell:{id:329,Count:1}}]}}:@

rule9=0,100,CommandBlock:RUINSTRIGGER /summon Villager ~0 ~2 ~0 {Profession:3,CustomName:SMELTER,CustomNameVisible:1,Offers:{Recipes:[{maxUses:10,buy:{id:265,Count:7},sell:{id:388,Count:1}},{maxUses:24,buy:{id:263,Count:16},sell:{id:388,Count:1}},{maxUses:1000,buy:{id:4,Count:64},sell:{id:1,Count:32}},{maxUses:1000,buy:{id:12,Count:64},buyB:{id:388,Count:1},sell:{id:20,Count:64}},{maxUses:1000,buy:{id:101,Count:16},sell:{id:265,Count:3}},{maxUses:1000,buy:{id:306,Count:1},sell:{id:265,Count:2}},{maxUses:1000,buy:{id:307,Count:1},sell:{id:265,Count:4}},{maxUses:1000,buy:{id:308,Count:1},sell:{id:265,Count:3}},{maxUses:1000,buy:{id:309,Count:1},sell:{id:265,Count:2}},{maxUses:1000,buy:{id:257,Count:1},sell:{id:265,Count:1}},{maxUses:1000,buy:{id:258,Count:1},sell:{id:265,Count:1}},{maxUses:1000,buy:{id:267,Count:1},sell:{id:265,Count:1}}]}}:@

# 
rule10=0,100,CommandBlock:RUINSTRIGGER /summon Villager ~0 ~2 ~0 {Profession:2,CustomName:CLOTH MERCHANT,CustomNameVisible:1,Offers:{Recipes:[{maxUses:1000,buy:{id:388,Count:1},sell:{id:35,Count:12}},{maxUses:1000,buy:{id:388,Count:1},sell:{id:35,Damage:1,Count:12}},{maxUses:1000,buy:{id:388,Count:1},sell:{id:35,Damage:2,Count:12}},{maxUses:1000,buy:{id:388,Count:1},sell:{id:35,Damage:3,Count:12}},{maxUses:1000,buy:{id:388,Count:1},sell:{id:35,Damage:4,Count:12}},{maxUses:1000,buy:{id:388,Count:1},sell:{id:35,Damage:5,Count:12}},{maxUses:1000,buy:{id:388,Count:1},sell:{id:35,Damage:6,Count:12}},{maxUses:1000,buy:{id:388,Count:1},sell:{id:35,Damage:7,Count:12}},{maxUses:1000,buy:{id:388,Count:1},sell:{id:35,Damage:8,Count:12}},{maxUses:1000,buy:{id:388,Count:1},sell:{id:35,Damage:9,Count:12}},{maxUses:1000,buy:{id:388,Count:1},sell:{id:35,Damage:10,Count:12}},{maxUses:1000,buy:{id:388,Count:1},sell:{id:35,Damage:11,Count:12}},{maxUses:1000,buy:{id:388,Count:1},sell:{id:35,Damage:12,Count:12}},{maxUses:1000,buy:{id:388,Count:1},sell:{id:35,Damage:13,Count:12}},{maxUses:1000,buy:{id:388,Count:1},sell:{id:35,Damage:14,Count:12}},{maxUses:1000,buy:{id:388,Count:1},sell:{id:35,Damage:15,Count:12}}]}}:@

# Dye Merchant spawner 
rule11=0,100,CommandBlock:RUINSTRIGGER /summon Villager ~0 ~2 ~0 {Profession:2,CustomName:DYE MERCHANT,CustomNameVisible:1,Offers:{Recipes:[{maxUses:50,buy:{id:351,Count:64},sell:{id:388,Count:1}},{maxUses:10,buy:{id:37,Count:64},sell:{id:388,Count:1}},{maxUses:10,buy:{id:38,Count:64},sell:{id:388,Count:1}},{maxUses:25,buy:{id:388,Count:1},sell:{id:351,Damage:1,Count:12}},{maxUses:25,buy:{id:388,Count:1},sell:{id:351,Damage:2,Count:12}},{maxUses:25,buy:{id:388,Count:1},sell:{id:351,Damage:3,Count:12}},{maxUses:25,buy:{id:388,Count:1},sell:{id:351,Damage:4,Count:3}},{maxUses:25,buy:{id:388,Count:1},sell:{id:351,Damage:5,Count:12}},{maxUses:25,buy:{id:388,Count:1},sell:{id:351,Damage:6,Count:12}},{maxUses:25,buy:{id:388,Count:1},sell:{id:351,Damage:7,Count:12}},{maxUses:25,buy:{id:388,Count:1},sell:{id:351,Damage:8,Count:12}},{maxUses:25,buy:{id:388,Count:1},sell:{id:351,Damage:9,Count:12}},{maxUses:25,buy:{id:388,Count:1},sell:{id:351,Damage:10,Count:12}},{maxUses:25,buy:{id:388,Count:1},sell:{id:351,Damage:11,Count:12}},{maxUses:25,buy:{id:388,Count:1},sell:{id:351,Damage:12,Count:12}},{maxUses:25,buy:{id:388,Count:1},sell:{id:351,Damage:13,Count:12}},{maxUses:25,buy:{id:388,Count:1},sell:{id:351,Damage:14,Count:12}},{maxUses:25,buy:{id:388,Count:1},sell:{id:351,Damage:15,Count:12}}]}}:@

rule12=0,100,minecraft:stone_slab-1
rule13=0,100,minecraft:double_stone_slab-0

# Fountain / pool water
rule14=0,100,minecraft:flowing_water

rule15=0,100,minecraft:grass-0

# Wool (randomized color)
rule16=0,100,minecraft:wool-2,minecraft:wool-3,minecraft:wool-5,minecraft:wool-6,minecraft:wool-9,minecraft:wool-10,minecraft:wool-11,minecraft:wool-13,minecraft:wool-15

rule17=0,100,minecraft:fence_gate-3
rule18=0,100,minecraft:fence-0
rule19=0,100,minecraft:cauldron-0
rule20=0,100,minecraft:birch_stairs-1
rule21=0,100,minecraft:noteblock-0
rule22=0,100,minecraft:sandstone_stairs-0

# Carpet (white) -- canopies and table tops
rule23=0,100,minecraft:carpet-0

rule24=0,100,minecraft:sandstone_stairs-5
rule25=0,100,minecraft:trapped_chest-2

# Randomized garden flowers
rule26=0,100,minecraft:red_flower-0,minecraft:red_flower-1,minecraft:red_flower-2

rule27=0,100,minecraft:fence_gate-2
rule28=0,100,minecraft:crafting_table-0
rule29=0,100,minecraft:lit_furnace-4
rule30=1,100,minecraft:wooden_door-2

# Randomized fruit (melon, pumpkin)
rule31=0,100,minecraft:melon_block-0,minecraft:pumpkin-4,minecraft:lit_pumpkin

rule32=2,100,minecraft:trapdoor-11
rule33=0,100,minecraft:dropper-3
rule34=0,100,minecraft:dispenser-3

# Iron Block (body of iron golem that is made upon structure spawn)
rule35=0,100,minecraft:iron_block-0

rule36=0,100,minecraft:stone_slab-7

# Stained Hardened Clay (blue) -- fountain decorative blocks
rule37=0,100,minecraft:stained_hardened_clay-11

# Barn: hay blocks with randomized positions
rule38=0,100,minecraft:hay_block-0,minecraft:hay_block-4,minecraft:hay_block-8

rule39=0,100,minecraft:fence_gate-0
rule40=1,100,minecraft:wooden_door-0
rule41=0,100,minecraft:birch_stairs-0
rule42=1,100,minecraft:wooden_door-3
rule43=0,100,minecraft:birch_stairs-5
rule44=2,100,minecraft:trapdoor-8
rule45=0,100,minecraft:birch_stairs-7
rule46=0,100,minecraft:birch_stairs-6

# Stone Slab (sandstone, upper)
rule47=0,100,minecraft:stone_slab-9

rule48=1,100,minecraft:wooden_door-1
rule49=0,100,minecraft:sandstone-1
rule50=1,100,minecraft:torch-5
rule51=2,100,minecraft:ladder-2

# Carpet (red) -- canopies & table top
rule52=0,100,minecraft:carpet-14

rule53=1,100,minecraft:wooden_door-8

# Carpet (blue) -- table top
rule54=0,100,minecraft:carpet-11

# Wool (yellow, white, red, blue) -- canopies
rule55=0,100,minecraft:wool-4
rule56=0,100,minecraft:wool-0 
rule57=0,100,minecraft:wool-14
rule58=0,100,minecraft:wool-11

rule59=0,100,minecraft:wooden_slab-2

# Iron Golem head (should make iron golem upon ruins spawn)
rule60=0,100,minecraft:lit_pumpkin

# Wool (white) -- canopies & table tops
rule61=0,100,minecraft:wool-1

# Wool (brown) -- canopies
rule62=0,100,minecraft:wool-12

rule63=0,100,minecraft:wooden_slab-10
rule64=0,100,minecraft:sandstone_stairs-3
rule65=0,100,minecraft:sandstone_stairs-2

# Carpet (yellow) -- canopies
rule66=0,100,minecraft:carpet-4

rule67=0,100,minecraft:sandstone_stairs-1
rule68=0,100,minecraft:sandstone_stairs-7
rule69=0,100,minecraft:sandstone_stairs-6

rule70=0,100,minecraft:lit_redstone_lamp-0

# Carpet (orange) -- canopies
rule71=0,100,minecraft:carpet-1

# Jungle leaves (no decay)
rule72=0,100,minecraft:leaves-7

# Fountain center (light blue stained glass)
rule73=0,100,minecraft:stained_glass-3

# Wool (brown -- canopies
rule74=0,100,minecraft:carpet-12

rule75=0,100,minecraft:spruce_stairs-1
rule76=0,100,minecraft:spruce_stairs-2
rule77=0,100,minecraft:birch_stairs-4
rule78=0,100,minecraft:sandstone_stairs-4

# Stained Hardened Clay (brown) -- antiquities shop rooftop
rule79=0,100,minecraft:stained_hardened_clay-12

rule80=0,100,minecraft:redstone_block-0
rule81=0,100,minecraft:birch_stairs-2
rule82=0,100,minecraft:planks-2
rule83=0,100,minecraft:birch_stairs-3
rule84=2,100,minecraft:ladder-3

# Rooftop garden farmland
rule85=0,100,minecraft:farmland-7,farmland-4,farmland-2

# Jungle leaves (no decay)
rule86=0,100,minecraft:leaves-7

rule87=2,100,minecraft:trapdoor-2

# Rooftop garden (wheat)
rule88=0,100,minecraft:wheat-7,minecraft:wheat-4,minecraft:wheat-1

rule89=2,100,minecraft:trapdoor-3
rule90=0,100,minecraft:quartz_stairs-2
rule91=0,100,minecraft:quartz_stairs-0

# Quartz Slab (upper)
rule92=0,100,minecraft:stone_slab-15
rule93=0,100,minecraft:quartz_stairs-3
rule94=0,100,minecraft:quartz_stairs-1

# ---------------------------------------------

layer
1,2,2,2,2,2,2,2,2,2,2,2,2,2,2,2,2,2,2,2,2,2,2,2,2,2,2,2,2,2,2,2,2,2,2,1
2,2,2,2,2,2,2,2,2,2,2,2,2,2,2,2,2,2,2,2,2,2,2,2,2,2,2,2,2,2,2,2,2,2,2,2
2,2,2,2,2,2,2,2,2,2,2,2,2,2,3,2,2,2,2,2,2,2,2,2,2,2,2,2,2,2,2,2,2,2,2,2
2,2,2,2,2,2,2,2,2,2,2,2,2,2,2,2,2,2,2,2,2,2,2,2,2,2,2,2,2,2,2,2,2,2,2,2
2,2,2,2,2,2,2,2,2,2,2,2,2,2,2,2,2,2,2,2,2,2,2,2,2,2,2,2,2,2,2,2,2,2,2,2
2,2,2,2,2,2,2,3,2,2,2,2,2,2,2,2,2,2,2,2,2,2,2,2,2,2,2,4,4,4,4,2,2,2,2,2
2,2,2,2,2,2,2,2,2,2,2,2,2,2,2,2,2,2,2,2,2,2,2,2,2,2,2,4,4,4,4,2,2,2,2,2
2,2,2,2,2,2,2,2,2,2,2,2,2,2,2,2,2,2,2,2,2,2,2,2,2,2,2,2,2,2,2,2,2,2,2,2
2,2,2,2,2,2,2,2,2,2,2,2,2,2,2,2,2,2,2,2,2,2,2,2,2,2,2,2,2,2,2,2,2,2,2,2
2,2,2,2,2,2,2,2,2,2,2,2,2,2,2,2,2,2,2,2,2,2,2,2,2,2,2,2,2,2,2,2,2,2,2,2
2,2,2,2,2,2,2,2,2,2,2,2,2,2,2,2,2,2,2,2,2,2,2,2,2,2,2,2,2,2,2,2,2,2,2,2
2,2,2,2,2,2,2,2,2,2,2,2,2,2,2,2,2,2,2,2,2,2,2,2,2,2,2,2,2,2,2,2,2,2,2,2
2,2,2,2,2,2,2,2,2,2,2,2,2,5,2,2,2,2,2,2,2,2,2,2,2,2,2,2,2,2,2,2,2,2,2,2
2,2,2,2,2,2,2,2,2,2,2,2,2,2,2,2,2,2,2,2,2,2,2,2,2,2,2,2,2,2,2,2,2,2,2,2
2,2,2,2,2,2,2,6,2,2,2,2,2,2,2,2,2,2,2,2,2,2,2,2,2,2,2,2,2,2,2,2,2,2,2,2
2,2,2,2,2,2,2,2,2,2,2,2,2,2,2,2,2,2,2,2,2,2,2,2,2,2,2,2,2,2,2,2,2,2,2,2
2,2,2,2,2,2,2,2,2,2,2,2,2,2,2,2,2,2,2,2,2,2,2,2,2,2,2,2,2,2,2,2,2,2,2,2
2,2,2,2,2,2,2,2,2,2,2,2,2,2,2,2,2,2,2,2,2,2,2,2,2,2,2,2,2,2,2,2,2,2,2,2
2,2,2,2,2,2,2,2,2,2,2,2,2,2,2,2,2,2,2,2,2,2,2,2,2,2,2,2,2,2,2,2,2,2,2,2
2,2,2,2,2,2,2,2,2,2,2,2,2,2,2,2,2,2,2,2,2,2,2,2,2,2,2,2,2,2,2,2,2,2,2,2
2,2,2,2,2,2,2,2,2,2,2,2,2,2,2,2,2,2,2,2,2,2,2,2,2,2,2,2,2,2,2,2,2,2,2,2
2,2,2,2,2,2,2,2,2,2,2,2,2,2,2,2,2,2,2,2,2,2,2,2,2,2,2,2,2,2,2,2,2,2,2,2
2,2,2,2,2,2,2,2,2,2,2,2,2,2,2,2,2,2,2,2,2,2,2,2,2,2,2,2,2,2,2,2,2,2,2,2
2,2,2,2,2,2,2,2,2,2,2,2,2,2,2,2,2,2,2,2,2,2,2,2,2,2,2,2,2,2,2,2,2,2,2,2
2,2,2,2,2,2,2,2,2,2,2,2,2,2,2,2,2,2,2,2,2,2,2,2,2,2,2,2,2,2,2,2,7,2,2,2
2,2,2,2,2,2,2,2,2,2,2,2,2,2,2,2,2,2,2,2,2,2,2,2,2,2,2,2,2,8,2,2,2,2,2,2
2,3,2,2,2,2,2,2,2,2,2,2,2,2,2,2,2,2,2,2,2,2,2,2,2,2,2,2,2,2,2,2,2,2,2,2
2,2,2,2,2,2,2,2,2,2,2,2,2,2,2,2,2,2,2,2,2,2,2,2,2,2,2,2,2,2,2,2,2,2,2,2
2,2,2,2,2,2,2,2,2,2,2,2,2,2,2,2,2,2,2,2,2,2,2,2,2,2,2,2,2,2,2,2,2,2,2,2
2,2,2,2,2,2,2,2,2,2,2,2,2,2,2,2,2,2,2,2,2,2,2,2,2,2,2,2,2,2,2,2,2,2,2,2
2,2,2,2,2,2,2,2,2,2,2,2,2,2,2,2,2,2,2,2,2,2,2,2,2,2,2,2,2,2,2,2,2,2,2,2
2,2,2,2,2,2,2,2,2,2,2,2,2,2,2,2,2,2,2,2,2,2,2,2,2,2,2,2,2,2,2,2,2,2,2,2
2,11,2,2,2,10,2,2,2,2,2,2,2,2,2,2,2,2,2,2,2,2,2,2,2,2,2,2,2,9,2,2,2,2,2,2
2,2,2,2,2,2,2,2,2,2,2,2,2,2,2,2,2,2,2,2,2,2,2,2,2,2,2,2,2,2,2,2,2,2,2,2
2,2,2,2,2,2,2,2,2,2,2,3,2,2,2,2,2,2,2,2,2,2,2,2,2,2,2,2,2,2,2,2,2,2,2,2
1,2,2,2,2,2,2,2,2,2,2,2,2,2,2,2,2,2,2,2,2,2,2,2,2,2,2,2,2,2,2,2,2,2,2,1
endlayer

layer
1,2,2,2,2,2,2,2,2,2,2,2,2,2,2,2,2,12,12,2,2,2,2,2,2,2,2,2,2,2,2,2,2,2,2,1
2,2,2,2,2,2,2,2,2,2,2,2,2,2,2,2,2,12,12,2,2,13,2,2,2,2,2,2,2,2,2,2,2,2,2,2
2,2,2,2,2,2,2,2,2,2,2,2,2,2,2,2,2,12,12,2,2,13,2,2,14,2,2,2,2,2,2,2,2,14,2,2
2,2,2,2,2,2,2,2,2,2,2,2,2,2,2,2,2,12,12,2,2,13,2,2,2,2,2,2,2,2,2,2,2,2,2,2
2,16,2,2,2,2,2,2,2,2,2,2,2,2,2,2,2,12,12,2,2,13,2,2,2,2,15,15,15,15,15,15,2,2,2,2
2,2,2,2,2,2,2,2,2,2,2,2,2,2,2,2,2,12,12,2,2,13,2,2,2,2,15,14,14,14,14,15,2,2,2,2
2,2,2,2,2,2,2,2,2,2,2,2,2,2,2,2,2,12,12,2,2,13,2,2,2,2,15,14,14,14,14,15,2,2,2,2
2,2,2,2,2,2,16,2,2,2,2,2,2,2,2,2,2,12,12,2,2,13,2,2,2,2,15,15,15,15,15,15,2,2,2,2
2,2,2,2,2,2,2,2,2,2,2,2,2,2,2,2,2,12,12,2,2,13,2,2,2,2,2,2,2,2,2,2,2,2,2,2
2,2,2,2,2,2,2,2,2,2,2,2,2,2,2,2,2,12,12,2,2,13,2,2,14,2,2,2,2,2,2,2,2,14,2,2
2,16,2,2,2,2,2,2,2,2,2,2,2,2,2,2,2,12,12,2,2,13,2,2,2,2,2,2,2,2,2,2,2,2,2,2
2,2,2,2,2,2,2,2,2,2,2,2,2,2,2,2,2,12,12,2,2,13,2,2,2,2,2,2,2,2,2,2,2,2,2,2
2,2,2,2,2,2,2,2,2,2,2,2,2,2,2,2,2,12,12,2,2,13,13,13,13,13,13,13,13,13,13,13,13,13,13,2
2,2,2,2,2,2,2,2,2,2,2,2,2,2,2,2,2,12,12,2,2,2,2,2,2,2,2,2,2,2,2,2,2,2,2,2
2,2,2,2,2,2,2,2,2,2,2,2,2,2,2,2,2,12,12,2,2,2,2,2,2,2,2,2,2,2,2,2,2,2,2,2
2,2,2,2,2,2,2,2,2,2,2,2,2,2,2,2,2,12,12,2,2,2,2,2,2,2,2,2,2,2,2,2,2,2,2,2
2,2,2,2,2,2,2,2,2,2,2,2,2,2,2,2,2,12,12,2,2,2,2,2,2,2,2,2,2,2,2,2,2,2,2,2
12,12,12,12,12,12,12,12,12,12,12,12,12,12,12,12,12,12,12,12,12,12,12,12,12,12,12,12,12,12,12,12,12,12,12,12
12,12,12,12,12,12,12,12,12,12,12,12,12,12,12,12,12,12,12,12,12,12,12,12,12,12,12,12,12,12,12,12,12,12,12,12
2,2,2,2,2,2,2,2,2,2,2,2,2,2,2,2,2,2,12,12,2,2,2,2,2,2,2,2,2,2,2,2,2,2,2,2
2,2,2,2,2,2,2,2,2,2,14,14,14,14,14,2,2,2,12,12,2,15,2,15,15,2,15,2,2,2,2,2,2,2,2,2
2,2,2,2,2,2,2,2,2,14,14,2,2,2,14,14,2,2,12,12,2,2,2,15,15,2,2,2,2,2,2,2,2,2,2,2
2,2,2,2,2,2,2,2,14,14,2,2,2,2,2,14,14,2,12,12,2,15,15,15,15,15,15,2,2,2,2,2,2,2,2,2
2,2,2,2,2,2,2,2,14,2,2,2,2,2,2,2,14,2,12,12,2,15,15,15,15,15,15,2,2,2,2,2,2,2,2,2
2,2,2,2,2,2,2,2,14,2,2,2,2,2,2,2,14,2,12,12,2,2,2,15,15,2,2,2,2,2,2,2,2,2,2,2
2,2,2,2,2,2,2,2,14,2,2,2,2,2,2,2,14,2,12,12,2,15,2,15,15,2,15,2,2,2,2,2,2,2,2,2
2,2,2,2,2,2,2,2,14,14,2,2,2,2,2,14,14,2,12,12,2,2,2,2,2,2,2,2,2,2,2,2,2,2,2,2
2,2,2,2,2,2,2,2,2,14,14,2,2,2,14,14,2,2,12,12,2,2,2,2,2,2,2,2,2,2,2,2,2,2,2,2
2,2,2,2,2,2,2,2,2,2,14,14,14,14,14,2,2,2,12,12,2,2,2,2,2,2,2,2,2,2,2,2,2,2,2,2
2,2,2,2,2,2,2,2,2,2,2,2,2,2,2,2,2,12,12,12,2,2,2,2,2,2,2,2,2,2,2,2,2,2,2,2
2,2,2,2,2,2,2,2,2,2,2,2,2,2,2,2,2,12,12,2,2,2,2,2,2,2,2,2,2,2,2,2,2,2,2,2
2,2,2,2,2,2,2,2,2,2,2,2,2,2,2,2,2,12,12,2,2,2,2,2,2,2,2,2,2,2,2,2,2,2,2,2
2,2,2,2,2,2,2,2,2,2,2,2,2,2,2,2,2,12,12,2,2,2,2,2,2,2,2,2,2,2,2,2,2,2,2,2
2,2,2,2,2,2,2,2,2,2,2,2,2,2,2,2,2,12,12,2,2,2,2,2,2,2,2,2,2,2,2,2,2,2,2,2
2,2,2,2,2,2,2,2,2,2,2,2,2,2,2,2,2,12,12,2,2,2,2,2,2,2,2,2,2,2,2,2,2,2,2,2
1,2,2,2,2,2,2,2,2,2,2,2,2,2,2,2,2,12,12,2,2,2,2,2,2,2,2,2,2,2,2,2,2,2,2,1
endlayer

layer
1,2,2,2,2,2,2,2,2,2,2,2,2,2,2,2,1,17,17,1,2,2,2,2,2,2,2,2,2,2,2,2,2,2,2,1
2,16,21,16,0,0,0,0,2,0,20,20,18,2,19,18,0,0,0,0,0,0,18,12,12,12,12,12,12,12,12,12,12,12,12,2
2,21,0,0,0,0,0,22,2,0,18,18,0,2,0,18,0,0,0,0,0,0,0,12,1,1,12,12,1,1,12,12,1,1,12,2
2,25,0,0,0,0,19,24,2,0,23,23,0,2,0,18,0,0,0,0,0,0,0,12,1,18,0,0,18,18,0,0,18,1,12,2
2,21,0,0,0,0,18,0,2,0,0,0,0,27,0,18,0,0,0,0,0,0,0,12,12,0,26,26,26,26,26,26,0,12,12,2
2,16,0,0,0,0,18,0,2,0,0,0,19,2,0,18,0,0,0,0,0,0,18,12,1,18,26,0,0,0,0,26,18,1,12,2
2,21,0,0,0,0,18,0,2,18,0,29,28,2,0,18,0,0,0,0,0,0,18,12,1,18,26,0,0,0,0,26,18,1,12,2
2,25,0,0,0,0,21,0,2,2,30,2,2,2,18,18,0,0,0,0,0,0,0,12,12,0,26,26,26,26,26,26,0,12,12,2
2,21,0,0,0,0,25,0,2,0,0,0,0,0,0,0,0,0,0,0,0,0,0,12,1,18,0,0,18,18,0,0,18,1,12,2
2,16,0,0,0,0,25,0,2,0,0,0,0,0,0,0,0,0,0,0,0,0,0,12,1,1,12,12,1,1,12,12,1,1,12,2
2,21,0,0,0,0,16,0,2,0,0,18,31,31,18,18,0,0,0,0,0,0,18,12,12,12,12,12,12,12,12,12,12,12,12,2
2,25,0,0,0,0,32,0,2,0,0,18,0,28,18,0,0,0,0,0,0,0,1,18,18,0,0,0,18,18,0,0,0,18,18,2
2,0,0,0,0,0,33,0,2,0,0,27,0,0,18,0,0,0,0,0,0,0,0,0,0,0,0,0,0,0,0,0,0,0,0,2
2,21,0,0,0,0,34,0,2,0,0,18,0,0,18,0,0,0,0,0,0,0,0,0,0,0,0,0,0,0,0,0,0,0,0,2
2,16,21,0,0,0,28,0,2,0,0,18,0,21,18,0,0,0,0,0,0,0,0,0,0,0,0,0,0,0,0,0,0,0,0,2
2,2,2,2,30,2,2,2,1,0,0,18,31,31,18,18,0,0,0,0,0,0,0,0,0,0,0,0,0,0,0,0,0,0,0,2
1,0,0,0,0,0,0,0,0,0,0,0,0,0,0,0,0,0,0,35,0,0,0,0,0,0,0,0,0,0,0,0,0,0,0,1
27,0,0,0,0,0,0,0,0,0,0,0,0,0,0,0,0,0,0,0,0,0,0,0,0,0,0,0,0,0,0,0,0,0,0,27
27,0,0,0,0,0,0,0,0,0,0,0,0,0,0,0,0,0,0,0,0,0,0,0,0,0,0,0,0,0,0,0,0,0,0,27
1,0,0,0,0,0,0,0,0,0,36,36,36,36,36,0,0,0,0,0,12,12,12,0,0,12,12,12,0,0,0,0,0,0,0,1
2,0,0,0,0,0,0,0,0,36,0,0,0,0,0,36,0,0,0,0,12,18,12,0,0,12,18,12,0,0,0,0,0,0,0,2
2,17,18,0,0,0,0,0,36,0,0,1,37,1,0,0,36,0,0,0,12,12,12,0,0,12,12,12,0,0,0,0,0,0,0,2
2,0,18,0,0,0,0,36,0,0,1,1,1,1,1,0,0,36,0,0,0,0,0,0,0,0,0,0,0,0,1,18,17,18,1,2
2,0,18,0,0,0,0,36,0,1,1,1,1,1,1,1,0,36,0,0,0,0,0,0,0,0,0,0,18,18,2,0,0,0,38,2
2,0,18,0,0,0,0,36,0,37,1,1,1,1,1,37,0,36,0,0,12,12,12,0,0,12,12,12,18,0,39,0,0,0,38,2
2,0,18,0,0,0,0,36,0,1,1,1,1,1,1,1,0,36,0,0,12,18,12,0,0,12,18,12,18,0,28,0,0,0,38,2
2,0,18,0,0,0,0,36,0,0,1,1,1,1,1,0,0,36,0,0,12,12,12,0,0,12,12,12,18,18,2,0,0,38,38,2
2,18,18,0,0,0,0,0,36,0,0,1,37,1,0,0,36,0,0,0,0,0,18,0,0,0,18,0,0,0,1,2,30,2,1,2
2,0,0,0,0,0,0,0,0,36,0,0,0,0,0,36,0,0,0,0,0,0,18,0,0,0,18,0,0,0,0,0,0,0,0,2
2,0,0,0,0,18,0,0,0,0,36,36,36,36,36,0,0,0,0,0,0,1,2,2,40,2,2,2,1,0,0,0,0,0,18,2
2,16,16,16,16,0,0,0,0,0,0,0,0,0,0,0,0,0,0,0,0,2,0,0,0,0,0,18,2,1,2,40,2,1,1,2
2,2,2,2,2,2,1,0,0,0,0,0,0,0,0,0,0,0,0,0,0,2,0,0,0,0,0,0,2,19,2,0,18,18,18,2
2,0,0,0,0,0,2,0,18,0,0,0,0,0,0,0,0,0,0,0,0,42,0,0,0,0,0,41,2,0,18,0,0,0,0,2
2,46,19,45,44,28,1,0,0,0,18,18,18,18,18,0,0,0,0,0,0,2,0,0,0,0,0,43,2,0,27,0,0,0,0,2
2,0,0,0,0,0,48,0,0,0,18,0,0,0,27,0,0,0,0,0,0,2,18,28,47,29,19,0,2,28,2,1,29,1,18,2
1,2,2,2,2,2,2,2,2,2,2,2,2,2,2,2,1,17,17,1,2,2,2,2,2,2,2,2,2,2,2,2,2,2,2,1
endlayer

layer
1,2,2,2,2,2,2,2,2,2,2,2,2,2,2,2,49,0,0,49,2,2,2,2,2,2,2,2,2,2,2,2,2,2,2,1
2,21,0,0,18,0,0,0,2,0,0,0,50,2,0,23,18,0,0,18,0,0,18,0,0,0,0,0,0,0,0,0,0,0,0,2
2,25,0,0,0,0,0,0,2,0,23,23,0,18,0,23,0,0,0,0,0,0,0,0,1,1,0,0,1,1,0,0,1,1,0,2
2,0,0,0,0,0,0,22,2,51,0,0,0,2,0,23,0,0,0,0,0,0,0,0,1,50,0,0,23,23,0,0,50,1,0,2
2,0,0,0,0,0,52,24,2,0,0,0,0,0,0,23,0,0,0,0,0,0,0,0,0,0,0,0,0,0,0,0,0,0,0,2
2,0,0,0,0,0,23,0,2,0,0,0,0,2,0,23,0,0,0,0,0,0,18,0,1,23,0,0,0,0,0,0,23,1,0,2
2,0,0,0,0,0,52,0,2,50,0,0,0,18,0,23,0,0,0,0,0,0,18,0,1,23,0,0,0,0,0,0,23,1,0,2
2,18,0,0,0,0,0,0,2,2,53,2,18,2,23,18,0,0,0,0,0,0,0,0,0,0,0,0,0,0,0,0,0,0,0,2
2,25,0,0,0,0,0,0,2,0,0,0,0,0,0,0,0,0,0,0,0,0,0,0,1,50,0,0,23,23,0,0,50,1,0,2
2,21,0,0,0,0,0,0,18,0,0,0,0,0,0,0,0,0,0,0,0,0,0,0,1,1,0,0,1,1,0,0,1,1,0,2
2,0,0,0,0,0,0,0,2,18,0,18,0,0,18,50,0,0,0,0,0,0,18,0,0,0,0,0,0,0,0,0,0,0,0,2
2,0,0,0,0,0,0,0,18,0,0,23,0,0,23,0,0,0,0,0,0,0,1,18,50,0,0,0,18,18,0,0,0,50,18,2
2,0,0,0,0,0,0,0,2,18,0,0,0,0,23,0,0,0,0,0,0,0,0,0,0,0,0,0,0,0,0,0,0,0,0,2
2,0,0,0,0,0,0,0,18,0,0,23,0,0,23,0,0,0,0,0,0,0,0,0,0,0,0,0,0,0,0,0,0,0,0,2
2,21,0,18,0,18,0,0,2,0,0,23,0,0,23,0,0,0,0,0,0,0,0,0,0,0,0,0,0,0,0,0,0,0,0,2
2,2,18,2,53,2,18,2,1,0,0,18,0,0,18,50,0,0,0,35,0,0,0,0,0,0,0,0,0,0,0,0,0,0,0,2
49,18,0,18,0,18,0,0,0,0,0,0,0,0,0,0,0,0,0,35,0,0,0,0,0,0,0,0,0,0,0,0,0,0,18,49
0,0,0,0,0,0,0,0,0,0,0,0,0,0,0,0,0,0,0,35,0,0,0,0,0,0,0,0,0,0,0,0,0,0,0,0
0,0,0,0,0,0,0,0,0,0,0,0,0,0,0,0,0,0,0,0,0,0,0,0,0,0,0,0,0,0,0,0,0,0,0,0
49,18,0,0,0,0,0,0,0,0,0,0,0,0,0,0,0,0,0,0,0,0,0,0,0,0,0,0,0,0,0,0,0,0,18,49
2,0,0,0,0,0,0,0,0,0,0,0,0,0,0,0,0,0,0,0,0,18,0,0,0,0,18,0,0,0,0,0,0,0,0,2
2,0,18,0,0,0,0,0,0,0,0,0,0,0,0,0,0,0,0,0,0,0,0,0,0,0,0,0,0,0,0,0,0,0,0,2
2,0,23,0,0,0,0,0,0,0,50,49,1,49,50,0,0,0,0,0,0,0,0,0,0,0,0,0,0,0,1,0,0,0,1,2
2,0,23,0,0,0,0,0,0,0,49,37,37,37,49,0,0,0,0,0,0,0,0,0,0,0,0,0,18,23,2,0,0,0,38,2
2,0,23,0,0,0,0,0,0,0,1,37,1,37,1,0,0,0,0,0,0,0,0,0,0,0,0,0,23,0,0,0,0,0,38,2
2,0,23,0,0,0,0,0,0,0,49,37,37,37,49,0,0,0,0,0,0,18,0,0,0,0,18,0,23,0,0,0,0,0,0,2
2,0,23,0,0,0,0,0,0,0,50,49,1,49,50,0,0,0,0,0,0,0,0,0,0,0,0,0,18,23,2,51,0,0,38,2
2,50,18,0,0,0,0,0,0,0,0,0,0,0,0,0,0,0,0,0,0,0,18,0,0,0,18,0,0,0,1,2,53,2,1,2
2,0,0,0,0,0,0,0,0,0,0,0,0,0,0,0,0,0,0,0,0,0,50,0,0,0,50,0,0,0,0,0,0,0,0,2
2,0,0,0,0,18,0,0,0,0,0,0,0,0,0,0,0,0,0,0,0,1,18,2,53,2,18,2,1,0,0,0,0,0,50,2
2,0,0,0,0,0,0,0,0,0,0,0,0,0,0,0,0,0,0,0,0,18,0,0,0,0,0,50,2,1,2,53,2,1,1,2
2,2,18,2,18,2,1,0,0,0,0,0,0,0,0,0,0,0,0,0,0,2,0,0,0,0,0,0,2,0,2,0,23,23,23,2
2,0,0,0,0,0,18,0,18,0,0,0,0,0,0,0,0,0,0,0,0,53,0,0,0,0,0,0,2,0,0,0,0,0,0,2
2,52,0,54,0,0,1,0,0,0,18,23,23,23,18,0,0,0,0,0,0,2,0,0,0,0,0,41,2,0,0,0,0,0,0,2
2,51,0,0,0,0,53,0,0,0,50,0,0,0,0,0,18,0,0,18,0,18,50,0,23,0,0,43,2,50,2,1,29,1,50,2
1,2,2,2,2,2,2,2,2,2,2,2,2,2,2,2,49,0,0,49,2,2,2,2,2,2,2,2,2,2,2,2,2,2,2,1
endlayer

layer
1,2,2,2,2,2,2,2,2,2,2,2,2,2,2,2,49,0,0,49,2,2,2,2,2,2,2,2,2,2,2,2,2,2,2,1
2,0,0,0,50,0,0,0,2,47,47,47,47,2,18,55,50,0,0,50,0,0,18,0,0,0,0,0,0,0,0,0,0,0,0,2
2,0,0,0,0,0,57,0,2,47,47,47,47,2,18,56,0,0,0,0,0,0,0,0,1,1,0,0,1,1,0,0,1,1,0,2
2,0,0,0,0,0,58,0,2,51,47,47,47,2,18,55,0,0,0,0,0,0,0,0,1,0,0,0,0,0,0,0,0,1,0,2
2,0,0,0,0,0,57,22,2,47,47,47,47,2,18,56,0,0,0,0,0,0,0,0,0,0,0,0,0,0,0,0,0,0,0,2
2,0,0,0,0,0,58,24,2,47,47,47,47,2,18,55,0,0,0,0,0,0,18,0,1,0,0,0,0,0,0,0,0,1,0,2
2,0,0,0,0,0,57,0,2,47,47,47,47,2,18,56,0,0,0,0,0,0,18,0,1,0,0,0,0,0,0,0,0,1,0,2
2,50,0,0,0,0,58,0,2,2,2,2,2,2,18,55,0,0,0,0,0,0,0,0,0,0,0,0,0,0,0,0,0,0,0,2
2,0,0,0,0,0,57,0,2,0,59,0,59,0,0,0,0,0,0,0,0,0,0,0,1,0,0,0,0,0,0,0,0,1,0,2
2,0,0,0,0,0,58,0,57,0,0,0,0,0,0,0,0,0,0,0,0,0,0,0,1,1,0,0,1,1,0,0,1,1,0,2
2,0,0,0,0,0,57,0,2,50,0,18,18,18,18,0,0,0,0,0,0,0,18,0,0,0,0,0,0,0,0,0,0,0,0,2
2,0,0,0,0,0,58,0,57,0,0,18,0,0,18,0,0,0,0,0,0,0,1,18,0,0,0,0,18,18,0,0,0,0,18,2
2,0,0,0,0,0,57,0,2,50,0,18,0,0,18,0,0,0,0,0,0,0,0,0,0,0,0,0,0,0,0,0,0,0,0,2
2,0,0,0,0,0,58,0,57,0,0,18,0,0,18,0,0,0,0,0,0,0,0,0,0,0,0,0,0,0,0,0,0,0,0,2
2,0,0,50,0,50,57,0,2,0,0,18,0,0,18,0,0,0,0,0,0,0,0,0,0,0,0,0,0,0,0,0,0,0,0,2
2,2,57,2,49,2,57,2,1,0,0,18,18,18,18,0,0,0,0,0,0,0,0,0,0,0,0,0,0,0,0,0,0,0,0,2
49,50,0,50,0,50,0,0,0,0,0,0,0,0,0,0,0,0,0,60,0,0,0,0,0,0,0,0,0,0,0,0,0,0,50,49
0,0,0,0,0,0,0,0,0,0,0,0,0,0,0,0,0,0,0,0,0,0,0,0,0,0,0,0,0,0,0,0,0,0,0,0
0,0,0,0,0,0,0,0,0,0,0,0,0,0,0,0,0,0,0,0,0,0,0,0,0,0,0,0,0,0,0,0,0,0,0,0
49,50,0,0,0,0,0,0,0,0,0,0,0,0,0,0,0,0,0,0,0,0,0,0,0,0,0,0,0,0,0,0,0,0,50,49
2,0,0,0,0,0,0,0,0,0,0,0,0,0,0,0,0,0,0,0,0,18,0,0,0,0,18,0,0,0,0,0,0,0,0,2
2,18,56,0,0,0,0,0,0,0,0,0,0,0,0,0,0,0,0,0,0,0,0,0,0,0,0,0,0,0,0,0,0,0,0,2
2,18,61,0,0,0,0,0,0,0,0,1,0,1,0,0,0,0,0,0,0,0,0,0,0,0,0,0,0,56,1,0,0,0,1,2
2,18,56,0,0,0,0,0,0,0,1,36,0,36,1,0,0,0,0,0,0,0,0,0,0,0,0,0,56,18,2,0,0,0,38,2
2,18,61,0,0,0,0,0,0,0,0,0,1,0,0,0,0,0,0,0,0,0,0,0,0,0,0,0,56,18,1,0,0,0,0,2
2,18,56,0,0,0,0,0,0,0,1,36,0,36,1,0,0,0,0,0,0,18,0,0,0,0,18,0,56,18,1,0,0,0,18,2
2,18,61,0,0,0,0,0,0,0,0,1,0,1,0,0,0,0,0,0,0,0,0,0,0,0,0,0,56,18,2,51,0,0,0,2
2,18,56,0,0,0,0,0,0,0,0,0,0,0,0,0,0,0,0,0,0,0,62,56,62,56,62,0,0,56,1,2,1,2,1,2
2,0,0,0,0,0,0,0,0,0,0,0,0,0,0,0,0,0,0,0,0,0,18,18,18,18,18,0,0,0,0,0,0,0,0,2
2,56,57,56,57,56,0,0,0,0,0,0,0,0,0,0,0,0,0,0,0,1,1,1,1,1,1,1,1,0,0,0,0,0,0,2
2,18,18,18,18,18,0,0,0,0,0,0,0,0,0,0,0,0,0,0,59,1,63,63,63,63,63,63,2,1,2,0,2,1,1,2
2,1,1,1,1,1,1,0,0,0,0,0,0,0,0,0,0,0,0,0,0,1,63,63,63,63,63,0,2,0,2,0,0,0,0,2
2,0,0,18,0,0,1,18,56,0,0,0,0,0,0,0,0,0,0,0,0,1,63,63,63,63,63,0,2,0,18,0,0,0,0,2
2,18,18,18,18,18,1,18,57,0,56,62,56,62,56,0,0,0,0,0,0,1,63,63,63,63,63,0,2,0,18,0,0,0,0,2
2,51,0,18,0,0,1,18,56,0,18,18,18,18,18,0,50,0,0,50,59,1,63,63,63,63,63,41,2,0,2,1,29,1,18,2
1,2,2,2,2,2,2,2,2,2,2,2,2,2,2,2,49,0,0,49,2,2,2,2,2,2,2,2,2,2,2,2,2,2,2,1
endlayer

layer
1,2,65,22,22,22,22,22,22,22,22,22,22,22,64,2,49,0,0,49,2,65,22,22,22,22,22,22,22,22,22,22,22,64,2,1
2,0,0,0,0,0,0,0,2,0,0,0,0,12,66,43,0,0,0,0,43,0,18,0,0,0,0,0,0,0,0,0,0,0,63,2
67,0,0,0,0,0,57,0,2,0,0,0,20,12,23,0,0,0,0,0,56,18,18,0,1,1,69,68,1,1,69,68,1,1,0,67
64,0,0,0,0,0,58,0,2,0,0,0,0,12,66,0,0,0,0,0,56,18,18,0,1,18,0,0,18,18,0,0,18,1,0,65
64,0,0,0,0,0,57,0,2,0,0,0,0,12,23,0,0,0,0,0,56,18,18,0,47,0,0,0,0,0,0,0,0,47,0,65
64,0,0,0,0,0,58,22,2,0,0,0,0,12,66,0,0,0,0,0,56,18,18,0,1,18,0,0,0,0,0,0,18,1,0,65
64,0,0,0,0,0,57,24,2,0,0,0,0,12,23,0,0,0,0,0,56,18,18,0,1,18,0,0,0,0,0,0,18,1,0,65
64,0,0,0,0,0,58,0,2,1,12,12,12,1,66,0,0,0,0,0,56,18,18,0,47,0,0,0,0,0,0,0,0,47,0,65
64,0,0,0,70,0,57,0,2,0,0,0,0,0,0,0,0,0,0,0,56,18,18,0,1,18,0,0,18,18,0,0,18,1,0,65
64,0,0,0,0,0,58,0,2,59,0,0,0,0,0,0,0,0,0,0,56,18,18,0,1,1,69,68,1,1,69,68,1,1,0,65
64,0,0,0,0,0,57,0,2,0,0,23,56,56,23,0,0,0,0,0,56,18,18,0,0,0,0,0,0,0,0,0,0,0,0,65
64,0,0,0,0,0,58,0,2,59,0,71,61,61,71,0,0,0,0,0,0,0,1,18,18,18,18,18,18,18,18,18,18,18,18,65
64,0,0,0,0,0,57,0,2,0,0,23,56,56,23,0,0,0,0,0,0,0,0,18,18,18,18,18,18,18,18,18,18,18,0,65
64,0,0,0,0,0,58,0,2,59,0,71,61,61,71,0,0,0,0,0,0,0,0,56,56,56,56,56,56,56,56,56,56,56,0,65
22,0,0,0,0,0,57,0,2,0,0,23,56,56,23,0,0,0,0,0,0,0,0,0,0,0,0,0,0,0,0,0,0,0,0,22
2,2,2,2,2,2,2,2,1,0,0,71,61,61,71,0,0,0,0,0,0,0,0,0,0,0,0,0,0,0,0,0,0,0,45,2
49,0,59,0,59,0,59,0,0,0,0,0,0,0,0,0,0,0,0,0,0,0,0,0,0,0,0,0,0,0,0,0,0,0,0,49
0,0,0,0,0,0,0,0,0,0,0,0,0,0,0,0,0,0,0,0,0,0,0,0,0,0,0,0,0,0,0,0,0,0,0,0
0,0,0,0,0,0,0,0,0,0,0,0,0,0,0,0,0,0,0,0,0,0,0,0,0,0,0,0,0,0,0,0,0,0,0,0
49,0,0,0,0,0,0,0,0,0,0,0,0,0,0,0,0,0,0,0,0,0,0,0,0,0,0,0,0,0,0,0,0,0,0,49
2,46,0,0,0,0,0,0,0,0,0,0,0,0,0,0,0,0,0,0,0,18,0,0,0,0,18,0,0,0,0,0,0,0,45,2
67,23,0,0,0,0,0,0,0,0,0,0,0,0,0,0,0,0,0,0,0,0,0,0,0,0,0,0,0,0,0,0,0,0,0,67
64,71,0,0,0,0,0,0,0,0,0,0,0,0,0,0,0,0,0,0,0,72,0,0,0,0,0,0,0,0,1,0,0,0,1,65
64,23,0,0,0,0,0,0,0,0,0,0,0,0,0,0,0,0,0,0,0,72,0,0,0,0,0,0,0,23,2,0,0,0,0,65
64,71,0,0,0,0,0,0,0,0,0,0,73,0,0,0,0,0,0,0,0,0,0,0,0,0,0,0,0,23,18,0,0,0,0,65
64,23,0,0,0,0,0,0,0,0,0,0,0,0,0,0,0,0,72,72,0,18,0,72,72,0,18,0,0,23,18,0,0,0,50,65
64,71,0,0,0,0,0,0,0,0,0,0,0,0,0,0,0,0,0,0,0,0,0,0,0,0,0,0,0,23,2,51,0,0,0,65
64,23,0,0,0,0,0,0,0,0,0,0,0,0,0,0,0,0,0,0,0,72,0,0,0,0,0,0,0,0,1,2,18,2,1,65
64,0,0,0,0,0,0,0,0,0,0,0,0,0,0,0,0,0,0,0,0,72,74,23,74,23,74,0,0,0,0,0,0,0,0,65
64,0,0,0,0,0,0,0,0,0,0,0,0,0,0,0,0,0,0,0,0,1,18,2,18,2,18,2,1,0,0,0,0,0,0,65
64,23,52,23,52,23,18,0,0,0,0,0,0,0,0,0,0,0,0,0,0,2,0,0,0,0,0,0,2,1,2,2,2,1,1,65
64,2,2,2,2,2,1,18,0,0,0,0,0,0,0,0,0,0,0,0,0,18,0,0,75,0,18,18,2,63,2,0,0,0,63,65
64,16,16,0,16,16,2,23,0,0,0,0,0,0,0,0,0,0,0,0,0,2,0,76,18,0,18,0,2,0,18,0,0,0,0,65
22,0,0,50,0,0,2,52,0,0,0,0,0,0,0,0,0,0,0,0,0,18,0,0,0,0,18,0,2,0,18,0,0,0,0,22
2,51,0,16,16,16,2,23,0,0,23,74,23,74,23,77,0,0,0,0,77,2,0,0,0,0,0,0,2,63,2,1,1,1,63,2
1,2,65,67,67,67,67,67,67,67,67,67,67,67,64,2,49,0,0,49,2,65,67,67,67,67,67,67,67,67,67,67,67,64,2,1
endlayer

layer
1,2,69,78,78,78,78,78,78,78,78,78,78,78,68,2,1,1,1,1,2,69,78,78,78,78,78,78,78,78,78,78,78,68,2,1
2,79,79,79,79,79,79,79,1,59,59,59,59,59,59,59,59,59,59,59,59,59,59,59,59,59,59,59,59,59,59,59,59,59,59,2
24,79,79,79,79,79,79,79,1,0,0,0,0,0,0,0,0,0,0,0,0,23,2,59,2,2,2,2,2,2,2,2,2,2,59,24
68,79,79,79,79,79,79,0,1,0,0,0,0,0,0,0,0,0,0,0,0,23,2,59,2,59,59,59,59,59,59,59,59,2,59,69
68,79,79,79,79,79,79,0,1,0,0,0,0,0,0,0,0,0,0,0,0,23,2,59,2,59,0,0,0,0,0,0,59,2,59,69
68,79,79,79,79,79,79,0,1,0,0,0,0,0,0,0,0,0,0,0,0,23,2,59,2,59,0,0,0,0,0,0,59,2,59,69
68,79,79,79,79,79,79,22,1,0,0,0,0,0,0,0,0,0,0,0,0,23,2,59,2,59,0,0,0,0,0,0,59,2,59,69
68,79,79,79,79,79,79,79,1,50,0,0,0,50,0,0,0,0,0,0,0,23,2,59,2,59,0,0,0,0,0,0,59,2,59,69
68,79,79,79,80,79,79,79,1,0,0,0,0,0,0,0,0,0,0,0,0,23,2,59,2,59,59,59,59,59,59,59,59,2,59,69
68,79,79,79,79,79,79,79,1,0,0,0,0,0,0,0,0,0,0,0,0,23,2,59,2,2,2,2,2,2,2,2,2,2,59,69
68,79,79,79,79,79,79,79,1,0,0,0,0,0,0,0,0,0,0,0,0,23,2,59,59,59,59,59,59,59,59,59,59,59,59,69
68,79,79,79,79,79,79,79,1,0,0,0,0,0,0,0,0,0,0,0,0,0,1,2,2,2,2,2,2,2,2,2,2,2,59,69
68,79,79,79,79,79,79,79,1,0,0,0,0,0,0,0,0,0,0,0,0,0,0,23,23,23,23,23,23,23,23,23,23,23,59,69
68,79,79,79,79,79,79,79,1,0,0,0,0,0,0,0,0,0,0,0,0,0,0,0,0,0,0,0,0,0,0,0,0,0,59,69
78,79,79,79,79,79,79,79,1,0,0,0,0,0,0,0,0,0,0,0,0,0,0,0,0,0,0,0,0,0,0,0,0,0,59,78
2,1,1,1,1,1,1,1,1,0,0,0,0,0,0,0,0,0,0,0,0,0,0,0,0,0,0,0,0,0,0,0,0,0,59,2
1,59,0,0,0,0,0,0,0,0,0,0,0,0,0,0,0,0,0,0,0,0,0,0,0,0,0,0,0,0,0,0,0,0,59,1
1,59,0,0,0,0,0,0,0,0,0,0,0,0,0,0,0,0,0,0,0,0,0,0,0,0,0,0,0,0,0,0,0,0,59,1
1,59,0,0,0,0,0,0,0,0,0,0,0,0,0,0,0,0,0,0,0,0,0,0,0,0,0,0,0,0,0,0,0,0,59,1
1,59,0,0,0,0,0,0,0,0,0,0,0,0,0,0,0,0,0,0,0,0,0,0,0,0,0,0,0,0,0,0,0,0,59,1
2,59,0,0,0,0,0,0,0,0,0,0,0,0,0,0,0,0,0,0,0,18,0,0,0,0,18,0,0,0,0,0,0,0,59,2
24,59,0,0,0,0,0,0,0,0,0,0,0,0,0,0,0,0,0,0,0,0,0,0,0,0,0,0,0,0,0,0,0,0,59,24
68,59,0,0,0,0,0,0,0,0,0,0,0,0,0,0,0,0,0,0,0,0,0,0,0,0,0,0,0,0,1,1,1,1,1,69
68,59,0,0,0,0,0,0,0,0,0,0,0,0,0,0,0,0,0,0,0,72,0,0,0,0,0,0,0,0,1,59,59,59,59,69
68,59,0,0,0,0,0,0,0,0,0,0,73,0,0,0,0,0,0,0,0,72,0,0,0,0,0,0,0,0,1,59,59,59,59,69
68,59,0,0,0,0,0,0,0,0,0,0,0,0,0,0,0,0,0,72,72,72,72,72,0,0,18,0,0,0,1,59,59,59,59,69
68,59,0,0,0,0,0,0,0,0,0,0,0,0,0,0,0,0,0,0,0,72,0,0,0,0,0,0,0,0,1,51,59,59,59,69
68,59,0,0,0,0,0,0,0,0,0,0,0,0,0,0,0,0,0,0,0,72,0,0,0,0,0,0,0,0,1,1,1,1,1,69
68,59,0,0,0,0,0,0,0,0,0,0,0,0,0,0,0,0,0,0,0,0,0,0,0,0,0,0,0,0,0,0,0,0,59,69
68,59,0,0,0,0,0,0,0,0,0,0,0,0,0,0,0,0,0,0,0,1,0,2,0,2,0,2,1,0,0,0,0,0,59,69
68,59,0,0,0,0,50,0,0,0,0,0,0,0,0,0,0,0,0,0,0,2,0,0,0,0,0,84,2,83,82,82,82,81,59,69
68,2,2,2,2,2,1,50,0,0,0,0,0,0,0,0,0,0,0,0,0,0,0,0,0,0,0,0,2,59,59,59,59,59,59,69
68,63,63,63,63,63,2,0,0,0,0,0,0,0,0,0,0,0,0,0,0,2,0,0,23,0,0,0,2,59,59,59,59,59,59,69
78,63,63,63,63,63,2,0,0,0,0,0,0,0,0,0,0,0,0,0,0,0,0,0,0,0,50,0,2,59,59,59,59,59,59,78
2,51,63,63,63,63,2,59,59,59,59,59,59,59,59,59,59,59,59,83,82,2,0,0,0,0,0,0,2,82,81,1,1,1,59,2
1,2,69,24,24,24,24,24,24,24,24,24,24,24,68,2,1,1,1,1,2,69,24,24,24,24,24,24,24,24,24,24,24,68,2,1
endlayer

layer
1,65,64,65,64,65,64,65,64,65,64,65,64,65,64,65,64,65,64,65,64,65,64,65,64,65,64,65,64,65,64,65,64,65,64,1
67,0,0,0,0,0,0,0,0,0,0,0,0,0,0,0,0,0,0,0,0,0,0,0,0,0,0,0,0,0,0,0,0,0,0,67
22,0,0,0,0,0,0,0,64,0,0,0,0,0,0,0,0,0,0,0,0,0,22,0,1,65,0,0,64,65,0,0,64,1,0,22
67,0,0,0,0,0,18,18,18,0,0,0,0,0,0,0,0,0,0,0,0,0,67,0,67,0,0,0,0,0,0,0,0,67,0,67
22,0,0,0,0,0,18,0,64,0,0,0,0,0,0,0,0,0,0,0,0,0,22,0,0,0,0,0,0,0,0,0,0,0,0,22
67,0,0,0,0,0,18,17,18,0,0,0,0,0,0,0,0,0,0,0,0,0,67,0,22,0,0,0,0,0,0,0,0,22,0,67
22,0,0,0,0,0,0,0,64,0,0,0,0,0,0,0,0,0,0,0,0,0,22,0,67,0,0,0,0,0,0,0,0,67,0,22
67,0,0,64,22,65,0,0,18,0,0,0,0,0,0,0,0,0,0,0,0,0,67,0,0,0,0,0,0,0,0,0,0,0,0,67
22,0,1,1,14,1,1,0,64,0,0,0,0,0,0,0,0,0,0,0,0,0,22,0,22,0,0,0,0,0,0,0,0,22,0,22
67,0,12,85,85,85,12,0,18,0,0,0,0,0,0,0,0,0,0,0,0,0,67,0,1,65,0,0,64,65,0,0,64,1,0,67
22,0,12,85,85,85,12,0,64,0,0,0,0,0,0,0,0,0,0,0,0,0,22,0,0,0,0,0,0,0,0,0,0,0,0,22
67,0,12,85,85,85,12,0,18,0,0,0,0,0,0,0,0,0,0,0,0,0,1,65,64,65,64,65,64,65,64,65,64,65,0,67
22,0,12,85,85,85,12,0,64,0,0,0,0,0,0,0,0,0,0,0,0,0,0,0,0,0,0,0,0,0,0,0,0,0,0,22
67,0,1,12,12,12,1,0,18,0,0,0,0,0,0,0,0,0,0,0,0,0,0,0,0,0,0,0,0,0,0,0,0,0,0,67
22,0,0,0,0,0,0,0,64,0,0,0,0,0,0,0,0,0,0,0,0,0,0,0,0,0,0,0,0,0,0,0,0,0,0,22
67,0,65,64,65,64,65,64,1,0,0,0,0,0,0,0,0,0,0,0,0,0,0,0,0,0,0,0,0,0,0,0,0,0,0,67
22,0,0,0,0,0,0,0,0,0,0,0,0,0,0,0,0,0,0,0,0,86,0,0,0,0,0,0,0,0,0,0,0,0,0,22
67,0,0,0,0,0,0,0,0,0,0,0,0,0,0,0,0,0,0,0,0,0,0,0,0,0,0,0,0,0,0,0,0,0,0,67
22,0,0,0,0,0,0,0,0,0,0,0,0,0,0,0,0,0,0,0,0,0,0,0,0,0,0,0,0,0,0,0,0,0,0,22
67,0,0,0,0,0,0,0,0,0,0,0,0,0,0,0,0,0,0,0,0,0,0,0,0,0,0,0,0,0,0,0,0,0,0,67
22,0,0,0,0,0,0,0,0,0,0,0,0,0,0,0,0,86,0,0,0,18,0,0,0,86,18,0,0,0,0,0,0,0,0,22
67,0,0,0,0,0,0,0,0,0,0,0,0,0,0,0,0,0,0,0,0,0,0,0,0,0,0,0,0,0,0,0,0,0,0,67
22,0,0,0,0,0,0,0,0,0,0,0,0,0,0,0,0,0,0,0,0,0,0,0,0,0,0,0,0,0,18,18,18,18,0,22
67,0,0,0,0,0,0,0,0,0,0,0,0,0,0,0,0,0,0,0,0,0,0,0,0,0,72,0,0,0,18,0,0,0,0,67
22,0,0,0,0,0,0,0,0,0,0,0,73,0,0,0,0,0,0,0,0,86,0,0,0,0,72,0,0,0,18,0,0,0,0,22
67,0,0,0,0,0,0,0,0,0,0,0,0,0,0,0,0,0,0,0,0,0,0,0,86,86,18,72,72,0,18,0,0,0,0,67
22,0,0,0,0,0,0,0,0,0,0,0,0,0,0,0,0,0,0,0,0,0,0,0,0,0,86,0,0,0,18,0,0,0,0,22
67,0,0,0,0,0,0,0,0,0,0,0,0,0,0,0,0,0,0,0,0,0,0,0,0,0,72,0,0,0,18,18,18,18,0,67
22,0,0,0,0,0,0,0,0,0,0,0,0,0,0,0,0,0,0,0,0,0,59,0,59,0,59,0,0,0,0,0,0,0,0,22
67,0,0,0,0,0,0,0,0,0,0,0,0,0,0,0,0,0,0,0,0,1,1,1,1,1,1,1,1,0,0,0,0,0,0,67
22,0,0,0,0,0,0,0,0,0,0,0,0,0,0,0,0,0,0,0,0,1,63,63,63,63,63,84,1,0,59,59,59,0,0,22
67,0,65,64,65,64,1,0,0,0,0,0,0,0,0,0,0,0,0,0,59,1,63,63,63,63,63,63,1,0,0,0,0,0,0,67
22,0,0,0,0,0,67,0,0,0,0,0,0,0,0,0,0,0,0,0,0,1,63,63,63,63,63,63,1,0,0,0,0,0,0,22
67,0,0,0,0,0,22,0,0,0,0,0,0,0,0,0,0,0,0,0,59,1,63,63,63,63,63,63,1,0,0,0,0,0,0,67
22,87,0,0,0,0,0,0,0,0,0,0,0,0,0,0,0,0,0,0,83,1,63,63,63,63,63,63,1,81,0,1,1,1,0,22
1,65,64,65,64,65,64,65,64,65,64,65,64,65,64,65,64,65,64,65,64,1,1,1,1,1,1,1,1,65,64,65,64,65,64,1
endlayer

layer
50,0,0,0,0,0,0,0,0,0,0,0,0,0,0,0,0,0,0,0,0,0,0,0,0,0,0,0,0,0,0,0,0,0,0,50
0,0,0,0,0,0,0,0,0,0,0,0,0,0,0,0,0,0,0,0,0,0,0,0,0,0,0,0,0,0,0,0,0,0,0,0
0,0,0,0,0,0,0,0,0,0,0,0,0,0,0,0,0,0,0,0,0,0,0,0,1,18,0,0,18,18,0,0,18,1,0,0
0,0,0,0,0,0,18,0,18,0,0,0,0,0,0,0,0,0,0,0,0,0,0,0,18,0,0,0,0,0,0,0,0,18,0,0
0,0,0,0,0,0,50,0,0,0,0,0,0,0,0,0,0,0,0,0,0,0,0,0,0,0,0,0,0,0,0,0,0,0,0,0
0,0,0,0,0,0,18,0,18,0,0,0,0,0,0,0,0,0,0,0,0,0,0,0,18,0,0,0,0,0,0,0,0,18,0,0
0,0,0,0,0,0,0,0,0,0,0,0,0,0,0,0,0,0,0,0,0,0,0,0,18,0,0,0,0,0,0,0,0,18,0,0
0,0,0,0,0,0,0,0,0,0,0,0,0,0,0,0,0,0,0,0,0,0,0,0,0,0,0,0,0,0,0,0,0,0,0,0
0,0,50,0,0,0,50,0,0,0,0,0,0,0,0,0,0,0,0,0,0,0,0,0,18,0,0,0,0,0,0,0,0,18,0,0
0,0,0,88,88,88,0,0,0,0,0,0,0,0,0,0,0,0,0,0,0,0,0,0,1,18,0,0,18,18,0,0,18,1,0,0
0,0,0,88,88,88,0,0,0,0,0,0,0,0,0,0,0,0,0,0,0,0,0,0,0,0,0,0,0,0,0,0,0,0,0,0
0,0,0,88,88,88,0,0,0,0,0,0,0,0,0,0,0,0,0,0,0,0,50,0,0,0,0,0,0,0,0,0,0,0,0,0
0,0,0,88,88,88,0,0,0,0,0,0,0,0,0,0,0,0,0,0,0,0,0,0,0,0,0,0,0,0,0,0,0,0,0,0
0,0,50,0,0,0,50,0,0,0,0,0,0,0,0,0,0,0,0,0,0,0,0,0,0,0,0,0,0,0,0,0,0,0,0,0
0,0,0,0,0,0,0,0,0,0,0,0,0,0,0,0,0,0,0,0,0,0,0,0,0,0,0,0,0,0,0,0,0,0,0,0
0,0,0,0,0,0,0,0,0,0,0,0,0,0,0,0,0,0,0,0,0,0,0,0,0,0,0,0,0,0,0,0,0,0,0,0
0,0,0,0,0,0,0,0,0,0,0,0,0,0,0,0,0,0,0,0,0,0,0,0,0,0,0,0,0,0,0,0,0,0,0,0
0,0,0,0,0,0,0,0,0,0,0,0,0,0,0,0,0,0,0,0,0,86,0,0,0,0,0,0,0,0,0,0,0,0,0,0
0,0,0,0,0,0,0,0,0,0,0,0,0,0,0,0,0,0,0,0,0,86,0,0,0,0,0,0,0,0,0,0,0,0,0,0
0,0,0,0,0,0,0,0,0,0,0,0,0,0,0,0,0,0,0,0,0,72,0,0,0,0,0,0,0,0,0,0,0,0,0,0
0,0,0,0,0,0,0,0,0,0,0,0,0,0,0,0,0,0,86,86,72,18,72,86,86,0,18,0,0,0,0,0,0,0,0,0
0,0,0,0,0,0,0,0,0,0,0,0,0,0,0,0,0,0,0,0,0,72,0,0,0,0,0,0,0,0,0,0,0,0,0,0
0,0,0,0,0,0,0,0,0,0,0,0,0,0,0,0,0,0,0,0,0,86,0,0,0,0,0,0,0,0,18,0,0,18,0,0
0,0,0,0,0,0,0,0,0,0,0,0,0,0,0,0,0,0,0,0,0,86,0,0,0,0,0,0,0,0,0,0,0,0,0,0
0,0,0,0,0,0,0,0,0,0,0,0,14,0,0,0,0,0,0,0,0,0,0,0,0,0,72,0,0,0,0,0,0,0,0,0
0,0,0,0,0,0,0,0,0,0,0,0,0,0,0,0,0,0,0,0,0,0,0,0,0,86,86,72,0,0,0,0,0,0,0,0
0,0,0,0,0,0,0,0,0,0,0,0,0,0,0,0,0,0,0,0,0,0,0,0,0,0,86,0,0,0,0,0,0,0,0,0
0,0,0,0,0,0,0,0,0,0,0,0,0,0,0,0,0,0,0,0,0,0,0,0,0,0,0,0,0,0,18,0,0,18,0,0
0,0,0,0,0,0,0,0,0,0,0,0,0,0,0,0,0,0,0,0,0,0,0,0,0,0,0,0,0,0,0,0,0,0,0,0
0,0,0,0,0,0,0,0,0,0,0,0,0,0,0,0,0,0,0,0,0,1,65,64,65,64,65,64,1,0,0,0,0,0,0,0
0,0,0,0,0,0,0,0,0,0,0,0,0,0,0,0,0,0,0,0,0,67,0,0,0,0,0,89,67,0,0,0,0,0,0,0
0,0,0,0,0,0,0,0,0,0,0,0,0,0,0,0,0,0,0,0,0,22,0,0,0,0,0,0,22,0,0,0,0,0,0,0
0,0,0,0,0,0,0,0,0,0,0,0,0,0,0,0,0,0,0,0,0,67,0,0,0,0,0,0,67,0,0,0,0,0,0,0
0,0,0,0,0,0,0,0,0,0,0,0,0,0,0,0,0,0,0,0,0,22,0,0,0,0,0,0,22,0,0,0,0,0,0,0
0,0,0,0,0,0,0,0,0,0,0,0,0,0,0,0,0,0,0,0,0,0,0,0,0,0,0,0,0,0,0,64,1,65,0,0
50,0,0,0,0,0,0,0,0,0,0,0,0,0,0,0,0,0,0,0,0,65,64,65,64,65,64,65,64,0,0,0,0,0,0,50
endlayer

layer
0,0,0,0,0,0,0,0,0,0,0,0,0,0,0,0,0,0,0,0,0,0,0,0,0,0,0,0,0,0,0,0,0,0,0,0
0,0,0,0,0,0,0,0,0,0,0,0,0,0,0,0,0,0,0,0,0,0,0,0,0,0,0,0,18,18,0,0,0,0,0,0
0,0,0,0,0,0,0,0,0,0,0,0,0,0,0,0,0,0,0,0,0,0,0,0,1,18,0,0,18,18,0,0,18,1,0,0
0,0,0,0,0,56,18,18,18,56,0,0,0,0,0,0,0,0,0,0,0,0,0,0,18,18,0,0,0,0,0,0,18,18,0,0
0,0,0,0,0,56,18,18,18,56,0,0,0,0,0,0,0,0,0,0,0,0,0,0,0,0,0,0,0,0,0,0,0,0,0,0
0,0,0,0,0,56,18,18,18,56,0,0,0,0,0,0,0,0,0,0,0,0,0,18,18,0,0,0,0,0,0,0,0,18,18,0
0,0,0,0,0,0,0,0,0,0,0,0,0,0,0,0,0,0,0,0,0,0,0,18,18,0,0,0,0,0,0,0,0,18,18,0
0,0,0,0,0,0,0,0,0,0,0,0,0,0,0,0,0,0,0,0,0,0,0,0,0,0,0,0,0,0,0,0,0,0,0,0
0,0,0,0,0,0,0,0,0,0,0,0,0,0,0,0,0,0,0,0,0,0,0,0,18,18,0,0,0,0,0,0,18,18,0,0
0,0,0,0,0,0,0,0,0,0,0,0,0,0,0,0,0,0,0,0,0,0,0,0,1,18,0,0,18,18,0,0,18,1,0,0
0,0,0,0,0,0,0,0,0,0,0,0,0,0,0,0,0,0,0,0,0,0,0,0,0,0,0,0,18,18,0,0,0,0,0,0
0,0,0,0,0,0,0,0,0,0,0,0,0,0,0,0,0,0,0,0,0,0,0,0,0,0,0,0,0,0,0,0,0,0,0,0
0,0,0,0,0,0,0,0,0,0,0,0,0,0,0,0,0,0,0,0,0,0,0,0,0,0,0,0,0,0,0,0,0,0,0,0
0,0,0,0,0,0,0,0,0,0,0,0,0,0,0,0,0,0,0,0,0,0,0,0,0,0,0,0,0,0,0,0,0,0,0,0
0,0,0,0,0,0,0,0,0,0,0,0,0,0,0,0,0,0,0,0,0,0,0,0,0,0,0,0,0,0,0,0,0,0,0,0
0,0,0,0,0,0,0,0,0,0,0,0,0,0,0,0,0,0,0,0,0,0,0,0,0,0,0,0,0,0,0,0,0,0,0,0
0,0,0,0,0,0,0,0,0,0,0,0,0,0,0,0,0,0,0,0,0,0,0,0,0,0,0,0,0,0,0,0,0,0,0,0
0,0,0,0,0,0,0,0,0,0,0,0,0,0,0,0,0,0,0,0,0,0,0,0,0,0,0,0,0,0,0,0,0,0,0,0
0,0,0,0,0,0,0,0,0,0,0,0,0,0,0,0,0,0,0,0,0,0,0,0,0,0,0,0,0,0,0,0,0,0,0,0
0,0,0,0,0,0,0,0,0,0,0,0,0,0,0,0,0,0,0,0,0,72,0,0,0,0,0,0,0,0,0,0,0,0,0,0
0,0,0,0,0,0,0,0,0,0,0,0,0,0,0,0,0,0,0,0,72,72,72,0,0,0,18,0,0,0,0,0,0,0,0,0
0,0,0,0,0,0,0,0,0,0,0,0,0,0,0,0,0,0,0,0,0,72,0,0,0,0,0,0,0,18,56,56,56,56,18,0
0,0,0,0,0,0,0,0,0,0,0,0,0,0,0,0,0,0,0,0,0,0,0,0,0,0,0,0,0,56,18,18,18,18,56,0
0,0,0,0,0,0,0,0,0,0,0,0,0,0,0,0,0,0,0,0,0,0,0,0,0,0,0,0,0,56,18,18,18,18,56,0
0,0,0,0,0,0,0,0,0,0,0,0,0,0,0,0,0,0,0,0,0,0,0,0,0,0,0,0,0,56,18,18,18,18,56,0
0,0,0,0,0,0,0,0,0,0,0,0,0,0,0,0,0,0,0,0,0,0,0,0,0,0,0,0,0,56,18,18,18,18,56,0
0,0,0,0,0,0,0,0,0,0,0,0,0,0,0,0,0,0,0,0,0,0,0,0,0,0,0,0,0,56,18,18,18,18,56,0
0,0,0,0,0,0,0,0,0,0,0,0,0,0,0,0,0,0,0,0,0,0,0,0,0,0,0,0,0,56,18,18,18,18,56,0
0,0,0,0,0,0,0,0,0,0,0,0,0,0,0,0,0,0,0,0,0,0,0,0,0,0,0,0,0,18,56,56,56,56,18,0
0,0,0,0,0,0,0,0,0,0,0,0,0,0,0,0,0,0,0,0,0,50,0,0,0,0,0,0,50,0,0,0,0,0,0,0
0,0,0,0,0,0,0,0,0,0,0,0,0,0,0,0,0,0,0,0,0,0,0,0,0,0,0,0,0,0,0,0,0,0,0,0
0,0,0,0,0,0,0,0,0,0,0,0,0,0,0,0,0,0,0,0,0,0,0,0,0,0,0,0,0,0,0,0,0,0,0,0
0,0,0,0,0,0,0,0,0,0,0,0,0,0,0,0,0,0,0,0,0,0,0,0,0,0,0,0,0,0,0,0,0,0,0,0
0,0,0,0,0,0,0,0,0,0,0,0,0,0,0,0,0,0,0,0,0,0,0,0,0,0,0,0,0,0,0,0,0,0,0,0
0,0,0,0,0,0,0,0,0,0,0,0,0,0,0,0,0,0,0,0,0,0,0,0,0,0,0,0,0,0,0,0,1,0,0,0
0,0,0,0,0,0,0,0,0,0,0,0,0,0,0,0,0,0,0,0,0,0,0,0,0,0,0,0,0,0,0,0,0,0,0,0
endlayer

layer
0,0,0,0,0,0,0,0,0,0,0,0,0,0,0,0,0,0,0,0,0,0,0,0,0,0,0,0,0,0,0,0,0,0,0,0
0,0,0,0,0,0,0,0,0,0,0,0,0,0,0,0,0,0,0,0,0,0,0,0,0,0,0,0,50,50,0,0,0,0,0,0
0,0,0,0,0,0,0,0,0,0,0,0,0,0,0,0,0,0,0,0,0,0,0,0,1,69,0,0,68,69,0,0,68,1,0,0
0,0,0,0,0,0,23,23,23,0,0,0,0,0,0,0,0,0,0,0,0,0,0,0,24,50,0,0,0,0,0,0,50,24,0,0
0,0,0,0,0,0,23,23,23,0,0,0,0,0,0,0,0,0,0,0,0,0,0,0,0,0,0,0,0,0,0,0,0,0,0,0
0,0,0,0,0,0,23,23,23,0,0,0,0,0,0,0,0,0,0,0,0,0,0,50,78,0,0,0,0,0,0,0,0,78,50,0
0,0,0,0,0,0,0,0,0,0,0,0,0,0,0,0,0,0,0,0,0,0,0,50,24,0,0,0,0,0,0,0,0,24,50,0
0,0,0,0,0,0,0,0,0,0,0,0,0,0,0,0,0,0,0,0,0,0,0,0,0,0,0,0,0,0,0,0,0,0,0,0
0,0,0,0,0,0,0,0,0,0,0,0,0,0,0,0,0,0,0,0,0,0,0,0,78,50,0,0,0,0,0,0,50,78,0,0
0,0,0,0,0,0,0,0,0,0,0,0,0,0,0,0,0,0,0,0,0,0,0,0,1,69,0,0,68,69,0,0,68,1,0,0
0,0,0,0,0,0,0,0,0,0,0,0,0,0,0,0,0,0,0,0,0,0,0,0,0,0,0,0,50,50,0,0,0,0,0,0
0,0,0,0,0,0,0,0,0,0,0,0,0,0,0,0,0,0,0,0,0,0,0,0,0,0,0,0,0,0,0,0,0,0,0,0
0,0,0,0,0,0,0,0,0,0,0,0,0,0,0,0,0,0,0,0,0,0,0,0,0,0,0,0,0,0,0,0,0,0,0,0
0,0,0,0,0,0,0,0,0,0,0,0,0,0,0,0,0,0,0,0,0,0,0,0,0,0,0,0,0,0,0,0,0,0,0,0
0,0,0,0,0,0,0,0,0,0,0,0,0,0,0,0,0,0,0,0,0,0,0,0,0,0,0,0,0,0,0,0,0,0,0,0
0,0,0,0,0,0,0,0,0,0,0,0,0,0,0,0,0,0,0,0,0,0,0,0,0,0,72,0,0,0,0,0,0,0,0,0
0,0,0,0,0,0,0,0,0,0,0,0,0,0,0,0,0,0,0,0,0,0,0,0,0,0,72,0,0,0,0,0,0,0,0,0
0,0,0,0,0,0,0,0,0,0,0,0,0,0,0,0,0,0,0,0,0,0,0,0,0,0,72,0,0,0,0,0,0,0,0,0
0,0,0,0,0,0,0,0,0,0,0,0,0,0,0,0,0,0,0,0,0,0,0,0,0,0,0,0,0,0,0,0,0,0,0,0
0,0,0,0,0,0,0,0,0,0,0,0,0,0,0,0,0,0,0,0,0,0,0,0,0,0,0,0,0,0,0,0,0,0,0,0
0,0,0,0,0,0,0,0,0,0,0,0,0,0,0,0,0,0,0,0,0,72,72,72,0,0,18,0,0,72,72,72,0,0,0,0
0,0,0,0,0,0,0,0,0,0,0,0,0,0,0,0,0,0,0,0,0,0,0,0,0,0,0,0,0,50,0,0,0,0,50,0
0,0,0,0,0,0,0,0,0,0,0,0,0,0,0,0,0,0,0,0,0,0,0,0,0,0,0,0,0,0,23,23,23,23,0,0
0,0,0,0,0,0,0,0,0,0,0,0,0,0,0,0,0,0,0,0,0,0,0,0,0,0,72,0,0,0,23,23,23,23,0,0
0,0,0,0,0,0,0,0,0,0,0,0,0,0,0,0,0,0,0,0,0,0,0,0,0,0,72,0,0,0,23,23,23,23,0,0
0,0,0,0,0,0,0,0,0,0,0,0,0,0,0,0,0,0,0,0,0,0,0,0,0,0,72,0,0,0,23,23,23,23,0,0
0,0,0,0,0,0,0,0,0,0,0,0,0,0,0,0,0,0,0,0,0,0,0,0,0,0,0,0,0,0,23,23,23,23,0,0
0,0,0,0,0,0,0,0,0,0,0,0,0,0,0,0,0,0,0,0,0,0,0,0,0,0,0,0,0,0,23,23,23,23,0,0
0,0,0,0,0,0,0,0,0,0,0,0,0,0,0,0,0,0,0,0,0,0,0,0,0,0,0,0,0,50,0,0,0,0,50,0
0,0,0,0,0,0,0,0,0,0,0,0,0,0,0,0,0,0,0,0,0,0,0,0,0,0,0,0,0,0,0,0,0,0,0,0
0,0,0,0,0,0,0,0,0,0,0,0,0,0,0,0,0,0,0,0,0,0,0,0,0,0,0,0,0,0,0,0,0,0,0,0
0,0,0,0,0,0,0,0,0,0,0,0,0,0,0,0,0,0,0,0,0,0,0,0,0,0,0,0,0,0,0,0,0,0,0,0
0,0,0,0,0,0,0,0,0,0,0,0,0,0,0,0,0,0,0,0,0,0,0,0,0,0,0,0,0,0,0,0,0,0,0,0
0,0,0,0,0,0,0,0,0,0,0,0,0,0,0,0,0,0,0,0,0,0,0,0,0,0,0,0,0,0,0,0,0,0,0,0
0,0,0,0,0,0,0,0,0,0,0,0,0,0,0,0,0,0,0,0,0,0,0,0,0,0,0,0,0,0,0,0,19,0,0,0
0,0,0,0,0,0,0,0,0,0,0,0,0,0,0,0,0,0,0,0,0,0,0,0,0,0,0,0,0,0,0,0,0,0,0,0
endlayer

layer
0,0,0,0,0,0,0,0,0,0,0,0,0,0,0,0,0,0,0,0,0,0,0,0,0,0,0,0,0,0,0,0,0,0,0,0
0,0,0,0,0,0,0,0,0,0,0,0,0,0,0,0,0,0,0,0,0,0,0,36,36,36,36,36,36,36,36,36,36,36,36,0
0,0,0,0,0,0,0,0,0,0,0,0,0,0,0,0,0,0,0,0,0,0,0,36,91,91,91,91,91,91,91,91,91,90,36,0
0,0,0,0,0,0,0,0,0,0,0,0,0,0,0,0,0,0,0,0,0,0,0,36,93,92,92,92,92,92,92,92,92,90,36,0
0,0,0,0,0,0,0,0,0,0,0,0,0,0,0,0,0,0,0,0,0,0,0,36,93,92,0,0,0,0,0,0,92,90,36,0
0,0,0,0,0,0,0,0,0,0,0,0,0,0,0,0,0,0,0,0,0,0,0,36,93,92,0,0,0,0,0,0,92,90,36,0
0,0,0,0,0,0,0,0,0,0,0,0,0,0,0,0,0,0,0,0,0,0,0,36,93,92,0,0,0,0,0,0,92,90,36,0
0,0,0,0,0,0,0,0,0,0,0,0,0,0,0,0,0,0,0,0,0,0,0,36,93,92,0,0,0,0,0,0,92,90,36,0
0,0,0,0,0,0,0,0,0,0,0,0,0,0,0,0,0,0,0,0,0,0,0,36,93,92,92,92,92,92,92,92,92,90,36,0
0,0,0,0,0,0,0,0,0,0,0,0,0,0,0,0,0,0,0,0,0,0,0,36,93,94,94,94,94,94,94,94,94,94,36,0
0,0,0,0,0,0,0,0,0,0,0,0,0,0,0,0,0,0,0,0,0,0,0,36,36,36,36,36,36,36,36,36,36,36,36,0
0,0,0,0,0,0,0,0,0,0,0,0,0,0,0,0,0,0,0,0,0,0,0,0,0,0,0,0,0,0,0,0,0,0,0,0
0,0,0,0,0,0,0,0,0,0,0,0,0,0,0,0,0,0,0,0,0,0,0,0,0,0,0,0,0,0,0,0,0,0,0,0
0,0,0,0,0,0,0,0,0,0,0,0,0,0,0,0,0,0,0,0,0,0,0,0,0,0,0,0,0,0,0,0,0,0,0,0
0,0,0,0,0,0,0,0,0,0,0,0,0,0,0,0,0,0,0,0,0,0,0,0,0,0,0,0,0,0,0,0,0,0,0,0
0,0,0,0,0,0,0,0,0,0,0,0,0,0,0,0,0,0,0,0,0,0,0,0,0,0,0,0,0,0,0,0,0,0,0,0
0,0,0,0,0,0,0,0,0,0,0,0,0,0,0,0,0,0,0,0,0,0,0,0,0,0,0,0,0,0,0,0,0,0,0,0
0,0,0,0,0,0,0,0,0,0,0,0,0,0,0,0,0,0,0,0,0,0,0,0,0,0,72,0,0,0,0,0,0,0,0,0
0,0,0,0,0,0,0,0,0,0,0,0,0,0,0,0,0,0,0,0,0,0,0,0,0,0,72,0,0,0,0,0,0,0,0,0
0,0,0,0,0,0,0,0,0,0,0,0,0,0,0,0,0,0,0,0,0,0,0,0,0,0,72,0,0,0,0,0,0,0,0,0
0,0,0,0,0,0,0,0,0,0,0,0,0,0,0,0,0,0,0,0,0,0,0,72,72,72,72,72,72,72,0,0,0,0,0,0
0,0,0,0,0,0,0,0,0,0,0,0,0,0,0,0,0,0,0,0,0,0,0,0,0,0,72,0,0,0,0,0,0,0,0,0
0,0,0,0,0,0,0,0,0,0,0,0,0,0,0,0,0,0,0,0,0,0,0,0,0,0,72,0,0,0,0,0,0,0,0,0
0,0,0,0,0,0,0,0,0,0,0,0,0,0,0,0,0,0,0,0,0,0,0,0,0,0,72,0,0,0,0,0,0,0,0,0
0,0,0,0,0,0,0,0,0,0,0,0,0,0,0,0,0,0,0,0,0,0,0,0,0,0,0,0,0,0,0,0,0,0,0,0
0,0,0,0,0,0,0,0,0,0,0,0,0,0,0,0,0,0,0,0,0,0,0,0,0,0,0,0,0,0,0,0,0,0,0,0
0,0,0,0,0,0,0,0,0,0,0,0,0,0,0,0,0,0,0,0,0,0,0,0,0,0,0,0,0,0,0,0,0,0,0,0
0,0,0,0,0,0,0,0,0,0,0,0,0,0,0,0,0,0,0,0,0,0,0,0,0,0,0,0,0,0,0,0,0,0,0,0
0,0,0,0,0,0,0,0,0,0,0,0,0,0,0,0,0,0,0,0,0,0,0,0,0,0,0,0,0,0,0,0,0,0,0,0
0,0,0,0,0,0,0,0,0,0,0,0,0,0,0,0,0,0,0,0,0,0,0,0,0,0,0,0,0,0,0,0,0,0,0,0
0,0,0,0,0,0,0,0,0,0,0,0,0,0,0,0,0,0,0,0,0,0,0,0,0,0,0,0,0,0,0,0,0,0,0,0
0,0,0,0,0,0,0,0,0,0,0,0,0,0,0,0,0,0,0,0,0,0,0,0,0,0,0,0,0,0,0,0,0,0,0,0
0,0,0,0,0,0,0,0,0,0,0,0,0,0,0,0,0,0,0,0,0,0,0,0,0,0,0,0,0,0,0,0,0,0,0,0
0,0,0,0,0,0,0,0,0,0,0,0,0,0,0,0,0,0,0,0,0,0,0,0,0,0,0,0,0,0,0,0,0,0,0,0
0,0,0,0,0,0,0,0,0,0,0,0,0,0,0,0,0,0,0,0,0,0,0,0,0,0,0,0,0,0,0,0,0,0,0,0
0,0,0,0,0,0,0,0,0,0,0,0,0,0,0,0,0,0,0,0,0,0,0,0,0,0,0,0,0,0,0,0,0,0,0,0
endlayer

layer
0,0,0,0,0,0,0,0,0,0,0,0,0,0,0,0,0,0,0,0,0,0,0,0,0,0,0,0,0,0,0,0,0,0,0,0
0,0,0,0,0,0,0,0,0,0,0,0,0,0,0,0,0,0,0,0,0,0,0,0,0,0,0,0,0,0,0,0,0,0,0,0
0,0,0,0,0,0,0,0,0,0,0,0,0,0,0,0,0,0,0,0,0,0,0,0,0,0,0,0,0,0,0,0,0,0,0,0
0,0,0,0,0,0,0,0,0,0,0,0,0,0,0,0,0,0,0,0,0,0,0,0,0,36,36,36,36,36,36,36,36,0,0,0
0,0,0,0,0,0,0,0,0,0,0,0,0,0,0,0,0,0,0,0,0,0,0,0,0,36,36,36,36,36,36,36,36,0,0,0
0,0,0,0,0,0,0,0,0,0,0,0,0,0,0,0,0,0,0,0,0,0,0,0,0,36,36,12,12,12,12,36,36,0,0,0
0,0,0,0,0,0,0,0,0,0,0,0,0,0,0,0,0,0,0,0,0,0,0,0,0,36,36,12,12,12,12,36,36,0,0,0
0,0,0,0,0,0,0,0,0,0,0,0,0,0,0,0,0,0,0,0,0,0,0,0,0,36,36,36,36,36,36,36,36,0,0,0
0,0,0,0,0,0,0,0,0,0,0,0,0,0,0,0,0,0,0,0,0,0,0,0,0,36,36,36,36,36,36,36,36,0,0,0
0,0,0,0,0,0,0,0,0,0,0,0,0,0,0,0,0,0,0,0,0,0,0,0,0,0,0,0,0,0,0,0,0,0,0,0
0,0,0,0,0,0,0,0,0,0,0,0,0,0,0,0,0,0,0,0,0,0,0,0,0,0,0,0,0,0,0,0,0,0,0,0
0,0,0,0,0,0,0,0,0,0,0,0,0,0,0,0,0,0,0,0,0,0,0,0,0,0,0,0,0,0,0,0,0,0,0,0
0,0,0,0,0,0,0,0,0,0,0,0,0,0,0,0,0,0,0,0,0,0,0,0,0,0,0,0,0,0,0,0,0,0,0,0
0,0,0,0,0,0,0,0,0,0,0,0,0,0,0,0,0,0,0,0,0,0,0,0,0,0,0,0,0,0,0,0,0,0,0,0
0,0,0,0,0,0,0,0,0,0,0,0,0,0,0,0,0,0,0,0,0,0,0,0,0,0,0,0,0,0,0,0,0,0,0,0
0,0,0,0,0,0,0,0,0,0,0,0,0,0,0,0,0,0,0,0,0,0,0,0,0,0,0,0,0,0,0,0,0,0,0,0
0,0,0,0,0,0,0,0,0,0,0,0,0,0,0,0,0,0,0,0,0,0,0,0,0,0,0,0,0,0,0,0,0,0,0,0
0,0,0,0,0,0,0,0,0,0,0,0,0,0,0,0,0,0,0,0,0,0,0,0,0,0,0,0,0,0,0,0,0,0,0,0
0,0,0,0,0,0,0,0,0,0,0,0,0,0,0,0,0,0,0,0,0,0,0,0,0,0,0,0,0,0,0,0,0,0,0,0
0,0,0,0,0,0,0,0,0,0,0,0,0,0,0,0,0,0,0,0,0,0,0,0,0,0,0,0,0,0,0,0,0,0,0,0
0,0,0,0,0,0,0,0,0,0,0,0,0,0,0,0,0,0,0,0,0,0,0,0,0,0,0,0,0,0,0,0,0,0,0,0
0,0,0,0,0,0,0,0,0,0,0,0,0,0,0,0,0,0,0,0,0,0,0,0,0,0,0,0,0,0,0,0,0,0,0,0
0,0,0,0,0,0,0,0,0,0,0,0,0,0,0,0,0,0,0,0,0,0,0,0,0,0,0,0,0,0,0,0,0,0,0,0
0,0,0,0,0,0,0,0,0,0,0,0,0,0,0,0,0,0,0,0,0,0,0,0,0,0,0,0,0,0,0,0,0,0,0,0
0,0,0,0,0,0,0,0,0,0,0,0,0,0,0,0,0,0,0,0,0,0,0,0,0,0,0,0,0,0,0,0,0,0,0,0
0,0,0,0,0,0,0,0,0,0,0,0,0,0,0,0,0,0,0,0,0,0,0,0,0,0,0,0,0,0,0,0,0,0,0,0
0,0,0,0,0,0,0,0,0,0,0,0,0,0,0,0,0,0,0,0,0,0,0,0,0,0,0,0,0,0,0,0,0,0,0,0
0,0,0,0,0,0,0,0,0,0,0,0,0,0,0,0,0,0,0,0,0,0,0,0,0,0,0,0,0,0,0,0,0,0,0,0
0,0,0,0,0,0,0,0,0,0,0,0,0,0,0,0,0,0,0,0,0,0,0,0,0,0,0,0,0,0,0,0,0,0,0,0
0,0,0,0,0,0,0,0,0,0,0,0,0,0,0,0,0,0,0,0,0,0,0,0,0,0,0,0,0,0,0,0,0,0,0,0
0,0,0,0,0,0,0,0,0,0,0,0,0,0,0,0,0,0,0,0,0,0,0,0,0,0,0,0,0,0,0,0,0,0,0,0
0,0,0,0,0,0,0,0,0,0,0,0,0,0,0,0,0,0,0,0,0,0,0,0,0,0,0,0,0,0,0,0,0,0,0,0
0,0,0,0,0,0,0,0,0,0,0,0,0,0,0,0,0,0,0,0,0,0,0,0,0,0,0,0,0,0,0,0,0,0,0,0
0,0,0,0,0,0,0,0,0,0,0,0,0,0,0,0,0,0,0,0,0,0,0,0,0,0,0,0,0,0,0,0,0,0,0,0
0,0,0,0,0,0,0,0,0,0,0,0,0,0,0,0,0,0,0,0,0,0,0,0,0,0,0,0,0,0,0,0,0,0,0,0
0,0,0,0,0,0,0,0,0,0,0,0,0,0,0,0,0,0,0,0,0,0,0,0,0,0,0,0,0,0,0,0,0,0,0,0
endlayer

