# GargoyleStone -- 5 May 2014
# Updated to MC 1.7.10, 13 Oct 2014
# Created by Ruins mod version 12.3 Ingame Parser
# authoring Player: Jordan_Greywolf

biomesToSpawnIn=extreme hills,extreme hills edge,extreme hills m,extreme hills+,extreme hills+ m,twilight forest,twilight clearing,roofed forest

weight=1
embed_into_distance=0
acceptable_target_blocks=
unacceptable_target_blocks=water,flowing_water

dimensions=13,8,9
allowable_overhang=0
max_cut_in=2
cut_in_buffer=1
max_leveling=5
leveling_buffer=1
preserve_water=0
preserve_lava=0
preserve_plants=1

rule1=0,100,minecraft:stonebrick,minecraft:stonebrick-1,minecraft:stonebrick-2

layer
0,0,0,0,0,0,0,0,0
0,0,0,0,1,0,0,0,0
0,0,1,1,1,1,1,0,0
0,0,1,1,1,1,1,0,0
0,0,0,0,0,0,0,0,0
0,0,0,0,0,0,0,0,0
0,0,1,0,0,0,1,0,0
0,0,1,0,0,0,1,0,0
endlayer

layer
0,0,0,0,1,0,0,0,0
0,0,0,0,0,0,0,0,0
0,0,1,1,1,1,1,0,0
0,0,0,1,1,1,0,0,0
0,0,0,0,0,0,0,0,0
0,0,1,0,0,0,1,0,0
0,0,1,0,0,0,1,0,0
0,0,0,0,0,0,0,0,0
endlayer

layer
0,0,0,0,1,0,0,0,0
0,0,0,0,0,0,0,0,0
0,0,1,1,1,1,1,0,0
0,0,1,1,1,1,1,0,0
0,0,0,1,1,0,0,0,0
0,0,1,0,0,0,1,0,0
0,0,0,0,0,0,0,0,0
0,0,0,0,0,0,0,0,0
endlayer

layer
0,0,0,0,1,0,0,0,0
0,0,0,0,0,0,0,0,0
0,0,0,0,1,0,0,0,0
0,0,0,1,1,1,0,0,0
0,0,0,1,1,1,0,0,0
0,0,1,1,1,1,1,0,0
0,0,0,0,0,0,0,0,0
0,0,0,0,0,0,0,0,0
endlayer

layer
0,0,0,0,1,0,0,0,0
0,0,0,0,0,0,0,0,0
0,0,0,0,1,0,0,0,0
0,0,0,0,1,0,0,0,0
0,0,0,1,1,1,0,0,0
0,0,0,1,1,1,0,0,0
0,0,0,0,0,0,0,0,0
0,0,0,0,0,0,0,0,0
endlayer

layer
0,0,1,0,1,0,1,0,0
0,0,0,0,0,0,0,0,0
0,0,0,0,1,0,0,0,0
0,0,0,1,1,1,0,0,0
0,0,0,1,1,1,0,0,0
0,0,0,0,1,0,0,0,0
0,0,0,0,0,0,0,0,0
0,0,0,0,0,0,0,0,0
endlayer

layer
1,0,1,0,0,0,1,0,1
0,0,1,0,0,0,1,0,0
0,0,0,0,0,0,0,0,0
0,0,1,1,1,1,1,0,0
0,0,0,0,1,0,0,0,0
0,0,0,0,1,0,0,0,0
0,0,0,1,1,1,0,0,0
0,0,0,0,1,0,0,0,0
endlayer

layer
1,1,1,0,0,0,1,1,1
0,0,1,0,0,0,1,0,0
0,0,1,0,0,0,1,0,0
0,0,1,0,0,0,1,0,0
0,0,0,0,1,0,0,0,0
0,0,0,1,1,1,0,0,0
0,0,0,1,1,1,0,0,0
0,0,0,0,0,0,0,0,0
endlayer

layer
1,1,1,0,0,0,1,1,1
0,0,1,0,0,0,1,0,0
0,0,1,0,0,0,1,0,0
0,0,0,0,0,0,0,0,0
0,0,0,0,0,0,0,0,0
0,0,0,1,0,1,0,0,0
0,0,0,0,0,0,0,0,0
0,0,0,0,0,0,0,0,0
endlayer

layer
1,1,1,0,0,0,1,1,1
0,0,1,0,0,0,1,0,0
0,0,0,0,0,0,0,0,0
0,0,0,0,0,0,0,0,0
0,0,0,0,0,0,0,0,0
0,0,0,0,0,0,0,0,0
0,0,0,0,0,0,0,0,0
0,0,0,0,0,0,0,0,0
endlayer

layer
0,1,1,0,0,0,1,1,0
0,0,1,0,0,0,1,0,0
0,0,0,0,0,0,0,0,0
0,0,0,0,0,0,0,0,0
0,0,0,0,0,0,0,0,0
0,0,0,0,0,0,0,0,0
0,0,0,0,0,0,0,0,0
0,0,0,0,0,0,0,0,0
endlayer

layer
0,0,0,0,0,0,0,0,0
0,1,1,0,0,0,1,1,0
0,0,0,0,0,0,0,0,0
0,0,0,0,0,0,0,0,0
0,0,0,0,0,0,0,0,0
0,0,0,0,0,0,0,0,0
0,0,0,0,0,0,0,0,0
0,0,0,0,0,0,0,0,0
endlayer

layer
0,0,0,0,0,0,0,0,0
0,0,0,0,0,0,0,0,0
0,0,1,0,0,0,1,0,0
0,0,0,0,0,0,0,0,0
0,0,0,0,0,0,0,0,0
0,0,0,0,0,0,0,0,0
0,0,0,0,0,0,0,0,0
0,0,0,0,0,0,0,0,0
endlayer

