# Vault T-Section
# MC 1.7.10; 12 Nov 2014
# Created by Ruins mod version 14.2 Ingame Parser
# authoring Player: Jordan_Greywolf
# Special Instructions: Place in /templateparser folder.

weight=1
embed_into_distance=0
acceptable_target_blocks=
unacceptable_target_blocks=
dimensions=6,16,12
allowable_overhang=9999
max_leveling=0
leveling_buffer=0
preserve_water=0
preserve_lava=0
preserve_plants=1

# Randomized Stone Brick
rule1=0,100,minecraft:stonebrick,minecraft:stonebrick-1,minecraft:stonebrick-2,minecraft:monster_egg-4

# Cobblestone Floor
rule2=0,100,minecraft:mossy_cobblestone-0

# Barrow Guardian Summoner
rule3=0,100,CommandBlock:/summon Skeleton ~0 ~2 ~0 {Equipment:[{Count:1,id:283,tag:{display:{Name:Rusty Warblade},ench:[{id:16,lvl:9}]}},{Count:1,id:305,tag:{display:{Name:Rusty Boots}}},{Count:1,id:304,tag:{display:{Name:Rusty Leggings}}},{Count:1,id:303,tag:{display:{Name:Rusty Coat}}},{id:397,Damage:2}],CustomName:Barrow Guardian,Attributes:[{Name:generic.followRange,Base:30}],DropChances:[0.5F,0.1F,0.1F,0.1F,0.0F],ActiveEffects:[{Id:12,Amplifier:1,Duration:999999,Ambient:1},{Id:3,Amplifier:1,Duration:999999,Ambient:1},{Id:21,Amplifier:1,Duration:999999,Ambient:1},{Id:14,Amplifier:1,Duration:999999,Ambient:1},{Id:11,Amplifier:1,Duration:999999,Ambient:1},{Id:1,Amplifier:1,Duration:999999,Ambient:1},{Id:5,Amplifier:1,Duration:999999.Ambient:1}],PersistenceRequired:1}:@

# Randomized Skull Placement
rule4=0,100,minecraft:skull-0,minecraft:skull-1,minecraft:skull-2,minecraft:skull-3
rule5=0,100,minecraft:web-0
rule6=0,100,minecraft:stone_brick_stairs-1
rule7=0,100,minecraft:stone_brick_stairs-0
rule8=0,100,minecraft:stone_brick_stairs-2
rule9=0,100,minecraft:cobblestone_wall-0
rule10=0,100,minecraft:stone_brick_stairs-3
rule11=0,100,minecraft:vine-2
rule12=0,100,IInventory;minecraft:trapped_chest;minecraft:paper#4#0#0+minecraft:bone#3#0#1+minecraft:rotten_flesh#3#0#2+minecraft:skull#1#2#3+minecraft:arrow#6#0#4+minecraft:web#3#0#5-2
rule13=0,100,minecraft:vine-8
rule14=0,100,minecraft:stone_brick_stairs-5
rule15=0,100,minecraft:stone_brick_stairs-7
rule16=0,100,minecraft:stone_brick_stairs-6
rule17=0,100,minecraft:stone_brick_stairs-4
rule18=0,100,minecraft:vine-4
rule19=0,100,minecraft:vine-0
rule20=0,100,preserveBlock

# Chiseled Stone
rule21=0,100,minecraft:stonebrick-3

layer
1,1,1,2,2,1,1,1,1,1,1,1
1,1,2,2,2,2,1,1,2,2,2,1
1,1,2,2,2,2,1,1,2,2,2,1
1,1,1,2,2,1,1,1,2,2,2,1
1,1,2,2,2,2,1,1,1,1,1,1
1,1,2,2,2,2,1,1,1,1,1,1
1,1,2,2,2,2,2,2,1,2,2,1
1,3,2,2,2,2,2,2,2,2,2,2
1,3,2,2,2,2,2,2,2,2,2,2
1,1,2,2,2,2,2,2,1,2,2,1
1,1,2,2,2,2,1,1,1,1,1,1
1,1,2,2,2,2,1,1,1,1,1,1
1,1,1,2,2,1,1,1,2,2,2,1
1,1,2,2,2,2,1,1,2,2,2,1
1,1,2,2,2,2,1,1,2,2,2,1
1,1,1,2,2,1,1,1,1,1,1,1
endlayer

layer
1,1,1,0,0,1,1,1,1,1,1,1
1,1,5,0,0,4,1,1,0,0,0,1
1,1,5,0,0,5,1,1,0,0,0,1
1,1,1,0,0,1,1,1,0,0,0,1
1,1,5,0,5,5,1,1,1,1,1,1
1,6,0,0,0,0,1,1,1,1,1,1
1,8,7,5,0,0,0,4,1,0,4,1
1,1,8,0,0,0,0,0,0,0,0,0
1,1,8,0,0,0,0,0,0,0,0,5
1,8,6,5,0,0,0,5,1,4,0,1
1,7,0,0,0,4,1,1,1,1,1,1
1,1,5,5,0,5,1,1,1,1,1,1
1,1,1,0,0,1,1,1,4,5,4,1
1,1,5,0,0,5,1,1,0,0,5,1
1,1,4,0,0,4,1,1,4,0,4,1
1,1,1,0,0,1,1,1,1,1,1,1
endlayer

layer
1,1,9,0,0,9,1,1,6,6,6,1
10,8,0,0,0,0,10,8,0,0,0,10
10,8,0,0,0,0,10,8,0,0,0,10
1,1,9,0,0,9,1,8,0,0,0,10
10,8,11,0,0,11,10,1,7,7,7,1
1,4,0,0,0,0,10,6,1,6,6,1
1,9,0,0,0,0,0,0,9,0,0,9
10,12,0,0,0,0,0,0,0,0,0,0
10,12,0,0,0,0,0,0,0,0,0,0
1,9,0,0,0,0,0,0,9,0,0,9
1,4,0,0,0,0,7,7,1,7,7,1
10,8,5,5,0,13,10,1,6,6,6,1
1,1,9,0,0,9,1,8,5,0,0,10
10,8,0,0,0,0,10,8,0,0,0,10
10,8,0,0,0,0,10,8,5,0,0,10
1,1,9,0,0,9,1,1,7,7,7,1
endlayer

layer
1,1,16,0,5,15,1,1,14,14,14,1
15,16,0,0,0,0,15,16,0,0,0,15
15,16,0,0,0,0,15,16,0,0,0,15
1,1,16,0,0,15,1,16,0,0,0,15
15,16,11,0,0,11,15,1,17,17,17,1
1,0,0,0,0,0,15,14,1,14,14,1
1,9,0,0,0,0,0,0,14,0,0,14
15,0,0,0,0,0,0,0,5,0,0,5
15,0,0,0,0,0,0,0,0,0,0,0
1,9,0,0,0,0,0,0,17,0,0,17
1,0,0,0,0,0,17,17,1,17,17,1
15,16,13,0,0,13,15,1,14,14,14,1
1,1,16,5,5,15,1,16,0,0,5,15
15,16,0,0,0,0,15,16,5,0,0,15
15,16,0,0,0,0,15,16,0,0,0,15
1,1,16,0,0,15,1,1,17,17,17,1
endlayer

layer
1,1,1,16,15,1,1,1,1,1,1,1
1,1,16,0,5,15,1,1,0,0,0,1
1,1,16,5,0,15,1,1,0,0,0,1
1,1,1,16,15,1,1,1,0,0,0,1
1,1,11,0,0,11,1,1,1,1,1,1
1,14,19,0,0,18,1,1,1,1,1,1
1,16,19,0,0,19,11,18,1,14,14,1
1,16,5,0,0,5,0,5,14,5,0,14
1,16,5,5,0,5,5,0,17,5,5,17
1,16,19,0,0,19,13,18,1,17,17,1
1,17,19,0,0,18,1,1,1,1,1,1
1,1,13,0,0,13,1,1,1,1,1,1
1,1,1,16,15,1,1,1,5,0,5,1
1,1,16,0,5,15,1,1,0,0,0,1
1,1,16,5,0,15,1,1,5,0,5,1
1,1,1,16,15,1,1,1,1,1,1,1
endlayer

layer
20,20,1,1,1,1,20,20,1,1,1,20
20,20,1,21,21,1,20,1,1,1,1,1
20,20,1,21,21,1,20,1,1,21,1,1
20,20,1,1,1,1,20,1,1,1,1,1
20,20,1,21,21,1,20,20,1,1,1,20
1,1,1,21,21,1,20,20,20,20,20,20
1,1,1,1,1,1,1,1,1,1,1,1
20,1,1,21,21,1,21,21,1,21,21,1
20,1,1,21,21,1,21,21,1,21,21,1
1,1,1,1,1,1,1,1,1,1,1,1
1,1,1,21,21,1,20,20,20,20,20,20
20,20,1,21,21,1,20,20,1,1,1,20
20,20,1,1,1,1,20,1,1,1,1,1
20,20,1,21,21,1,20,1,1,21,1,1
20,20,1,21,21,1,20,1,1,1,1,1
20,20,1,1,1,1,20,20,1,1,1,20
endlayer

